Workbook

Sheet Take-off
B1: 1900
B2: Take-off distance Beech 1900C | G2: Version
B3: Interpoleringsverktyg för startsträcka från OM-B. | G3: 46290
B4: RWY: | C4: Custom airport
C5: =IFERROR(__xludf.dummyfunction("SUBSTITUTE(IMPORTDATA(""https://aviationweather.gov/api/data/metar?ids="" & LEFT(C4, 4) & ""&format=raw""), ""METAR "", """")"),"ESKM 051820Z AUTO 23007KT 110V280 9999 NCD 15/11 Q0994") -> ESKM 051820Z AUTO 23007KT 110V280 9999 NCD 15/11 Q0994
B6: Wind: | C6: =IFERROR(__xludf.dummyfunction("IF(E6<>"""", E6, IF($G$8, E6, IFERROR(IF(REGEXMATCH(C5, ""\bVRB""), ""000"", VALUE(REGEXEXTRACT(C5, ""\b(\d{3})\d{2,3}(?:G\d{2,3})?(?:KT|MPS)\b""))), ""-"")))"),230) -> 230 | D6: ° | F6: =IF(C24<0, "Tailwind", "") -> Tailwind
B7: Windspeed | C7: =IFERROR(__xludf.dummyfunction("IF(E7<>"""", E7, IF($G$8, E7, IFERROR(VALUE(REGEXEXTRACT(C5, ""\b(?:\d{3}|VRB)(\d{2,3})(?:G\d{2,3})?(?:KT|MPS)\b"")), ""-"")))"),7) -> 7 | D7: kt
B8: Outside air temperature: | C8: =IFERROR(__xludf.dummyfunction("IF(E8<>"""", E8, IF($G$8, E8, IFERROR(VALUE(SUBSTITUTE(REGEXEXTRACT(C5, ""\b(M?\d{2})\/(?:M?\d{2})\b""), ""M"", ""-"")), ""-"")))"),15) -> 15 | D8: °C | F8: Remove manual MET | G8: =FALSE() -> FALSE
B9: QNH | C9: =IFERROR(__xludf.dummyfunction("IF(E9<>"""", E9, IF($G$8, E9, IFERROR(VALUE(REGEXEXTRACT(C5, ""\bQ(\d{4})\b"")), ""-"")))"),994) -> 994 | D9: Hpa
B10: Runway Condition Code | C10: 5 | E10: MANUAL MET -> | F10: REFRESH METAR | G10: =FALSE() -> FALSE
B11: Runway contaminant | C11: Dry snow | I11: BORT
B12: Contaminant depth | C12: 3 | D12: mm | E12: Max: | F12: =VLOOKUP(C11,'Dropdown lists'!B34:G40,5,FALSE()) -> mm
B13: Engine Anti-ice | C13: OFF | E13: Technique | F13: Rolling take off | I13: Engine anti-ice can be disregarded (OFF in calculation) whenever 3300 lbs/ft take-off power can be obtained
B14: Take off mass: | C14: 15800 | D14: Lbs | E14: MTOW=16600 lbs
B15: Airport data (Exapandable)
B16: Treshold elevation: | C16: {=_xlfn.XLOOKUP($C$4, 'Airport data'!$A$5:$A1006, 'Airport data'!$B$5:$B1006)} -> 200 | D16: ft
B17: Runway Slope: | C17: {=_xlfn.XLOOKUP($C$4, 'Airport data'!$A$5:$A1006, 'Airport data'!$G$5:$G1006)} -> 0 | D17: % | F17: + = upphill
B18: RWY Heading: | C18: {=_xlfn.XLOOKUP( $C$4, 'Airport data'!$A$5:$A1006, 'Airport data'!$H$5:$H1006)} -> 120 | D18: °
B19: ASDA: | C19: {=_xlfn.XLOOKUP( $C$4, 'Airport data'!$A$5:$A1006, 'Airport data'!$E$5:$E1006)-10} -> 1990 | D19: m | F19: Req gradient: | G19: {=_xlfn.XLOOKUP( $C$4, 'Airport data'!$A$5:$A1006, 'Airport data'!$I$5:$I1006)} -> 3.3
B20: TORA: | C20: {=_xlfn.XLOOKUP( $C$4, 'Airport data'!$A$5:$A1006, 'Airport data'!$C$5:$C1006)-10} -> 1990 | D20: m
B21: TODA: | C21: {=_xlfn.XLOOKUP( $C$4, 'Airport data'!$A$5:$A1006, 'Airport data'!$D$5:$D1006)-10} -> 1990 | D21: m | E21: TOR | F21: =C35*1.15 -> 1064.8359
B22: LDA: | C22: {=_xlfn.XLOOKUP( $C$4, 'Airport data'!$A$5:$A1006, 'Airport data'!$F$5:$F1006)} -> 2000 | D22: m
B23: Calculated data
B24: Head/Tail wind | C24: ='TAKE OFF Performance FLAPS UP'!D36 -> -2.394141 | D24: Kt | E24: Take-off Distance Factor | F24: {=_xlfn.XLOOKUP('Take-off'!$C$10,'Dropdown lists'!$B$4:$B$9,'Dropdown lists'!$D$4:$D$9)} -> 1.07
B25: Crosswind | C25: =ABS('TAKE OFF Performance FLAPS UP'!C41*C7) -> 6.5778483 | D25: Kt | E25: Limit | F25: {=_xlfn.XLOOKUP(C10, 'Dropdown lists'!$B$4:$B$10, 'Dropdown lists'!$E$4:$E$10)} -> 25
B26: FLAPS: | C26: UP | D26: TAKE-OFF | E26: APP | G26: FULL
B27: Dry Runway (Expandable) | I27: Kommer inte att användas med take-off faktorer - Då är RWYCC 6 samma sak
B28: Ground Roll [m] | C28: ='TAKE OFF Performance FLAPS UP'!E29 -> 865.36848 | D28: ='TAKE OFF Performance FLAPS TAKE'!E29 -> 843.64506 | E28: ='TAKE OFF Performance FLAPS APPR'!E29 -> 824.16979
B29: Take off distance [m] | C29: =MAX('TAKE OFF Performance FLAPS UP'!E30:E32) -> 1842.1269 | D29: =MAX('TAKE OFF Performance FLAPS TAKE'!E30:E32) -> 1711.2732 | E29: =MAX('TAKE OFF Performance FLAPS APPR'!E30:E32) -> 1780.1208
B30: Accelerade & STOP [m] | C30: ='TAKE OFF Performance FLAPS UP'!E33 -> 1580.0603 | D30: ='TAKE OFF Performance FLAPS TAKE'!E33 -> 1441.3942 | E30: ='TAKE OFF Performance FLAPS APPR'!E33 -> 1344.4176
B31: V1 [kts] | C31: ='TAKE OFF Performance FLAPS UP'!E$22 -> 110.6 | D31: ='TAKE OFF Performance FLAPS TAKE'!E$22 -> 106.5 | E31: ='TAKE OFF Performance FLAPS APPR'!E22 -> 103.5
B32: VR [kts] | C32: ='TAKE OFF Performance FLAPS UP'!E$22 -> 110.6 | D32: ='TAKE OFF Performance FLAPS TAKE'!E$22 -> 106.5 | E32: ='TAKE OFF Performance FLAPS APPR'!E22 -> 103.5
B33: V2 [kts] | C33: ='TAKE OFF Performance FLAPS UP'!I22 -> 118 | D33: ='TAKE OFF Performance FLAPS TAKE'!I22 -> 113.8 | E33: ='TAKE OFF Performance FLAPS APPR'!I22 -> 111.6
B34: Selected contaminant
B35: Ground Roll [m] | C35: ='TAKE OFF Performance FLAPS UP'!E29*F24 -> 925.94428 | D35: ='TAKE OFF Performance FLAPS TAKE'!E29*F24 -> 902.70022 | E35: ='TAKE OFF Performance FLAPS APPR'!E29*F24 -> 881.86168
B36: Take off distance [m] | C36: =MAX('TAKE OFF Performance FLAPS UP'!E30:E32)*F24 -> 1971.0758 | D36: =MAX('TAKE OFF Performance FLAPS TAKE'!E30:E32)*F24 -> 1831.0623 | E36: =MAX('TAKE OFF Performance FLAPS APPR'!E30:E32)*F24 -> 1904.7292
B37: Accelerade & STOP [m] | C37: ='TAKE OFF Performance FLAPS UP'!E33*F24 -> 1690.6645 | D37: ='TAKE OFF Performance FLAPS TAKE'!E33*F24 -> 1542.2918 | E37: ='TAKE OFF Performance FLAPS APPR'!E33*F24 -> 1438.5269
B38: V1 [kts] | C38: ='TAKE OFF Performance FLAPS UP'!E$22 -> 110.6 | D38: ='TAKE OFF Performance FLAPS TAKE'!E$22 -> 106.5 | E38: ='TAKE OFF Performance FLAPS APPR'!E22 -> 103.5
B39: VR [kts] | C39: ='TAKE OFF Performance FLAPS UP'!E$22 -> 110.6 | D39: ='TAKE OFF Performance FLAPS TAKE'!E$22 -> 106.5 | E39: ='TAKE OFF Performance FLAPS APPR'!E22 -> 103.5
B40: V2 [kts] | C40: ='TAKE OFF Performance FLAPS UP'!I22 -> 118 | D40: ='TAKE OFF Performance FLAPS TAKE'!I$22 -> 113.8 | E40: ='TAKE OFF Performance FLAPS APPR'!I22 -> 111.6
...

Sheet Landing
B2: Landning distance Beech 1900C | G2: Version
B3: Interpoleringsverktyg för landningsträcka | G3: 46001
B4: RWY | C4: Custom airport
C5: =IFERROR(__xludf.dummyfunction("SUBSTITUTE(IMPORTDATA(""https://aviationweather.gov/api/data/metar?ids="" & LEFT(C4, 4) & ""&format=raw""), ""METAR "", """")"),"ESKM 051820Z AUTO 23007KT 110V280 9999 NCD 15/11 Q0994") -> ESKM 051820Z AUTO 23007KT 110V280 9999 NCD 15/11 Q0994
B6: Wind: | C6: =IFERROR(__xludf.dummyfunction("IF(E6<>"""", E6, IF($G$8, E6, IFERROR(IF(REGEXMATCH(C5, ""\bVRB""), ""000"", VALUE(REGEXEXTRACT(C5, ""\b(\d{3})\d{2,3}(?:G\d{2,3})?(?:KT|MPS)\b""))), ""-"")))"),230) -> 230 | D6: ° | F6: =IF(C21<0, "Tailwind", "") -> Tailwind
C7: =IFERROR(__xludf.dummyfunction("IF(E7<>"""", E7, IF($G$8, E7, IFERROR(VALUE(REGEXEXTRACT(C5, ""\b(?:\d{3}|VRB)(\d{2,3})(?:G\d{2,3})?(?:KT|MPS)\b"")), ""-"")))"),7) -> 7 | D7: kt
B8: Outside air temperature: | C8: =IFERROR(__xludf.dummyfunction("IF(E8<>"""", E8, IF($G$8, E8, IFERROR(VALUE(SUBSTITUTE(REGEXEXTRACT(C5, ""\b(M?\d{2})\/(?:M?\d{2})\b""), ""M"", ""-"")), ""-"")))"),15) -> 15 | D8: °C | F8: Remove manual MET | G8: =FALSE() -> FALSE
B9: QNH | C9: =IFERROR(__xludf.dummyfunction("IF(E9<>"""", E9, IF($G$8, E9, IFERROR(VALUE(REGEXEXTRACT(C5, ""\bQ(\d{4})\b"")), ""-"")))"),994) -> 994 | D9: Hpa
B10: Runway Condition Code | C10: 5 | E10: MANUAL MET -> | F10: REFRESH METAR | G10: =FALSE() -> FALSE
B11: Landing mass: | C11: 15500 | D11: Lbs
B12: Max landing weight | C12: 16100 | D12: Lbs
B14: Airport data (Exapandable) | C14: =IF(C11>C12, "Overweight landning","")
B15: Elevation: | C15: {=_xlfn.XLOOKUP($C$4,'Airport data'!$A$5:$A1003,'Airport data'!$B$5:$B1003)} -> 200 | D15: ft
B16: Runway Slope: | C16: {=_xlfn.XLOOKUP($C$4,'Airport data'!$A$5:$A1003,'Airport data'!$G$5:$G1003)} -> 0 | D16: % | F16: + = upphill
B17: RWY Heading: | C17: {=_xlfn.XLOOKUP($C$4,'Airport data'!$A$5:$A1003,'Airport data'!$H$5:$H1003)} -> 120 | D17: °
B18: LDA: | C18: {=_xlfn.XLOOKUP($C$4,'Airport data'!$A$5:$A1003,'Airport data'!$F$5:$F1003)} -> 2000 | D18: m
B19: Calculated data
B20: Landing Distance Factor | C20: {=_xlfn.XLOOKUP(C10,'Dropdown lists'!$B$4:$B$9,'Dropdown lists'!$C$4:$C$9)} -> 1.82
B21: Head/Tail wind | C21: ='LDG Performance'!D32 -> -2.394141 | D21: Kt
B22: Crosswind | C22: =ABS('LDG Performance'!C37*C7) -> 6.5778483 | D22: Kt | F22: Limit | G22: {=_xlfn.XLOOKUP(C10,'Dropdown lists'!$B$4:$B$9,'Dropdown lists'!$E$4:$E$9)} -> 25
B24: FLAPS: | C24: UP | D24: TAKE-OFF | F24: APP | G24: FULL
B25: Landing Distance
B26: VREF [kts] | C26: ='LDG Performance'!M21 -> 127 | G26: ='LDG Performance'!E21 -> 111.28571
B27: Landing Distance factored [m] | C27: =('LDG Performance'!B90/3.28)*Landing!C20 -> 2331.5264 | G27: ='Landing distance data'!C104*C20 -> 1537.3843
B28: Flap Up based on AFM graph
C29: =IF(ISBLANK(C10), "Dry & Unfactored *1,67", "" )
B30: Missed approach
B31: OEI Climb Gradient [%] | C31: =IF( C21>0, 'OEI CLIMB GRADIENT'!P47*(125/(125+50%*C21)), 'OEI CLIMB GRADIENT'!P47*(125/(125-150%*C21)) ) -> 3.3900791 | D31: Gradient includes wind, 150% & 50%
C35: Flaps UP | D35: Flaps FULL
B36: LDA | C36: =Landing!$C$18 -> 2000 | D36: =Landing!$C$18 -> 2000
B37: Landing distance | C37: =C27 -> 2331.5264 | D37: =G27 -> 1537.3843

Sheet Airport data
A1: Airport | B1: Runway Threshold Elevation: | C1: TORA | D1: TODA | E1: ASDA | F1: LDA: | G1: RWY Slope: | H1: RWY HDG | I1: Minimum departure climb gradient, obstacles | J1: Uppdaterad | K1: ESCAPE ROUTE INFO
K2: Min cloud base | L2: Routing
B4: [ft] | C4: [m] | D4: [m] | E4: [m] | F4: [m] | G4: [%] | H4: [°] | I4: [%] | J4: [Date] | K4: [ft] | L4: [Text]
A5: No airport selected | B5: - | D5: - | E5: - | F5: - | G5: - | H5: - | J5: -
A6: Custom airport | B6: 200 | C6: 2000 | D6: 2000 | E6: 2000 | F6: 2000 | G6: 0 | H6: 120 | I6: 3.3 | K6: 666 | L6: Kör mot OY gör en racetrack entry och stig på QDR 090 till MSA. | N6: ÄNDRA ljusgröna RADER VID BEHOV

Sheet Dropdown lists
B1: Factors | E1: X-wind
C2: LDF | D2: Takeoff Faktor
B3: RWCC | C3: Faktor | E3: Limit
B4: 1 | C4: 2.22 | D4: 1.59 | E4: 4
B5: 2 | C5: 2.12 | D5: 1.41 | E5: 9
B6: 3 | C6: 1.97 | D6: 1.22 | E6: 14
B7: 4 | C7: 1.92 | D7: 1.14 | E7: 20
B8: 5 | C8: 1.82 | D8: 1.07 | E8: 25
B9: 6 | C9: 1.67 | D9: 1 | E9: 25
E10: 25
B12: FLAPS
B19: Runway take off
B27: Engine anti-ice
B30: ON
B31: OFF
B33: Runway contaminant | E33: Faktor | F33: Måttenhet | G33: Max
B34: Wet Runway | E34: 0 | G34: N/A
B35: Compacted snow | E35: 0 | G35: N/A
B36: Dry snow | E36: 0.005 | F36: mm | G36: N/A
B37: Wet snow | E37: 0.01 | F37: mm | G37: 50
B38: Slush | E38: 0.02 | F38: mm | G38: 25
B39: Standing water | E39: 0.02 | F39: mm | G39: 25
B40: No contaminant | E40: 0 | G40: N/A
B44: Technique
B47: Static T/O power
B48: Rolling take off

Sheet LDG Performance
A1: LANDING PERFORMANCE (Normal)
H2: EMG RETURN | I2: EMG RETURN | J2: FLAPS UP | K2: EMG RETURN | L2: FLAPS UP | M2: Normal
A3: Landing Mass | D3: Speeds | H3: Speeds | J3: Speeds | L3: Speeds
D4: Vref | H4: Vref | J4: Vref | L4: Vref
A5: 12000 | D5: 101 | H5: 101 | J5: 116 | L5: 116
A6: 12000 | D6: 101 | H6: 101 | J6: 116 | L6: 116
A7: 14000 | D7: 107 | H7: 107 | J7: 122 | L7: 122
A8: 16100 | D8: 113 | H8: 113 | J8: 129 | L8: 129
A9: 16600 | D9: 115 | H9: 115 | J9: 130 | L9: 130
A11: Table size Landing distance
B12: Rows: | C12: =MATCH(MAX(A5:A9),A5:A9,0) -> 5
B13: Columns: | C13: =MATCH(MAX(D5),D5,0) -> 1
D15: x_n: | E15: =D4 -> Vref | I15: =H4 -> Vref | K15: =J4 -> Vref | M15: =L4 -> Vref
D16: y_n: | E16: =Landing!C11 -> 15500 | I16: ='Take-off'!C14 -> 15800 | K16: ='Take-off'!C14 -> 15800 | M16: =Landing!C11 -> 15500
D17: n1: | E17: {=INDEX($A$5:$A$9,MATCH(E16,$A$5:$A$9,1))} -> 14000 | I17: {=INDEX($A$5:$A$9,MATCH(I16,$A$5:$A$9,1))} -> 14000 | K17: {=INDEX($A$5:$A$9,MATCH(K16,$A$5:$A$9,1))} -> 14000 | M17: {=INDEX($A$5:$A$9,MATCH(M16,$A$5:$A$9,1))} -> 14000
D18: n2: | E18: {=INDEX($A$5:$A$9,IF(MATCH(E16,$A$5:$A$9,1)<$C$12,MATCH(E16,$A$5:$A$9,1)+1,MATCH(E16,$A$5:$A$9,1)))} -> 16100 | I18: {=INDEX($A$5:$A$9,IF(MATCH(I16,$A$5:$A$9,1)<$C$12,MATCH(I16,$A$5:$A$9,1)+1,MATCH(I16,$A$5:$A$9,1)))} -> 16100 | K18: {=INDEX($A$5:$A$9,IF(MATCH(K16,$A$5:$A$9,1)<$C$12,MATCH(K16,$A$5:$A$9,1)+1,MATCH(K16,$A$5:$A$9,1)))} -> 16100 | M18: {=INDEX($A$5:$A$9,IF(MATCH(M16,$A$5:$A$9,1)<$C$12,MATCH(M16,$A$5:$A$9,1)+1,MATCH(M16,$A$5:$A$9,1)))} -> 16100
D19: y1_n1: | E19: {=INDEX(D5:D9,MATCH(E16,$A$5:$A$9,1),MATCH(E15,D4,1))} -> 107 | I19: {=INDEX(H5:H9,MATCH(I16,$A$5:$A$9,1),MATCH(I15,H4,1))} -> 107 | K19: {=INDEX(J5:J9,MATCH(K16,$A$5:$A$9,1),MATCH(K15,J4,1))} -> 122 | M19: {=INDEX(L5:L9,MATCH(M16,$A$5:$A$9,1),MATCH(M15,L4,1))} -> 122
D20: y1_n2: | E20: {=INDEX(D5:D9,IF(MATCH(E16,$A$5:$A$9,1)<$C$12,MATCH(E16,$A$5:$A$9,1)+1,MATCH(E16,$A$5:$A$9,1)),MATCH(E15,D4,1))} -> 113 | I20: {=INDEX(H5:H9,IF(MATCH(I16,$A$5:$A$9,1)<$C$12,MATCH(I16,$A$5:$A$9,1)+1,MATCH(I16,$A$5:$A$9,1)),MATCH(I15,H4,1))} -> 113 | K20: {=INDEX(J5:J9,IF(MATCH(K16,$A$5:$A$9,1)<$C$12,MATCH(K16,$A$5:$A$9,1)+1,MATCH(K16,$A$5:$A$9,1)),MATCH(K15,J4,1))} -> 129 | M20: {=INDEX(L5:L9,IF(MATCH(M16,$A$5:$A$9,1)<$C$12,MATCH(M16,$A$5:$A$9,1)+1,MATCH(M16,$A$5:$A$9,1)),MATCH(M15,L4,1))} -> 129
D21: Vref: | E21: =IFERROR(E19+(E16-E17)*(E20-E19)/(E18-E17),E19) -> 111.28571 | I21: =IFERROR(I19+(I16-I17)*(I20-I19)/(I18-I17),I19) -> 112.14286 | K21: =IFERROR(K19+(K16-K17)*(K20-K19)/(K18-K17),K19) -> 128 | M21: =IFERROR(M19+(M16-M17)*(M20-M19)/(M18-M17),M19) -> 127
B29: Windcalc
B31: WCA | C31: Factor | D31: H/T wind
B32: =IF(ABS(Landing!C17-Landing!C6)>270,360-ABS(Landing!C17-Landing!C6),Landing!C17-Landing!C6) -> -110 | C32: =IF(ABS(B32)>90,ABS(COS(B32*PI()/180))*(-1),ABS(COS(B32*PI()/180))) -> -0.34202014 | D32: =IF( ISBLANK(Landing!C6), Landing!C7*-1, Landing!C7*C32) -> -2.394141
B37: Crosswind factor | C37: =IF(ABS(B32)>90,ABS(SIN(B32*PI()/180))*(-1),ABS(SIN(B32*PI()/180))) -> -0.93969262
A48: Emergency Return
B53: Unfactorised | C53: Factorised
B54: ='Landing distance data'!K104 -> 854.96258 | C54: =B54*C55 -> 1556.0319
B55: Landing Distance Factor: | C55: =IF( ISBLANK('Take-off'!C10),MIN('Dropdown lists'!C4:C10), VLOOKUP('Take-off'!C10,'Dropdown lists'!B4:C10,2)) -> 1.82
A66: LANDING PERFORMANCE (UP)
A68: Landing Distance Flaps LAND [feet] | B68: Landing distance | D68: EMG RETURN
B69: UP | D69: EMG RETURN
A70: 1000 | B70: 1650
A71: 1500 | B71: 2400
A72: 2000 | B72: 3120
A73: 2500 | B73: 3850
A74: 3000 | B74: 4500
A75: 3500 | B75: 5200
A76: 4000 | B76: 5800
A77: 4500 | B77: 6500
A78: 5000 | B78: 99999
A80: Table size Landing distance
...

Sheet TAKE OFF Performance FLAPS UP
A1: Take off PERFORMANCE (FLAPS UP)
A2: UP
A3: Landing Mass | D3: Speeds | H3: Speeds
D4: V1/R | H4: V2
A5: 12000 | D5: 107 | H5: 118
A6: 13000 | D6: =((D7-D5)/($A7-$A5))*($A6-$A5)+D5 -> 107 | H6: =((H7-H5)/($A7-$A5))*($A6-$A5)+H5 -> 118
A7: 14000 | D7: 107 | H7: 118
A8: 15000 | D8: =((D9-D7)/($A9-$A7))*($A8-$A7)+D7 -> 109 | H8: =((H9-H7)/($A9-$A7))*($A8-$A7)+H7 -> 118
A9: 16000 | D9: 111 | H9: 118
A10: 16600 | D10: 112 | H10: 120
D12: Table size Vref | H12: V2
D13: Rows: | E13: =MATCH(MAX($A5:$A10),$A5:$A10,0) -> 6 | I13: =MATCH(MAX($A5:$A10),$A5:$A10,0) -> 6
D14: Columns: | E14: =MATCH(MAX(D5),D5,0) -> 1 | I14: =MATCH(MAX(H5),H5,0) -> 1
D16: x_n: | E16: =D4 -> V1/R | I16: =H4 -> V2
D17: y_n: | E17: ='Take-off'!$C$14 -> 15800 | I17: ='Take-off'!$C$14 -> 15800
D18: n1: | E18: {=INDEX($A5:$A10,MATCH(E17,$A5:$A10,1))} -> 15000 | I18: {=INDEX($A5:$A10,MATCH(I17,$A5:$A10,1))} -> 15000
D19: n2: | E19: {=INDEX($A5:$A10,IF(MATCH(E17,$A5:$A10,1)<E13,MATCH(E17,$A5:$A10,1)+1,MATCH(E17,$A5:$A10,1)))} -> 16000 | I19: {=INDEX($A5:$A10,IF(MATCH(I17,$A5:$A10,1)<I13,MATCH(I17,$A5:$A10,1)+1,MATCH(I17,$A5:$A10,1)))} -> 16000
D20: y1_n1: | E20: {=INDEX(D5:D10,MATCH(E17,$A5:$A10,1),MATCH(E16,D4,1))} -> 109 | I20: {=INDEX(H5:H10,MATCH(I17,$A5:$A10,1),MATCH(I16,H4,1))} -> 118
D21: y1_n2: | E21: {=INDEX(D5:D10,IF(MATCH(E17,$A5:$A10,1)<E13,MATCH(E17,$A5:$A10,1)+1,MATCH(E17,$A5:$A10,1)),MATCH(E16,D4,1))} -> 111 | I21: {=INDEX(H5:H10,IF(MATCH(I17,$A5:$A10,1)<I13,MATCH(I17,$A5:$A10,1)+1,MATCH(I17,$A5:$A10,1)),MATCH(I16,H4,1))} -> 118
D22: Vref: | E22: =IFERROR(E20+(E17-E18)*(E21-E20)/(E19-E18),E20) -> 110.6 | I22: =IFERROR(I20+(I17-I18)*(I21-I20)/(I19-I18),I20) -> 118
A26: Landing distance required calculations
B28: Flat | C28: Teknik | D28: Slope | E28: Unfactored | F28: Factored
A29: Ground Roll | B29: ='Takeoff distance (2)'!C75/3.28 -> 712.92946 | C29: =IF('Take-off'!$F$13='Dropdown lists'!$B$48, 500/3.28, 0) -> 152.43902 | D29: =IF('Take-off'!$C$17>0, ((+'Take-off'!$C$17*5)%*SUM(B29:C29)),0 ) -> 0 | E29: =SUM(B29:D29) -> 865.36848 | F29: {=_xlfn.XLOOKUP('Take-off'!$C$10,'Dropdown lists'!$B$4:$B$9,'Dropdown lists'!$D$4:$D$9)*E29} -> 925.94428
A30: Take off distance | B30: ='Takeoff distance (2)'!C94/3.28 -> 1084.6381 | C30: =IF('Take-off'!$F$13='Dropdown lists'!$B$48, 500/3.28, 0) -> 152.43902 | D30: =IF('Take-off'!$C$17>0, ((+'Take-off'!$C$17*5)%*SUM(B30:C30)),0 ) -> 0 | E30: =SUM(B30:D30)*115% -> 1422.6387 | F30: {=_xlfn.XLOOKUP('Take-off'!$C$10,'Dropdown lists'!$B$4:$B$9,'Dropdown lists'!$D$4:$D$9)*E30} -> 1522.2234
A31: Accelerate GO DRY | B31: ='Accelerate and GO (2)'!C75/3.28 -> 1689.6879 | C31: =IF('Take-off'!$F$13='Dropdown lists'!$B$48, 500/3.28, 0) -> 152.43902 | D31: =IF('Take-off'!$C$17>0, ((+'Take-off'!$C$17*5)%*SUM(B31:C31)),0 ) -> 0 | E31: =SUM(B31:D31) -> 1842.1269 | F31: {=_xlfn.XLOOKUP('Take-off'!$C$10,'Dropdown lists'!$B$4:$B$9,'Dropdown lists'!$D$4:$D$9)*E31} -> 1971.0758
A32: Accelerate GO WET/CONT | B32: =B31 -> 1689.6879 | C32: =IF('Take-off'!$F$13='Dropdown lists'!$B$48, 500/3.28, 0) -> 152.43902 | D32: =IF('Take-off'!$C$17>0, ((+'Take-off'!$C$17*5)%*SUM(B32:C32)),0 ) -> 0 | E32: =SUM(B32:D32) -> 1842.1269 | F32: {=_xlfn.XLOOKUP('Take-off'!$C$10,'Dropdown lists'!$B$4:$B$9,'Dropdown lists'!$D$4:$D$9)*E32} -> 1971.0758
A33: Accelerate stop | B33: ='Accelerate and stop2'!C76/3.28 -> 1427.6213 | C33: =IF('Take-off'!$F$13='Dropdown lists'!$B$48, 500/3.28, 0) -> 152.43902 | D33: =IF('Take-off'!$C$17>0, ((+'Take-off'!$C$17*5)%*SUM(B33:C33)),0 ) -> 0 | E33: =SUM(B33:D33) -> 1580.0603 | F33: {=_xlfn.XLOOKUP('Take-off'!$C$10,'Dropdown lists'!$B$4:$B$9,'Dropdown lists'!$D$4:$D$9)*E33} -> 1690.6645
B35: WCA | C35: Factor | D35: H/T wind
B36: =IF(ABS('Take-off'!C18-'Take-off'!C6)>270,360-ABS('Take-off'!C18-'Take-off'!C6),'Take-off'!C18-'Take-off'!C6) -> -110 | C36: =IF(ABS(B36)>90,ABS(COS(B36*PI()/180))*(-1),ABS(COS(B36*PI()/180))) -> -0.34202014 | D36: =IF( ISBLANK('Take-off'!C6), 'Take-off'!C7*-1, 'Take-off'!C7*C36) -> -2.394141
A37: TDR | B37: Unfactorised | C37: Factorised
B41: Crosswind factor | C41: =IF(ABS(B36)>90,ABS(SIN(B36*PI()/180))*(-1),ABS(SIN(B36*PI()/180))) -> -0.93969262

Sheet TAKE OFF Performance FLAPS TAKE
A1: TAKE OFF PERFORMANCE (FLAPS TAKE-OFF)
A2: TAKE-OFF | N2: Contaminated runway | X2: Contaminated forts
A3: Mass | D3: Speeds | H3: Speeds | N3: Wet runway | S3: Compacted snow | X3: Dry snow | Y3: Wet snow | Z3: Slush | AA3: Standing water
D4: V1/R | H4: V2 | N4: TOFL | O4: V1 | P4: VR | Q4: V2 | S4: TOFL | T4: V1 | U4: VR | V4: V2 | X4: TOFL | Y4: TOFL | Z4: TOFL | AA4: TOFL | AB4: V1 | AC4: VR | AD4: V2
A5: 12000 | D5: 102 | H5: 112 | N5: ='Takeoff distance contaminated'!AQ103 -> 5190.8147 | O5: ='Takeoff distance contaminated'!AQ141 -> 102 | P5: ='Takeoff distance contaminated'!AQ177 -> 102 | Q5: ='Takeoff distance contaminated'!AQ213 -> 105 | S5: ='Takeoff distance contaminated'!AQ297 -> 8195.403 | T5: ='Takeoff distance contaminated'!AQ399 -> 111.38306 | U5: ='Takeoff distance contaminated'!AQ438 -> 9999 | V5: ='Takeoff distance contaminated'!AQ474 -> 9999 | X5: ='Takeoff distance contamined 2'!AQ127 -> 5707.6744 | Y5: ='Takeoff distance contamined 2'!AQ215 -> 5788.9526 | Z5: ='Takeoff distance contamined 2'!AQ304 -> 5786.4234 | AA5: ='Takeoff distance contamined 2'!AQ374 -> 5792.563 | AB5: ='Takeoff distance contamined 2'!AQ409 -> 102 | AC5: ='Takeoff distance contamined 2'!AQ409 -> 102 | AD5: ='Takeoff distance contamined 2'!AQ444 -> 105
A6: 13000 | D6: =((D7-D5)/($A7-$A5))*($A6-$A5)+D5 -> 102 | H6: =((H7-H5)/($A7-$A5))*($A6-$A5)+H5 -> 112 | N6: ='Takeoff distance contaminated'!AI103 -> 5277.2903 | O6: ='Takeoff distance contaminated'!AI141 -> 102 | P6: ='Takeoff distance contaminated'!AI177 -> 102.77 | Q6: ='Takeoff distance contaminated'!AI213 -> 105 | S6: ='Takeoff distance contaminated'!AI297 -> 8195.403 | T6: ='Takeoff distance contaminated'!AI399 -> 111.38306 | U6: ='Takeoff distance contaminated'!AI438 -> 9999 | V6: ='Takeoff distance contaminated'!AI474 -> 9999 | X6: ='Takeoff distance contamined 2'!AI127 -> 5808.4569 | Y6: ='Takeoff distance contamined 2'!AI215 -> 5889.6907 | Z6: ='Takeoff distance contamined 2'!AI304 -> 5892.4635 | AA6: ='Takeoff distance contamined 2'!AI374 -> 5897.4508 | AB6: ='Takeoff distance contamined 2'!AI409 -> 102.77 | AC6: ='Takeoff distance contamined 2'!AI409 -> 102.77 | AD6: ='Takeoff distance contamined 2'!AI444 -> 105
A7: 14000 | D7: 102 | H7: 112 | N7: ='Takeoff distance contaminated'!AA103 -> 5373.235 | O7: ='Takeoff distance contaminated'!AA141 -> 102 | P7: ='Takeoff distance contaminated'!AA177 -> 106 | Q7: ='Takeoff distance contaminated'!AA213 -> 108 | S7: ='Takeoff distance contaminated'!AA297 -> 8195.403 | T7: ='Takeoff distance contaminated'!AA399 -> 111.38306 | U7: ='Takeoff distance contaminated'!AA438 -> 9999 | V7: ='Takeoff distance contaminated'!AA474 -> 9999 | X7: ='Takeoff distance contamined 2'!AA127 -> 6287.8634 | Y7: ='Takeoff distance contamined 2'!AA215 -> 6366.4101 | Z7: ='Takeoff distance contamined 2'!AA304 -> 6398.5487 | AA7: ='Takeoff distance contamined 2'!AA374 -> 6331.7911 | AB7: ='Takeoff distance contamined 2'!AA409 -> 106 | AC7: ='Takeoff distance contamined 2'!AA409 -> 106 | AD7: ='Takeoff distance contamined 2'!AA444 -> 108
A8: 15000 | D8: =((D9-D7)/($A9-$A7))*($A8-$A7)+D7 -> 104.5 | H8: =((H9-H7)/($A9-$A7))*($A8-$A7)+H7 -> 113 | N8: ='Takeoff distance contaminated'!S103 -> 5689.7409 | O8: ='Takeoff distance contaminated'!S141 -> 104 | P8: ='Takeoff distance contaminated'!S177 -> 109 | Q8: ='Takeoff distance contaminated'!S213 -> 111 | S8: ='Takeoff distance contaminated'!S297 -> 8195.403 | T8: ='Takeoff distance contaminated'!S399 -> 111.38306 | U8: ='Takeoff distance contaminated'!S438 -> 9999 | V8: ='Takeoff distance contaminated'!S474 -> 9999 | X8: ='Takeoff distance contamined 2'!S127 -> 6811.6949 | Y8: ='Takeoff distance contamined 2'!S215 -> 6895.4473 | Z8: ='Takeoff distance contamined 2'!S304 -> 6959.2219 | AA8: ='Takeoff distance contamined 2'!S374 -> 6950.047 | AB8: ='Takeoff distance contamined 2'!S409 -> 109 | AC8: ='Takeoff distance contamined 2'!S409 -> 109 | AD8: ='Takeoff distance contamined 2'!S444 -> 111
A9: 16000 | D9: 107 | H9: 114 | N9: ='Takeoff distance contaminated'!K103 -> 6118.2072 | O9: ='Takeoff distance contaminated'!K141 -> 107 | P9: ='Takeoff distance contaminated'!K177 -> 113 | Q9: ='Takeoff distance contaminated'!K213 -> 114 | S9: ='Takeoff distance contaminated'!K297 -> 8195.403 | T9: ='Takeoff distance contaminated'!K399 -> 111.38306 | U9: ='Takeoff distance contaminated'!K438 -> 9999 | V9: ='Takeoff distance contaminated'!K474 -> 9999 | X9: ='Takeoff distance contamined 2'!K127 -> 7402.9582 | Y9: ='Takeoff distance contamined 2'!K215 -> 7268.8125 | Z9: ='Takeoff distance contamined 2'!K304 -> 7582.6616 | AA9: ='Takeoff distance contamined 2'!K374 -> 7591.631 | AB9: ='Takeoff distance contamined 2'!K409 -> 113 | AC9: ='Takeoff distance contamined 2'!K409 -> 113 | AD9: ='Takeoff distance contamined 2'!K444 -> 114
A10: 16600 | D10: 108 | H10: 115 | N10: ='Takeoff distance contaminated'!C103 -> 6409.0672 | O10: ='Takeoff distance contaminated'!C141 -> 108.77 | P10: ='Takeoff distance contaminated'!C177 -> 114.77 | Q10: ='Takeoff distance contaminated'!C213 -> 115 | S10: ='Takeoff distance contaminated'!C297 -> 8195.403 | T10: ='Takeoff distance contaminated'!C399 -> 111.38306 | U10: ='Takeoff distance contaminated'!C438 -> 9999 | V10: ='Takeoff distance contaminated'!C474 -> 9999 | X10: ='Takeoff distance contamined 2'!C127 -> 7785.7437 | Y10: ='Takeoff distance contamined 2'!C215 -> 7819.8269 | Z10: ='Takeoff distance contamined 2'!C304 -> 7957.1143 | AA10: ='Takeoff distance contamined 2'!C374 -> 7978.233 | AB10: ='Takeoff distance contamined 2'!C409 -> 114.77 | AC10: ='Takeoff distance contamined 2'!C409 -> 114.77 | AD10: ='Takeoff distance contamined 2'!C444 -> 115
D12: Table size Vref | H12: V2
D13: Rows: | E13: =MATCH(MAX($A5:$A10),$A5:$A10,0) -> 6 | I13: =MATCH(MAX($A5:$A10),$A5:$A10,0) -> 6 | N13: =MATCH(MAX($A5:$A10),$A5:$A10,0) -> 6 | O13: =MATCH(MAX($A5:$A10),$A5:$A10,0) -> 6 | P13: =MATCH(MAX($A5:$A10),$A5:$A10,0) -> 6 | Q13: =MATCH(MAX($A5:$A10),$A5:$A10,0) -> 6 | S13: =MATCH(MAX($A5:$A10),$A5:$A10,0) -> 6 | T13: =MATCH(MAX($A5:$A10),$A5:$A10,0) -> 6 | U13: =MATCH(MAX($A5:$A10),$A5:$A10,0) -> 6 | V13: =MATCH(MAX($A5:$A10),$A5:$A10,0) -> 6 | X13: =MATCH(MAX($A5:$A10),$A5:$A10,0) -> 6 | Y13: =MATCH(MAX($A5:$A10),$A5:$A10,0) -> 6 | Z13: =MATCH(MAX($A5:$A10),$A5:$A10,0) -> 6 | AA13: =MATCH(MAX($A5:$A10),$A5:$A10,0) -> 6 | AB13: =MATCH(MAX($A5:$A10),$A5:$A10,0) -> 6 | AC13: =MATCH(MAX($A5:$A10),$A5:$A10,0) -> 6 | AD13: =MATCH(MAX($A5:$A10),$A5:$A10,0) -> 6
D14: Columns: | E14: =MATCH(MAX(D5),D5,0) -> 1 | I14: =MATCH(MAX(H5),H5,0) -> 1 | N14: =MATCH(MAX(N5),N5,0) -> 1 | O14: =MATCH(MAX(O5),O5,0) -> 1 | P14: =MATCH(MAX(P5),P5,0) -> 1 | Q14: =MATCH(MAX(Q5),Q5,0) -> 1 | S14: =MATCH(MAX(S5),S5,0) -> 1 | T14: =MATCH(MAX(T5),T5,0) -> 1 | U14: =MATCH(MAX(U5),U5,0) -> 1 | V14: =MATCH(MAX(V5),V5,0) -> 1 | X14: =MATCH(MAX(X5),X5,0) -> 1 | Y14: =MATCH(MAX(Y5),Y5,0) -> 1 | Z14: =MATCH(MAX(Z5),Z5,0) -> 1 | AA14: =MATCH(MAX(AA5),AA5,0) -> 1 | AB14: =MATCH(MAX(AB5),AB5,0) -> 1 | AC14: =MATCH(MAX(AC5),AC5,0) -> 1 | AD14: =MATCH(MAX(AD5),AD5,0) -> 1
D16: x_n: | E16: =D4 -> V1/R | I16: =H4 -> V2 | N16: =N4 -> TOFL | O16: =O4 -> V1 | P16: =P4 -> VR | Q16: =Q4 -> V2 | S16: =S4 -> TOFL | T16: =T4 -> V1 | U16: =U4 -> VR | V16: =V4 -> V2 | X16: =X4 -> TOFL | Y16: =Y4 -> TOFL | Z16: =Z4 -> TOFL | AA16: =AA4 -> TOFL | AB16: =AB4 -> V1 | AC16: =AC4 -> VR | AD16: =AD4 -> V2
D17: y_n: | E17: ='Take-off'!$C$14 -> 15800 | I17: ='Take-off'!$C$14 -> 15800 | N17: ='Take-off'!$C$14 -> 15800 | O17: ='Take-off'!$C$14 -> 15800 | P17: ='Take-off'!$C$14 -> 15800 | Q17: ='Take-off'!$C$14 -> 15800 | S17: ='Take-off'!$C$14 -> 15800 | T17: ='Take-off'!$C$14 -> 15800 | U17: ='Take-off'!$C$14 -> 15800 | V17: ='Take-off'!$C$14 -> 15800 | X17: ='Take-off'!$C$14 -> 15800 | Y17: ='Take-off'!$C$14 -> 15800 | Z17: ='Take-off'!$C$14 -> 15800 | AA17: ='Take-off'!$C$14 -> 15800 | AB17: ='Take-off'!$C$14 -> 15800 | AC17: ='Take-off'!$C$14 -> 15800 | AD17: ='Take-off'!$C$14 -> 15800
D18: n1: | E18: {=INDEX($A5:$A10,MATCH(E17,$A5:$A10,1))} -> 15000 | I18: {=INDEX($A5:$A10,MATCH(I17,$A5:$A10,1))} -> 15000 | N18: =INDEX($A5:$A10,MATCH(N17,$A5:$A10,1)) -> 15000 | O18: =INDEX($A5:$A10,MATCH(O17,$A5:$A10,1)) -> 15000 | P18: =INDEX($A5:$A10,MATCH(P17,$A5:$A10,1)) -> 15000 | Q18: =INDEX($A5:$A10,MATCH(Q17,$A5:$A10,1)) -> 15000 | S18: =INDEX($A5:$A10,MATCH(S17,$A5:$A10,1)) -> 15000 | T18: =INDEX($A5:$A10,MATCH(T17,$A5:$A10,1)) -> 15000 | U18: =INDEX($A5:$A10,MATCH(U17,$A5:$A10,1)) -> 15000 | V18: =INDEX($A5:$A10,MATCH(V17,$A5:$A10,1)) -> 15000 | X18: =INDEX($A5:$A10,MATCH(X17,$A5:$A10,1)) -> 15000 | Y18: =INDEX($A5:$A10,MATCH(Y17,$A5:$A10,1)) -> 15000 | Z18: =INDEX($A5:$A10,MATCH(Z17,$A5:$A10,1)) -> 15000 | AA18: =INDEX($A5:$A10,MATCH(AA17,$A5:$A10,1)) -> 15000 | AB18: =INDEX($A5:$A10,MATCH(AB17,$A5:$A10,1)) -> 15000 | AC18: =INDEX($A5:$A10,MATCH(AC17,$A5:$A10,1)) -> 15000 | AD18: =INDEX($A5:$A10,MATCH(AD17,$A5:$A10,1)) -> 15000
D19: n2: | E19: {=INDEX($A5:$A10,IF(MATCH(E17,$A5:$A10,1)<E13,MATCH(E17,$A5:$A10,1)+1,MATCH(E17,$A5:$A10,1)))} -> 16000 | I19: {=INDEX($A5:$A10,IF(MATCH(I17,$A5:$A10,1)<I13,MATCH(I17,$A5:$A10,1)+1,MATCH(I17,$A5:$A10,1)))} -> 16000 | N19: =INDEX($A5:$A10,IF(MATCH(N17,$A5:$A10,1)<N13,MATCH(N17,$A5:$A10,1)+1,MATCH(N17,$A5:$A10,1))) -> 16000 | O19: =INDEX($A5:$A10,IF(MATCH(O17,$A5:$A10,1)<O13,MATCH(O17,$A5:$A10,1)+1,MATCH(O17,$A5:$A10,1))) -> 16000 | P19: =INDEX($A5:$A10,IF(MATCH(P17,$A5:$A10,1)<P13,MATCH(P17,$A5:$A10,1)+1,MATCH(P17,$A5:$A10,1))) -> 16000 | Q19: =INDEX($A5:$A10,IF(MATCH(Q17,$A5:$A10,1)<Q13,MATCH(Q17,$A5:$A10,1)+1,MATCH(Q17,$A5:$A10,1))) -> 16000 | S19: =INDEX($A5:$A10,IF(MATCH(S17,$A5:$A10,1)<S13,MATCH(S17,$A5:$A10,1)+1,MATCH(S17,$A5:$A10,1))) -> 16000 | T19: =INDEX($A5:$A10,IF(MATCH(T17,$A5:$A10,1)<T13,MATCH(T17,$A5:$A10,1)+1,MATCH(T17,$A5:$A10,1))) -> 16000 | U19: =INDEX($A5:$A10,IF(MATCH(U17,$A5:$A10,1)<U13,MATCH(U17,$A5:$A10,1)+1,MATCH(U17,$A5:$A10,1))) -> 16000 | V19: =INDEX($A5:$A10,IF(MATCH(V17,$A5:$A10,1)<V13,MATCH(V17,$A5:$A10,1)+1,MATCH(V17,$A5:$A10,1))) -> 16000 | X19: =INDEX($A5:$A10,IF(MATCH(X17,$A5:$A10,1)<X13,MATCH(X17,$A5:$A10,1)+1,MATCH(X17,$A5:$A10,1))) -> 16000 | Y19: =INDEX($A5:$A10,IF(MATCH(Y17,$A5:$A10,1)<Y13,MATCH(Y17,$A5:$A10,1)+1,MATCH(Y17,$A5:$A10,1))) -> 16000 | Z19: =INDEX($A5:$A10,IF(MATCH(Z17,$A5:$A10,1)<Z13,MATCH(Z17,$A5:$A10,1)+1,MATCH(Z17,$A5:$A10,1))) -> 16000 | AA19: =INDEX($A5:$A10,IF(MATCH(AA17,$A5:$A10,1)<AA13,MATCH(AA17,$A5:$A10,1)+1,MATCH(AA17,$A5:$A10,1))) -> 16000 | AB19: =INDEX($A5:$A10,IF(MATCH(AB17,$A5:$A10,1)<AB13,MATCH(AB17,$A5:$A10,1)+1,MATCH(AB17,$A5:$A10,1))) -> 16000 | AC19: =INDEX($A5:$A10,IF(MATCH(AC17,$A5:$A10,1)<AC13,MATCH(AC17,$A5:$A10,1)+1,MATCH(AC17,$A5:$A10,1))) -> 16000 | AD19: =INDEX($A5:$A10,IF(MATCH(AD17,$A5:$A10,1)<AD13,MATCH(AD17,$A5:$A10,1)+1,MATCH(AD17,$A5:$A10,1))) -> 16000
D20: y1_n1: | E20: {=INDEX(D5:D10,MATCH(E17,$A5:$A10,1),MATCH(E16,D4,1))} -> 104.5 | I20: {=INDEX(H5:H10,MATCH(I17,$A5:$A10,1),MATCH(I16,H4,1))} -> 113 | N20: =INDEX(N5:N10,MATCH(N17,$A5:$A10,1),MATCH(N16,N4,1)) -> 5689.7409 | O20: =INDEX(O5:O10,MATCH(O17,$A5:$A10,1),MATCH(O16,O4,1)) -> 104 | P20: =INDEX(P5:P10,MATCH(P17,$A5:$A10,1),MATCH(P16,P4,1)) -> 109 | Q20: =INDEX(Q5:Q10,MATCH(Q17,$A5:$A10,1),MATCH(Q16,Q4,1)) -> 111 | S20: =INDEX(S5:S10,MATCH(S17,$A5:$A10,1),MATCH(S16,S4,1)) -> 8195.403 | T20: =INDEX(T5:T10,MATCH(T17,$A5:$A10,1),MATCH(T16,T4,1)) -> 111.38306 | U20: =INDEX(U5:U10,MATCH(U17,$A5:$A10,1),MATCH(U16,U4,1)) -> 9999 | V20: =INDEX(V5:V10,MATCH(V17,$A5:$A10,1),MATCH(V16,V4,1)) -> 9999 | X20: =INDEX(X5:X10,MATCH(X17,$A5:$A10,1),MATCH(X16,X4,1)) -> 6811.6949 | Y20: =INDEX(Y5:Y10,MATCH(Y17,$A5:$A10,1),MATCH(Y16,Y4,1)) -> 6895.4473 | Z20: =INDEX(Z5:Z10,MATCH(Z17,$A5:$A10,1),MATCH(Z16,Z4,1)) -> 6959.2219 | AA20: =INDEX(AA5:AA10,MATCH(AA17,$A5:$A10,1),MATCH(AA16,AA4,1)) -> 6950.047 | AB20: =INDEX(AB5:AB10,MATCH(AB17,$A5:$A10,1),MATCH(AB16,AB4,1)) -> 109 | AC20: =INDEX(AC5:AC10,MATCH(AC17,$A5:$A10,1),MATCH(AC16,AC4,1)) -> 109 | AD20: =INDEX(AD5:AD10,MATCH(AD17,$A5:$A10,1),MATCH(AD16,AD4,1)) -> 111
D21: y1_n2: | E21: {=INDEX(D5:D10,IF(MATCH(E17,$A5:$A10,1)<E13,MATCH(E17,$A5:$A10,1)+1,MATCH(E17,$A5:$A10,1)),MATCH(E16,D4,1))} -> 107 | I21: {=INDEX(H5:H10,IF(MATCH(I17,$A5:$A10,1)<I13,MATCH(I17,$A5:$A10,1)+1,MATCH(I17,$A5:$A10,1)),MATCH(I16,H4,1))} -> 114 | N21: =INDEX(N5:N10,IF(MATCH(N17,$A5:$A10,1)<N13,MATCH(N17,$A5:$A10,1)+1,MATCH(N17,$A5:$A10,1)),MATCH(N16,N4,1)) -> 6118.2072 | O21: =INDEX(O5:O10,IF(MATCH(O17,$A5:$A10,1)<O13,MATCH(O17,$A5:$A10,1)+1,MATCH(O17,$A5:$A10,1)),MATCH(O16,O4,1)) -> 107 | P21: =INDEX(P5:P10,IF(MATCH(P17,$A5:$A10,1)<P13,MATCH(P17,$A5:$A10,1)+1,MATCH(P17,$A5:$A10,1)),MATCH(P16,P4,1)) -> 113 | Q21: =INDEX(Q5:Q10,IF(MATCH(Q17,$A5:$A10,1)<Q13,MATCH(Q17,$A5:$A10,1)+1,MATCH(Q17,$A5:$A10,1)),MATCH(Q16,Q4,1)) -> 114 | S21: =INDEX(S5:S10,IF(MATCH(S17,$A5:$A10,1)<S13,MATCH(S17,$A5:$A10,1)+1,MATCH(S17,$A5:$A10,1)),MATCH(S16,S4,1)) -> 8195.403 | T21: =INDEX(T5:T10,IF(MATCH(T17,$A5:$A10,1)<T13,MATCH(T17,$A5:$A10,1)+1,MATCH(T17,$A5:$A10,1)),MATCH(T16,T4,1)) -> 111.38306 | U21: =INDEX(U5:U10,IF(MATCH(U17,$A5:$A10,1)<U13,MATCH(U17,$A5:$A10,1)+1,MATCH(U17,$A5:$A10,1)),MATCH(U16,U4,1)) -> 9999 | V21: =INDEX(V5:V10,IF(MATCH(V17,$A5:$A10,1)<V13,MATCH(V17,$A5:$A10,1)+1,MATCH(V17,$A5:$A10,1)),MATCH(V16,V4,1)) -> 9999 | X21: =INDEX(X5:X10,IF(MATCH(X17,$A5:$A10,1)<X13,MATCH(X17,$A5:$A10,1)+1,MATCH(X17,$A5:$A10,1)),MATCH(X16,X4,1)) -> 7402.9582 | Y21: =INDEX(Y5:Y10,IF(MATCH(Y17,$A5:$A10,1)<Y13,MATCH(Y17,$A5:$A10,1)+1,MATCH(Y17,$A5:$A10,1)),MATCH(Y16,Y4,1)) -> 7268.8125 | Z21: =INDEX(Z5:Z10,IF(MATCH(Z17,$A5:$A10,1)<Z13,MATCH(Z17,$A5:$A10,1)+1,MATCH(Z17,$A5:$A10,1)),MATCH(Z16,Z4,1)) -> 7582.6616 | AA21: =INDEX(AA5:AA10,IF(MATCH(AA17,$A5:$A10,1)<AA13,MATCH(AA17,$A5:$A10,1)+1,MATCH(AA17,$A5:$A10,1)),MATCH(AA16,AA4,1)) -> 7591.631 | AB21: =INDEX(AB5:AB10,IF(MATCH(AB17,$A5:$A10,1)<AB13,MATCH(AB17,$A5:$A10,1)+1,MATCH(AB17,$A5:$A10,1)),MATCH(AB16,AB4,1)) -> 113 | AC21: =INDEX(AC5:AC10,IF(MATCH(AC17,$A5:$A10,1)<AC13,MATCH(AC17,$A5:$A10,1)+1,MATCH(AC17,$A5:$A10,1)),MATCH(AC16,AC4,1)) -> 113 | AD21: =INDEX(AD5:AD10,IF(MATCH(AD17,$A5:$A10,1)<AD13,MATCH(AD17,$A5:$A10,1)+1,MATCH(AD17,$A5:$A10,1)),MATCH(AD16,AD4,1)) -> 114
D22: Vref: | E22: =IFERROR(E20+(E17-E18)*(E21-E20)/(E19-E18),E20) -> 106.5 | I22: =IFERROR(I20+(I17-I18)*(I21-I20)/(I19-I18),I20) -> 113.8 | N22: =IFERROR(N20+(N17-N18)*(N21-N20)/(N19-N18),N20) -> 6032.5139 | O22: =IFERROR(O20+(O17-O18)*(O21-O20)/(O19-O18),O20) -> 106.4 | P22: =IFERROR(P20+(P17-P18)*(P21-P20)/(P19-P18),P20) -> 112.2 | Q22: =IFERROR(Q20+(Q17-Q18)*(Q21-Q20)/(Q19-Q18),Q20) -> 113.4 | S22: =IFERROR(S20+(S17-S18)*(S21-S20)/(S19-S18),S20) -> 8195.403 | T22: =IFERROR(T20+(T17-T18)*(T21-T20)/(T19-T18),T20) -> 111.38306 | U22: =IFERROR(U20+(U17-U18)*(U21-U20)/(U19-U18),U20) -> 9999 | V22: =IFERROR(V20+(V17-V18)*(V21-V20)/(V19-V18),V20) -> 9999 | X22: =IFERROR(X20+(X17-X18)*(X21-X20)/(X19-X18),X20) -> 7284.7056 | Y22: =IFERROR(Y20+(Y17-Y18)*(Y21-Y20)/(Y19-Y18),Y20) -> 7194.1395 | Z22: =IFERROR(Z20+(Z17-Z18)*(Z21-Z20)/(Z19-Z18),Z20) -> 7457.9737 | AA22: =IFERROR(AA20+(AA17-AA18)*(AA21-AA20)/(AA19-AA18),AA20) -> 7463.3142 | AB22: =IFERROR(AB20+(AB17-AB18)*(AB21-AB20)/(AB19-AB18),AB20) -> 112.2 | AC22: =IFERROR(AC20+(AC17-AC18)*(AC21-AC20)/(AC19-AC18),AC20) -> 112.2 | AD22: =IFERROR(AD20+(AD17-AD18)*(AD21-AD20)/(AD19-AD18),AD20) -> 113.4
M23: Fot->Meter | N23: =N22/3.28 -> 1839.1811 | S23: =S22/3.28 -> 2498.5985 | W23: Fot->Meter+corr för anti-skid | X23: =(X22/3.28)*105% -> 2331.9942 | Y23: =(Y22/3.28)*104% -> 2281.0686 | Z23: =(Z22+150)/3.28 -> 2319.5042 | AA23: =(AA22+100)/3.28 -> 2305.8885
N25: Korr för V1<=VR | O25: =IF(P22<O22,P22,O22) -> 106.4 | S25: Korr för V1<=VR | T25: =IF(U22<T22,U22,T22) -> 111.38306 | AA25: Korr för V1<=VR | AB25: =IF(AC22<AB22,AC22,AB22) -> 112.2
A26: Landing distance required calculations
B28: Flat | C28: Technique | D28: Slope | E28: Unfactored | F28: Factored
A29: Ground Roll | B29: ='Takeoff distance (2)'!P75/3.28 -> 691.20604 | C29: =IF('Take-off'!$F$13='Dropdown lists'!$B$48, 500/3.28, 0) -> 152.43902 | D29: =IF('Take-off'!$C$17>0, ((+'Take-off'!$C$17*5)%*SUM(B29:C29)),0 ) -> 0 | E29: =SUM(B29:D29) -> 843.64506 | F29: {=_xlfn.XLOOKUP('Take-off'!$C$10,'Dropdown lists'!$B$4:$B$9,'Dropdown lists'!$D$4:$D$9)*E29} -> 902.70022
A30: Take off distance | B30: ='Takeoff distance (2)'!P94/3.28 -> 1052.053 | C30: =IF('Take-off'!$F$13='Dropdown lists'!$B$48, 500/3.28, 0) -> 152.43902 | D30: =IF('Take-off'!$C$17>0, ((+'Take-off'!$C$17*5)%*SUM(B30:C30)),0 ) -> 0 | E30: =SUM(B30:D30)*115% -> 1385.1658 | F30: {=_xlfn.XLOOKUP('Take-off'!$C$10,'Dropdown lists'!$B$4:$B$9,'Dropdown lists'!$D$4:$D$9)*E30} -> 1482.1274
A31: Accelerate GO DRY | B31: ='Accelerate and GO (2)'!P75/3.28 -> 1558.8342 | C31: =IF('Take-off'!$F$13='Dropdown lists'!$B$48, 500/3.28, 0) -> 152.43902 | D31: =IF('Take-off'!$C$17>0, ((+'Take-off'!$C$17*5)%*SUM(B31:C31)),0 ) -> 0 | E31: =SUM(B31:D31) -> 1711.2732 | F31: {=_xlfn.XLOOKUP('Take-off'!$C$10,'Dropdown lists'!$B$4:$B$9,'Dropdown lists'!$D$4:$D$9)*E31} -> 1831.0623
A32: Accelerate GO WET/CONT | B32: =B31 -> 1558.8342 | C32: =IF('Take-off'!$F$13='Dropdown lists'!$B$48, 500/3.28, 0) -> 152.43902 | D32: =IF('Take-off'!$C$17>0, ((+'Take-off'!$C$17*5)%*SUM(B32:C32)),0 ) -> 0 | E32: =SUM(B32:D32) -> 1711.2732 | F32: {=_xlfn.XLOOKUP('Take-off'!$C$10,'Dropdown lists'!$B$4:$B$9,'Dropdown lists'!$D$4:$D$9)*E32} -> 1831.0623
A33: Accelerate stop distance | B33: ='Accelerate and stop2'!P76/3.28 -> 1288.9552 | C33: =IF('Take-off'!$F$13='Dropdown lists'!$B$48, 500/3.28, 0) -> 152.43902 | D33: =IF('Take-off'!$C$17>0, ((+'Take-off'!$C$17*5)%*SUM(B33:C33)),0 ) -> 0 | E33: =SUM(B33:D33) -> 1441.3942 | F33: {=_xlfn.XLOOKUP('Take-off'!$C$10,'Dropdown lists'!$B$4:$B$9,'Dropdown lists'!$D$4:$D$9)*E33} -> 1542.2918
B34: WCA | C34: Factor | D34: H/T wind
B35: =IF(ABS('Take-off'!C18-'Take-off'!C6)>270,360-ABS('Take-off'!C18-'Take-off'!C6),'Take-off'!C18-'Take-off'!C6) -> -110 | C35: =IF(ABS(B35)>90,ABS(COS(B35*PI()/180))*(-1),ABS(COS(B35*PI()/180))) -> -0.34202014 | D35: =IF( ISBLANK('Take-off'!C6), 'Take-off'!C7*-1, 'Take-off'!C7*C35) -> -2.394141
B36: Unfactorised | C36: Factorised
B40: Crosswind factor | C40: =IF(ABS(B35)>90,ABS(SIN(B35*PI()/180))*(-1),ABS(SIN(B35*PI()/180))) -> -0.93969262

Sheet TAKE OFF Performance FLAPS APPR
A1: TAKE OFF PERFORMANCE (FLAPS APPROACH)
A2: TAKE-OFF
A3: Mass | D3: Speeds | H3: Speeds
D4: V1/R | H4: V2
A5: 12000 | D5: 99 | H5: 108
A6: 13000 | D6: =((D7-D5)/($A7-$A5))*($A6-$A5)+D5 -> 99 | H6: =((H7-H5)/($A7-$A5))*($A6-$A5)+H5 -> 108
A7: 14000 | D7: 99 | H7: 108
A8: 15000 | D8: =((D9-D7)/($A9-$A7))*($A8-$A7)+D7 -> 101.5 | H8: =((H9-H7)/($A9-$A7))*($A8-$A7)+H7 -> 110
A9: 16000 | D9: 104 | H9: 112
A10: 16600 | D10: 105 | H10: 114
D12: Table size Vref | H12: V2
D13: Rows: | E13: =MATCH(MAX($A5:$A10),$A5:$A10,0) -> 6 | I13: =MATCH(MAX($A5:$A10),$A5:$A10,0) -> 6
D14: Columns: | E14: =MATCH(MAX(D5),D5,0) -> 1 | I14: =MATCH(MAX(H5),H5,0) -> 1
D16: x_n: | E16: =D4 -> V1/R | I16: =H4 -> V2
D17: y_n: | E17: ='Take-off'!$C$14 -> 15800 | I17: ='Take-off'!$C$14 -> 15800
D18: n1: | E18: {=INDEX($A5:$A10,MATCH(E17,$A5:$A10,1))} -> 15000 | I18: {=INDEX($A5:$A10,MATCH(I17,$A5:$A10,1))} -> 15000
D19: n2: | E19: {=INDEX($A5:$A10,IF(MATCH(E17,$A5:$A10,1)<E13,MATCH(E17,$A5:$A10,1)+1,MATCH(E17,$A5:$A10,1)))} -> 16000 | I19: {=INDEX($A5:$A10,IF(MATCH(I17,$A5:$A10,1)<I13,MATCH(I17,$A5:$A10,1)+1,MATCH(I17,$A5:$A10,1)))} -> 16000
D20: y1_n1: | E20: {=INDEX(D5:D10,MATCH(E17,$A5:$A10,1),MATCH(E16,D4,1))} -> 101.5 | I20: {=INDEX(H5:H10,MATCH(I17,$A5:$A10,1),MATCH(I16,H4,1))} -> 110
D21: y1_n2: | E21: {=INDEX(D5:D10,IF(MATCH(E17,$A5:$A10,1)<E13,MATCH(E17,$A5:$A10,1)+1,MATCH(E17,$A5:$A10,1)),MATCH(E16,D4,1))} -> 104 | I21: {=INDEX(H5:H10,IF(MATCH(I17,$A5:$A10,1)<I13,MATCH(I17,$A5:$A10,1)+1,MATCH(I17,$A5:$A10,1)),MATCH(I16,H4,1))} -> 112
D22: Vref: | E22: =IFERROR(E20+(E17-E18)*(E21-E20)/(E19-E18),E20) -> 103.5 | I22: =IFERROR(I20+(I17-I18)*(I21-I20)/(I19-I18),I20) -> 111.6
A26: Landing distance required calculations
B28: Flat | C28: Technique | D28: Slope | E28: Unfactored | F28: Factored
A29: Ground Roll | B29: ='Takeoff distance (2)'!AC75/3.28 -> 671.73077 | C29: =IF('Take-off'!$F$13='Dropdown lists'!$B$48, 500/3.28, 0) -> 152.43902 | D29: =IF('Take-off'!$C$17>0, ((+'Take-off'!$C$17*5)%*SUM(B29:C29)),0 ) -> 0 | E29: =SUM(B29:D29) -> 824.16979 | F29: {=_xlfn.XLOOKUP('Take-off'!$C$10,'Dropdown lists'!$B$4:$B$9,'Dropdown lists'!$D$4:$D$9)*E29} -> 881.86168
A30: Take off distance | B30: ='Takeoff distance (2)'!AC94/3.28 -> 1007.5962 | C30: =IF('Take-off'!$F$13='Dropdown lists'!$B$48, 500/3.28, 0) -> 152.43902 | D30: =IF('Take-off'!$C$17>0, ((+'Take-off'!$C$17*5)%*SUM(B30:C30)),0 ) -> 0 | E30: =SUM(B30:D30)*115% -> 1334.0405 | F30: {=_xlfn.XLOOKUP('Take-off'!$C$10,'Dropdown lists'!$B$4:$B$9,'Dropdown lists'!$D$4:$D$9)*E30} -> 1427.4233
A31: Accelerate GO DRY | B31: ='Accelerate and GO (2)'!AD75/3.28 -> 1627.6818 | C31: =IF('Take-off'!$F$13='Dropdown lists'!$B$48, 500/3.28, 0) -> 152.43902 | D31: =IF('Take-off'!$C$17>0, ((+'Take-off'!$C$17*5)%*SUM(B31:C31)),0 ) -> 0 | E31: =SUM(B31:D31) -> 1780.1208 | F31: {=_xlfn.XLOOKUP('Take-off'!$C$10,'Dropdown lists'!$B$4:$B$9,'Dropdown lists'!$D$4:$D$9)*E31} -> 1904.7292
A32: Accelerate GO WET/CONT | B32: =B31 -> 1627.6818 | C32: =IF('Take-off'!$F$13='Dropdown lists'!$B$48, 500/3.28, 0) -> 152.43902 | D32: =IF('Take-off'!$C$17>0, ((+'Take-off'!$C$17*5)%*SUM(B32:C32)),0 ) -> 0 | E32: =SUM(B32:D32) -> 1780.1208 | F32: {=_xlfn.XLOOKUP('Take-off'!$C$10,'Dropdown lists'!$B$4:$B$9,'Dropdown lists'!$D$4:$D$9)*E32} -> 1904.7292
A33: Accelerate STOP distance | B33: ='Accelerate and stop2'!AC76/3.28 -> 1191.9786 | C33: =IF('Take-off'!$F$13='Dropdown lists'!$B$48, 500/3.28, 0) -> 152.43902 | D33: =IF('Take-off'!$C$17>0, ((+'Take-off'!$C$17*5)%*SUM(B33:C33)),0 ) -> 0 | E33: =SUM(B33:D33) -> 1344.4176 | F33: {=_xlfn.XLOOKUP('Take-off'!$C$10,'Dropdown lists'!$B$4:$B$9,'Dropdown lists'!$D$4:$D$9)*E33} -> 1438.5269
B35: WCA | C35: Factor | D35: H/T wind
B36: =IF(ABS('Take-off'!C18-'Take-off'!C6)>270,360-ABS('Take-off'!C18-'Take-off'!C6),'Take-off'!C18-'Take-off'!C6) -> -110 | C36: =IF(ABS(B36)>90,ABS(COS(B36*PI()/180))*(-1),ABS(COS(B36*PI()/180))) -> -0.34202014 | D36: =IF( ISBLANK('Take-off'!C6), 'Take-off'!C7*-1, 'Take-off'!C7*C36) -> -2.394141
B41: Crosswind factor | C41: =IF(ABS(B36)>90,ABS(SIN(B36*PI()/180))*(-1),ABS(SIN(B36*PI()/180))) -> -0.93969262
A42: GRadient adjustments

Sheet Landing distance data
B1: Pressure Alt | C1: x_n: | D1: =IF(Landing!$C$9="",Landing!$C$15,MAX(0,Landing!$C$15+30*(1013-Landing!$C$9))) -> 770 | F1: EMG Return | G1: =IF('Take-off'!$C$9="",'Take-off'!$C$16,MAX(0,'Take-off'!$C$16+30*(1013-'Take-off'!$C$9))) -> 770
B2: Temp in calc | C2: y_n: | D2: =Landing!C8 -> 15 | G2: =MAX( IF('Take-off'!C13='Dropdown lists'!B30, 'Take-off'!$C$8+5, 'Take-off'!$C$8),0) -> 15
I5: EMG RETURN
C6: NORMAL
A8: Landing
B10: Density Altitude
B11: -500 | C11: 0 | D11: 1000 | E11: 2000 | F11: 3000 | G11: 3500
A12: -40 | B12: 1450 | C12: 1450 | D12: 1450 | E12: 1450 | F12: 1500 | G12: 99999
A13: -30 | B13: 1450 | C13: 1450 | D13: 1450 | E13: 1450 | F13: 1500 | G13: 99999
A14: -20 | B14: 1450 | C14: 1450 | D14: 1450 | E14: 1500 | F14: 1550 | G14: 99999
A15: -10 | B15: 1475 | C15: 1475 | D15: 1525 | E15: 1575 | F15: 1630 | G15: 99999
A16: 0 | B16: 1500 | C16: 1500 | D16: 1550 | E16: 1630 | F16: 1700 | G16: 99999
A17: 10 | B17: 1575 | C17: 1575 | D17: 1630 | E17: 1700 | F17: 1750 | G17: 99999
A18: 20 | B18: 1630 | C18: 1630 | D18: 1700 | E18: 1750 | F18: 1800 | G18: 99999
A19: 30 | B19: 1685 | C19: 1685 | D19: 1750 | E19: 1800 | F19: 1850 | G19: 99999
A20: 40 | B20: 1740 | C20: 1740 | D20: 1800 | E20: 1860 | F20: 1950 | G20: 99999
A21: 35 | B21: 99999 | C21: 99999 | D21: 99999 | E21: 99999 | F21: 99999 | G21: 99999
B23: x_n: | C23: =D1 -> 770 | D23: Table size | J23: x_n: | K23: =G1 -> 770 | L23: Table size
B24: x1_n: | C24: {=INDEX($B11:$G11,MATCH(C23,$B11:$G11,1))} -> 0 | D24: Rows: | E24: =MATCH(MAX($A12:$A21),$A12:$A21,1) -> 9 | J24: x1_n: | K24: {=INDEX($B11:$G11,MATCH(K23,$B11:$G11,1))} -> 0 | L24: Rows: | M24: =MATCH(MAX($A12:$A21),$A12:$A21,1) -> 9
B25: x2_n: | C25: {=INDEX($B11:$G11,IF(MATCH(C23,$B11:$G11,1)<E25,MATCH(C23,$B11:$G11,1)+1,MATCH(C23,$B11:$G11,1)))} -> 1000 | D25: Columns: | E25: =MATCH(MAX($B11:$G11),$B11:$G11,0) -> 6 | J25: x2_n: | K25: {=INDEX($B11:$G11,IF(MATCH(K23,$B11:$G11,1)<M25,MATCH(K23,$B11:$G11,1)+1,MATCH(K23,$B11:$G11,1)))} -> 1000 | L25: Columns: | M25: =MATCH(MAX($B11:$G11),$B11:$G11,0) -> 6
B26: y_n: | C26: =D2 -> 15 | J26: y_n: | K26: =G2 -> 15
B27: n1: | C27: {=INDEX($A12:$A21,MATCH(C26,$A12:$A21,1))} -> 10 | J27: n1: | K27: {=INDEX($A12:$A21,MATCH(K26,$A12:$A21,1))} -> 10
B28: n2: | C28: {=INDEX($A12:$A21,IF(MATCH(C26,$A12:$A21,1)<E24,MATCH(C26,$A12:$A21,1)+1,MATCH(C26,$A12:$A21,1)))} -> 20 | J28: n2: | K28: {=INDEX($A12:$A21,IF(MATCH(K26,$A12:$A21,1)<M24,MATCH(K26,$A12:$A21,1)+1,MATCH(K26,$A12:$A21,1)))} -> 20
B29: y1_n1: | C29: {=INDEX($B12:$G21,MATCH(C26,$A12:$A21,1),MATCH(C23,$B11:$G11,1))} -> 1575 | J29: y1_n1: | K29: {=INDEX($B12:$G21,MATCH(K26,$A12:$A21,1),MATCH(K23,$B11:$G11,1))} -> 1575
B30: y2_n1: | C30: {=INDEX($B12:$G21,MATCH(C26,$A12:$A21,1),IF(MATCH(C23,$B11:$G11,1)<E25,MATCH(C23,$B11:$G11,1)+1,MATCH(C26,$A12:$A21,1)))} -> 1630 | J30: y2_n1: | K30: {=INDEX($B12:$G21,MATCH(K26,$A12:$A21,1),IF(MATCH(K23,$B11:$G11,1)<M25,MATCH(K23,$B11:$G11,1)+1,MATCH(K26,$A12:$A21,1)))} -> 1630
B31: y1_n2: | C31: {=INDEX($B12:$G21,IF(MATCH(C26,$A12:$A21,1)<E24,MATCH(C26,$A12:$A21,1)+1,MATCH(C26,$A12:$A21,1)),MATCH(C23,$B11:$G11,1))} -> 1630 | J31: y1_n2: | K31: {=INDEX($B12:$G21,IF(MATCH(K26,$A12:$A21,1)<M24,MATCH(K26,$A12:$A21,1)+1,MATCH(K26,$A12:$A21,1)),MATCH(K23,$B11:$G11,1))} -> 1630
B32: y2_n2: | C32: {=INDEX($B12:$G21,IF(MATCH(C26,$A12:$A21,1)<E24,MATCH(C26,$A12:$A21,1)+1,MATCH(C26,$A12:$A21,1)),IF(MATCH(C23,$B11:$G11,1)<E25,MATCH(C23,$B11:$G11,1)+1,MATCH(C23,$B11:$G11,1)))} -> 1700 | J32: y2_n2: | K32: {=INDEX($B12:$G21,IF(MATCH(K26,$A12:$A21,1)<M24,MATCH(K26,$A12:$A21,1)+1,MATCH(K26,$A12:$A21,1)),IF(MATCH(K23,$B11:$G11,1)<M25,MATCH(K23,$B11:$G11,1)+1,MATCH(K23,$B11:$G11,1)))} -> 1700
B33: y_n1: | C33: =IFERROR(C29+(C23-C24)*(C30-C29)/(C25-C24),C29) -> 1617.35 | J33: y_n1: | K33: =IFERROR(K29+(K23-K24)*(K30-K29)/(K25-K24),K29) -> 1617.35
B34: y_n2: | C34: =IFERROR(C31+(C23-C24)*(C32-C31)/(C25-C24),C31) -> 1683.9 | J34: y_n2: | K34: =IFERROR(K31+(K23-K24)*(K32-K31)/(K25-K24),K31) -> 1683.9
B35: Distance | C35: =IFERROR(C33+(C26-C27)*(C34-C33)/(C28-C27),C33) -> 1650.625 | J35: Distance | K35: =IFERROR(K33+(K26-K27)*(K34-K33)/(K28-K27),K33) -> 1650.625
B37: Vikt
B38: 1400 | C38: 1650 | D38: 1900 | E38: 10500
A39: 10000 | B39: 870 | C39: 1030 | D39: 1170 | E39: 99999
A40: 11000 | B40: 975 | C40: 1130 | D40: 1300 | E40: 99999
A41: 12000 | B41: 1050 | C41: 1250 | D41: 1400 | E41: 99999
A42: 13000 | B42: 1100 | C42: 1330 | D42: 1515 | E42: 99999
A43: 14000 | B43: 1200 | C43: 1450 | D43: 1630 | E43: 99999
A44: 15000 | B44: 1300 | C44: 1540 | D44: 1750 | E44: 99999
A45: 16000 | B45: 1400 | C45: 1650 | D45: 1900 | E45: 99999
A46: 16600 | B46: 1450 | C46: 1700 | D46: 1970 | E46: 99999
...

Sheet Takeoff distance  contamined 2
B1: Pressure Alt | C1: x_n: | D1: =IF('Take-off'!$C$9="",'Take-off'!$C$16,MAX(0,'Take-off'!$C$16+30*(1013-'Take-off'!$C$9))) -> 770
B2: Temp in calc | C2: y_n: | D2: ='Take-off'!$C$8 -> 15
A4: Contaminated Runway - flaps take off | I4: Contaminated Runway - flaps take off | Q4: Contaminated Runway - flaps take off | Y4: Contaminated Runway - flaps take off | AG4: Contaminated Runway - flaps take off | AO4: Contaminated Runway - flaps take off | AW4: Wet Runway - flaps take off
A5: Aircraft WEIGHT: | I5: Aircraft WEIGHT: | Q5: Aircraft WEIGHT: | Y5: Aircraft WEIGHT: | AG5: Aircraft WEIGHT: | AO5: Aircraft WEIGHT: | AW5: Aircraft WEIGHT:
C6: 16600 | D6: Lbs | K6: 16000 | L6: Lbs | S6: 15000 | T6: Lbs | AA6: 14000 | AB6: Lbs | AI6: 13000 | AJ6: Lbs | AQ6: 12000 | AR6: Lbs | AY6: 13000 | AZ6: Lbs
A7: Ambient Temperature | C7: Field Elevation (ft.) | I7: Ambient Temperature | K7: Field Elevation (ft.) | Q7: Ambient Temperature | S7: Field Elevation (ft.) | Y7: Ambient Temperature | AA7: Field Elevation (ft.) | AG7: Ambient Temperature | AI7: Field Elevation (ft.) | AO7: Ambient Temperature | AQ7: Field Elevation (ft.) | AW7: Ambient Temperature | AY7: Field Elevation (ft.)
A9: °C | C9: 0 | D9: 1000 | E9: 2000 | F9: 3000 | G9: 4000 | I9: °C | K9: 0 | L9: 1000 | M9: 2000 | N9: 3000 | O9: 4000 | Q9: °C | S9: 0 | T9: 1000 | U9: 2000 | V9: 3000 | W9: 4000 | Y9: °C | AA9: 0 | AB9: 1000 | AC9: 2000 | AD9: 3000 | AE9: 4000 | AG9: °C | AI9: 0 | AJ9: 1000 | AK9: 2000 | AL9: 3000 | AM9: 4000 | AO9: °C | AQ9: 0 | AR9: 1000 | AS9: 2000 | AT9: 3000 | AU9: 4000 | AW9: °C | AY9: 0 | AZ9: 1000 | BA9: 2000 | BB9: 3000 | BC9: 4000
A10: -30 | C10: 5957 | D10: 6214 | E10: 6488 | F10: 6779 | G10: 99999 | I10: -30 | K10: 5679 | L10: 5922 | M10: 6179 | N10: 6453 | O10: 99999 | Q10: -30 | S10: 5234 | T10: 5454 | U10: 5687 | V10: 5933 | W10: 99999 | Y10: -30 | AA10: 4836 | AB10: 5034 | AC10: 5245 | AD10: 5468 | AE10: 99999 | AG10: -30 | AI10: 4538 | AJ10: 4700 | AK10: 4872 | AL10: 5055 | AM10: 99999 | AO10: -30 | AQ10: 4507 | AR10: 4664 | AS10: 4830 | AT10: 5005 | AU10: 99999 | AW10: 0 | BC10: 99999
A11: -25 | C11: 6100 | D11: 6365 | E11: 6646 | F11: 6948 | G11: 99999 | I11: -25 | K11: 5815 | L11: 6065 | M11: 6329 | N11: 6612 | O11: 99999 | Q11: -25 | S11: 5356 | T11: 5583 | U11: 5822 | V11: 6076 | W11: 99999 | Y11: -25 | AA11: 4946 | AB11: 5151 | AC11: 5367 | AD11: 5596 | AE11: 99999 | AG11: -25 | AI11: 4628 | AJ11: 4795 | AK11: 4972 | AL11: 5160 | AM11: 99999 | AO11: -25 | AQ11: 4594 | AR11: 4755 | AS11: 4926 | AT11: 5107 | AU11: 99999 | AW11: 10 | BC11: 99999
A12: -20 | C12: 6245 | D12: 6518 | E12: 6809 | F12: 7120 | G12: 99999 | I12: -20 | K12: 5951 | L12: 6208 | M12: 6481 | N12: 6774 | O12: 99999 | Q12: -20 | S12: 5480 | T12: 5713 | U12: 5958 | V12: 6221 | W12: 99999 | Y12: -20 | AA12: 5058 | AB12: 5268 | AC12: 5490 | AD12: 5728 | AE12: 99999 | AG12: -20 | AI12: 4719 | AJ12: 4891 | AK12: 5074 | AL12: 5273 | AM12: 99999 | AO12: -20 | AQ12: 4682 | AR12: 4848 | AS12: 5024 | AT12: 5210 | AU12: 99999 | BC12: 99999
A13: -15 | C13: 6391 | D13: 6673 | E13: 6972 | F13: 7294 | G13: 99999 | I13: -15 | K13: 6089 | L13: 6353 | M13: 6635 | N13: 6938 | O13: 99999 | Q13: -15 | S13: 5605 | T13: 5843 | U13: 6096 | V13: 6368 | W13: 99999 | Y13: -15 | AA13: 5170 | AB13: 5386 | AC13: 5614 | AD13: 5860 | AE13: 99999 | AG13: -15 | AI13: 4812 | AJ13: 4988 | AK13: 5175 | AL13: 5392 | AM13: 99999 | AO13: -15 | AQ13: 4771 | AR13: 4941 | AS13: 5122 | AT13: 5313 | AU13: 99999 | BC13: 99999
A14: -10 | C14: 6539 | D14: 6828 | E14: 7138 | F14: 7470 | G14: 99999 | I14: -10 | K14: 6227 | L14: 6500 | M14: 6791 | N14: 7103 | O14: 99999 | Q14: -10 | S14: 5730 | T14: 5975 | U14: 6236 | V14: 6517 | W14: 99999 | Y14: -10 | AA14: 5283 | AB14: 5505 | AC14: 5741 | AD14: 5992 | AE14: 99999 | AG14: -10 | AI14: 4904 | AJ14: 5086 | AK14: 5286 | AL14: 5512 | AM14: 99999 | AO14: -10 | AQ14: 4861 | AR14: 5036 | AS14: 5221 | AT14: 5417 | AU14: 99999 | BC14: 99999
A15: -5 | C15: 6688 | D15: 6986 | E15: 7306 | F15: 7647 | G15: 99999 | I15: -5 | K15: 6367 | L15: 6647 | M15: 6949 | N15: 7270 | O15: 99999 | Q15: -5 | S15: 5856 | T15: 6107 | U15: 6378 | V15: 6667 | W15: 99999 | Y15: -5 | AA15: 5397 | AB15: 5625 | AC15: 5869 | AD15: 6127 | AE15: 99999 | AG15: -5 | AI15: 4998 | AJ15: 5184 | AK15: 5401 | AL15: 5633 | AM15: 99999 | AO15: -5 | AQ15: 4951 | AR15: 5130 | AS15: 5321 | AT15: 5522 | AU15: 99999 | BC15: 99999
A16: 0 | C16: 6838 | D16: 7146 | E16: 7476 | F16: 7826 | G16: 99999 | I16: 0 | K16: 6509 | L16: 6799 | M16: 7109 | N16: 7439 | O16: 99999 | Q16: 0 | S16: 5983 | T16: 6243 | U16: 6522 | V16: 6819 | W16: 99999 | Y16: 0 | AA16: 5512 | AB16: 5747 | AC16: 5997 | AD16: 6263 | AE16: 99999 | AG16: 0 | AI16: 5092 | AJ16: 5291 | AK16: 5516 | AL16: 5755 | AM16: 99999 | AO16: 0 | AQ16: 5042 | AR16: 5226 | AS16: 5421 | AT16: 5628 | AU16: 99999 | BC16: 99999
A17: 5 | C17: 6990 | D17: 7308 | E17: 7646 | F17: 8006 | G17: 99999 | I17: 5 | K17: 6651 | L17: 6951 | M17: 7270 | N17: 7609 | O17: 99999 | Q17: 5 | S17: 6111 | T17: 6380 | U17: 6666 | V17: 6972 | W17: 99999 | Y17: 5 | AA17: 5628 | AB17: 5870 | AC17: 6126 | AD17: 6400 | AE17: 99999 | AG17: 5 | AI17: 5187 | AJ17: 5402 | AK17: 5633 | AL17: 5878 | AM17: 99999 | AO17: 5 | AQ17: 5133 | AR17: 5322 | AS17: 5522 | AT17: 5734 | AU17: 99999 | BC17: 99999
A18: 10 | C18: 7145 | D18: 7472 | E18: 7819 | F18: 8189 | G18: 99999 | I18: 10 | K18: 6797 | L18: 7105 | M18: 7432 | N18: 7781 | O18: 99999 | Q18: 10 | S18: 6241 | T18: 6518 | U18: 6813 | V18: 7127 | W18: 99999 | Y18: 10 | AA18: 5746 | AB18: 5994 | AC18: 6257 | AD18: 6540 | AE18: 99999 | AG18: 10 | AI18: 5290 | AJ18: 5513 | AK18: 5633 | AL18: 6001 | AM18: 99999 | AO18: 10 | AQ18: 5225 | AR18: 5419 | AS18: 5624 | AT18: 5841 | AU18: 99999 | BC18: 99999
A19: 15 | C19: 7301 | D19: 7636 | E19: 7993 | F19: 8373 | G19: 99999 | I19: 15 | K19: 6944 | L19: 7260 | M19: 7596 | N19: 7953 | O19: 99999 | Q19: 15 | S19: 6373 | T19: 6658 | U19: 6960 | V19: 7283 | W19: 99999 | Y19: 15 | AA19: 5864 | AB19: 6118 | AC19: 6390 | AD19: 6680 | AE19: 99999 | AG19: 15 | AI19: 5397 | AJ19: 5626 | AK19: 5868 | AL19: 6126 | AM19: 99999 | AO19: 15 | AQ19: 5318 | AR19: 5516 | AS19: 5727 | AT19: 5950 | AU19: 99999 | BC19: 99999
A20: 20 | C20: 7458 | D20: 7802 | E20: 8168 | F20: 8558 | G20: 99999 | I20: 20 | K20: 7092 | L20: 7416 | M20: 7761 | N20: 8128 | O20: 99999 | Q20: 20 | S20: 6507 | T20: 6798 | U20: 7110 | V20: 7440 | W20: 99999 | Y20: 20 | AA20: 5983 | AB20: 6244 | AC20: 6523 | AD20: 6822 | AE20: 99999 | AG20: 20 | AI20: 5504 | AJ20: 5739 | AK20: 5987 | AL20: 6253 | AM20: 99999 | AO20: 20 | AQ20: 5411 | AR20: 5613 | AS20: 5830 | AT20: 6058 | AU20: 99999 | AW20: 20 | BC20: 99999
A21: 25 | C21: 7617 | D21: 7969 | E21: 8345 | F21: 8757 | G21: 99999 | I21: 25 | K21: 7242 | L21: 7574 | M21: 7927 | N21: 8314 | O21: 99999 | Q21: 25 | S21: 6641 | T21: 6941 | U21: 7259 | V21: 7607 | W21: 99999 | Y21: 25 | AA21: 6103 | AB21: 6372 | AC21: 6659 | AD21: 6972 | AE21: 99999 | AG21: 25 | AI21: 5612 | AJ21: 5852 | AK21: 6108 | AL21: 6387 | AM21: 99999 | AO21: 25 | AQ21: 5505 | AR21: 5713 | AS21: 5934 | AT21: 6170 | AU21: 99999 | BC21: 99999
A22: 30 | C22: 7777 | D22: 8139 | E22: 8555 | F22: 99999 | G22: 99999 | I22: 30 | K22: 7392 | L22: 7733 | M22: 8124 | N22: 8610 | O22: 99999 | Q22: 30 | S22: 6777 | T22: 7084 | U22: 7434 | V22: 7863 | W22: 99999 | Y22: 30 | AA22: 6225 | AB22: 6501 | AC22: 6814 | AD22: 7194 | AE22: 99999 | AG22: 30 | AI22: 5721 | AJ22: 5967 | AK22: 6243 | AL22: 6578 | AM22: 99999 | AO22: 30 | AQ22: 5600 | AR22: 5813 | AS22: 6043 | AT22: 6170 | AU22: 99999 | AW22: 30 | BC22: 99999
A23: 40 | C23: 99999 | D23: 99999 | E23: 99999 | F23: 99999 | G23: 99999 | I23: 40 | K23: 99999 | L23: 99999 | M23: 99999 | N23: 99999 | O23: 99999 | Q23: 40 | S23: 99999 | T23: 99999 | U23: 99999 | V23: 99999 | W23: 99999 | Y23: 40 | AA23: 99999 | AB23: 99999 | AC23: 99999 | AD23: 99999 | AE23: 99999 | AG23: 40 | AI23: 99999 | AJ23: 99999 | AK23: 99999 | AL23: 99999 | AM23: 99999 | AO23: 40 | AQ23: 99999 | AR23: 99999 | AS23: 99999 | AT23: 99999 | AU23: 99999 | AW23: 40 | AY23: 99999 | AZ23: 99999 | BA23: 99999 | BB23: 99999 | BC23: 99999
C24: -- | D24: -- | E24: -- | F24: -- | G24: -- | K24: -- | L24: -- | M24: -- | N24: -- | O24: -- | S24: -- | T24: -- | U24: -- | V24: -- | W24: -- | AA24: -- | AB24: -- | AC24: -- | AD24: -- | AE24: -- | AI24: -- | AJ24: -- | AK24: -- | AL24: -- | AM24: -- | AQ24: -- | AR24: -- | AS24: -- | AT24: -- | AU24: -- | AY24: -- | AZ24: -- | BA24: -- | BB24: -- | BC24: --
B26: x_n: | C26: =$D$1 -> 770 | D26: Table size | J26: x_n: | K26: =$D$1 -> 770 | L26: Table size | R26: x_n: | S26: =$D$1 -> 770 | T26: Table size | Z26: x_n: | AA26: =$D$1 -> 770 | AB26: Table size | AH26: x_n: | AI26: =$D$1 -> 770 | AJ26: Table size | AP26: x_n: | AQ26: =$D$1 -> 770 | AR26: Table size | AX26: x_n: | AY26: =$D$1 -> 770 | AZ26: Table size
B27: x1_n: | C27: {=INDEX(C9:G9,MATCH(C26,C9:G9,1))} -> 0 | D27: Rows: | E27: =MATCH(MAX(A10:A24),A10:A24,0) -> 14 | J27: x1_n: | K27: {=INDEX(K9:O9,MATCH(K26,K9:O9,1))} -> 0 | L27: Rows: | M27: =MATCH(MAX(I10:I24),I10:I24,0) -> 14 | R27: x1_n: | S27: {=INDEX(S9:W9,MATCH(S26,S9:W9,1))} -> 0 | T27: Rows: | U27: =MATCH(MAX(Q10:Q24),Q10:Q24,0) -> 14 | Z27: x1_n: | AA27: {=INDEX(AA9:AE9,MATCH(AA26,AA9:AE9,1))} -> 0 | AB27: Rows: | AC27: =MATCH(MAX(Y10:Y24),Y10:Y24,0) -> 14 | AH27: x1_n: | AI27: {=INDEX(AI9:AM9,MATCH(AI26,AI9:AM9,1))} -> 0 | AJ27: Rows: | AK27: =MATCH(MAX(AG10:AG24),AG10:AG24,0) -> 14 | AP27: x1_n: | AQ27: {=INDEX(AQ9:AU9,MATCH(AQ26,AQ9:AU9,1))} -> 0 | AR27: Rows: | AS27: =MATCH(MAX(AO10:AO24),AO10:AO24,0) -> 14 | AX27: x1_n: | AY27: {=INDEX(AY9:BC9,MATCH(AY26,AY9:BC9,1))} -> 0 | AZ27: Rows: | BA27: =MATCH(MAX(AW10:AW24),AW10:AW24,0) -> 14
B28: x2_n: | C28: {=INDEX(C9:G9,IF(MATCH(C26,C9:G9,1)<E28,MATCH(C26,C9:G9,1)+1,MATCH(C26,C9:G9,1)))} -> 1000 | D28: Columns: | E28: =MATCH(MAX(C9:G9),C9:G9,0) -> 5 | J28: x2_n: | K28: {=INDEX(K9:O9,IF(MATCH(K26,K9:O9,1)<M28,MATCH(K26,K9:O9,1)+1,MATCH(K26,K9:O9,1)))} -> 1000 | L28: Columns: | M28: =MATCH(MAX(K9:O9),K9:O9,0) -> 5 | R28: x2_n: | S28: {=INDEX(S9:W9,IF(MATCH(S26,S9:W9,1)<U28,MATCH(S26,S9:W9,1)+1,MATCH(S26,S9:W9,1)))} -> 1000 | T28: Columns: | U28: =MATCH(MAX(S9:W9),S9:W9,0) -> 5 | Z28: x2_n: | AA28: {=INDEX(AA9:AE9,IF(MATCH(AA26,AA9:AE9,1)<AC28,MATCH(AA26,AA9:AE9,1)+1,MATCH(AA26,AA9:AE9,1)))} -> 1000 | AB28: Columns: | AC28: =MATCH(MAX(AA9:AE9),AA9:AE9,0) -> 5 | AH28: x2_n: | AI28: {=INDEX(AI9:AM9,IF(MATCH(AI26,AI9:AM9,1)<AK28,MATCH(AI26,AI9:AM9,1)+1,MATCH(AI26,AI9:AM9,1)))} -> 1000 | AJ28: Columns: | AK28: =MATCH(MAX(AI9:AM9),AI9:AM9,0) -> 5 | AP28: x2_n: | AQ28: {=INDEX(AQ9:AU9,IF(MATCH(AQ26,AQ9:AU9,1)<AS28,MATCH(AQ26,AQ9:AU9,1)+1,MATCH(AQ26,AQ9:AU9,1)))} -> 1000 | AR28: Columns: | AS28: =MATCH(MAX(AQ9:AU9),AQ9:AU9,0) -> 5 | AX28: x2_n: | AY28: {=INDEX(AY9:BC9,IF(MATCH(AY26,AY9:BC9,1)<BA28,MATCH(AY26,AY9:BC9,1)+1,MATCH(AY26,AY9:BC9,1)))} -> 1000 | AZ28: Columns: | BA28: =MATCH(MAX(AY9:BC9),AY9:BC9,0) -> 5
B29: y_n: | C29: =$D$2 -> 15 | J29: y_n: | K29: =$D$2 -> 15 | R29: y_n: | S29: =$D$2 -> 15 | Z29: y_n: | AA29: =$D$2 -> 15 | AH29: y_n: | AI29: =$D$2 -> 15 | AP29: y_n: | AQ29: =$D$2 -> 15 | AX29: y_n: | AY29: =$D$2 -> 15
B30: n1: | C30: {=INDEX(A10:A24,MATCH(C29,A10:A24,1))} -> 15 | J30: n1: | K30: {=INDEX(I10:I24,MATCH(K29,I10:I24,1))} -> 15 | R30: n1: | S30: {=INDEX(Q10:Q24,MATCH(S29,Q10:Q24,1))} -> 15 | Z30: n1: | AA30: {=INDEX(Y10:Y24,MATCH(AA29,Y10:Y24,1))} -> 15 | AH30: n1: | AI30: {=INDEX(AG10:AG24,MATCH(AI29,AG10:AG24,1))} -> 15 | AP30: n1: | AQ30: {=INDEX(AO10:AO24,MATCH(AQ29,AO10:AO24,1))} -> 15 | AX30: n1: | AY30: {=INDEX(AW10:AW24,MATCH(AY29,AW10:AW24,1))} -> 10
B31: n2: | C31: {=INDEX(A10:A24,IF(MATCH(C29,A10:A24,1)<E27,MATCH(C29,A10:A24,1)+1,MATCH(C29,A10:A24,1)))} -> 20 | J31: n2: | K31: {=INDEX(I10:I24,IF(MATCH(K29,I10:I24,1)<M27,MATCH(K29,I10:I24,1)+1,MATCH(K29,I10:I24,1)))} -> 20 | R31: n2: | S31: {=INDEX(Q10:Q24,IF(MATCH(S29,Q10:Q24,1)<U27,MATCH(S29,Q10:Q24,1)+1,MATCH(S29,Q10:Q24,1)))} -> 20 | Z31: n2: | AA31: {=INDEX(Y10:Y24,IF(MATCH(AA29,Y10:Y24,1)<AC27,MATCH(AA29,Y10:Y24,1)+1,MATCH(AA29,Y10:Y24,1)))} -> 20 | AH31: n2: | AI31: {=INDEX(AG10:AG24,IF(MATCH(AI29,AG10:AG24,1)<AK27,MATCH(AI29,AG10:AG24,1)+1,MATCH(AI29,AG10:AG24,1)))} -> 20 | AP31: n2: | AQ31: {=INDEX(AO10:AO24,IF(MATCH(AQ29,AO10:AO24,1)<AS27,MATCH(AQ29,AO10:AO24,1)+1,MATCH(AQ29,AO10:AO24,1)))} -> 20 | AX31: n2: | AY31: =INDEX(AW10:AW24,IF(MATCH(AY29,AW10:AW24,1)<BA27,MATCH(AY29,AW10:AW24,1)+1,MATCH(AY29,AW10:AW24,1))) -> 0
B32: y1_n1: | C32: {=INDEX(C10:G24,MATCH(C29,A10:A24,1),MATCH(C26,C9:G9,1))} -> 7301 | J32: y1_n1: | K32: {=INDEX(K10:O24,MATCH(K29,I10:I24,1),MATCH(K26,K9:O9,1))} -> 6944 | R32: y1_n1: | S32: {=INDEX(S10:W24,MATCH(S29,Q10:Q24,1),MATCH(S26,S9:W9,1))} -> 6373 | Z32: y1_n1: | AA32: {=INDEX(AA10:AE24,MATCH(AA29,Y10:Y24,1),MATCH(AA26,AA9:AE9,1))} -> 5864 | AH32: y1_n1: | AI32: {=INDEX(AI10:AM24,MATCH(AI29,AG10:AG24,1),MATCH(AI26,AI9:AM9,1))} -> 5397 | AP32: y1_n1: | AQ32: {=INDEX(AQ10:AU24,MATCH(AQ29,AO10:AO24,1),MATCH(AQ26,AQ9:AU9,1))} -> 5318 | AX32: y1_n1: | AY32: =INDEX(AY10:BC24,MATCH(AY29,AW10:AW24,1),MATCH(AY26,AY9:BC9,1)) -> 0
