Workbook

Sheet Take-off
B1: SE-LTL
B2: Take-off distance Beech 200 | F2: SE-LTL | G2: Version
B3: Interpoleringsverktyg för startsträcka från AFM. | G3: 46266
B4: Flygplats och bana: | C4: ESUP RWY 29
C5: ESUP 300450Z AUTO 00000KT 9999 ///////// M02/M02 Q1034
B6: Wind direction: | C6: =IFERROR(__xludf.DUMMYFUNCTION("IF(E6<>"""", E6, IF($G$8, E6, IFERROR(IF(REGEXMATCH(C5, ""\bVRB""), ""000"", VALUE(REGEXEXTRACT(C5, ""\b(\d{3})\d{2,3}(?:G\d{2,3})?(?:KT|MPS)\b""))), ""-"")))"),0.0) -> 0 | D6: ° | F6: =IF(C24<0, "Tailwind", "")
B7: Wind speed: | C7: =IFERROR(__xludf.DUMMYFUNCTION("IF(E7<>"""", E7, IF($G$8, E7, IFERROR(VALUE(REGEXEXTRACT(C5, ""\b(?:\d{3}|VRB)(\d{2,3})(?:G\d{2,3})?(?:KT|MPS)\b"")), ""-"")))"),0.0) -> 0 | D7: kt
B8: Outside air temperature: | C8: =IFERROR(__xludf.DUMMYFUNCTION("IF(E8<>"""", E8, IF($G$8, E8, IFERROR(VALUE(SUBSTITUTE(REGEXEXTRACT(C5, ""\b(M?\d{2})\/(?:M?\d{2})\b""), ""M"", ""-"")), ""-"")))"),-2.0) -> -2 | D8: °C | F8: Remove manual MET | G8: FALSE
B9: QNH | C9: =IFERROR(__xludf.DUMMYFUNCTION("IF(E9<>"""", E9, IF($G$8, E9, IFERROR(VALUE(REGEXEXTRACT(C5, ""\bQ(\d{4})\b"")), ""-"")))"),1034.0) -> 1034 | D9: Hpa
B10: Runway Condition Code | C10: 5 | E10: MANUAL MET -> | F10: REFRESH METAR | G10: FALSE
B11: Runway contaminant | C11: No contaminant
B12: Contaminant depth | C12: 0 | D12: mm | E12: Max: | F12: =VLOOKUP(C11,'Dropdown lists'!B34:F40,5,FALSE) -> N/A
B13: Engine Anti-ice | C13: OFF | I13: Engine anti-ice can be disregarded (OFF in calculation) whenever 3300 lbs/ft take-off power can be obtained
B14: Take off mass: | C14: 12500 | D14: Lbs
B15: Airport data (Expandable) | I15: Från 1900an. Men borde vara lika på alla om man får ut max torque. Men det är inte utskrivet vad jag sett.
B16: Treshold elevation: | C16: {=INDEX('Airport data'!$A$5:$L1006,MATCH($C$4,'Airport data'!$A$5:$A1006,0),2)} -> 541 | D16: ft
B17: Runway Slope: | C17: {=INDEX('Airport data'!$A$5:$L1006,MATCH($C$4,'Airport data'!$A$5:$A1006,0),7)} -> 0 | D17: % | E17: + = upphill
B18: RWY Heading: | C18: {=INDEX('Airport data'!$A$5:$L1006,MATCH($C$4,'Airport data'!$A$5:$A1006,0),8)} -> 285 | D18: °
B19: ASDA: | C19: {=INDEX('Airport data'!$A$5:$L1006,MATCH($C$4,'Airport data'!$A$5:$A1006,0),5)-10} -> 2290 | D19: m | E19: Req gradient: | G19: {=INDEX('Airport data'!$A$5:$L1006,MATCH($C$4,'Airport data'!$A$5:$A1006,0),9)} -> 3.3
B20: TORA: | C20: {=INDEX('Airport data'!$A$5:$L1006,MATCH($C$4,'Airport data'!$A$5:$A1006,0),3)-10} -> 2290 | D20: m
B21: TODA: | C21: {=INDEX('Airport data'!$A$5:$L1006,MATCH($C$4,'Airport data'!$A$5:$A1006,0),4)-10} -> 2290 | D21: m | E21: TOR | F21: =C35*1.15 -> 560.27439 | J21: villkorsberoende format wind, xwind, limit
B22: LDA: | C22: {=INDEX('Airport data'!$A$5:$L1006,MATCH($C$4,'Airport data'!$A$5:$A1006,0),6)} -> 2300 | D22: m | J22: Ny källa metar script landing
B23: Calculated data | J23: Jämförelse rätt metar
B24: Head/Tail wind | C24: ='LTL_TAKE OFF Performance FLAPS '!D34 -> 0 | D24: Kt
B25: Crosswind | C25: =ABS('LTL_TAKE OFF Performance FLAPS '!C39*C7) -> 0 | D25: Kt | E25: Limit | F25: {=IF(ISBLANK(#REF!), 25, INDEX('Dropdown lists'!$B$4:$D$10,MATCH(C10,'Dropdown lists'!$B$4:$B$10,0),3))} -> 25
B26: FLAPS: | C26: UP | D26: TAKE-OFF | E26: APP | G26: FULL
B27: Dry Runway (Expandable)
B28: Ground Roll [m] | C28: ='LTL_TAKE OFF Performance FLAPS '!G28 -> 487.19512
B29: Take off distance [m] | C29: =MAX('LTL_TAKE OFF Performance FLAPS '!G29:G30) -> 963.41463
B30: Accelerade & STOP [m] | C30: =MAX('LTL_TAKE OFF Performance FLAPS '!G32) -> 926.82927
B31: V1 [kts] | C31: ='LTL_TAKE OFF Performance FLAPS '!E$22 -> 94
B32: VR [kts] | C32: ='LTL_TAKE OFF Performance FLAPS '!E$22 -> 94
B33: V2 [kts] | C33: ='LTL_TAKE OFF Performance FLAPS '!I22 -> 103
B34: Selected contaminant
B35: Ground Roll [m] | C35: ='LTL_TAKE OFF Performance FLAPS '!Q28 -> 487.19512
B36: Take off distance [m] | C36: =MAX('LTL_TAKE OFF Performance FLAPS '!Q29:Q31) -> 963.41463
B37: Accelerade & STOP [m] | C37: =MAX('LTL_TAKE OFF Performance FLAPS '!Q32) -> 926.82927
B38: V1 [kts] | C38: ='LTL_TAKE OFF Performance FLAPS '!E$22 -> 94
B39: VR [kts] | C39: ='LTL_TAKE OFF Performance FLAPS '!E$22 -> 94
B40: V2 [kts] | C40: ='LTL_TAKE OFF Performance FLAPS '!I$22 -> 103 | I40: Standard Procedure Design Gradient (PDG): 3,3%
...

Sheet Landing
B2: Landning distance Beech 200 - SE-LTL | G2: Version
B3: Interpoleringsverktyg för landningsträcka | G3: 2026-XY-ZV
B4: Flygplats och bana: | C4: ESUP RWY 29
C5: ESUP 300450Z AUTO 00000KT 9999 ///////// M02/M02 Q1034
B6: Wind direction: | C6: =IFERROR(__xludf.DUMMYFUNCTION("IF(E6<>"""", E6, IF($G$8, E6, IFERROR(IF(REGEXMATCH(C5, ""\bVRB""), ""000"", VALUE(REGEXEXTRACT(C5, ""\b(\d{3})\d{2,3}(?:G\d{2,3})?(?:KT|MPS)\b""))), ""-"")))"),0.0) -> 0 | D6: ° | F6: =IF(C21<0, "Tailwind", "")
B7: Wind speed: | C7: =IFERROR(__xludf.DUMMYFUNCTION("IF(E7<>"""", E7, IF($G$8, E7, IFERROR(VALUE(REGEXEXTRACT(C5, ""\b(?:\d{3}|VRB)(\d{2,3})(?:G\d{2,3})?(?:KT|MPS)\b"")), ""-"")))"),0.0) -> 0 | D7: kt
B8: Outside air temperature: | C8: =IFERROR(__xludf.DUMMYFUNCTION("IF(E8<>"""", E8, IF($G$8, E8, IFERROR(VALUE(SUBSTITUTE(REGEXEXTRACT(C5, ""\b(M?\d{2})\/(?:M?\d{2})\b""), ""M"", ""-"")), ""-"")))"),-2.0) -> -2 | D8: °C | F8: Remove manual MET | G8: FALSE
B9: QNH | C9: =IFERROR(__xludf.DUMMYFUNCTION("IF(E9<>"""", E9, IF($G$8, E9, IFERROR(VALUE(REGEXEXTRACT(C5, ""\bQ(\d{4})\b"")), ""-"")))"),1034.0) -> 1034 | D9: Hpa
B10: Runway Condition Code | C10: 6 | E10: Manual MET -> | F10: REFRESH METAR | G10: FALSE
B11: Landing weight | C11: 12500 | D11: Lbs
B12: Max landing weight | C12: 12500 | D12: Lbs
B14: Airport data | C14: =IF(C11>C12, "Overweight landning","")
B15: Elevation: | C15: {=INDEX('Airport data'!$B$5:$H$43,MATCH($C$4,'Airport data'!$A$5:$A$43,0),1)} -> 541 | D15: ft
B16: Runway Slope: | C16: {=INDEX('Airport data'!$B$5:$H$43,MATCH($C$4,'Airport data'!$A$5:$A$43,0),5)} -> 2300 | D16: % | F16: + = upphill
B17: RWY Heading: | C17: {=INDEX('Airport data'!$B$5:$H$43,MATCH($C$4,'Airport data'!$A$5:$A$43,0),7)} -> 285 | D17: °
B18: LDA: | C18: {=INDEX('Airport data'!$B$5:$H$43,MATCH($C$4,'Airport data'!$A$5:$A$43,0),4)} -> 2300 | D18: m
B19: Calculated data
B20: Landing Distance Factor | C20: =IF( ISBLANK(Landing!C10),1.67, VLOOKUP(Landing!C10,'Dropdown lists'!B4:C10,2)) -> 1.67
B21: Head/Tail wind | C21: ='LTL_LDG Performance'!D32 -> 0 | D21: Kt
B22: Crosswind | C22: =ABS('LTL_LDG Performance'!C37*C7) -> 0 | D22: Kt | F22: Limit | G22: {=IF(ISBLANK(C10), 25, INDEX('Dropdown lists'!$B$4:$D$10,MATCH($C$10,'Dropdown lists'!$B$4:$B$10,0),3))} -> 25
B24: FLAPS: | C24: UP | D24: TAKE-OFF | F24: APP | G24: FULL
B25: Landing Distance
B26: VREF [kts] | C26: ='LTL_LDG Performance'!M21 -> 121 | G26: ='LTL_LDG Performance'!E21 -> 97
B27: Landing Distance factored [m] | C27: =('LTL_LDG Performance'!B88/3.28)*Landing!C20 -> 1926.5385 | G27: ='LTL_Landing distance data'!C102*C20 -> 1133.2579
B28: Flap Up based on AFM graph
C29: =IF(ISBLANK(C10), "Dry & Unfactored *1,67", "" )
B30: Missed approach
B31: OEI Climb Gradient [%] | C31: =IF( C21>0, 'LTL_OEI CLIMB GRADIENT'!P46*(125/(125+50%*C21)), 'LTL_OEI CLIMB GRADIENT'!P46*(125/(125-150%*C21)) ) -> 4.94 | D31: Gradient includes wind, 150% & 50%
C35: Flaps UP | D35: Flaps FULL
B36: LDA | C36: =Landing!$C$18 -> 2300 | D36: =Landing!$C$18 -> 2300
B37: Landing distance | C37: =C27 -> 1926.5385 | D37: =G27 -> 1133.2579

Sheet Airport data
A1: Airport | B1: Runway Threshold Elevation: | C1: TORA | D1: TODA | E1: ASDA | F1: LDA: | G1: RWY Slope: | H1: RWY HDG | I1: Minimum departure climb gradient, obstacles | J1: Uppdaterad | K1: ESCAPE ROUTE INFO
K2: Min cloud base | L2: Routing
B4: [ft] | C4: [m] | D4: [m] | E4: [m] | F4: [m] | G4: [%] | H4: [°] | I4: [%] | J4: [Date]
A5: No airport selected | B5: - | D5: - | E5: - | F5: - | G5: - | H5: - | J5: -
A6: Custom airport | B6: 200 | C6: 2000 | D6: 2000 | E6: 2000 | F6: 2000 | G6: 0 | H6: 120 | I6: 3.3 | K6: 666 | L6: Kör mot OY gör en racetrack entry och stig på QDR 090 till MSA. | N6: ÄNDRA ljusgröna RADER VID BEHOV
A8: ESKM RWY 16 | B8: 631 | C8: =D8 -> 1814 | D8: 1814 | E8: 1814 | F8: 1814 | G8: 0 | H8: 156 | I8: 5
A9: ESKM RWY 34 | B9: 618 | C9: =D9 -> 1814 | D9: 1814 | E9: 1814 | F9: 1814 | G9: 0 | H9: 336 | I9: 3.3
A10: ESND RWY 09 | B10: 1172 | C10: =D10 -> 1701 | D10: 1701 | E10: 1701 | F10: 1701 | G10: 0 | H10: 82 | I10: 3.3 | P10: ESSA
A11: ESND RWY 27 | B11: 1177 | C11: =D11 -> 1701 | D11: 1701 | E11: 1701 | F11: 1701 | G11: 0 | H11: 262 | I11: 3.3
A12: ESNU 14 B | B12: 25 | C12: =D12 -> 1721 | D12: 1721 | E12: 1721 | F12: 2302 | G12: 0 | H12: 130 | I12: 3.4 | J12: 45604
A13: ESNU 14 FULL | B13: 25 | C13: =D13 -> 2302 | D13: 2302 | E13: 2302 | F13: 2302 | G13: 0 | H13: 130 | I13: 3.4 | J13: 45604
A14: ESNU 32 | B14: 17 | C14: =D14 -> 2302 | D14: 2302 | E14: 2302 | F14: 2242 | G14: 0 | H14: 310 | I14: 3.3 | J14: 45604
A15: ESNU 32 D | B15: 17 | C15: =D15 -> 1599 | D15: 1599 | E15: 1599 | F15: 2242 | G15: 0 | H15: 310 | I15: 3.3 | J15: 45604
A16: ESNZ RWY 12 G | B16: 1194 | C16: =D16 -> 1907 | D16: 1907 | E16: 1907 | F16: 2500 | G16: 1.5 | H16: 109 | I16: 4.2
A17: ESNZ RWY 30 | B17: 1234 | C17: =D17 -> 2500 | D17: 2500 | E17: 2500 | F17: 2500 | G17: -1.5 | H17: 289 | I17: 3.5
A18: ESOH RWY 18 | B18: 474 | C18: =D18 -> 1508 | D18: 1508 | E18: 1508 | F18: 1508 | G18: 0 | H18: 172 | I18: 3.8
A19: ESOH RWY 36 | B19: 469 | C19: =D19 -> 1508 | D19: 1508 | E19: 1508 | F19: 1508 | G19: 0 | H19: 352 | I19: 5.5
A20: ESPA RWY 14 A3 | B20: 65 | C20: =D20 -> 2260 | D20: 2260 | E20: 3160 | F20: 3350 | G20: 0 | H20: 127 | I20: 3.3
A21: ESPA RWY 32 A5 | B21: 21 | C21: =D21 -> 2335 | D21: 2335 | E21: 2395 | F21: 3350 | G21: 0 | H21: 307 | I21: 3.3
A22: ESSA 01L FULL | B22: 98 | C22: =D22 -> 3301 | D22: 3301 | E22: 3301 | F22: 3301 | G22: 0 | H22: 4 | I22: 3.3
A23: ESSA 01L Y3 | B23: 98 | C23: =D23 -> 2276 | D23: 2276 | E23: 2276 | F23: 2500 | G23: 0 | H23: 4 | I23: 3.3
A24: ESSA 01R FULL | B24: 138 | C24: =D24 -> 2500 | D24: 2500 | E24: 2500 | F24: 2500 | G24: 0 | H24: 4 | I24: 3.3
A25: ESSA 01R W3 | B25: 138 | C25: =D25 -> 2147 | D25: 2147 | E25: 2147 | F25: 2147 | G25: 0 | H25: 4 | I25: 3.3
A26: ESSA 08 FULL | B26: 108 | C26: =D26 -> 2800 | D26: 2800 | E26: 2500 | F26: 2500 | G26: 0 | H26: 70 | I26: 3.3
A27: ESSA 08 X3 | B27: 108 | C27: =D27 -> 2179 | D27: 2179 | E27: 1879 | F27: 2500 | G27: 0 | H27: 70 | I27: 3.3
... A43: ESUP RWY 29 | B43: 541 | C43: =D43 -> 2300 | D43: 2300 | E43: 2300 | F43: 2300 | G43: 0 | H43: 285 | I43: 3.3
A44: ESUT RWY 15 | B44: 1503 | C44: 1594 | D44: 1594 | E44: 1594 | F44: 1445 | G44: 0 | H44: 150 | I44: 2.4 | K44: 150 | L44: Climb STRAIGHT ahead to "SUT" LOCATOR and enter published holding.
A46: Source: | B46: AIP | D46: AIP AD | E46: AIP AD | F46: AIP | G46: AIP AD 2.12 | H46: AIP | I46: Uträknat från AIP "AOC"

Sheet Dropdown lists
B1: Factors | D1: X-wind
B3: RWCC | C3: Faktor | D3: Limit
B4: 1 | C4: 2.9 | D4: 4
B5: 2 | C5: 2.7 | D5: 9
B6: 3 | C6: 2.4 | D6: 14
B7: 4 | C7: 2.2 | D7: 20
B8: 5 | C8: 2 | D8: 25
B9: 6 | C9: 1.67 | D9: 25
D10: 25
B12: FLAPS
B19: Runway take off
B27: Engine anti-ice
I29: =IF('Take-off'!$C$11='Dropdown lists'!B34,) -> FALSE
B30: ON
B31: OFF
B33: Runway contaminant | D33: Faktor | E33: Måttenhet | F33: Max
B34: Wet Runway | D34: 0 | F34: N/A
B35: Compacted snow | D35: 0 | F35: N/A
B36: Dry snow | D36: 0.005 | E36: mm | F36: N/A
B37: Wet snow | D37: 0.01 | E37: mm | F37: 50
B38: Slush | D38: 0.02 | E38: mm | F38: 25
B39: Standing water | D39: 0.02 | E39: mm | F39: 25
B40: No contaminant | D40: 0 | F40: N/A
B44: Technique
B47: Static T/O power
B48: Rolling take off

Sheet LTL_LDG Performance
A1: LANDING PERFORMANCE (Normal)
H2: EMG RETURN | I2: EMG RETURN | J2: FLAPS UP | K2: EMG RETURN | L2: FLAPS UP | M2: Normal
A3: Landing Mass | D3: Speeds | H3: Speeds | J3: Speeds | L3: Speeds
D4: Vref | H4: Vref | J4: Vref | L4: Vref
A5: 9000 | D5: 80 | H5: 80 | J5: 103 | L5: 103
A6: 10000 | D6: 85 | H6: 85 | J6: 108 | L6: 108
A7: 11000 | D7: 90 | H7: 90 | J7: 113 | L7: 113
A8: 12000 | D8: 95 | H8: 95 | J8: 119 | L8: 119
A9: 12500 | D9: 97 | H9: 97 | J9: 121 | L9: 121
A11: Table size Landing distance
B12: Rows: | C12: =MATCH(MAX(A5:A9),A5:A9,0) -> 5
B13: Columns: | C13: =MATCH(MAX(D5),D5,0) -> 1
D15: x_n: | E15: =D4 -> Vref | I15: =H4 -> Vref | K15: =J4 -> Vref | M15: =L4 -> Vref
D16: y_n: | E16: =Landing!C11 -> 12500 | I16: ='Take-off'!C14 -> 12500 | K16: ='Take-off'!C14 -> 12500 | M16: =Landing!C11 -> 12500
D17: n1: | E17: {=INDEX($A$5:$A$9,MATCH(E16,$A$5:$A$9,1))} -> 12500 | I17: {=INDEX($A$5:$A$9,MATCH(I16,$A$5:$A$9,1))} -> 12500 | K17: {=INDEX($A$5:$A$9,MATCH(K16,$A$5:$A$9,1))} -> 12500 | M17: {=INDEX($A$5:$A$9,MATCH(M16,$A$5:$A$9,1))} -> 12500
D18: n2: | E18: {=INDEX($A$5:$A$9,IF(MATCH(E16,$A$5:$A$9,1)<$C$12,MATCH(E16,$A$5:$A$9,1)+1,MATCH(E16,$A$5:$A$9,1)))} -> 12500 | I18: {=INDEX($A$5:$A$9,IF(MATCH(I16,$A$5:$A$9,1)<$C$12,MATCH(I16,$A$5:$A$9,1)+1,MATCH(I16,$A$5:$A$9,1)))} -> 12500 | K18: {=INDEX($A$5:$A$9,IF(MATCH(K16,$A$5:$A$9,1)<$C$12,MATCH(K16,$A$5:$A$9,1)+1,MATCH(K16,$A$5:$A$9,1)))} -> 12500 | M18: {=INDEX($A$5:$A$9,IF(MATCH(M16,$A$5:$A$9,1)<$C$12,MATCH(M16,$A$5:$A$9,1)+1,MATCH(M16,$A$5:$A$9,1)))} -> 12500
D19: y1_n1: | E19: {=INDEX(D5:D9,MATCH(E16,$A$5:$A$9,1),MATCH(E15,D4,1))} -> 97 | I19: {=INDEX(H5:H9,MATCH(I16,$A$5:$A$9,1),MATCH(I15,H4,1))} -> 97 | K19: {=INDEX(J5:J9,MATCH(K16,$A$5:$A$9,1),MATCH(K15,J4,1))} -> 121 | M19: {=INDEX(L5:L9,MATCH(M16,$A$5:$A$9,1),MATCH(M15,L4,1))} -> 121
D20: y1_n2: | E20: {=INDEX(D5:D9,IF(MATCH(E16,$A$5:$A$9,1)<$C$12,MATCH(E16,$A$5:$A$9,1)+1,MATCH(E16,$A$5:$A$9,1)),MATCH(E15,D4,1))} -> 97 | I20: {=INDEX(H5:H9,IF(MATCH(I16,$A$5:$A$9,1)<$C$12,MATCH(I16,$A$5:$A$9,1)+1,MATCH(I16,$A$5:$A$9,1)),MATCH(I15,H4,1))} -> 97 | K20: {=INDEX(J5:J9,IF(MATCH(K16,$A$5:$A$9,1)<$C$12,MATCH(K16,$A$5:$A$9,1)+1,MATCH(K16,$A$5:$A$9,1)),MATCH(K15,J4,1))} -> 121 | M20: {=INDEX(L5:L9,IF(MATCH(M16,$A$5:$A$9,1)<$C$12,MATCH(M16,$A$5:$A$9,1)+1,MATCH(M16,$A$5:$A$9,1)),MATCH(M15,L4,1))} -> 121
D21: Vref: | E21: =IFERROR(E19+(E16-E17)*(E20-E19)/(E18-E17),E19) -> 97 | I21: =IFERROR(I19+(I16-I17)*(I20-I19)/(I18-I17),I19) -> 97 | K21: =IFERROR(K19+(K16-K17)*(K20-K19)/(K18-K17),K19) -> 121 | M21: =IFERROR(M19+(M16-M17)*(M20-M19)/(M18-M17),M19) -> 121
B29: Windcalc
B31: WCA | C31: Factor | D31: H/T wind
B32: =IF(ABS(Landing!C17-Landing!C6)>270,360-ABS(Landing!C17-Landing!C6),Landing!C17-Landing!C6) -> 75 | C32: =IF(ABS(B32)>90,ABS(COS(B32*PI()/180))*(-1),ABS(COS(B32*PI()/180))) -> 0.25881905 | D32: =IF( ISBLANK(Landing!C6), Landing!C7*-1, Landing!C7*C32) -> 0
B37: Crosswind factor | C37: =IF(ABS(B32)>90,ABS(SIN(B32*PI()/180))*(-1),ABS(SIN(B32*PI()/180))) -> 0.96592583
A48: Emergency Return
B53: Unfactorised | C53: Factorised
B54: ='LTL_Landing distance data'!K102 -> 682.62195 | C54: =B54*C55 -> 1365.2439
B55: Landing Distance Factor: | C55: =IF( ISBLANK('Take-off'!C10),MIN('Dropdown lists'!C4:C10), VLOOKUP('Take-off'!C10,'Dropdown lists'!B4:C10,2)) -> 2
A66: LANDING PERFORMANCE (UP)
A68: Landing Distance Flaps LAND [feet] | B68: Landing distance | D68: EMG RETURN
B69: UP | D69: EMG RETURN
A70: 500 | B70: 850
A71: 1000 | B71: 1700
A72: 1500 | B72: 2550
A73: 2000 | B73: 3400
A74: 2500 | B74: 4250
A75: 2900 | B75: 5000 | G75: 2900Ft Max i grafen
A76: 3500 | B76: 99999
A78: Table size Landing distance
B79: Rows: | C79: =MATCH(MAX(A70:A76),A70:A76,0) -> 7
B80: Columns: | C80: =MATCH(MAX(B70),B70,0) -> 1
...

Sheet LTL_TAKE OFF Performance FLAPS 
A1: Take off PERFORMANCE (FLAPS UP)
A2: UP
A3: Landing Mass | D3: Speeds | H3: Speeds
D4: V1/R | H4: V2
A5: 9000 | D5: 94 | H5: 103
A6: 10000 | D6: 94 | H6: 103
A7: 11000 | D7: 94 | H7: 103
A8: 11500 | D8: 94 | H8: 103
A9: 12000 | D9: 94 | H9: 103
A10: 12500 | D10: 94 | H10: 103
D12: Table size Vref | H12: V2
D13: Rows: | E13: =MATCH(MAX($A5:$A10),$A5:$A10,0) -> 6 | I13: =MATCH(MAX($A5:$A10),$A5:$A10,0) -> 6
D14: Columns: | E14: =MATCH(MAX(D5),D5,0) -> 1 | I14: =MATCH(MAX(H5),H5,0) -> 1
D16: x_n: | E16: =D4 -> V1/R | I16: =H4 -> V2
D17: y_n: | E17: ='Take-off'!$C$14 -> 12500 | I17: ='Take-off'!$C$14 -> 12500
D18: n1: | E18: {=INDEX($A5:$A10,MATCH(E17,$A5:$A10,1))} -> 12500 | I18: {=INDEX($A5:$A10,MATCH(I17,$A5:$A10,1))} -> 12500
D19: n2: | E19: {=INDEX($A5:$A10,IF(MATCH(E17,$A5:$A10,1)<E13,MATCH(E17,$A5:$A10,1)+1,MATCH(E17,$A5:$A10,1)))} -> 12500 | I19: {=INDEX($A5:$A10,IF(MATCH(I17,$A5:$A10,1)<I13,MATCH(I17,$A5:$A10,1)+1,MATCH(I17,$A5:$A10,1)))} -> 12500
D20: y1_n1: | E20: {=INDEX(D5:D10,MATCH(E17,$A5:$A10,1),MATCH(E16,D4,1))} -> 94 | I20: {=INDEX(H5:H10,MATCH(I17,$A5:$A10,1),MATCH(I16,H4,1))} -> 103
D21: y1_n2: | E21: {=INDEX(D5:D10,IF(MATCH(E17,$A5:$A10,1)<E13,MATCH(E17,$A5:$A10,1)+1,MATCH(E17,$A5:$A10,1)),MATCH(E16,D4,1))} -> 94 | I21: {=INDEX(H5:H10,IF(MATCH(I17,$A5:$A10,1)<I13,MATCH(I17,$A5:$A10,1)+1,MATCH(I17,$A5:$A10,1)),MATCH(I16,H4,1))} -> 103
D22: Vref: | E22: =IFERROR(E20+(E17-E18)*(E21-E20)/(E19-E18),E20) -> 94 | I22: =IFERROR(I20+(I17-I18)*(I21-I20)/(I19-I18),I20) -> 103
A25: Landing distance required calculations
B27: Flat | C27: Teknik | D27: Runwayfactor <5 | E27: Runwayfactor <3 | F27: Slope | G27: Totalt | I27: Factor for Contaminant type | J27: Contaminant depth | K27: Tot before | L27: Correction | M27: Runwayfactor <5 | N27: Runwayfactor <3 | O27: Rulebased factor | P27: Correction 15ft istället för 35ft | Q27: Total contaminated
A28: Ground Roll | B28: ='LTL_Takeoff distance (2)'!C74/3.28 -> 487.19512 | C28: 0 | D28: N/A | E28: N/A | F28: =IF('Take-off'!$C$17>0, ((+'Take-off'!$C$17*5)%*SUM(B28:E28)),0 ) -> 0 | G28: =SUM(B28:F28) -> 487.19512 | I28: =VLOOKUP('Take-off'!$C$11, 'Dropdown lists'!$B$34:$D$40, 3, FALSE) -> 0 | J28: ='Take-off'!$C$12 -> 0 | K28: =SUM(B28:F28) -> 487.19512 | L28: =K28*(I28*J28) -> 0 | M28: =IF('Take-off'!$C$10<5, 30%*K28, 0) -> 0 | N28: =IF('Take-off'!$C$10<3, 20%*K28, 0) -> 0 | O28: 0 | Q28: =SUM(K28:O28) -> 487.19512
A29: Take off distance | B29: ='LTL_Takeoff distance (2)'!C93/3.28 -> 618.10976 | C29: 0 | D29: N/A | E29: N/A | F29: =IF('Take-off'!$C$17>0, ((+'Take-off'!$C$17*5)%*SUM(B29:E29)),0 ) -> 0 | G29: =SUM(B29:F29)*115% -> 710.82622 | I29: =VLOOKUP('Take-off'!$C$11, 'Dropdown lists'!$B$34:$D$40, 3, FALSE) -> 0 | J29: ='Take-off'!$C$12 -> 0 | K29: =SUM(B29:F29) -> 618.10976 | L29: =K29*(I29*J29) -> 0 | M29: =IF('Take-off'!$C$10<5, 30%*K29, 0) -> 0 | N29: =IF('Take-off'!$C$10<3, 20%*K29, 0) -> 0 | O29: =15%*SUM(K29:N29) -> 92.716463 | Q29: =SUM(K29:O29) -> 710.82622
A30: Accelerate GO DRY | B30: ='LTL_Accelerate and GO (2)'!C74/3.28 -> 963.41463 | C30: 0 | D30: N/A | E30: N/A | F30: =IF('Take-off'!$C$17>0, ((+'Take-off'!$C$17*5)%*SUM(B30:E30)),0 ) -> 0 | G30: =SUM(B30:F30) -> 963.41463 | I30: =VLOOKUP('Take-off'!$C$11, 'Dropdown lists'!$B$34:$D$40, 3, FALSE) -> 0 | J30: ='Take-off'!$C$12 -> 0 | K30: =SUM(B30:F30) -> 963.41463 | Q30: =G30 -> 963.41463
A31: Accelerate GO WET/CONT | B31: =B30 -> 963.41463 | C31: 0 | D31: N/A | E31: N/A | F31: =IF('Take-off'!$C$17>0, ((+'Take-off'!$C$17*5)%*SUM(B31:E31)),0 ) -> 0 | G31: =SUM(B31:F31) -> 963.41463 | H31: 35 fot | I31: =VLOOKUP('Take-off'!$C$11, 'Dropdown lists'!$B$34:$D$40, 3, FALSE) -> 0 | J31: ='Take-off'!$C$12 -> 0 | K31: =SUM(B31:F31) -> 963.41463 | L31: =K31*(I31*J31) -> 0 | M31: =IF('Take-off'!$C$10<5, 30%*K31, 0) -> 0 | N31: =IF('Take-off'!$C$10<3, 20%*K31, 0) -> 0 | O31: 0 | P31: =-20/('Take-off'!C42/100)/3.28 -> -110.06726 | Q31: =SUM(K31:P31) -> 853.34738
A32: Accelerate stop | B32: ='LTL_Accelerate and stop2'!C74/3.28 -> 926.82927 | C32: 0 | D32: N/A | E32: N/A | F32: =IF('Take-off'!$C$17>0, ((+'Take-off'!$C$17*5)%*SUM(B32:E32)),0 ) -> 0 | G32: =SUM(B32:F32) -> 926.82927 | I32: =VLOOKUP('Take-off'!$C$11, 'Dropdown lists'!$B$34:$D$40, 3, FALSE) -> 0 | J32: ='Take-off'!$C$12 -> 0 | K32: =SUM(B32:F32) -> 926.82927 | L32: =K32*(I32*J32) -> 0 | M32: =IF('Take-off'!$C$10<5, 30%*K32, 0) -> 0 | N32: =IF('Take-off'!$C$10<3, 20%*K32, 0) -> 0 | O32: 0 | Q32: =SUM(K32:O32) -> 926.82927
B33: WCA | C33: Factor | D33: H/T wind
B34: =IF(ABS('Take-off'!C18-'Take-off'!C6)>270,360-ABS('Take-off'!C18-'Take-off'!C6),'Take-off'!C18-'Take-off'!C6) -> 75 | C34: =IF(ABS(B34)>90,ABS(COS(B34*PI()/180))*(-1),ABS(COS(B34*PI()/180))) -> 0.25881905 | D34: =IF( ISBLANK('Take-off'!C6), 'Take-off'!C7*-1, 'Take-off'!C7*C34) -> 0
A35: TDR | B35: Unfactorised | C35: Factorised
B39: Crosswind factor | C39: =IF(ABS(B34)>90,ABS(SIN(B34*PI()/180))*(-1),ABS(SIN(B34*PI()/180))) -> 0.96592583

Sheet Blad3
A1: TAKE OFF PERFORMANCE (FLAPS APPROACH)
A2: TAKE-OFF
A3: Mass | D3: Speeds | H3: Speeds
D4: V1/R | H4: V2
A5: 9000 | D5: 1 | H5: 2
A6: 10000 | D6: 1 | H6: 2
A7: 11000 | D7: 1 | H7: 2
A8: 11500 | D8: 1 | H8: 2
A9: 12000 | D9: 1 | H9: 2
A10: 12500 | D10: 1 | H10: 2
D12: Table size Vref | H12: V2
D13: Rows: | E13: =MATCH(MAX($A5:$A10),$A5:$A10,0) -> 6 | I13: =MATCH(MAX($A5:$A10),$A5:$A10,0) -> 6
D14: Columns: | E14: =MATCH(MAX(D5),D5,0) -> 1 | I14: =MATCH(MAX(H5),H5,0) -> 1
D16: x_n: | E16: =D4 -> V1/R | I16: =H4 -> V2
D17: y_n: | E17: ='Take-off'!$C$14 -> 12500 | I17: ='Take-off'!$C$14 -> 12500
D18: n1: | E18: {=INDEX($A5:$A10,MATCH(E17,$A5:$A10,1))} -> 12500 | I18: {=INDEX($A5:$A10,MATCH(I17,$A5:$A10,1))} -> 12500
D19: n2: | E19: {=INDEX($A5:$A10,IF(MATCH(E17,$A5:$A10,1)<E13,MATCH(E17,$A5:$A10,1)+1,MATCH(E17,$A5:$A10,1)))} -> 12500 | I19: {=INDEX($A5:$A10,IF(MATCH(I17,$A5:$A10,1)<I13,MATCH(I17,$A5:$A10,1)+1,MATCH(I17,$A5:$A10,1)))} -> 12500
D20: y1_n1: | E20: {=INDEX(D5:D10,MATCH(E17,$A5:$A10,1),MATCH(E16,D4,1))} -> 1 | I20: {=INDEX(H5:H10,MATCH(I17,$A5:$A10,1),MATCH(I16,H4,1))} -> 2
D21: y1_n2: | E21: {=INDEX(D5:D10,IF(MATCH(E17,$A5:$A10,1)<E13,MATCH(E17,$A5:$A10,1)+1,MATCH(E17,$A5:$A10,1)),MATCH(E16,D4,1))} -> 1 | I21: {=INDEX(H5:H10,IF(MATCH(I17,$A5:$A10,1)<I13,MATCH(I17,$A5:$A10,1)+1,MATCH(I17,$A5:$A10,1)),MATCH(I16,H4,1))} -> 2
D22: Vref: | E22: =IFERROR(E20+(E17-E18)*(E21-E20)/(E19-E18),E20) -> 1 | I22: =IFERROR(I20+(I17-I18)*(I21-I20)/(I19-I18),I20) -> 2
A23: Windcorrected distances
A25: Landing distance required calculations
B27: Flat | C27: Technique | D27: Runwayfactor <5 | E27: Runwayfactor <3 | F27: Slope | G27: Totalt | I27: Factor for Contaminant type | J27: Contaminant depth | K27: Tot before | L27: Correction | M27: Runwayfactor <5 | N27: Runwayfactor <3 | O27: Rulebased factor | P27: Correction 15ft istället för 35ft | Q27: Total contaminated
A28: Take off distance | B28: ='LTL_Takeoff distance (2)'!AC93/3.28 -> #N/A | C28: =IF('Take-off'!#REF!='Dropdown lists'!$B$48, 500/3.28, 0) -> #ERROR! | D28: N/A | E28: N/A | F28: =IF('Take-off'!$C$17>0, ((+'Take-off'!$C$17*5)%*SUM(B28:E28)),0 ) -> 0 | G28: =SUM(B28:F28)*115% -> #N/A | I28: =VLOOKUP('Take-off'!$C$11, 'Dropdown lists'!$B$34:$D$40, 3, FALSE) -> 0 | J28: ='Take-off'!$C$12 -> 0 | K28: =SUM(B28:F28) -> #N/A | L28: =K28*(I28*J28) -> #N/A | M28: =IF('Take-off'!$C$10<5, 30%*K28, 0) -> 0 | N28: =IF('Take-off'!$C$10<3, 20%*K28, 0) -> 0 | O28: =15%*SUM(K28:N28) -> #N/A | Q28: =SUM(K28:O28) -> #N/A
A29: Accelerate STOP distance | B29: ='LTL_Accelerate and stop2'!AC74/3.28 -> #N/A | C29: =IF('Take-off'!#REF!='Dropdown lists'!$B$48, 500/3.28, 0) -> #ERROR! | D29: N/A | E29: N/A | F29: =IF('Take-off'!$C$17>0, ((+'Take-off'!$C$17*5)%*SUM(B29:E29)),0 ) -> 0 | G29: =SUM(B29:F29) -> #N/A | I29: =VLOOKUP('Take-off'!$C$11, 'Dropdown lists'!$B$34:$D$40, 3, FALSE) -> 0 | J29: ='Take-off'!$C$12 -> 0 | K29: =SUM(B29:F29) -> #N/A | L29: =K29*(I29*J29) -> #N/A | M29: =IF('Take-off'!$C$10<5, 30%*K29, 0) -> 0 | N29: =IF('Take-off'!$C$10<3, 20%*K29, 0) -> 0 | O29: 0 | Q29: =SUM(K29:O29) -> #N/A
A30: Accelerate GO DRY | B30: ='LTL_Accelerate and GO (2)'!AD74/3.28 -> #N/A | C30: =IF('Take-off'!#REF!='Dropdown lists'!$B$48, 500/3.28, 0) -> #ERROR! | D30: N/A | E30: N/A | F30: =IF('Take-off'!$C$17>0, ((+'Take-off'!$C$17*5)%*SUM(B30:E30)),0 ) -> 0 | G30: =SUM(B30:F30) -> #N/A | I30: =VLOOKUP('Take-off'!$C$11, 'Dropdown lists'!$B$34:$D$40, 3, FALSE) -> 0 | J30: ='Take-off'!$C$12 -> 0 | K30: =SUM(B30:F30) -> #N/A | L30: =K30*(I30*J30) -> #N/A | M30: =IF('Take-off'!$C$10<5, 30%*K30, 0) -> 0 | N30: =IF('Take-off'!$C$10<3, 20%*K30, 0) -> 0 | O30: 0 | Q30: =G30 -> #N/A
A31: Accelerate GO WET/CONT | B31: =B30 -> #N/A | C31: =IF('Take-off'!#REF!='Dropdown lists'!$B$48, 500/3.28, 0) -> #ERROR! | D31: N/A | E31: N/A | F31: =IF('Take-off'!$C$17>0, ((+'Take-off'!$C$17*5)%*SUM(B31:E31)),0 ) -> 0 | G31: =SUM(B31:F31) -> #N/A | H31: 35 fot | I31: =VLOOKUP('Take-off'!$C$11, 'Dropdown lists'!$B$34:$D$40, 3, FALSE) -> 0 | J31: ='Take-off'!$C$12 -> 0 | K31: =SUM(B31:F31) -> #N/A | L31: =K31*(I31*J31) -> #N/A | M31: =IF('Take-off'!$C$10<5, 30%*K31, 0) -> 0 | N31: =IF('Take-off'!$C$10<3, 20%*K31, 0) -> 0 | O31: 0 | P31: =-20/('Take-off'!E42/100)/3.28 -> #DIV/0! | Q31: =SUM(K31:P31) -> #N/A
B33: WCA | C33: Factor | D33: H/T wind
B34: =IF(ABS('Take-off'!C18-'Take-off'!C6)>270,360-ABS('Take-off'!C18-'Take-off'!C6),'Take-off'!C18-'Take-off'!C6) -> 75 | C34: =IF(ABS(B34)>90,ABS(COS(B34*PI()/180))*(-1),ABS(COS(B34*PI()/180))) -> 0.25881905 | D34: =IF( ISBLANK('Take-off'!C6), 'Take-off'!C7*-1, 'Take-off'!C7*C34) -> 0
B39: Crosswind factor | C39: =IF(ABS(B34)>90,ABS(SIN(B34*PI()/180))*(-1),ABS(SIN(B34*PI()/180))) -> 0.96592583
A40: GRadient adjustments

Sheet LTL_Landing distance data
B1: Pressure Alt | C1: x_n: | D1: =IF(Landing!$C$9="",Landing!$C$15,MAX(0,Landing!$C$15+30*(1013-Landing!$C$9))) -> 0 | F1: EMG Return | G1: =IF('Take-off'!$C$9="",'Take-off'!$C$16,MAX(0,'Take-off'!$C$16+30*(1013-'Take-off'!$C$9))) -> 0
B2: Temp in calc | C2: y_n: | D2: =Landing!C8 -> -2 | G2: =MAX( IF('Take-off'!C13='Dropdown lists'!B30, 'Take-off'!$C$8+5, 'Take-off'!$C$8),0) -> 0
I5: EMG RETURN
C6: NORMAL
A8: Landing
B10: Density Altitude
B11: 0 | C11: 1000 | D11: 2000 | E11: 3000 | F11: 3500
A12: -30 | B12: 800 | C12: 830 | D12: 860 | E12: 900 | F12: 99999
A13: -20 | B13: 800 | C13: 830 | D13: 860 | E13: 900 | F13: 99999
A14: -10 | B14: 810 | C14: 850 | D14: 900 | E14: 950 | F14: 99999
A15: 0 | B15: 830 | C15: 880 | D15: 915 | E15: 975 | F15: 99999
A16: 10 | B16: 850 | C16: 900 | D16: 930 | E16: 1000 | F16: 99999
A17: 20 | B17: 900 | C17: 950 | D17: 990 | E17: 1050 | F17: 99999
A18: 30 | B18: 910 | C18: 975 | D18: 1020 | E18: 1075 | F18: 99999
A19: 35 | B19: 99999 | C19: 99999 | D19: 99999 | E19: 99999 | F19: 99999
B21: x_n: | C21: =D1 -> 0 | D21: Table size | J21: x_n: | K21: =G1 -> 0 | L21: Table size
B22: x1_n: | C22: {=INDEX($B11:$F11,MATCH(C21,$B11:$F11,1))} -> 0 | D22: Rows: | E22: =MATCH(MAX($A12:$A19),$A12:$A19,1) -> 8 | J22: x1_n: | K22: {=INDEX($B11:$F11,MATCH(K21,$B11:$F11,1))} -> 0 | L22: Rows: | M22: =MATCH(MAX($A12:$A19),$A12:$A19,1) -> 8
B23: x2_n: | C23: {=INDEX($B11:$F11,IF(MATCH(C21,$B11:$F11,1)<E23,MATCH(C21,$B11:$F11,1)+1,MATCH(C21,$B11:$F11,1)))} -> 1000 | D23: Columns: | E23: =MATCH(MAX($B11:$F11),$B11:$F11,0) -> 5 | J23: x2_n: | K23: {=INDEX($B11:$F11,IF(MATCH(K21,$B11:$F11,1)<M23,MATCH(K21,$B11:$F11,1)+1,MATCH(K21,$B11:$F11,1)))} -> 1000 | L23: Columns: | M23: =MATCH(MAX($B11:$F11),$B11:$F11,0) -> 5
B24: y_n: | C24: =D2 -> -2 | J24: y_n: | K24: =G2 -> 0
B25: n1: | C25: {=INDEX($A12:$A19,MATCH(C24,$A12:$A19,1))} -> -10 | J25: n1: | K25: {=INDEX($A12:$A19,MATCH(K24,$A12:$A19,1))} -> 0
B26: n2: | C26: {=INDEX($A12:$A19,IF(MATCH(C24,$A12:$A19,1)<E22,MATCH(C24,$A12:$A19,1)+1,MATCH(C24,$A12:$A19,1)))} -> 0 | J26: n2: | K26: {=INDEX($A12:$A19,IF(MATCH(K24,$A12:$A19,1)<M22,MATCH(K24,$A12:$A19,1)+1,MATCH(K24,$A12:$A19,1)))} -> 10
B27: y1_n1: | C27: {=INDEX($B12:$F19,MATCH(C24,$A12:$A19,1),MATCH(C21,$B11:$F11,1))} -> 810 | J27: y1_n1: | K27: {=INDEX($B12:$F19,MATCH(K24,$A12:$A19,1),MATCH(K21,$B11:$F11,1))} -> 830
B28: y2_n1: | C28: {=INDEX($B12:$F19,MATCH(C24,$A12:$A19,1),IF(MATCH(C21,$B11:$F11,1)<E23,MATCH(C21,$B11:$F11,1)+1,MATCH(C24,$A12:$A19,1)))} -> 850 | J28: y2_n1: | K28: {=INDEX($B12:$F19,MATCH(K24,$A12:$A19,1),IF(MATCH(K21,$B11:$F11,1)<M23,MATCH(K21,$B11:$F11,1)+1,MATCH(K24,$A12:$A19,1)))} -> 880
B29: y1_n2: | C29: {=INDEX($B12:$F19,IF(MATCH(C24,$A12:$A19,1)<E22,MATCH(C24,$A12:$A19,1)+1,MATCH(C24,$A12:$A19,1)),MATCH(C21,$B11:$F11,1))} -> 830 | J29: y1_n2: | K29: {=INDEX($B12:$F19,IF(MATCH(K24,$A12:$A19,1)<M22,MATCH(K24,$A12:$A19,1)+1,MATCH(K24,$A12:$A19,1)),MATCH(K21,$B11:$F11,1))} -> 850
B30: y2_n2: | C30: {=INDEX($B12:$F19,IF(MATCH(C24,$A12:$A19,1)<E22,MATCH(C24,$A12:$A19,1)+1,MATCH(C24,$A12:$A19,1)),IF(MATCH(C21,$B11:$F11,1)<E23,MATCH(C21,$B11:$F11,1)+1,MATCH(C21,$B11:$F11,1)))} -> 880 | J30: y2_n2: | K30: {=INDEX($B12:$F19,IF(MATCH(K24,$A12:$A19,1)<M22,MATCH(K24,$A12:$A19,1)+1,MATCH(K24,$A12:$A19,1)),IF(MATCH(K21,$B11:$F11,1)<M23,MATCH(K21,$B11:$F11,1)+1,MATCH(K21,$B11:$F11,1)))} -> 900
B31: y_n1: | C31: =IFERROR(C27+(C21-C22)*(C28-C27)/(C23-C22),C27) -> 810 | J31: y_n1: | K31: =IFERROR(K27+(K21-K22)*(K28-K27)/(K23-K22),K27) -> 830
B32: y_n2: | C32: =IFERROR(C29+(C21-C22)*(C30-C29)/(C23-C22),C29) -> 830 | J32: y_n2: | K32: =IFERROR(K29+(K21-K22)*(K30-K29)/(K23-K22),K29) -> 850
B33: Distance | C33: =IFERROR(C31+(C24-C25)*(C32-C31)/(C26-C25),C31) -> 826 | J33: Distance | K33: =IFERROR(K31+(K24-K25)*(K32-K31)/(K26-K25),K31) -> 830
B35: Vikt
B36: 500 | C36: 1000 | D36: 1500 | E36: 2000
A37: 9000 | B37: 375 | C37: 690 | D37: 1090 | E37: 99999
A38: 9500 | B38: 390 | C38: 750 | D38: 1150 | E38: 99999
A39: 10000 | B39: 400 | C39: 780 | D39: 1200 | E39: 99999
A40: 10500 | B40: 410 | C40: 810 | D40: 1250 | E40: 99999
A41: 11000 | B41: 440 | C41: 850 | D41: 1320 | E41: 99999
A42: 11500 | B42: 475 | C42: 900 | D42: 1390 | E42: 99999
A43: 12000 | B43: 490 | C43: 950 | D43: 1450 | E43: 99999
A44: 12500 | B44: 500 | C44: 1000 | D44: 1500 | E44: 99999
B46: x_n: | C46: =C33 -> 826 | D46: Table size | J46: x_n: | K46: =K33 -> 830 | L46: Table size
B47: x1_n: | C47: {=INDEX($B36:$E36,MATCH(C46,$B36:$E36,1))} -> 500 | D47: Rows: | E47: =MATCH(MAX($A37:$A44),$A37:$A44,1) -> 8 | J47: x1_n: | K47: {=INDEX($B36:$E36,MATCH(K46,$B36:$E36,1))} -> 500 | L47: Rows: | M47: =MATCH(MAX($A37:$A44),$A37:$A44,1) -> 8
...

Sheet LTL_Accelerate and GO (2)
B1: Pressure Alt | C1: x_n: | D1: =IF('Take-off'!$C$9="",'Take-off'!$C$16,MAX(0,'Take-off'!$C$16+30*(1013-'Take-off'!$C$9))) -> 0
B2: Temp in calc | C2: y_n: | D2: =IF('Take-off'!C13='Dropdown lists'!B30, 'Take-off'!$C$8+6, 'Take-off'!$C$8) -> -2 | E2: Includes ICE-Vane. Could be disregarded for us
B3: FLAPS UP | O3: FLAPS TAKEOFF | AB3: FLAPS APPROACH
B4: Density altitude | O4: Density altitude | AB4: Density altitude
A5: Temp/PA | B5: 0 | C5: 1000 | D5: 2000 | E5: 3000 | F5: 4000 | N5: Temp/PA | O5: 0 | P5: 1000 | Q5: 2000 | R5: 3000 | S5: 4000 | AA5: Temp/PA | AB5: 0 | AC5: 1000 | AD5: 2000 | AE5: 3000 | AF5: 4000
A6: -30 | B6: 2700 | C6: 2800 | D6: 2900 | E6: 3200 | F6: 99999 | N6: -30 | S6: 99999 | AA6: -30 | AF6: 99999
A7: -20 | B7: 2800 | C7: 2980 | D7: 3100 | E7: 3400 | F7: 99999 | N7: -20 | S7: 99999 | AA7: -20 | AF7: 99999
A8: -10 | B8: 3000 | C8: 3200 | D8: 3400 | E8: 3600 | F8: 99999 | N8: -10 | S8: 99999 | AA8: -10 | AF8: 99999
A9: 0 | B9: 3200 | C9: 3400 | D9: 3600 | E9: 3900 | F9: 99999 | N9: 0 | S9: 99999 | AA9: 0 | AF9: 99999
A10: 10 | B10: 3370 | C10: 3600 | D10: 3800 | E10: 4200 | F10: 99999 | N10: 10 | S10: 99999 | AA10: 10 | AF10: 99999
A11: 20 | B11: 3570 | C11: 3800 | D11: 4150 | E11: 4700 | F11: 99999 | N11: 20 | S11: 99999 | AA11: 20 | AF11: 99999
A12: 30 | B12: 3800 | C12: 4200 | D12: 4600 | E12: 5300 | F12: 99999 | AA12: 30 | AF12: 99999
A13: 40 | B13: 4400 | C13: 5000 | D13: 5600 | E13: 6800 | F13: 99999 | N13: 30 | S13: 99999 | AA13: 40 | AF13: 99999
A14: 35 | B14: 99999 | C14: 99999 | D14: 99999 | E14: 99999 | F14: 99999 | N14: 35 | O14: 99999 | P14: 99999 | Q14: 99999 | R14: 99999 | S14: 99999 | AA14: 45 | AB14: 99999 | AC14: 99999 | AD14: 99999 | AE14: 99999 | AF14: 99999
B16: x_n: | C16: =D1 -> 0 | D16: Table size | O16: x_n: | P16: =D1 -> 0 | Q16: Table size | AB16: x_n: | AC16: =D1 -> 0 | AD16: Table size
B17: x1_n: | C17: {=INDEX(B5:F5,MATCH(C16,B5:F5,1))} -> 0 | D17: Rows: | E17: =MATCH(MAX(A6:A14),A6:A14,1) -> 9 | O17: x1_n: | P17: {=INDEX(O5:S5,MATCH(P16,O5:S5,1))} -> 0 | Q17: Rows: | R17: =MATCH(MAX(N6:N14),N6:N14,1) -> 9 | AB17: x1_n: | AC17: {=INDEX(AB5:AF5,MATCH(AC16,AB5:AF5,1))} -> 0 | AD17: Rows: | AE17: =MATCH(MAX(AA6:AA14),AA6:AA14,1) -> 9
B18: x2_n: | C18: {=INDEX(B5:F5,IF(MATCH(C16,B5:F5,1)<E18,MATCH(C16,B5:F5,1)+1,MATCH(C16,B5:F5,1)))} -> 1000 | D18: Columns: | E18: =MATCH(MAX(B5:F5),B5:F5,0) -> 5 | O18: x2_n: | P18: {=INDEX(O5:S5,IF(MATCH(P16,O5:S5,1)<R18,MATCH(P16,O5:S5,1)+1,MATCH(P16,O5:S5,1)))} -> 1000 | Q18: Columns: | R18: =MATCH(MAX(O5:S5),O5:S5,0) -> 5 | AB18: x2_n: | AC18: {=INDEX(AB5:AF5,IF(MATCH(AC16,AB5:AF5,1)<AE18,MATCH(AC16,AB5:AF5,1)+1,MATCH(AC16,AB5:AF5,1)))} -> 1000 | AD18: Columns: | AE18: =MATCH(MAX(AB5:AF5),AB5:AF5,0) -> 5
B19: y_n: | C19: =D2 -> -2 | O19: y_n: | P19: =D2 -> -2 | AB19: y_n: | AC19: =D2 -> -2
B20: n1: | C20: {=INDEX(A6:A14,MATCH(C19,A6:A14,1))} -> -10 | O20: n1: | P20: {=INDEX(N6:N14,MATCH(P19,N6:N14,1))} -> -10 | AB20: n1: | AC20: {=INDEX(AA6:AA14,MATCH(AC19,AA6:AA14,1))} -> -10
B21: n2: | C21: {=INDEX(A6:A14,IF(MATCH(C19,A6:A14,1)<E17,MATCH(C19,A6:A14,1)+1,MATCH(C19,A6:A14,1)))} -> 0 | O21: n2: | P21: {=INDEX(N6:N14,IF(MATCH(P19,N6:N14,1)<R17,MATCH(P19,N6:N14,1)+1,MATCH(P19,N6:N14,1)))} -> 0 | AB21: n2: | AC21: {=INDEX(AA6:AA14,IF(MATCH(AC19,AA6:AA14,1)<AE17,MATCH(AC19,AA6:AA14,1)+1,MATCH(AC19,AA6:AA14,1)))} -> 0
B22: y1_n1: | C22: {=INDEX(B6:F14,MATCH(C19,A6:A14,1),MATCH(C16,B5:F5,1))} -> 3000 | O22: y1_n1: | P22: {=INDEX(O6:S14,MATCH(P19,N6:N14,1),MATCH(P16,O5:S5,1))} | AB22: y1_n1: | AC22: {=INDEX(AB6:AF14,MATCH(AC19,AA6:AA14,1),MATCH(AC16,AB5:AF5,1))}
B23: y2_n1: | C23: {=INDEX(B6:F14,MATCH(C19,A6:A14,1),IF(MATCH(C16,B5:F5,1)<E18,MATCH(C16,B5:F5,1)+1,MATCH(C19,A6:A14,1)))} -> 3200 | O23: y2_n1: | P23: {=INDEX(O6:S14,MATCH(P19,N6:N14,1),IF(MATCH(P16,O5:S5,1)<R18,MATCH(P16,O5:S5,1)+1,MATCH(P19,N6:N14,1)))} | AB23: y2_n1: | AC23: {=INDEX(AB6:AF14,MATCH(AC19,AA6:AA14,1),IF(MATCH(AC16,AB5:AF5,1)<AE18,MATCH(AC16,AB5:AF5,1)+1,MATCH(AC19,AA6:AA14,1)))}
B24: y1_n2: | C24: {=INDEX(B6:F14,IF(MATCH(C19,A6:A14,1)<E17,MATCH(C19,A6:A14,1)+1,MATCH(C19,A6:A14,1)),MATCH(C16,B5:F5,1))} -> 3200 | O24: y1_n2: | P24: {=INDEX(O6:S14,IF(MATCH(P19,N6:N14,1)<R17,MATCH(P19,N6:N14,1)+1,MATCH(P19,N6:N14,1)),MATCH(P16,O5:S5,1))} | AB24: y1_n2: | AC24: {=INDEX(AB6:AF14,IF(MATCH(AC19,AA6:AA14,1)<AE17,MATCH(AC19,AA6:AA14,1)+1,MATCH(AC19,AA6:AA14,1)),MATCH(AC16,AB5:AF5,1))}
B25: y2_n2: | C25: {=INDEX(B6:F14,IF(MATCH(C19,A6:A14,1)<E17,MATCH(C19,A6:A14,1)+1,MATCH(C19,A6:A14,1)),IF(MATCH(C16,B5:F5,1)<E18,MATCH(C16,B5:F5,1)+1,MATCH(C16,B5:F5,1)))} -> 3400 | O25: y2_n2: | P25: {=INDEX(O6:S14,IF(MATCH(P19,N6:N14,1)<R17,MATCH(P19,N6:N14,1)+1,MATCH(P19,N6:N14,1)),IF(MATCH(P16,O5:S5,1)<R18,MATCH(P16,O5:S5,1)+1,MATCH(P16,O5:S5,1)))} | AB25: y2_n2: | AC25: {=INDEX(AB6:AF14,IF(MATCH(AC19,AA6:AA14,1)<AE17,MATCH(AC19,AA6:AA14,1)+1,MATCH(AC19,AA6:AA14,1)),IF(MATCH(AC16,AB5:AF5,1)<AE18,MATCH(AC16,AB5:AF5,1)+1,MATCH(AC16,AB5:AF5,1)))}
B26: y_n1: | C26: =IFERROR(C22+(C16-C17)*(C23-C22)/(C18-C17),C22) -> 3000 | O26: y_n1: | P26: =IFERROR(P22+(P16-P17)*(P23-P22)/(P18-P17),P22) -> 0 | AB26: y_n1: | AC26: =IFERROR(AC22+(AC16-AC17)*(AC23-AC22)/(AC18-AC17),AC22) -> 0
B27: y_n2: | C27: =IFERROR(C24+(C16-C17)*(C25-C24)/(C18-C17),C24) -> 3200 | O27: y_n2: | P27: =IFERROR(P24+(P16-P17)*(P25-P24)/(P18-P17),P24) -> 0 | AB27: y_n2: | AC27: =IFERROR(AC24+(AC16-AC17)*(AC25-AC24)/(AC18-AC17),AC24) -> 0
B28: Distance | C28: =IFERROR(C26+(C19-C20)*(C27-C26)/(C21-C20),C26) -> 3160 | O28: Distance | P28: =IFERROR(P26+(P19-P20)*(P27-P26)/(P21-P20),P26) -> 0 | AB28: Distance | AC28: =IFERROR(AC26+(AC19-AC20)*(AC27-AC26)/(AC21-AC20),AC26) -> 0
B30: Vikt | O30: Vikt | AB30: Vikt
A31: % | B31: 2000 | C31: 3000 | D31: 4000 | E31: 5000 | F31: 6000 | G31: 7000 | H31: 8000 | P31: % | Q31: 2000 | R31: 3000 | S31: 4000 | T31: 4500 | AD31: % | AE31: 4000 | AF31: 5000 | AG31: 6100 | AH31: 7200 | AI31: 8300 | AJ31: 9400 | AK31: 10000
A32: 9000 | B32: 1200 | C32: 1760 | D32: 2200 | E32: 2600 | F32: 3000 | G32: 3400 | H32: 99999 | P32: 10000 | T32: 99999 | AD32: 9000 | AK32: 99999
A33: 9500 | B33: 1250 | C33: 1800 | D33: 2400 | E33: 2800 | F33: 3200 | G33: 3600 | H33: 99999 | P33: 11000 | T33: 99999 | AD33: 9500 | AK33: 99999
A34: 10000 | B34: 1300 | C34: 2000 | D34: 2600 | E34: 3100 | F34: 3600 | G34: 4000 | H34: 99999 | P34: 12000 | T34: 99999 | AD34: 10000 | AK34: 99999
A35: 10500 | B35: 1400 | C35: 2200 | D35: 2820 | E35: 3400 | F35: 3900 | G35: 4400 | H35: 99999 | P35: 13000 | T35: 99999 | AD35: 10500 | AK35: 99999
A36: 11000 | B36: 1600 | C36: 2350 | D36: 3200 | E36: 3700 | F36: 4400 | G36: 4900 | H36: 99999 | P36: 14000 | T36: 99999 | AD36: 11000 | AK36: 99999
A37: 11500 | B37: 1700 | C37: 2600 | D37: 3400 | E37: 4100 | F37: 4800 | G37: 5450 | H37: 99999 | P37: 15000 | T37: 99999 | AD37: 11500 | AK37: 99999
A38: 12000 | B38: 1810 | C38: 2780 | D38: 3700 | E38: 4500 | F38: 5400 | G38: 6200 | H38: 99999 | P38: 16000 | T38: 99999 | AD38: 12000 | AK38: 99999
A39: 12500 | B39: 2000 | C39: 3000 | D39: 4000 | E39: 5000 | F39: 6000 | G39: 7000 | H39: 99999 | P39: 16600 | T39: 99999 | AD39: 12500 | AK39: 99999
A40: 12600 | B40: 99999 | C40: 99999 | D40: 99999 | E40: 99999 | F40: 99999 | G40: 99999 | H40: 99999 | P40: 16700 | Q40: 99999 | R40: 99999 | S40: 99999 | T40: 99999 | AD40: 12600 | AE40: 99999 | AF40: 99999 | AG40: 99999 | AH40: 99999 | AI40: 99999 | AJ40: 99999 | AK40: 99999
B42: x_n: | C42: =C28 -> 3160 | D42: Table size | O42: x_n: | P42: =P28 -> 0 | Q42: Table size | AB42: x_n: | AC42: =AC28 -> 0 | AD42: Table size
B43: x1_n: | C43: {=INDEX(B31:H31,MATCH(C42,B31:H31,1))} -> 3000 | D43: Rows: | E43: =MATCH(MAX(A32:A40),A32:A40,1) -> 9 | O43: x1_n: | P43: {=INDEX(Q31:T31,MATCH(P42,Q31:T31,1))} -> #N/A | Q43: Rows: | R43: =MATCH(MAX(P32:P40),P32:P40,1) -> 9 | AB43: x1_n: | AC43: {=INDEX(AE31:AK31,MATCH(AC42,AE31:AK31,1))} -> #N/A | AD43: Rows: | AE43: =MATCH(MAX(AD32:AD40),AD32:AD40,1) -> 9
...

Sheet LTL_Accelerate and stop2
B1: Pressure Alt | C1: x_n: | D1: =IF('Take-off'!$C$9="",'Take-off'!$C$16,MAX(0,'Take-off'!$C$16+30*(1013-'Take-off'!$C$9))) -> 0
B2: Temp in calc | C2: y_n: | D2: =IF('Take-off'!C13='Dropdown lists'!B30, 'Take-off'!$C$8, 'Take-off'!$C$8) -> -2
B3: FLAPS UP | O3: FLAPS TAKEOFF | AB3: FLAPS APPROACH
B4: Density altitude | O4: Density altitude | AB4: Density altitude
A5: Temp/PA | B5: 0 | C5: 1000 | D5: 2000 | E5: 3000 | F5: 4000 | N5: Temp/PA | O5: 0 | P5: 1000 | Q5: 2000 | R5: 3000 | S5: 4000 | AA5: Temp/PA | AB5: 0 | AC5: 1000 | AD5: 2000 | AE5: 3000 | AF5: 4000
A6: -30 | B6: 2800 | C6: 2900 | D6: 3000 | E6: 3120 | F6: 99999 | N6: -30 | S6: 99999 | AA6: -30 | AF6: 99999
A7: -20 | B7: 2800 | C7: 2900 | D7: 3050 | E7: 3200 | F7: 99999 | N7: -20 | S7: 99999 | AA7: -20 | AF7: 99999
A8: -10 | B8: 2900 | C8: 3100 | D8: 3200 | E8: 3310 | F8: 99999 | N8: -10 | S8: 99999 | AA8: -10 | AF8: 99999
A9: 0 | B9: 3075 | C9: 3200 | D9: 3300 | E9: 3490 | F9: 99999 | N9: 0 | S9: 99999 | AA9: 0 | AF9: 99999
A10: 10 | B10: 3200 | C10: 3350 | D10: 3450 | E10: 3650 | F10: 99999 | N10: 10 | S10: 99999 | AA10: 10 | AF10: 99999
A11: 20 | B11: 3300 | C11: 3480 | D11: 3600 | E11: 3800 | F11: 99999 | N11: 20 | S11: 99999 | AA11: 20 | AF11: 99999
A12: 30 | B12: 3450 | C12: 3650 | D12: 3800 | E12: 4050 | F12: 99999 | AA12: 30 | AF12: 99999
A13: 40 | B13: 3650 | C13: 3850 | D13: 4100 | E13: 4350 | F13: 99999 | N13: 30 | S13: 99999 | AA13: 40 | AF13: 99999
A14: 45 | B14: 99999 | C14: 99999 | D14: 99999 | E14: 99999 | F14: 99999 | N14: 35 | O14: 99999 | P14: 99999 | Q14: 99999 | R14: 99999 | S14: 99999 | AA14: 45 | AB14: 99999 | AC14: 99999 | AD14: 99999 | AE14: 99999 | AF14: 99999
B16: x_n: | C16: =D1 -> 0 | D16: Table size | O16: x_n: | P16: =D1 -> 0 | Q16: Table size | AB16: x_n: | AC16: =D1 -> 0 | AD16: Table size
B17: x1_n: | C17: {=INDEX(B5:F5,MATCH(C16,B5:F5,1))} -> 0 | D17: Rows: | E17: =MATCH(MAX(A6:A14),A6:A14,1) -> 9 | O17: x1_n: | P17: {=INDEX(O5:S5,MATCH(P16,O5:S5,1))} -> 0 | Q17: Rows: | R17: =MATCH(MAX(N6:N14),N6:N14,1) -> 9 | AB17: x1_n: | AC17: {=INDEX(AB5:AF5,MATCH(AC16,AB5:AF5,1))} -> 0 | AD17: Rows: | AE17: =MATCH(MAX(AA6:AA14),AA6:AA14,1) -> 9
B18: x2_n: | C18: {=INDEX(B5:F5,IF(MATCH(C16,B5:F5,1)<E18,MATCH(C16,B5:F5,1)+1,MATCH(C16,B5:F5,1)))} -> 1000 | D18: Columns: | E18: =MATCH(MAX(B5:F5),B5:F5,0) -> 5 | O18: x2_n: | P18: {=INDEX(O5:S5,IF(MATCH(P16,O5:S5,1)<R18,MATCH(P16,O5:S5,1)+1,MATCH(P16,O5:S5,1)))} -> 1000 | Q18: Columns: | R18: =MATCH(MAX(O5:S5),O5:S5,0) -> 5 | AB18: x2_n: | AC18: {=INDEX(AB5:AF5,IF(MATCH(AC16,AB5:AF5,1)<AE18,MATCH(AC16,AB5:AF5,1)+1,MATCH(AC16,AB5:AF5,1)))} -> 1000 | AD18: Columns: | AE18: =MATCH(MAX(AB5:AF5),AB5:AF5,0) -> 5
B19: y_n: | C19: =D2 -> -2 | O19: y_n: | P19: =D2 -> -2 | AB19: y_n: | AC19: =D2 -> -2
B20: n1: | C20: {=INDEX(A6:A14,MATCH(C19,A6:A14,1))} -> -10 | O20: n1: | P20: {=INDEX(N6:N14,MATCH(P19,N6:N14,1))} -> -10 | AB20: n1: | AC20: {=INDEX(AA6:AA14,MATCH(AC19,AA6:AA14,1))} -> -10
B21: n2: | C21: {=INDEX(A6:A14,IF(MATCH(C19,A6:A14,1)<E17,MATCH(C19,A6:A14,1)+1,MATCH(C19,A6:A14,1)))} -> 0 | O21: n2: | P21: {=INDEX(N6:N14,IF(MATCH(P19,N6:N14,1)<R17,MATCH(P19,N6:N14,1)+1,MATCH(P19,N6:N14,1)))} -> 0 | AB21: n2: | AC21: {=INDEX(AA6:AA14,IF(MATCH(AC19,AA6:AA14,1)<AE17,MATCH(AC19,AA6:AA14,1)+1,MATCH(AC19,AA6:AA14,1)))} -> 0
B22: y1_n1: | C22: {=INDEX(B6:F14,MATCH(C19,A6:A14,1),MATCH(C16,B5:F5,1))} -> 2900 | O22: y1_n1: | P22: {=INDEX(O6:S14,MATCH(P19,N6:N14,1),MATCH(P16,O5:S5,1))} | AB22: y1_n1: | AC22: {=INDEX(AB6:AF14,MATCH(AC19,AA6:AA14,1),MATCH(AC16,AB5:AF5,1))}
B23: y2_n1: | C23: {=INDEX(B6:F14,MATCH(C19,A6:A14,1),IF(MATCH(C16,B5:F5,1)<E18,MATCH(C16,B5:F5,1)+1,MATCH(C19,A6:A14,1)))} -> 3100 | O23: y2_n1: | P23: {=INDEX(O6:S14,MATCH(P19,N6:N14,1),IF(MATCH(P16,O5:S5,1)<R18,MATCH(P16,O5:S5,1)+1,MATCH(P19,N6:N14,1)))} | AB23: y2_n1: | AC23: {=INDEX(AB6:AF14,MATCH(AC19,AA6:AA14,1),IF(MATCH(AC16,AB5:AF5,1)<AE18,MATCH(AC16,AB5:AF5,1)+1,MATCH(AC19,AA6:AA14,1)))}
B24: y1_n2: | C24: {=INDEX(B6:F14,IF(MATCH(C19,A6:A14,1)<E17,MATCH(C19,A6:A14,1)+1,MATCH(C19,A6:A14,1)),MATCH(C16,B5:F5,1))} -> 3075 | O24: y1_n2: | P24: {=INDEX(O6:S14,IF(MATCH(P19,N6:N14,1)<R17,MATCH(P19,N6:N14,1)+1,MATCH(P19,N6:N14,1)),MATCH(P16,O5:S5,1))} | AB24: y1_n2: | AC24: {=INDEX(AB6:AF14,IF(MATCH(AC19,AA6:AA14,1)<AE17,MATCH(AC19,AA6:AA14,1)+1,MATCH(AC19,AA6:AA14,1)),MATCH(AC16,AB5:AF5,1))}
B25: y2_n2: | C25: {=INDEX(B6:F14,IF(MATCH(C19,A6:A14,1)<E17,MATCH(C19,A6:A14,1)+1,MATCH(C19,A6:A14,1)),IF(MATCH(C16,B5:F5,1)<E18,MATCH(C16,B5:F5,1)+1,MATCH(C16,B5:F5,1)))} -> 3200 | O25: y2_n2: | P25: {=INDEX(O6:S14,IF(MATCH(P19,N6:N14,1)<R17,MATCH(P19,N6:N14,1)+1,MATCH(P19,N6:N14,1)),IF(MATCH(P16,O5:S5,1)<R18,MATCH(P16,O5:S5,1)+1,MATCH(P16,O5:S5,1)))} | AB25: y2_n2: | AC25: {=INDEX(AB6:AF14,IF(MATCH(AC19,AA6:AA14,1)<AE17,MATCH(AC19,AA6:AA14,1)+1,MATCH(AC19,AA6:AA14,1)),IF(MATCH(AC16,AB5:AF5,1)<AE18,MATCH(AC16,AB5:AF5,1)+1,MATCH(AC16,AB5:AF5,1)))}
B26: y_n1: | C26: =IFERROR(C22+(C16-C17)*(C23-C22)/(C18-C17),C22) -> 2900 | O26: y_n1: | P26: =IFERROR(P22+(P16-P17)*(P23-P22)/(P18-P17),P22) -> 0 | AB26: y_n1: | AC26: =IFERROR(AC22+(AC16-AC17)*(AC23-AC22)/(AC18-AC17),AC22) -> 0
B27: y_n2: | C27: =IFERROR(C24+(C16-C17)*(C25-C24)/(C18-C17),C24) -> 3075 | O27: y_n2: | P27: =IFERROR(P24+(P16-P17)*(P25-P24)/(P18-P17),P24) -> 0 | AB27: y_n2: | AC27: =IFERROR(AC24+(AC16-AC17)*(AC25-AC24)/(AC18-AC17),AC24) -> 0
B28: Distance | C28: =IFERROR(C26+(C19-C20)*(C27-C26)/(C21-C20),C26) -> 3040 | O28: Distance | P28: =IFERROR(P26+(P19-P20)*(P27-P26)/(P21-P20),P26) -> 0 | AB28: Distance | AC28: =IFERROR(AC26+(AC19-AC20)*(AC27-AC26)/(AC21-AC20),AC26) -> 0
B30: Vikt | O30: Vikt | AB30: Vikt
A31: % | B31: 2500 | C31: 3000 | D31: 3500 | E31: 4000 | F31: 4500 | G31: 5000 | N31: % | O31: 3600 | P31: 4300 | Q31: 5000 | R31: 5700 | S31: 6000 | AA31: % | AB31: 3000 | AC31: 3450 | AD31: 3900 | AE31: 4350 | AF31: 4800 | AG31: 5000
A32: 9000 | B32: 2200 | C32: 2700 | D32: 3050 | E32: 3400 | F32: 3900 | G32: 99999 | N32: 10000 | S32: 99999 | AA32: 9000 | AG32: 99999
A33: 9500 | B33: 2250 | C33: 2750 | D33: 3110 | E33: 3500 | F33: 3950 | G33: 99999 | N33: 11000 | S33: 99999 | AA33: 9500 | AG33: 99999
A34: 10000 | B34: 2290 | C34: 2780 | D34: 3190 | E34: 3600 | F34: 4000 | G34: 99999 | N34: 12000 | S34: 99999 | AA34: 10000 | AG34: 99999
A35: 10500 | B35: 2310 | C35: 2800 | D35: 3250 | E35: 3675 | F35: 4100 | G35: 99999 | N35: 13000 | S35: 99999 | AA35: 10500 | AG35: 99999
A36: 11000 | B36: 2375 | C36: 2850 | D36: 3300 | E36: 3750 | F36: 4200 | G36: 99999 | N36: 14000 | S36: 99999 | AA36: 11000 | AG36: 99999
A37: 11500 | B37: 2400 | C37: 2900 | D37: 3380 | E37: 3820 | F37: 4300 | G37: 99999 | N37: 15000 | S37: 99999 | AA37: 11500 | AG37: 99999
A38: 12000 | B38: 2450 | C38: 2950 | D38: 3450 | E38: 3910 | F38: 4400 | G38: 99999 | N38: 16000 | S38: 99999 | AA38: 12000 | AG38: 99999
A39: 12500 | B39: 2500 | C39: 3000 | D39: 3500 | E39: 4000 | F39: 4500 | G39: 99999 | N39: 16600 | S39: 99999 | AA39: 12500 | AG39: 99999
A40: 12600 | B40: 99999 | C40: 99999 | D40: 99999 | E40: 99999 | F40: 99999 | G40: 99999 | N40: 16700 | O40: 99999 | P40: 99999 | Q40: 99999 | R40: 99999 | S40: 99999 | AA40: 12600 | AB40: 99999 | AC40: 99999 | AD40: 99999 | AE40: 99999 | AF40: 99999 | AG40: 99999
B42: x_n: | C42: =C28 -> 3040 | D42: Table size | O42: x_n: | P42: =P28 -> 0 | Q42: Table size | AB42: x_n: | AC42: =AC28 -> 0 | AD42: Table size
B43: x1_n: | C43: {=INDEX(B31:G31,MATCH(C42,B31:G31,1))} -> 3000 | D43: Rows: | E43: =MATCH(MAX(A32:A40),A32:A40,1) -> 9 | O43: x1_n: | P43: {=INDEX(O31:S31,MATCH(P42,O31:S31,1))} -> #N/A | Q43: Rows: | R43: =MATCH(MAX(N32:N40),N32:N40,1) -> 9 | AB43: x1_n: | AC43: {=INDEX(AB31:AG31,MATCH(AC42,AB31:AG31,1))} -> #N/A | AD43: Rows: | AE43: =MATCH(MAX(AA32:AA40),AA32:AA40,1) -> 9
...

Sheet LTL_OEI CLIMB GRADIENT
B1: Pressure Alt | C1: x_n: | D1: =IF(Landing!$C$9="",Landing!$C$15,MAX(0,Landing!$C$15+30*(1013-Landing!$C$9))) -> 0
B2: Temp in calc | C2: y_n: | D2: =Landing!C8 -> -2
B3: NET GRADIENT OF CLIMB - FLAPS UP
B4: Density altitude
A5: Temp/PA | B5: 0 | C5: 1000 | D5: 2000 | E5: 3000 | F5: 4000
A6: -30 | B6: 790 | C6: 780 | D6: 760 | E6: 750 | F6: 0
A7: -20 | B7: 770 | C7: 760 | D7: 740 | E7: 730 | F7: 0
A8: -10 | B8: 760 | C8: 740 | D8: 730 | E8: 710 | F8: 0
A9: 0 | B9: 740 | C9: 725 | D9: 710 | E9: 690 | F9: 0
A10: 10 | B10: 720 | C10: 710 | D10: 690 | E10: 670 | F10: 0
A11: 20 | B11: 700 | C11: 690 | D11: 670 | E11: 650 | F11: 0
A12: 30 | B12: 680 | C12: 670 | D12: 660 | E12: 620 | F12: 0
A13: 40 | B13: 665 | C13: 620 | D13: 580 | E13: 530 | F13: 0
A14: 45 | B14: 0 | C14: 0 | D14: 0 | E14: 0 | F14: 0
B16: x_n: | C16: =D1 -> 0 | D16: Table size
B17: x1_n: | C17: {=INDEX(B5:F5,MATCH(C16,B5:F5,1))} -> 0 | D17: Rows: | E17: =MATCH(MAX(A6:A14),A6:A14,1) -> 9
B18: x2_n: | C18: {=INDEX(B5:F5,IF(MATCH(C16,B5:F5,1)<E18,MATCH(C16,B5:F5,1)+1,MATCH(C16,B5:F5,1)))} -> 1000 | D18: Columns: | E18: =MATCH(MAX(B5:F5),B5:F5,0) -> 5
B19: y_n: | C19: =D2 -> -2
B20: n1: | C20: {=INDEX(A6:A14,MATCH(C19,A6:A14,1))} -> -10
B21: n2: | C21: {=INDEX(A6:A14,IF(MATCH(C19,A6:A14,1)<E17,MATCH(C19,A6:A14,1)+1,MATCH(C19,A6:A14,1)))} -> 0
B22: y1_n1: | C22: {=INDEX(B6:F14,MATCH(C19,A6:A14,1),MATCH(C16,B5:F5,1))} -> 760
B23: y2_n1: | C23: {=INDEX(B6:F14,MATCH(C19,A6:A14,1),IF(MATCH(C16,B5:F5,1)<E18,MATCH(C16,B5:F5,1)+1,MATCH(C19,A6:A14,1)))} -> 740
B24: y1_n2: | C24: {=INDEX(B6:F14,IF(MATCH(C19,A6:A14,1)<E17,MATCH(C19,A6:A14,1)+1,MATCH(C19,A6:A14,1)),MATCH(C16,B5:F5,1))} -> 740
B25: y2_n2: | C25: {=INDEX(B6:F14,IF(MATCH(C19,A6:A14,1)<E17,MATCH(C19,A6:A14,1)+1,MATCH(C19,A6:A14,1)),IF(MATCH(C16,B5:F5,1)<E18,MATCH(C16,B5:F5,1)+1,MATCH(C16,B5:F5,1)))} -> 725
B26: y_n1: | C26: =IFERROR(C22+(C16-C17)*(C23-C22)/(C18-C17),C22) -> 760
B27: y_n2: | C27: =IFERROR(C24+(C16-C17)*(C25-C24)/(C18-C17),C24) -> 740
B28: Distance | C28: =IFERROR(C26+(C19-C20)*(C27-C26)/(C21-C20),C26) -> 744
B30: ROC | O30: ROC->Gradient
A31: % | B31: 500 | C31: 600 | D31: 700 | E31: 800 | F31: 900 | Q31: % | R31: 440 | S31: 500 | T31: 550 | U31: 650 | V31: 760 | W31: 860 | X31: 960 | Y31: 1060 | Z31: 1160 | AA31: 1200 | AB31: 1200
A32: 9000 | B32: 1050 | C32: 1150 | D32: 1200 | E32: 1200 | F32: 0 | Q32: 1 | R32: 3 | S32: 3.5 | T32: 4 | U32: 5 | V32: 6 | W32: 7 | X32: 8 | Y32: 9 | Z32: 10 | AA32: 10.5 | AB32: 11
A33: 9500 | B33: 940 | C33: 1050 | D33: 1180 | E33: 1200 | F33: 0
A34: 10000 | B34: 860 | C34: 960 | D34: 1080 | E34: 1200 | F34: 0 | P34: x_n: | Q34: =C54 -> 644 | R34: Table size
A35: 10500 | B35: 775 | C35: 880 | D35: 950 | E35: 1100 | F35: 0 | P35: x1_n: | Q35: {=INDEX(R31:AB31,MATCH(Q34,R31:AB31,1))} -> 550 | R35: Rows: | S35: =MATCH(MAX(Q32),Q32,1) -> 1
A36: 11000 | B36: 700 | C36: 800 | D36: 910 | E36: 1020 | F36: 0 | P36: x2_n: | Q36: {=INDEX(R31:AB31,IF(MATCH(Q34,R31:AB31,1)<S36,MATCH(Q34,R31:AB31,1)+1,MATCH(Q34,R31:AB31,1)))} -> 650 | R36: Columns: | S36: =MATCH(MAX(R31:AB31),R31:AB31,0) -> 10
A37: 11500 | B37: 630 | C37: 725 | D37: 830 | E37: 940 | F37: 0 | P37: y_n: | Q37: 1
A38: 12000 | B38: 560 | C38: 660 | D38: 760 | E38: 865 | F38: 0 | P38: n1: | Q38: {=INDEX(Q32,MATCH(Q37,Q32,1))} -> 1
A39: 12500 | B39: 500 | C39: 600 | D39: 700 | E39: 800 | F39: 0 | P39: n2: | Q39: {=INDEX(Q32,IF(MATCH(Q37,Q32,1)<S35,MATCH(Q37,Q32,1)+1,MATCH(Q37,Q32,1)))} -> 1
O40: y1_n1: | P40: {=INDEX(R32:AB32,MATCH(Q37,Q32,1),MATCH(Q34,R31:AB31,1))} -> 4
B41: x_n: | C41: =C28 -> 744 | D41: Table size | O41: y2_n1: | P41: {=INDEX(R32:AB32,MATCH(Q37,Q32,1),IF(MATCH(Q34,R31:AB31,1)<S36,MATCH(Q34,R31:AB31,1)+1,MATCH(Q37,Q32,1)))} -> 5
B42: x1_n: | C42: {=INDEX(B31:F31,MATCH(C41,B31:F31,1))} -> 700 | D42: Rows: | E42: =MATCH(MAX(A32:A39),A32:A39,1) -> 8 | O42: y1_n2: | P42: {=INDEX(R32:AB32,IF(MATCH(Q37,Q32,1)<S35,MATCH(Q37,Q32,1)+1,MATCH(Q37,Q32,1)),MATCH(Q34,R31:AB31,1))} -> 4
...

Sheet LTL_NET GRADIENT OF CLIMB
B1: Pressure Alt | C1: x_n: | D1: =IF('Take-off'!$C$9="",'Take-off'!$C$16,MAX(0,'Take-off'!$C$16+30*(1013-'Take-off'!$C$9)))+35 -> 35 | F1: 35 fot extra
B2: Temp in calc | C2: y_n: | D2: =IF('Take-off'!$C$13='Dropdown lists'!$B$30, 'Take-off'!$C$8+10, 'Take-off'!$C$8) -> -2 | E2: Includes ICE-Vane. Could be disregarded for us
B3: NET GRADIENT OF CLIMB - FLAPS UP | O3: NET GRADIENT OF CLIMB - FLAPS TAKEOFF | AB3: NET GRADIENT OF CLIMB - FLAPS APPROACH
B4: Density altitude | O4: Density altitude | AB4: Density altitude
A5: Temp/PA | B5: 0 | C5: 1000 | D5: 2000 | E5: 3000 | F5: 4000 | N5: Temp/PA | O5: 0 | P5: 1000 | Q5: 2000 | R5: 3000 | S5: 4000 | AA5: Temp/PA | AB5: 0 | AC5: 1000 | AD5: 2000 | AE5: 3000 | AF5: 4000
A6: -30 | B6: 6 | C6: 5.8 | D6: 5.6 | E6: 5.4 | F6: 0 | N6: -30 | S6: 99999 | AA6: -30 | AF6: 99999
A7: -20 | B7: 6 | C7: 5.8 | D7: 5.45 | E7: 5.2 | F7: 0 | N7: -20 | S7: 99999 | AA7: -20 | AF7: 99999
A8: -10 | B8: 5.75 | C8: 5.5 | D8: 5.2 | E8: 4.9 | F8: 0 | N8: -10 | S8: 99999 | AA8: -10 | AF8: 99999
A9: 0 | B9: 5.5 | C9: 5.2 | D9: 4.9 | E9: 4.6 | F9: 0 | N9: 0 | S9: 99999 | AA9: 0 | AF9: 99999
A10: 10 | B10: 5.2 | C10: 4.9 | D10: 4.6 | E10: 4.4 | F10: 0 | N10: 10 | S10: 99999 | AA10: 10 | AF10: 99999
A11: 20 | B11: 4.95 | C11: 4.65 | D11: 4.4 | E11: 4 | F11: 0 | N11: 20 | S11: 99999 | AA11: 20 | AF11: 99999
A12: 30 | B12: 4.7 | C12: 4.25 | D12: 3.9 | E12: 3.4 | F12: 0 | AA12: 30 | AF12: 99999
A13: 40 | B13: 4 | C13: 3.4 | D13: 3 | E13: 2.5 | F13: 0 | N13: 30 | S13: 99999 | AA13: 40 | AF13: 99999
A14: 45 | B14: 0 | C14: 0 | D14: 0 | E14: 0 | F14: 0 | N14: 35 | O14: 99999 | P14: 99999 | Q14: 99999 | R14: 99999 | S14: 99999 | AA14: 45 | AB14: 99999 | AC14: 99999 | AD14: 99999 | AE14: 99999 | AF14: 99999
B16: x_n: | C16: =D1 -> 35 | D16: Table size | O16: x_n: | P16: =D1 -> 35 | Q16: Table size | AB16: x_n: | AC16: =D1 -> 35 | AD16: Table size
B17: x1_n: | C17: {=INDEX(B5:F5,MATCH(C16,B5:F5,1))} -> 0 | D17: Rows: | E17: =MATCH(MAX(A6:A14),A6:A14,1) -> 9 | O17: x1_n: | P17: {=INDEX(O5:S5,MATCH(P16,O5:S5,1))} -> 0 | Q17: Rows: | R17: =MATCH(MAX(N6:N14),N6:N14,1) -> 9 | AB17: x1_n: | AC17: {=INDEX(AB5:AF5,MATCH(AC16,AB5:AF5,1))} -> 0 | AD17: Rows: | AE17: =MATCH(MAX(AA6:AA14),AA6:AA14,1) -> 9
B18: x2_n: | C18: {=INDEX(B5:F5,IF(MATCH(C16,B5:F5,1)<E18,MATCH(C16,B5:F5,1)+1,MATCH(C16,B5:F5,1)))} -> 1000 | D18: Columns: | E18: =MATCH(MAX(B5:F5),B5:F5,0) -> 5 | O18: x2_n: | P18: {=INDEX(O5:S5,IF(MATCH(P16,O5:S5,1)<R18,MATCH(P16,O5:S5,1)+1,MATCH(P16,O5:S5,1)))} -> 1000 | Q18: Columns: | R18: =MATCH(MAX(O5:S5),O5:S5,0) -> 5 | AB18: x2_n: | AC18: {=INDEX(AB5:AF5,IF(MATCH(AC16,AB5:AF5,1)<AE18,MATCH(AC16,AB5:AF5,1)+1,MATCH(AC16,AB5:AF5,1)))} -> 1000 | AD18: Columns: | AE18: =MATCH(MAX(AB5:AF5),AB5:AF5,0) -> 5
B19: y_n: | C19: =D2 -> -2 | O19: y_n: | P19: =D2 -> -2 | AB19: y_n: | AC19: =D2 -> -2
B20: n1: | C20: {=INDEX(A6:A14,MATCH(C19,A6:A14,1))} -> -10 | O20: n1: | P20: {=INDEX(N6:N14,MATCH(P19,N6:N14,1))} -> -10 | AB20: n1: | AC20: {=INDEX(AA6:AA14,MATCH(AC19,AA6:AA14,1))} -> -10
B21: n2: | C21: {=INDEX(A6:A14,IF(MATCH(C19,A6:A14,1)<E17,MATCH(C19,A6:A14,1)+1,MATCH(C19,A6:A14,1)))} -> 0 | O21: n2: | P21: {=INDEX(N6:N14,IF(MATCH(P19,N6:N14,1)<R17,MATCH(P19,N6:N14,1)+1,MATCH(P19,N6:N14,1)))} -> 0 | AB21: n2: | AC21: {=INDEX(AA6:AA14,IF(MATCH(AC19,AA6:AA14,1)<AE17,MATCH(AC19,AA6:AA14,1)+1,MATCH(AC19,AA6:AA14,1)))} -> 0
B22: y1_n1: | C22: {=INDEX(B6:F14,MATCH(C19,A6:A14,1),MATCH(C16,B5:F5,1))} -> 5.75 | O22: y1_n1: | P22: {=INDEX(O6:S14,MATCH(P19,N6:N14,1),MATCH(P16,O5:S5,1))} | AB22: y1_n1: | AC22: {=INDEX(AB6:AF14,MATCH(AC19,AA6:AA14,1),MATCH(AC16,AB5:AF5,1))}
B23: y2_n1: | C23: {=INDEX(B6:F14,MATCH(C19,A6:A14,1),IF(MATCH(C16,B5:F5,1)<E18,MATCH(C16,B5:F5,1)+1,MATCH(C19,A6:A14,1)))} -> 5.5 | O23: y2_n1: | P23: {=INDEX(O6:S14,MATCH(P19,N6:N14,1),IF(MATCH(P16,O5:S5,1)<R18,MATCH(P16,O5:S5,1)+1,MATCH(P19,N6:N14,1)))} | AB23: y2_n1: | AC23: {=INDEX(AB6:AF14,MATCH(AC19,AA6:AA14,1),IF(MATCH(AC16,AB5:AF5,1)<AE18,MATCH(AC16,AB5:AF5,1)+1,MATCH(AC19,AA6:AA14,1)))}
B24: y1_n2: | C24: {=INDEX(B6:F14,IF(MATCH(C19,A6:A14,1)<E17,MATCH(C19,A6:A14,1)+1,MATCH(C19,A6:A14,1)),MATCH(C16,B5:F5,1))} -> 5.5 | O24: y1_n2: | P24: {=INDEX(O6:S14,IF(MATCH(P19,N6:N14,1)<R17,MATCH(P19,N6:N14,1)+1,MATCH(P19,N6:N14,1)),MATCH(P16,O5:S5,1))} | AB24: y1_n2: | AC24: {=INDEX(AB6:AF14,IF(MATCH(AC19,AA6:AA14,1)<AE17,MATCH(AC19,AA6:AA14,1)+1,MATCH(AC19,AA6:AA14,1)),MATCH(AC16,AB5:AF5,1))}
B25: y2_n2: | C25: {=INDEX(B6:F14,IF(MATCH(C19,A6:A14,1)<E17,MATCH(C19,A6:A14,1)+1,MATCH(C19,A6:A14,1)),IF(MATCH(C16,B5:F5,1)<E18,MATCH(C16,B5:F5,1)+1,MATCH(C16,B5:F5,1)))} -> 5.2 | O25: y2_n2: | P25: {=INDEX(O6:S14,IF(MATCH(P19,N6:N14,1)<R17,MATCH(P19,N6:N14,1)+1,MATCH(P19,N6:N14,1)),IF(MATCH(P16,O5:S5,1)<R18,MATCH(P16,O5:S5,1)+1,MATCH(P16,O5:S5,1)))} | AB25: y2_n2: | AC25: {=INDEX(AB6:AF14,IF(MATCH(AC19,AA6:AA14,1)<AE17,MATCH(AC19,AA6:AA14,1)+1,MATCH(AC19,AA6:AA14,1)),IF(MATCH(AC16,AB5:AF5,1)<AE18,MATCH(AC16,AB5:AF5,1)+1,MATCH(AC16,AB5:AF5,1)))}
B26: y_n1: | C26: =IFERROR(C22+(C16-C17)*(C23-C22)/(C18-C17),C22) -> 5.74125 | O26: y_n1: | P26: =IFERROR(P22+(P16-P17)*(P23-P22)/(P18-P17),P22) -> 0 | AB26: y_n1: | AC26: =IFERROR(AC22+(AC16-AC17)*(AC23-AC22)/(AC18-AC17),AC22) -> 0
B27: y_n2: | C27: =IFERROR(C24+(C16-C17)*(C25-C24)/(C18-C17),C24) -> 5.4895 | O27: y_n2: | P27: =IFERROR(P24+(P16-P17)*(P25-P24)/(P18-P17),P24) -> 0 | AB27: y_n2: | AC27: =IFERROR(AC24+(AC16-AC17)*(AC25-AC24)/(AC18-AC17),AC24) -> 0
B28: Distance | C28: =IFERROR(C26+(C19-C20)*(C27-C26)/(C21-C20),C26) -> 5.53985 | O28: Distance | P28: =IFERROR(P26+(P19-P20)*(P27-P26)/(P21-P20),P26) -> 0 | AB28: Distance | AC28: =IFERROR(AC26+(AC19-AC20)*(AC27-AC26)/(AC21-AC20),AC26) -> 0
B30: Gradient | O30: Vikt | AB30: Vikt
A31: % | B31: 2 | C31: 3 | D31: 4 | E31: 5 | F31: 6 | G31: 7 | O31: % | P31: 1 | Q31: 2 | R31: 3 | S31: 4 | T31: 5 | AA31: % | AB31: 0.9 | AC31: 2 | AD31: 3.1 | AE31: 4.5 | AF31: 5
A32: 9000 | B32: 7.2 | C32: 8.6 | D32: 10 | E32: 10.2 | F32: 10.2 | G32: 0 | O32: 10000 | T32: 99999 | AA32: 9000 | AF32: 99999
A33: 9500 | B33: 6.4 | C33: 7.8 | D33: 9 | E33: 10.2 | F33: 10.2 | G33: 0 | O33: 11000 | T33: 99999 | AA33: 9500 | AF33: 99999
A34: 10000 | B34: 5.7 | C34: 6.9 | D34: 8.1 | E34: 9.4 | F34: 10.2 | G34: 0 | O34: 12000 | T34: 99999 | AA34: 10000 | AF34: 99999
A35: 10500 | B35: 4.9 | C35: 6.1 | D35: 7.2 | E35: 8.4 | F35: 9.6 | G35: 0 | O35: 13000 | T35: 99999 | AA35: 10500 | AF35: 99999
A36: 11000 | B36: 4.2 | C36: 5.3 | D36: 6.4 | E36: 7.5 | F36: 8.6 | G36: 0 | O36: 14000 | T36: 99999 | AA36: 11000 | AF36: 99999
A37: 11500 | B37: 3.4 | C37: 4.5 | D37: 5.6 | E37: 6.6 | F37: 7.7 | G37: 0 | O37: 15000 | T37: 99999 | AA37: 11500 | AF37: 99999
A38: 12000 | B38: 2.8 | C38: 3.75 | D38: 4.8 | E38: 5.8 | F38: 6.8 | G38: 0 | O38: 16000 | T38: 99999 | AA38: 12000 | AF38: 99999
A39: 12500 | B39: 2 | C39: 3 | D39: 4 | E39: 5 | F39: 6 | G39: 0 | O39: 16600 | T39: 99999 | AA39: 12500 | AF39: 99999
A40: 12600 | B40: 0 | C40: 0 | D40: 0 | E40: 0 | F40: 0 | G40: 0 | O40: 16700 | P40: 99999 | Q40: 99999 | R40: 99999 | S40: 99999 | T40: 99999 | AA40: 12600 | AB40: 99999 | AC40: 99999 | AD40: 99999 | AE40: 99999 | AF40: 99999
B42: x_n: | C42: =C28 -> 5.53985 | D42: Table size | O42: x_n: | P42: =P28 -> 0 | Q42: Table size | AB42: x_n: | AC42: =AC28 -> 0 | AD42: Table size
B43: x1_n: | C43: {=INDEX(B31:G31,MATCH(C42,B31:G31,1))} -> 5 | D43: Rows: | E43: =MATCH(MAX(A32:A40),A32:A40,1) -> 9 | O43: x1_n: | P43: {=INDEX(P31:T31,MATCH(P42,P31:T31,1))} -> #N/A | Q43: Rows: | R43: =MATCH(MAX(O32:O40),O32:O40,1) -> 9 | AB43: x1_n: | AC43: {=INDEX(AB31:AF31,MATCH(AC42,AB31:AF31,1))} -> #N/A | AD43: Rows: | AE43: =MATCH(MAX(AA32:AA40),AA32:AA40,1) -> 9
...

Sheet LTL_Takeoff distance (2)
B1: Pressure Alt | C1: x_n: | D1: =IF('Take-off'!$C$9="",'Take-off'!$C$16,MAX(0,'Take-off'!$C$16+30*(1013-'Take-off'!$C$9))) -> 0
B2: Temp in calc | C2: y_n: | D2: =IF('Take-off'!$C$13='Dropdown lists'!$B$30, 'Take-off'!$C$8+10, 'Take-off'!$C$8) -> -2 | E2: Includes ICE-Vane. Could be disregarded for us
B3: TAKE OFF DISTANCE - FLAPS UP | O3: TAKE OFF DISTANCE - FLAPS TAKEOFF | AB3: TAKE OFF DISTANCE - FLAPS APPROACH
B4: Density altitude | O4: Density altitude | AB4: Density altitude
A5: Temp/PA | B5: 0 | C5: 1000 | D5: 2000 | E5: 3000 | F5: 4000 | N5: Temp/PA | O5: 0 | P5: 1000 | Q5: 2000 | R5: 3000 | S5: 4000 | AA5: Temp/PA | AB5: 0 | AC5: 1000 | AD5: 2000 | AE5: 3000 | AF5: 4000
A6: -30 | B6: 1400 | C6: 1490 | D6: 1550 | E6: 1600 | F6: 99999 | N6: -30 | S6: 99999 | AA6: -30 | AF6: 99999
A7: -20 | B7: 1450 | C7: 1550 | D7: 1600 | E7: 1700 | F7: 99999 | N7: -20 | S7: 99999 | AA7: -20 | AF7: 99999
A8: -10 | B8: 1550 | C8: 1600 | D8: 1700 | E8: 1800 | F8: 99999 | N8: -10 | S8: 99999 | AA8: -10 | AF8: 99999
A9: 0 | B9: 1610 | C9: 1700 | D9: 1800 | E9: 1900 | F9: 99999 | N9: 0 | S9: 99999 | AA9: 0 | AF9: 99999
A10: 10 | B10: 1700 | C10: 1800 | D10: 1900 | E10: 2015 | F10: 99999 | N10: 10 | S10: 99999 | AA10: 10 | AF10: 99999
A11: 20 | B11: 1780 | C11: 1900 | D11: 2000 | E11: 2150 | F11: 99999 | N11: 20 | S11: 99999 | AA11: 20 | AF11: 99999
A12: 30 | B12: 1880 | C12: 2000 | D12: 2130 | E12: 2320 | F12: 99999 | AA12: 30 | AF12: 99999
A13: 40 | B13: 2075 | C13: 2200 | D13: 2380 | E13: 2600 | F13: 99999 | N13: 30 | S13: 99999 | AA13: 40 | AF13: 99999
A14: 45 | B14: 99999 | C14: 99999 | D14: 99999 | E14: 99999 | F14: 99999 | N14: 35 | O14: 99999 | P14: 99999 | Q14: 99999 | R14: 99999 | S14: 99999 | AA14: 45 | AB14: 99999 | AC14: 99999 | AD14: 99999 | AE14: 99999 | AF14: 99999
B16: x_n: | C16: =D1 -> 0 | D16: Table size | O16: x_n: | P16: =D1 -> 0 | Q16: Table size | AB16: x_n: | AC16: =D1 -> 0 | AD16: Table size
B17: x1_n: | C17: {=INDEX(B5:F5,MATCH(C16,B5:F5,1))} -> 0 | D17: Rows: | E17: =MATCH(MAX(A6:A14),A6:A14,1) -> 9 | O17: x1_n: | P17: {=INDEX(O5:S5,MATCH(P16,O5:S5,1))} -> 0 | Q17: Rows: | R17: =MATCH(MAX(N6:N14),N6:N14,1) -> 9 | AB17: x1_n: | AC17: {=INDEX(AB5:AF5,MATCH(AC16,AB5:AF5,1))} -> 0 | AD17: Rows: | AE17: =MATCH(MAX(AA6:AA14),AA6:AA14,1) -> 9
