Workbook

Sheet Take-off
B2: Take-off distance Beech 200 | G2: Version
B3: Interpoleringsverktyg för startsträcka från AFM. | G3: 2026-XY-ZV
B4: Flygplats och bana: | C4: Custom airport | I4: Om Rullgardiner krånglar, kopiera från flikarna "Airport data" eller "Rullgardinsmenyer"
B6: Wind: | C6: 0 | D6: ° | E6: =IF(C24<0, "Tailwind", "") | I6: eller skriv EXAKT lika
C7: 0 | D7: kt
B8: Outside air temperature: | C8: -35 | D8: °C
B9: QNH | C9: 1013 | D9: Hpa
B10: Runway Condition Code | C10: 6
B11: Runway contaminant | C11: No contaminant
B12: Contaminant depth | C12: 0 | D12: mm | E12: Max: | G12: =VLOOKUP(C11,'Dropdown lists'!B34:F40,5,FALSE()) -> N/A
B13: Engine Anti-ice | C13: OFF | I13: Engine anti-ice can be disregarded (OFF in calculation) whenever 3300 lbs/ft take-off power can be obtained
B14: Take off mass: | C14: 12500 | D14: Lbs
B15: Airport data
B16: Treshold elevation: | C16: =_xlfn.XLOOKUP(C4,'Airport data'!A5:A999,'Airport data'!B5:B999) -> 0 | D16: ft
B17: Runway Slope: | C17: =_xlfn.XLOOKUP(C4,'Airport data'!A5:A999,'Airport data'!G5:G999) -> 0 | D17: % | E17: + = upphill
B18: RWY Heading: | C18: =_xlfn.XLOOKUP(C4,'Airport data'!A5:A999,'Airport data'!H5:H999) -> 0 | D18: °
B19: ASDA: | C19: =_xlfn.XLOOKUP(C4,'Airport data'!A5:A999,'Airport data'!E5:E999)-10 -> -10 | D19: m | F19: Req gradient: | G19: =_xlfn.XLOOKUP(C4,'Airport data'!A5:A999,'Airport data'!I5:I999) -> 0
B20: TORA: | C20: =_xlfn.XLOOKUP(C4,'Airport data'!A5:A999,'Airport data'!C5:C999)-10 -> -10 | D20: m
B21: TODA: | C21: =_xlfn.XLOOKUP(C4,'Airport data'!A5:A999,'Airport data'!D5:D999)-10 -> -10 | D21: m | E21: TOR | F21: =C35*1.15 -> 560.97561
B22: LDA: | C22: =_xlfn.XLOOKUP(C4,'Airport data'!A5:A999,'Airport data'!F5:F999) -> 0 | D22: m
B23: Calculated data
B24: Head/Tail wind | C24: ='TAKE OFF Performance FLAPS UP'!D34 -> 0 | D24: Kt | E24: Take-off Distance Factor | G24: =_xlfn.XLOOKUP(C10,'Dropdown lists'!B4:B9,'Dropdown lists'!D4:D9) -> 1
B25: Crosswind | C25: =ABS('TAKE OFF Performance FLAPS UP'!C39*C7) -> 0 | D25: Kt | E25: Limit | F25: =_xlfn.XLOOKUP(C10,'Dropdown lists'!B4:B9,'Dropdown lists'!E4:E9) -> 25
B26: FLAPS: | C26: UP | D26: TAKE-OFF | E26: APP | G26: FULL
B27: Dry Runway
B28: Ground Roll [m] | C28: ='TAKE OFF Performance FLAPS UP'!E28 -> 487.80488 | E28: ='TAKE OFF Performance FLAPS APPR'!E28 -> 481.70732 | I28: Kommer inte att användas med take-off faktorer - Då är RWYCC 6 samma sak
B29: Take off distance | C29: =MAX('TAKE OFF Performance FLAPS UP'!E29:E30) -> 1707.3171 | E29: =MAX('TAKE OFF Performance FLAPS APPR'!E29:E30) -> 1280.4878
B30: Accelerade & STOP [m] | C30: ='TAKE OFF Performance FLAPS UP'!E32 -> 899.39024 | E30: ='TAKE OFF Performance FLAPS APPR'!E32 -> 914.63415
B31: V1 [kts] | C31: ='TAKE OFF Performance FLAPS UP'!E$22 -> 95 | E31: ='TAKE OFF Performance FLAPS APPR'!E22 -> 94
B32: VR [kts] | C32: ='TAKE OFF Performance FLAPS UP'!E$22 -> 95 | E32: ='TAKE OFF Performance FLAPS APPR'!E22 -> 94
B33: V2 [kts] | C33: ='TAKE OFF Performance FLAPS UP'!I22 -> 121 | E33: ='TAKE OFF Performance FLAPS APPR'!I22 -> 106
B34: Selected contaminant
B35: Ground Roll [m] | C35: ='TAKE OFF Performance FLAPS UP'!E28*G24 -> 487.80488 | E35: ='TAKE OFF Performance FLAPS APPR'!E28*G24 -> 481.70732
B36: Take off distance | C36: =MAX('TAKE OFF Performance FLAPS UP'!E29:E31)*G24 -> 1707.3171 | E36: =MAX('TAKE OFF Performance FLAPS APPR'!E29:E31)*G24 -> 1280.4878
B37: Accelerade & STOP [m] | C37: ='TAKE OFF Performance FLAPS UP'!E32*G24 -> 899.39024 | E37: ='TAKE OFF Performance FLAPS APPR'!E32*G24 -> 914.63415
B38: V1 [kts] | C38: ='TAKE OFF Performance FLAPS UP'!E$22 -> 95 | E38: ='TAKE OFF Performance FLAPS APPR'!E22 -> 94
B39: VR [kts] | C39: ='TAKE OFF Performance FLAPS UP'!E$22 -> 95 | E39: ='TAKE OFF Performance FLAPS APPR'!E22 -> 94
B40: V2 [kts] | C40: ='TAKE OFF Performance FLAPS UP'!I$22 -> 121 | E40: ='TAKE OFF Performance FLAPS APPR'!I22 -> 106
B41: Climb
B42: Net Gradient OEI wings level [%] | C42: =IF( C24>0, 'NET GRADIENT OF CLIMB'!C56*(125/(125-50%*ABS(C24))), 'NET GRADIENT OF CLIMB'!C56*(125/(125+150%*ABS(C24))) ) -> 5.393 | E42: =IF( C24>0, 'NET GRADIENT OF CLIMB'!AC56*(125/(125-50%* ABS(C24))), 'NET GRADIENT OF CLIMB'!AC56*(125/(125+150%* ABS(C24))) ) -> 4.193 | I42: Standard Procedure Design Gradient (PDG): 3,3%
...

Sheet Landing
B2: Landning distance Beech 200 | G2: Version
B3: Interpoleringsverktyg för landningsträcka | G3: 2026-XY-ZV
B4: Flygplats och bana: | C4: Custom airport | I4: Om Rullgardiner krånglar, kopiera från flikarna "Airport data" eller "Rullgardinsmenyer"
B6: Wind: | C6: 100 | D6: ° | E6: =IF(C21<0, "Tailwind", "") | I6: eller skriv exakt lika
C7: 0 | D7: kt
B8: Outside air temperature: | C8: 0 | D8: °C
B9: QNH | C9: 1013 | D9: Hpa
B10: Runway Condition Code | C10: 3
B11: Landing mass: | C11: 11000 | D11: Lbs
B12: Max landing weight | C12: 12500 | D12: Lbs
B14: Airport data | C14: =IF(C11>C12, "Overweight landning","")
B15: Elevation: | C15: =_xlfn.XLOOKUP(C4,'Airport data'!A5:A999,'Airport data'!B5:B999) -> 0 | D15: ft
B16: Runway Slope: | C16: =_xlfn.XLOOKUP(C4,'Airport data'!A5:A999,'Airport data'!G5:G999) -> 0 | D16: % | E16: + = upphill
B17: RWY Heading: | C17: =_xlfn.XLOOKUP(C4,'Airport data'!A5:A999,'Airport data'!H5:H999) -> 0 | D17: °
B18: LDA: | C18: =_xlfn.XLOOKUP(C4,'Airport data'!A5:A999,'Airport data'!F5:F999) -> 0 | D18: m
B19: Calculated data
B20: Landing Distance Factor | C20: =_xlfn.XLOOKUP(C10,'Dropdown lists'!B4:B9,'Dropdown lists'!C4:C9) -> 2.16
B21: Head/Tail wind | C21: ='LDG Performance'!D32 -> 0 | D21: Kt
B22: Crosswind | C22: =ABS('LDG Performance'!C37*C7) -> 0 | D22: Kt | E22: Limit | G22: =_xlfn.XLOOKUP(C10,'Dropdown lists'!B4:B9,'Dropdown lists'!E4:E9) -> 14
B24: FLAPS: | C24: UP | D24: TAKE-OFF | E24: APP | G24: FULL
B25: Landing Distance
B26: VREF [kts] | C26: ='LDG Performance'!M21 -> 126 | G26: ='LDG Performance'!E21 -> 99
B27: Landing Distance factored [m] | C27: =('LDG Performance'!B87/3.28)*Landing!C20 -> 1532.5942 | G27: ='Landing distance data'!C104*C20 -> 1185.0665
B28: Flap Up based on AFM graph
C29: =IF(ISBLANK(C10), "Dry & Unfactored *1,67", "" )
B30: Missed approach
B31: OEI Climb Gradient [%] | C31: =IF( C21>0, 'OEI CLIMB GRADIENT'!P47*(125/(125+50%*C21)), 'OEI CLIMB GRADIENT'!P47*(125/(125-150%*C21)) ) -> 7 | D31: Gradient includes wind, 150% & 50%
C35: Flaps UP | D35: Flaps FULL
B36: LDA | C36: =Landing!$C$18 -> 0 | D36: =Landing!$C$18 -> 0
B37: Landing distance | C37: =C27 -> 1532.5942 | D37: =G27 -> 1185.0665

Sheet Airport data
A1: Airport | B1: Runway Threshold Elevation: | C1: TORA | D1: TODA | E1: ASDA | F1: LDA: | G1: RWY Slope: | H1: RWY HDG | I1: Minimum departure climb gradient, obstacles | J1: Uppdaterad | K1: ESCAPE ROUTE INFO
K2: Min cloud base | L2: Routing
B4: [ft] | C4: [m] | D4: [m] | E4: [m] | F4: [m] | G4: [%] | H4: [°] | I4: [%] | J4: [Date]
A5: No airport selected | B5: - | D5: - | E5: - | F5: - | G5: - | H5: - | J5: -
A6: Custom airport | M6: ÄNDRA ljusgröna RADER VID BEHOV

Sheet Dropdown lists
B1: Factors | E1: X-wind
D2: Takeoff Faktor
B3: RWCC | C3: Faktor | E3: Limit
B4: 1 | C4: 2.66 | D4: 1.59 | E4: 4
B5: 2 | C5: 2.46 | D5: 1.41 | E5: 9
B6: 3 | C6: 2.16 | D6: 1.22 | E6: 14
B7: 4 | C7: 1.96 | D7: 1.14 | E7: 20
B8: 5 | C8: 1.76 | D8: 1.07 | E8: 25
B9: 6 | C9: 1.43 | D9: 1 | E9: 25
B12: FLAPS
B19: Runway take off
B27: Engine anti-ice
B30: ON
B31: OFF
B33: Runway contaminant | D33: Faktor | E33: Måttenhet | F33: Max
B34: Wet Runway | D34: 0 | F34: N/A
B35: Compacted snow | D35: 0 | F35: N/A
B36: Dry snow | D36: 0.005 | E36: mm | F36: N/A
B37: Wet snow | D37: 0.01 | E37: mm | F37: 50
B38: Slush | D38: 0.02 | E38: mm | F38: 25
B39: Standing water | D39: 0.02 | E39: mm | F39: 25
B40: No contaminant | D40: 0 | F40: N/A
B44: Technique
B47: Static T/O power
B48: Rolling take off

Sheet LDG Performance
A1: LANDING PERFORMANCE (Normal)
H2: EMG RETURN | I2: EMG RETURN | J2: FLAPS UP | K2: EMG RETURN | L2: FLAPS UP | M2: Normal
A3: Landing Mass | D3: Speeds | H3: Speeds | J3: Speeds | L3: Speeds
D4: Vref | H4: Vref | J4: Vref | L4: Vref
A5: 9000 | D5: 93 | H5: 93 | J5: 117 | L5: 117
A6: 10000 | D6: 96 | H6: 96 | J6: 122 | L6: 122
A7: 11000 | D7: 99 | H7: 99 | J7: 126 | L7: 126
A8: 12000 | D8: 102 | H8: 102 | J8: 130 | L8: 130
A9: 12500 | D9: 103 | H9: 103 | J9: 132 | L9: 132
A11: Table size Landing distance
B12: Rows: | C12: =MATCH(MAX(A5:A9),A5:A9,0) -> 5
B13: Columns: | C13: =MATCH(MAX(D5),D5,0) -> 1
D15: x_n: | E15: =D4 -> Vref | I15: =H4 -> Vref | K15: =J4 -> Vref | M15: =L4 -> Vref
D16: y_n: | E16: =Landing!C11 -> 11000 | I16: ='Take-off'!C14 -> 12500 | K16: ='Take-off'!C14 -> 12500 | M16: =Landing!C11 -> 11000
D17: n1: | E17: {=INDEX($A$5:$A$9,MATCH(E16,$A$5:$A$9,1))} -> 11000 | I17: {=INDEX($A$5:$A$9,MATCH(I16,$A$5:$A$9,1))} -> 12500 | K17: {=INDEX($A$5:$A$9,MATCH(K16,$A$5:$A$9,1))} -> 12500 | M17: {=INDEX($A$5:$A$9,MATCH(M16,$A$5:$A$9,1))} -> 11000
D18: n2: | E18: {=INDEX($A$5:$A$9,IF(MATCH(E16,$A$5:$A$9,1)<$C$12,MATCH(E16,$A$5:$A$9,1)+1,MATCH(E16,$A$5:$A$9,1)))} -> 12000 | I18: {=INDEX($A$5:$A$9,IF(MATCH(I16,$A$5:$A$9,1)<$C$12,MATCH(I16,$A$5:$A$9,1)+1,MATCH(I16,$A$5:$A$9,1)))} -> 12500 | K18: {=INDEX($A$5:$A$9,IF(MATCH(K16,$A$5:$A$9,1)<$C$12,MATCH(K16,$A$5:$A$9,1)+1,MATCH(K16,$A$5:$A$9,1)))} -> 12500 | M18: {=INDEX($A$5:$A$9,IF(MATCH(M16,$A$5:$A$9,1)<$C$12,MATCH(M16,$A$5:$A$9,1)+1,MATCH(M16,$A$5:$A$9,1)))} -> 12000
D19: y1_n1: | E19: {=INDEX(D5:D9,MATCH(E16,$A$5:$A$9,1),MATCH(E15,D4,1))} -> 99 | I19: {=INDEX(H5:H9,MATCH(I16,$A$5:$A$9,1),MATCH(I15,H4,1))} -> 103 | K19: {=INDEX(J5:J9,MATCH(K16,$A$5:$A$9,1),MATCH(K15,J4,1))} -> 132 | M19: {=INDEX(L5:L9,MATCH(M16,$A$5:$A$9,1),MATCH(M15,L4,1))} -> 126
D20: y1_n2: | E20: {=INDEX(D5:D9,IF(MATCH(E16,$A$5:$A$9,1)<$C$12,MATCH(E16,$A$5:$A$9,1)+1,MATCH(E16,$A$5:$A$9,1)),MATCH(E15,D4,1))} -> 102 | I20: {=INDEX(H5:H9,IF(MATCH(I16,$A$5:$A$9,1)<$C$12,MATCH(I16,$A$5:$A$9,1)+1,MATCH(I16,$A$5:$A$9,1)),MATCH(I15,H4,1))} -> 103 | K20: {=INDEX(J5:J9,IF(MATCH(K16,$A$5:$A$9,1)<$C$12,MATCH(K16,$A$5:$A$9,1)+1,MATCH(K16,$A$5:$A$9,1)),MATCH(K15,J4,1))} -> 132 | M20: {=INDEX(L5:L9,IF(MATCH(M16,$A$5:$A$9,1)<$C$12,MATCH(M16,$A$5:$A$9,1)+1,MATCH(M16,$A$5:$A$9,1)),MATCH(M15,L4,1))} -> 130
D21: Vref: | E21: =IFERROR(E19+(E16-E17)*(E20-E19)/(E18-E17),E19) -> 99 | I21: =IFERROR(I19+(I16-I17)*(I20-I19)/(I18-I17),I19) -> 103 | K21: =IFERROR(K19+(K16-K17)*(K20-K19)/(K18-K17),K19) -> 132 | M21: =IFERROR(M19+(M16-M17)*(M20-M19)/(M18-M17),M19) -> 126
B29: Windcalc
B31: WCA | C31: Factor | D31: H/T wind
B32: =IF(ABS(Landing!C17-Landing!C6)>270,360-ABS(Landing!C17-Landing!C6),Landing!C17-Landing!C6) -> -100 | C32: =IF(ABS(B32)>90,ABS(COS(B32*PI()/180))*(-1),ABS(COS(B32*PI()/180))) -> -0.17364818 | D32: =IF( ISBLANK(Landing!C6), Landing!C7*-1, Landing!C7*C32) -> 0
B37: Crosswind factor | C37: =IF(ABS(B32)>90,ABS(SIN(B32*PI()/180))*(-1),ABS(SIN(B32*PI()/180))) -> -0.98480775
A48: Emergency Return
B53: Unfactorised | C53: Factorised
B54: ='Landing distance data'!K104 -> 585.50443 | C54: =B54*C55 -> 837.27134
B55: Landing Distance Factor: | C55: =IF( ISBLANK('Take-off'!C10),MIN('Dropdown lists'!C4:C10), VLOOKUP('Take-off'!C10,'Dropdown lists'!B4:C10,2)) -> 1.43
A66: LANDING PERFORMANCE (UP)
A68: Landing Distance Flaps LAND [feet] | B68: Landing distance | D68: EMG RETURN
B69: UP | D69: EMG RETURN
A70: 1100 | B70: 1550
A71: 2000 | B71: 2550
A72: 2500 | B72: 3130
A73: 3000 | B73: 3700
A74: 3500 | B74: 4250
A75: 4000 | B75: 5850
A77: Table size Landing distance
B78: Rows: | C78: =MATCH(MAX(A70:A75),A70:A75,0) -> 6
B79: Columns: | C79: =MATCH(MAX(B70),B70,0) -> 1
A81: x_n: | B81: =B69 -> UP | D81: =D69 -> EMG RETURN
...

Sheet TAKE OFF Performance FLAPS UP
A1: Take off PERFORMANCE (FLAPS UP)
A2: UP
A3: Landing Mass | D3: Speeds | H3: Speeds
D4: V1/R | H4: V2
A5: 9000 | D5: 95 | H5: 108
A6: 10000 | D6: 95 | H6: 111
A7: 11000 | D7: 95 | H7: 115
A8: 11500 | D8: 95 | H8: =AVERAGE(H7,H9) -> 117
A9: 12000 | D9: 95 | H9: 119
A10: 12500 | D10: 95 | H10: 121
D12: Table size Vref | H12: V2
D13: Rows: | E13: =MATCH(MAX($A5:$A10),$A5:$A10,0) -> 6 | I13: =MATCH(MAX($A5:$A10),$A5:$A10,0) -> 6
D14: Columns: | E14: =MATCH(MAX(D5),D5,0) -> 1 | I14: =MATCH(MAX(H5),H5,0) -> 1
D16: x_n: | E16: =D4 -> V1/R | I16: =H4 -> V2
D17: y_n: | E17: ='Take-off'!$C$14 -> 12500 | I17: ='Take-off'!$C$14 -> 12500
D18: n1: | E18: {=INDEX($A5:$A10,MATCH(E17,$A5:$A10,1))} -> 12500 | I18: =INDEX($A5:$A10,MATCH(I17,$A5:$A10,1)) -> 12500
D19: n2: | E19: {=INDEX($A5:$A10,IF(MATCH(E17,$A5:$A10,1)<E13,MATCH(E17,$A5:$A10,1)+1,MATCH(E17,$A5:$A10,1)))} -> 12500 | I19: =INDEX($A5:$A10,IF(MATCH(I17,$A5:$A10,1)<I13,MATCH(I17,$A5:$A10,1)+1,MATCH(I17,$A5:$A10,1))) -> 12500
D20: y1_n1: | E20: {=INDEX(D5:D10,MATCH(E17,$A5:$A10,1),MATCH(E16,D4,1))} -> 95 | I20: {=INDEX(H5:H10,MATCH(I17,$A5:$A10,1),MATCH(I16,H4,1))} -> 121
D21: y1_n2: | E21: {=INDEX(D5:D10,IF(MATCH(E17,$A5:$A10,1)<E13,MATCH(E17,$A5:$A10,1)+1,MATCH(E17,$A5:$A10,1)),MATCH(E16,D4,1))} -> 95 | I21: {=INDEX(H5:H10,IF(MATCH(I17,$A5:$A10,1)<I13,MATCH(I17,$A5:$A10,1)+1,MATCH(I17,$A5:$A10,1)),MATCH(I16,H4,1))} -> 121
D22: Vref: | E22: =IFERROR(E20+(E17-E18)*(E21-E20)/(E19-E18),E20) -> 95 | I22: =IFERROR(I20+(I17-I18)*(I21-I20)/(I19-I18),I20) -> 121
A25: Landing distance required calculations
B27: Flat | C27: Teknik | D27: Slope | E27: Totalt
A28: Ground Roll | B28: ='Takeoff distance (2)'!C75/3.28 -> 487.80488 | C28: 0 | D28: =IF('Take-off'!$C$17>0, ((+'Take-off'!$C$17*5)%*SUM(B28:C28)),0 ) -> 0 | E28: =SUM(B28:D28) -> 487.80488
A29: Take off distance | B29: ='Takeoff distance (2)'!C94/3.28 -> 838.41463 | C29: 0 | D29: =IF('Take-off'!$C$17>0, ((+'Take-off'!$C$17*5)%*SUM(B29:C29)),0 ) -> 0 | E29: =SUM(B29:D29)*115% -> 964.17683
A30: Accelerate GO DRY | B30: ='Accelerate and GO (2)'!C75/3.28 -> 1707.3171 | C30: 0 | D30: =IF('Take-off'!$C$17>0, ((+'Take-off'!$C$17*5)%*SUM(B30:C30)),0 ) -> 0 | E30: =SUM(B30:D30) -> 1707.3171
A31: Accelerate GO WET/CONT | B31: =B30 -> 1707.3171 | C31: 0 | D31: =IF('Take-off'!$C$17>0, ((+'Take-off'!$C$17*5)%*SUM(B31:C31)),0 ) -> 0 | E31: =SUM(B31:D31) -> 1707.3171
A32: Accelerate stop | B32: ='Accelerate and stop2'!C75/3.28 -> 899.39024 | C32: 0 | D32: =IF('Take-off'!$C$17>0, ((+'Take-off'!$C$17*5)%*SUM(B32:C32)),0 ) -> 0 | E32: =SUM(B32:D32) -> 899.39024
B33: WCA | C33: Factor | D33: H/T wind
B34: =IF(ABS('Take-off'!C18-'Take-off'!C6)>270,360-ABS('Take-off'!C18-'Take-off'!C6),'Take-off'!C18-'Take-off'!C6) -> 0 | C34: =IF(ABS(B34)>90,ABS(COS(B34*PI()/180))*(-1),ABS(COS(B34*PI()/180))) -> 1 | D34: =IF( ISBLANK('Take-off'!C6), 'Take-off'!C7*-1, 'Take-off'!C7*C34) -> 0
A35: TDR | B35: Unfactorised | C35: Factorised
B39: Crosswind factor | C39: =IF(ABS(B34)>90,ABS(SIN(B34*PI()/180))*(-1),ABS(SIN(B34*PI()/180))) -> 0

Sheet TAKE OFF Performance FLAPS APPR
A1: TAKE OFF PERFORMANCE (FLAPS APPROACH)
A2: TAKE-OFF
A3: Mass | D3: Speeds | H3: Speeds
D4: V1/R | H4: V2
A5: 9000 | D5: 94 | H5: 99
A6: 10000 | D6: 94 | H6: 101
A7: 11000 | D7: 94 | H7: 103
A8: 11500 | D8: 94 | H8: =AVERAGE(H7,H9) -> 104
A9: 12000 | D9: 94 | H9: 105
A10: 12500 | D10: 94 | H10: 106
D12: Table size Vref | H12: V2
D13: Rows: | E13: =MATCH(MAX($A5:$A10),$A5:$A10,0) -> 6 | I13: =MATCH(MAX($A5:$A10),$A5:$A10,0) -> 6
D14: Columns: | E14: =MATCH(MAX(D5),D5,0) -> 1 | I14: =MATCH(MAX(H5),H5,0) -> 1
D16: x_n: | E16: =D4 -> V1/R | I16: =H4 -> V2
D17: y_n: | E17: ='Take-off'!$C$14 -> 12500 | I17: ='Take-off'!$C$14 -> 12500
D18: n1: | E18: {=INDEX($A5:$A10,MATCH(E17,$A5:$A10,1))} -> 12500 | I18: =INDEX($A5:$A10,MATCH(I17,$A5:$A10,1)) -> 12500
D19: n2: | E19: {=INDEX($A5:$A10,IF(MATCH(E17,$A5:$A10,1)<E13,MATCH(E17,$A5:$A10,1)+1,MATCH(E17,$A5:$A10,1)))} -> 12500 | I19: =INDEX($A5:$A10,IF(MATCH(I17,$A5:$A10,1)<I13,MATCH(I17,$A5:$A10,1)+1,MATCH(I17,$A5:$A10,1))) -> 12500
D20: y1_n1: | E20: {=INDEX(D5:D10,MATCH(E17,$A5:$A10,1),MATCH(E16,D4,1))} -> 94 | I20: {=INDEX(H5:H10,MATCH(I17,$A5:$A10,1),MATCH(I16,H4,1))} -> 106
D21: y1_n2: | E21: {=INDEX(D5:D10,IF(MATCH(E17,$A5:$A10,1)<E13,MATCH(E17,$A5:$A10,1)+1,MATCH(E17,$A5:$A10,1)),MATCH(E16,D4,1))} -> 94 | I21: {=INDEX(H5:H10,IF(MATCH(I17,$A5:$A10,1)<I13,MATCH(I17,$A5:$A10,1)+1,MATCH(I17,$A5:$A10,1)),MATCH(I16,H4,1))} -> 106
D22: Vref: | E22: =IFERROR(E20+(E17-E18)*(E21-E20)/(E19-E18),E20) -> 94 | I22: =IFERROR(I20+(I17-I18)*(I21-I20)/(I19-I18),I20) -> 106
A23: Windcorrected distances
A25: Landing distance required calculations
B27: Flat | C27: Technique | D27: Slope | E27: Totalt
A28: Ground Roll | B28: ='Takeoff distance (2)'!AC75/3.28 -> 481.70732 | C28: 0 | D28: =IF('Take-off'!$C$17>0, ((+'Take-off'!$C$17*5)%*SUM(B28:C28)),0 ) -> 0 | E28: =SUM(B28:D28) -> 481.70732
A29: Take off distance | B29: ='Takeoff distance (2)'!AC94/3.28 -> 689.78659 | C29: 0 | D29: =IF('Take-off'!$C$17>0, ((+'Take-off'!$C$17*5)%*SUM(B29:C29)),0 ) -> 0 | E29: =SUM(B29:D29)*115% -> 793.25457
A30: Accelerate GO DRY | B30: ='Accelerate and GO (2)'!AD75/3.28 -> 1280.4878 | C30: 0 | D30: =IF('Take-off'!$C$17>0, ((+'Take-off'!$C$17*5)%*SUM(B30:C30)),0 ) -> 0 | E30: =SUM(B30:D30) -> 1280.4878
A31: Accelerate GO WET/CONT | B31: =B30 -> 1280.4878 | C31: 0 | D31: =IF('Take-off'!$C$17>0, ((+'Take-off'!$C$17*5)%*SUM(B31:C31)),0 ) -> 0 | E31: =SUM(B31:D31) -> 1280.4878
A32: Accelerate STOP distance | B32: ='Accelerate and stop2'!AC75/3.28 -> 914.63415 | C32: 0 | D32: =IF('Take-off'!$C$17>0, ((+'Take-off'!$C$17*5)%*SUM(B32:C32)),0 ) -> 0 | E32: =SUM(B32:D32) -> 914.63415
B33: WCA | C33: Factor | D33: H/T wind
B34: =IF(ABS('Take-off'!C18-'Take-off'!C6)>270,360-ABS('Take-off'!C18-'Take-off'!C6),'Take-off'!C18-'Take-off'!C6) -> 0 | C34: =IF(ABS(B34)>90,ABS(COS(B34*PI()/180))*(-1),ABS(COS(B34*PI()/180))) -> 1 | D34: =IF( ISBLANK('Take-off'!C6), 'Take-off'!C7*-1, 'Take-off'!C7*C34) -> 0
B39: Crosswind factor | C39: =IF(ABS(B34)>90,ABS(SIN(B34*PI()/180))*(-1),ABS(SIN(B34*PI()/180))) -> 0
A40: GRadient adjustments

Sheet Landing distance data
B1: Pressure Alt | C1: x_n: | D1: =IF(Landing!$C$9="",Landing!$C$15,MAX(0,Landing!$C$15+30*(1013-Landing!$C$9))) -> 0 | F1: EMG Return | G1: =IF('Take-off'!$C$9="",'Take-off'!$C$16,MAX(0,'Take-off'!$C$16+30*(1013-'Take-off'!$C$9))) -> 0
B2: Temp in calc | C2: y_n: | D2: =Landing!C8 -> 0 | G2: =MAX( IF('Take-off'!C13='Dropdown lists'!B30, 'Take-off'!$C$8+5, 'Take-off'!$C$8),0) -> 0
I5: EMG RETURN
C6: NORMAL
A8: Landing
B10: Density Altitude
B11: -500 | C11: 0 | D11: 1000 | E11: 2000 | F11: 3000 | G11: 3500
A12: -40 | B12: 1000 | C12: 1000 | D12: 1030 | E12: 1050 | F12: 1100 | G12: 99999
A13: -30 | B13: 1000 | C13: 1000 | D13: 1030 | E13: 1050 | F13: 1100 | G13: 99999
A14: -20 | B14: 1000 | C14: 1000 | D14: 1030 | E14: 1050 | F14: 1100 | G14: 99999
A15: -10 | B15: 1025 | C15: 1025 | D15: 1050 | E15: 1100 | F15: 1130 | G15: 99999
A16: 0 | B16: 1050 | C16: 1050 | D16: 1100 | E16: 1140 | F16: 1175 | G16: 99999
A17: 10 | B17: 1100 | C17: 1100 | D17: 1140 | E17: 1175 | F17: 1225 | G17: 99999
A18: 20 | B18: 1130 | C18: 1130 | D18: 1175 | E18: 1225 | F18: 1270 | G18: 99999
A19: 30 | B19: 1175 | C19: 1175 | D19: 1225 | E19: 1260 | F19: 1320 | G19: 99999
A20: 40 | B20: 1210 | C20: 1210 | D20: 1250 | E20: 1300 | F20: 1350 | G20: 99999
A21: 45 | B21: 99999 | C21: 99999 | D21: 99999 | E21: 99999 | F21: 99999 | G21: 99999
B23: x_n: | C23: =D1 -> 0 | D23: Table size | J23: x_n: | K23: =G1 -> 0 | L23: Table size
B24: x1_n: | C24: =INDEX($B11:$G11,MATCH(C23,$B11:$G11,1)) -> 0 | D24: Rows: | E24: =MATCH(MAX($A12:$A21),$A12:$A21,1) -> 10 | J24: x1_n: | K24: =INDEX($B11:$G11,MATCH(K23,$B11:$G11,1)) -> 0 | L24: Rows: | M24: =MATCH(MAX($A12:$A21),$A12:$A21,1) -> 10
B25: x2_n: | C25: {=INDEX($B11:$G11,IF(MATCH(C23,$B11:$G11,1)<E25,MATCH(C23,$B11:$G11,1)+1,MATCH(C23,$B11:$G11,1)))} -> 1000 | D25: Columns: | E25: =MATCH(MAX($B11:$G11),$B11:$G11,0) -> 6 | J25: x2_n: | K25: {=INDEX($B11:$G11,IF(MATCH(K23,$B11:$G11,1)<M25,MATCH(K23,$B11:$G11,1)+1,MATCH(K23,$B11:$G11,1)))} -> 1000 | L25: Columns: | M25: =MATCH(MAX($B11:$G11),$B11:$G11,0) -> 6
B26: y_n: | C26: =D2 -> 0 | J26: y_n: | K26: =G2 -> 0
B27: n1: | C27: =INDEX($A12:$A21,MATCH(C26,$A12:$A21,1)) -> 0 | J27: n1: | K27: =INDEX($A12:$A21,MATCH(K26,$A12:$A21,1)) -> 0
B28: n2: | C28: {=INDEX($A12:$A21,IF(MATCH(C26,$A12:$A21,1)<E24,MATCH(C26,$A12:$A21,1)+1,MATCH(C26,$A12:$A21,1)))} -> 10 | J28: n2: | K28: {=INDEX($A12:$A21,IF(MATCH(K26,$A12:$A21,1)<M24,MATCH(K26,$A12:$A21,1)+1,MATCH(K26,$A12:$A21,1)))} -> 10
B29: y1_n1: | C29: =INDEX($B12:$G21,MATCH(C26,$A12:$A21,1),MATCH(C23,$B11:$G11,1)) -> 1050 | J29: y1_n1: | K29: =INDEX($B12:$G21,MATCH(K26,$A12:$A21,1),MATCH(K23,$B11:$G11,1)) -> 1050
B30: y2_n1: | C30: {=INDEX($B12:$G21,MATCH(C26,$A12:$A21,1),IF(MATCH(C23,$B11:$G11,1)<E25,MATCH(C23,$B11:$G11,1)+1,MATCH(C26,$A12:$A21,1)))} -> 1100 | J30: y2_n1: | K30: {=INDEX($B12:$G21,MATCH(K26,$A12:$A21,1),IF(MATCH(K23,$B11:$G11,1)<M25,MATCH(K23,$B11:$G11,1)+1,MATCH(K26,$A12:$A21,1)))} -> 1100
B31: y1_n2: | C31: {=INDEX($B12:$G21,IF(MATCH(C26,$A12:$A21,1)<E24,MATCH(C26,$A12:$A21,1)+1,MATCH(C26,$A12:$A21,1)),MATCH(C23,$B11:$G11,1))} -> 1100 | J31: y1_n2: | K31: {=INDEX($B12:$G21,IF(MATCH(K26,$A12:$A21,1)<M24,MATCH(K26,$A12:$A21,1)+1,MATCH(K26,$A12:$A21,1)),MATCH(K23,$B11:$G11,1))} -> 1100
B32: y2_n2: | C32: {=INDEX($B12:$G21,IF(MATCH(C26,$A12:$A21,1)<E24,MATCH(C26,$A12:$A21,1)+1,MATCH(C26,$A12:$A21,1)),IF(MATCH(C23,$B11:$G11,1)<E25,MATCH(C23,$B11:$G11,1)+1,MATCH(C23,$B11:$G11,1)))} -> 1140 | J32: y2_n2: | K32: {=INDEX($B12:$G21,IF(MATCH(K26,$A12:$A21,1)<M24,MATCH(K26,$A12:$A21,1)+1,MATCH(K26,$A12:$A21,1)),IF(MATCH(K23,$B11:$G11,1)<M25,MATCH(K23,$B11:$G11,1)+1,MATCH(K23,$B11:$G11,1)))} -> 1140
B33: y_n1: | C33: =IFERROR(C29+(C23-C24)*(C30-C29)/(C25-C24),C29) -> 1050 | J33: y_n1: | K33: =IFERROR(K29+(K23-K24)*(K30-K29)/(K25-K24),K29) -> 1050
B34: y_n2: | C34: =IFERROR(C31+(C23-C24)*(C32-C31)/(C25-C24),C31) -> 1100 | J34: y_n2: | K34: =IFERROR(K31+(K23-K24)*(K32-K31)/(K25-K24),K31) -> 1100
B35: Distance | C35: =IFERROR(C33+(C26-C27)*(C34-C33)/(C28-C27),C33) -> 1050 | J35: Distance | K35: =IFERROR(K33+(K26-K27)*(K34-K33)/(K28-K27),K33) -> 1050
B37: Vikt
B38: 1000 | C38: 1175 | D38: 1400 | E38: 2000
A39: 9000 | B39: 840 | C39: 975 | D39: 1100 | E39: 99999
A40: 9500 | B40: 870 | C40: 1000 | D40: 1140 | E40: 99999
A41: 10000 | B41: 890 | C41: 1025 | D41: 1160 | E41: 99999
A42: 10500 | B42: 920 | C42: 1060 | D42: 1200 | E42: 99999
A43: 11000 | B43: 940 | C43: 1080 | D43: 1240 | E43: 99999
A44: 11500 | B44: 950 | C44: 1110 | D44: 1320 | E44: 99999
A45: 12000 | B45: 975 | C45: 1150 | D45: 1350 | E45: 99999
A46: 12500 | B46: 1000 | C46: 1175 | D46: 1400 | E46: 99999
...

Sheet Accelerate and GO (2)
B1: Pressure Alt | C1: x_n: | D1: =IF('Take-off'!$C$9="",'Take-off'!$C$16,MAX(0,'Take-off'!$C$16+30*(1013-'Take-off'!$C$9))) -> 0
B2: Temp in calc | C2: y_n: | D2: =IF('Take-off'!C13='Dropdown lists'!B30, 'Take-off'!$C$8+6, 'Take-off'!$C$8) -> -35 | E2: Includes ICE-Vane. Could be disregarded for us
B3: FLAPS UP | O3: FLAPS TAKEOFF | AB3: FLAPS APPROACH
B4: Density altitude | O4: Density altitude | AB4: Density altitude
A5: Temp/PA | B5: -500 | C5: 0 | D5: 1000 | E5: 2000 | F5: 3000 | G5: 4000 | O5: Temp/PA | P5: 0 | Q5: 1000 | R5: 2000 | S5: 3000 | T5: 4000 | AA5: Temp/PA | AB5: -500 | AC5: 0 | AD5: 1000 | AE5: 2000 | AF5: 3000 | AG5: 4000
A6: -40 | B6: 5600 | C6: 5600 | D6: 5600 | E6: 6000 | F6: 6400 | G6: 99999 | O6: -30 | T6: 99999 | AA6: -40 | AB6: 4200 | AC6: 4200 | AD6: 4400 | AE6: 4600 | AF6: 4900 | AG6: 99999
A7: -30 | B7: 5600 | C7: 5600 | D7: 5600 | E7: 6000 | F7: 6400 | G7: 99999 | AA7: -30 | AB7: 4200 | AC7: 4200 | AD7: 4400 | AE7: 4600 | AF7: 4900 | AG7: 99999
A8: -20 | B8: 5600 | C8: 5600 | D8: 5600 | E8: 6000 | F8: 6400 | G8: 99999 | O8: -20 | T8: 99999 | AA8: -20 | AB8: 4200 | AC8: 4200 | AD8: 4400 | AE8: 4600 | AF8: 4900 | AG8: 99999
A9: -10 | B9: 5800 | C9: 5800 | D9: 6100 | E9: 6500 | F9: 6900 | G9: 99999 | O9: -10 | T9: 99999 | AA9: -10 | AB9: 4400 | AC9: 4400 | AD9: 4700 | AE9: 5000 | AF9: 5200 | AG9: 99999
A10: 0 | B10: 6170 | C10: 6170 | D10: 6500 | E10: 6900 | F10: 7400 | G10: 99999 | O10: 0 | T10: 99999 | AA10: 0 | AB10: 4700 | AC10: 4700 | AD10: 5000 | AE10: 5300 | AF10: 5600 | AG10: 99999
A11: 10 | B11: 6500 | C11: 6500 | D11: 6900 | E11: 7400 | F11: 7800 | G11: 99999 | O11: 10 | T11: 99999 | AA11: 10 | AB11: 5000 | AC11: 5000 | AD11: 5300 | AE11: 5600 | AF11: 6000 | AG11: 99999
A12: 20 | B12: 6900 | C12: 6900 | D12: 7400 | E12: 7850 | F12: 8400 | G12: 99999 | O12: 20 | T12: 99999 | AA12: 20 | AB12: 5300 | AC12: 5300 | AD12: 5600 | AE12: 6000 | AF12: 6400 | AG12: 99999
A13: 30 | B13: 7400 | C13: 7400 | D13: 8000 | E13: 8700 | F13: 9400 | G13: 99999 | O13: 30 | T13: 99999 | AA13: 30 | AB13: 5600 | AC13: 5600 | AD13: 6000 | AE13: 6600 | AF13: 7500 | AG13: 99999
A14: 40 | B14: 8200 | C14: 8200 | D14: 9000 | E14: 10000 | F14: 11200 | G14: 99999 | O14: 35 | P14: 99999 | Q14: 99999 | R14: 99999 | S14: 99999 | T14: 99999 | AA14: 40 | AB14: 6400 | AC14: 6400 | AD14: 7200 | AE14: 8100 | AF14: 9200 | AG14: 99999
A15: 45 | B15: 99999 | C15: 99999 | D15: 99999 | E15: 99999 | F15: 99999 | G15: 99999 | AA15: 45 | AB15: 99999 | AC15: 99999 | AD15: 99999 | AE15: 99999 | AF15: 99999 | AG15: 99999
O16: x_n: | P16: =D1 -> 0 | Q16: Table size
B17: x_n: | C17: =D1 -> 0 | D17: Table size | O17: x1_n: | P17: =INDEX(P5:T5,MATCH(P16,P5:T5,1)) -> 0 | Q17: Rows: | R17: =MATCH(MAX(O6:O14),O6:O14,1) -> 9 | AB17: x_n: | AC17: =D1 -> 0 | AD17: Table size
B18: x1_n: | C18: =INDEX(B5:G5,MATCH(C17,B5:G5,1)) -> 0 | D18: Rows: | E18: =MATCH(MAX(A6:A15),A6:A15,1) -> 10 | O18: x2_n: | P18: {=INDEX(P5:T5,IF(MATCH(P16,P5:T5,1)<R18,MATCH(P16,P5:T5,1)+1,MATCH(P16,P5:T5,1)))} -> 1000 | Q18: Columns: | R18: =MATCH(MAX(P5:T5),P5:T5,0) -> 5 | AB18: x1_n: | AC18: =INDEX(AB5:AG5,MATCH(AC17,AB5:AG5,1)) -> 0 | AD18: Rows: | AE18: =MATCH(MAX(AA6:AA15),AA6:AA15,1) -> 10
B19: x2_n: | C19: {=INDEX(B5:G5,IF(MATCH(C17,B5:G5,1)<E19,MATCH(C17,B5:G5,1)+1,MATCH(C17,B5:G5,1)))} -> 1000 | D19: Columns: | E19: =MATCH(MAX(B5:G5),B5:G5,0) -> 6 | O19: y_n: | P19: =D2 -> -35 | AB19: x2_n: | AC19: {=INDEX(AB5:AG5,IF(MATCH(AC17,AB5:AG5,1)<AE19,MATCH(AC17,AB5:AG5,1)+1,MATCH(AC17,AB5:AG5,1)))} -> 1000 | AD19: Columns: | AE19: =MATCH(MAX(AB5:AG5),AB5:AG5,0) -> 6
B20: y_n: | C20: =D2 -> -35 | O20: n1: | P20: =INDEX(O6:O14,MATCH(P19,O6:O14,1)) -> #N/A | AB20: y_n: | AC20: =D2 -> -35
B21: n1: | C21: =INDEX(A6:A15,MATCH(C20,A6:A15,1)) -> -40 | O21: n2: | P21: {=INDEX(O6:O14,IF(MATCH(P19,O6:O14,1)<R17,MATCH(P19,O6:O14,1)+1,MATCH(P19,O6:O14,1)))} -> #N/A | AB21: n1: | AC21: =INDEX(AA6:AA15,MATCH(AC20,AA6:AA15,1)) -> -40
B22: n2: | C22: {=INDEX(A6:A15,IF(MATCH(C20,A6:A15,1)<E18,MATCH(C20,A6:A15,1)+1,MATCH(C20,A6:A15,1)))} -> -30 | O22: y1_n1: | P22: =INDEX(P6:T14,MATCH(P19,O6:O14,1),MATCH(P16,P5:T5,1)) -> #N/A | AB22: n2: | AC22: {=INDEX(AA6:AA15,IF(MATCH(AC20,AA6:AA15,1)<AE18,MATCH(AC20,AA6:AA15,1)+1,MATCH(AC20,AA6:AA15,1)))} -> -30
B23: y1_n1: | C23: =INDEX(B6:G15,MATCH(C20,A6:A15,1),MATCH(C17,B5:G5,1)) -> 5600 | O23: y2_n1: | P23: =INDEX(P6:T14,MATCH(P19,O6:O14,1),IF(MATCH(P16,P5:T5,1)<R18,MATCH(P16,P5:T5,1)+1,MATCH(P19,O6:O14,1))) -> #N/A | AB23: y1_n1: | AC23: =INDEX(AB6:AG15,MATCH(AC20,AA6:AA15,1),MATCH(AC17,AB5:AG5,1)) -> 4200
B24: y2_n1: | C24: {=INDEX(B6:G15,MATCH(C20,A6:A15,1),IF(MATCH(C17,B5:G5,1)<E19,MATCH(C17,B5:G5,1)+1,MATCH(C20,A6:A15,1)))} -> 5600 | O24: y1_n2: | P24: =INDEX(P6:T14,IF(MATCH(P19,O6:O14,1)<R17,MATCH(P19,O6:O14,1)+1,MATCH(P19,O6:O14,1)),MATCH(P16,P5:T5,1)) -> #N/A | AB24: y2_n1: | AC24: {=INDEX(AB6:AG15,MATCH(AC20,AA6:AA15,1),IF(MATCH(AC17,AB5:AG5,1)<AE19,MATCH(AC17,AB5:AG5,1)+1,MATCH(AC20,AA6:AA15,1)))} -> 4400
B25: y1_n2: | C25: {=INDEX(B6:G15,IF(MATCH(C20,A6:A15,1)<E18,MATCH(C20,A6:A15,1)+1,MATCH(C20,A6:A15,1)),MATCH(C17,B5:G5,1))} -> 5600 | O25: y2_n2: | P25: =INDEX(P6:T14,IF(MATCH(P19,O6:O14,1)<R17,MATCH(P19,O6:O14,1)+1,MATCH(P19,O6:O14,1)),IF(MATCH(P16,P5:T5,1)<R18,MATCH(P16,P5:T5,1)+1,MATCH(P16,P5:T5,1))) -> #N/A | AB25: y1_n2: | AC25: {=INDEX(AB6:AG15,IF(MATCH(AC20,AA6:AA15,1)<AE18,MATCH(AC20,AA6:AA15,1)+1,MATCH(AC20,AA6:AA15,1)),MATCH(AC17,AB5:AG5,1))} -> 4200
B26: y2_n2: | C26: {=INDEX(B6:G15,IF(MATCH(C20,A6:A15,1)<E18,MATCH(C20,A6:A15,1)+1,MATCH(C20,A6:A15,1)),IF(MATCH(C17,B5:G5,1)<E19,MATCH(C17,B5:G5,1)+1,MATCH(C17,B5:G5,1)))} -> 5600 | O26: y_n1: | P26: =IFERROR(P22+(P16-P17)*(P23-P22)/(P18-P17),P22) -> #N/A | AB26: y2_n2: | AC26: {=INDEX(AB6:AG15,IF(MATCH(AC20,AA6:AA15,1)<AE18,MATCH(AC20,AA6:AA15,1)+1,MATCH(AC20,AA6:AA15,1)),IF(MATCH(AC17,AB5:AG5,1)<AE19,MATCH(AC17,AB5:AG5,1)+1,MATCH(AC17,AB5:AG5,1)))} -> 4400
B27: y_n1: | C27: =IFERROR(C23+(C17-C18)*(C24-C23)/(C19-C18),C23) -> 5600 | O27: y_n2: | P27: =IFERROR(P24+(P16-P17)*(P25-P24)/(P18-P17),P24) -> #N/A | AB27: y_n1: | AC27: =IFERROR(AC23+(AC17-AC18)*(AC24-AC23)/(AC19-AC18),AC23) -> 4200
B28: y_n2: | C28: =IFERROR(C25+(C17-C18)*(C26-C25)/(C19-C18),C25) -> 5600 | O28: Distance | P28: =IFERROR(P26+(P19-P20)*(P27-P26)/(P21-P20),P26) -> #N/A | AB28: y_n2: | AC28: =IFERROR(AC25+(AC17-AC18)*(AC26-AC25)/(AC19-AC18),AC25) -> 4200
B29: Distance | C29: =IFERROR(C27+(C20-C21)*(C28-C27)/(C22-C21),C27) -> 5600 | AB29: Distance | AC29: =IFERROR(AC27+(AC20-AC21)*(AC28-AC27)/(AC22-AC21),AC27) -> 4200
O30: Vikt
B31: Vikt | N31: % | O31: 2000 | P31: 3000 | Q31: 4000 | R31: 4500 | AB31: Vikt
A32: % | B32: 5600 | C32: 7000 | D32: 8400 | E32: 10000 | F32: 11400 | G32: 12000 | O32: 10000 | S32: 99999 | AC32: % | AD32: 4200 | AE32: 6400 | AF32: 8400 | AG32: 10400 | AH32: 11000
A33: 9000 | B33: 2600 | C33: 3200 | D33: 3700 | E33: 4200 | F33: 4600 | G33: 99999 | O33: 11000 | S33: 99999 | AC33: 9000 | AD33: 2400 | AE33: 3100 | AF33: 3700 | AG33: 4300 | AH33: 99999
A34: 9500 | B34: 2900 | C34: 3600 | D34: 4100 | E34: 4600 | F34: 5200 | G34: 99999 | O34: 12000 | S34: 99999 | AC34: 9500 | AD34: 2500 | AE34: 3400 | AF34: 4150 | AG34: 4800 | AH34: 99999
A35: 10000 | B35: 3200 | C35: 4000 | D35: 4600 | E35: 5200 | F35: 5900 | G35: 99999 | O35: 13000 | S35: 99999 | AC35: 10000 | AD35: 2700 | AE35: 3700 | AF35: 4600 | AG35: 5400 | AH35: 99999
A36: 10500 | B36: 3600 | C36: 4400 | D36: 5200 | E36: 5900 | F36: 6700 | G36: 99999 | O36: 14000 | S36: 99999 | AC36: 10500 | AD36: 3000 | AE36: 4150 | AF36: 5200 | AG36: 6000 | AH36: 99999
A37: 11000 | B37: 4000 | C37: 5000 | D37: 5900 | E37: 6700 | F37: 7600 | G37: 99999 | O37: 15000 | S37: 99999 | AC37: 11000 | AD37: 3200 | AE37: 4600 | AF37: 5800 | AG37: 6800 | AH37: 99999
A38: 11500 | B38: 4500 | C38: 5600 | D38: 6600 | E38: 7700 | F38: 8800 | G38: 99999 | O38: 16000 | S38: 99999 | AC38: 11500 | AD38: 3600 | AE38: 5150 | AF38: 6500 | AG38: 7800 | AH38: 99999
A39: 12000 | B39: 5000 | C39: 6300 | D39: 7400 | E39: 8700 | F39: 10000 | G39: 99999 | O39: 16600 | S39: 99999 | AC39: 12000 | AD39: 3900 | AE39: 5700 | AF39: 7350 | AG39: 9000 | AH39: 99999
A40: 12500 | B40: 5600 | C40: 7000 | D40: 8400 | E40: 10000 | F40: 11400 | G40: 99999 | O40: 16700 | P40: 99999 | Q40: 99999 | R40: 99999 | S40: 99999 | AC40: 12500 | AD40: 4200 | AE40: 6400 | AF40: 8400 | AG40: 10400 | AH40: 99999
...

Sheet Accelerate and stop2
B1: Pressure Alt | C1: x_n: | D1: =IF('Take-off'!$C$9="",'Take-off'!$C$16,MAX(0,'Take-off'!$C$16+30*(1013-'Take-off'!$C$9))) -> 0
B2: Temp in calc | C2: y_n: | D2: ='Take-off'!$C$8 -> -35 | E2: Includes ICE-Vane. Could be disregarded for us
B3: FLAPS UP | O3: FLAPS TAKEOFF | AB3: FLAPS APPROACH
B4: Density altitude | O4: Density altitude | AB4: Density altitude
A5: Temp/PA | B5: -500 | C5: 0 | D5: 1000 | E5: 2000 | F5: 3000 | G5: 4000 | N5: Temp/PA | O5: 0 | P5: 1000 | Q5: 2000 | R5: 3000 | S5: 4000 | AA5: Temp/PA | AB5: -500 | AC5: 0 | AD5: 1000 | AE5: 2000 | AF5: 3000 | AG5: 4000
A6: -40 | B6: 2950 | C6: 2950 | D6: 3100 | E6: 3175 | F6: 3300 | G6: 99999 | N6: -30 | S6: 99999 | AA6: -40 | AB6: 3000 | AC6: 3000 | AD6: 3100 | AE6: 3200 | AF6: 3350 | AG6: 99999
A7: -30 | B7: 2950 | C7: 2950 | D7: 3100 | E7: 3175 | F7: 3300 | G7: 99999 | AA7: -30 | AB7: 3000 | AC7: 3000 | AD7: 3100 | AE7: 3200 | AF7: 3350 | AG7: 99999
A8: -20 | B8: 2950 | C8: 2950 | D8: 3100 | E8: 3175 | F8: 3300 | G8: 99999 | N8: -20 | S8: 99999 | AA8: -20 | AB8: 3000 | AC8: 3000 | AD8: 3100 | AE8: 3200 | AF8: 3350 | AG8: 99999
A9: -10 | B9: 3050 | C9: 3050 | D9: 3150 | E9: 3300 | F9: 3450 | G9: 99999 | N9: -10 | S9: 99999 | AA9: -10 | AB9: 3050 | AC9: 3050 | AD9: 3200 | AE9: 3300 | AF9: 3450 | AG9: 99999
A10: 0 | B10: 3150 | C10: 3150 | D10: 3300 | E10: 3450 | F10: 3600 | G10: 99999 | N10: 0 | S10: 99999 | AA10: 0 | AB10: 3200 | AC10: 3200 | AD10: 3350 | AE10: 3500 | AF10: 3600 | AG10: 99999
A11: 10 | B11: 3300 | C11: 3300 | D11: 3450 | E11: 3620 | F11: 3800 | G11: 99999 | N11: 10 | S11: 99999 | AA11: 10 | AB11: 3350 | AC11: 3350 | AD11: 3450 | AE11: 3600 | AF11: 3800 | AG11: 99999
A12: 20 | B12: 3450 | C12: 3450 | D12: 3620 | E12: 3800 | F12: 4000 | G12: 99999 | N12: 20 | S12: 99999 | AA12: 20 | AB12: 3450 | AC12: 3450 | AD12: 3650 | AE12: 3800 | AF12: 4000 | AG12: 99999
A13: 30 | B13: 3630 | C13: 3630 | D13: 3800 | E13: 4000 | F13: 4200 | G13: 99999 | N13: 30 | S13: 99999 | AA13: 30 | AB13: 3600 | AC13: 3600 | AD13: 3800 | AE13: 3950 | AF13: 4250 | AG13: 99999
A14: 40 | B14: 3850 | C14: 3850 | D14: 4000 | E14: 4370 | F14: 4550 | G14: 99999 | N14: 35 | O14: 99999 | P14: 99999 | Q14: 99999 | R14: 99999 | S14: 99999 | AA14: 40 | AB14: 3850 | AC14: 3850 | AD14: 4050 | AE14: 4250 | AF14: 4500 | AG14: 99999
A15: 45 | B15: 99999 | C15: 99999 | D15: 99999 | E15: 99999 | F15: 99999 | G15: 99999 | AA15: 45 | AB15: 99999 | AC15: 99999 | AD15: 99999 | AE15: 99999 | AF15: 99999 | AG15: 99999
O16: x_n: | P16: =D1 -> 0 | Q16: Table size
B17: x_n: | C17: =D1 -> 0 | D17: Table size | O17: x1_n: | P17: =INDEX(O5:S5,MATCH(P16,O5:S5,1)) -> 0 | Q17: Rows: | R17: =MATCH(MAX(N6:N14),N6:N14,1) -> 9 | AB17: x_n: | AC17: =D1 -> 0 | AD17: Table size
B18: x1_n: | C18: =INDEX(B5:G5,MATCH(C17,B5:G5,1)) -> 0 | D18: Rows: | E18: =MATCH(MAX(A6:A15),A6:A15,1) -> 10 | O18: x2_n: | P18: {=INDEX(O5:S5,IF(MATCH(P16,O5:S5,1)<R18,MATCH(P16,O5:S5,1)+1,MATCH(P16,O5:S5,1)))} -> 1000 | Q18: Columns: | R18: =MATCH(MAX(O5:S5),O5:S5,0) -> 5 | AB18: x1_n: | AC18: =INDEX(AB5:AG5,MATCH(AC17,AB5:AG5,1)) -> 0 | AD18: Rows: | AE18: =MATCH(MAX(AA6:AA15),AA6:AA15,1) -> 10
B19: x2_n: | C19: {=INDEX(B5:G5,IF(MATCH(C17,B5:G5,1)<E19,MATCH(C17,B5:G5,1)+1,MATCH(C17,B5:G5,1)))} -> 1000 | D19: Columns: | E19: =MATCH(MAX(B5:G5),B5:G5,0) -> 6 | O19: y_n: | P19: =D2 -> -35 | AB19: x2_n: | AC19: {=INDEX(AB5:AG5,IF(MATCH(AC17,AB5:AG5,1)<AE19,MATCH(AC17,AB5:AG5,1)+1,MATCH(AC17,AB5:AG5,1)))} -> 1000 | AD19: Columns: | AE19: =MATCH(MAX(AB5:AG5),AB5:AG5,0) -> 6
B20: y_n: | C20: =D2 -> -35 | O20: n1: | P20: =INDEX(N6:N14,MATCH(P19,N6:N14,1)) -> #N/A | AB20: y_n: | AC20: =D2 -> -35
B21: n1: | C21: =INDEX(A6:A15,MATCH(C20,A6:A15,1)) -> -40 | O21: n2: | P21: {=INDEX(N6:N14,IF(MATCH(P19,N6:N14,1)<R17,MATCH(P19,N6:N14,1)+1,MATCH(P19,N6:N14,1)))} -> #N/A | AB21: n1: | AC21: =INDEX(AA6:AA15,MATCH(AC20,AA6:AA15,1)) -> -40
B22: n2: | C22: {=INDEX(A6:A15,IF(MATCH(C20,A6:A15,1)<E18,MATCH(C20,A6:A15,1)+1,MATCH(C20,A6:A15,1)))} -> -30 | O22: y1_n1: | P22: =INDEX(O6:S14,MATCH(P19,N6:N14,1),MATCH(P16,O5:S5,1)) -> #N/A | AB22: n2: | AC22: {=INDEX(AA6:AA15,IF(MATCH(AC20,AA6:AA15,1)<AE18,MATCH(AC20,AA6:AA15,1)+1,MATCH(AC20,AA6:AA15,1)))} -> -30
B23: y1_n1: | C23: =INDEX(B6:G15,MATCH(C20,A6:A15,1),MATCH(C17,B5:G5,1)) -> 2950 | O23: y2_n1: | P23: =INDEX(O6:S14,MATCH(P19,N6:N14,1),IF(MATCH(P16,O5:S5,1)<R18,MATCH(P16,O5:S5,1)+1,MATCH(P19,N6:N14,1))) -> #N/A | AB23: y1_n1: | AC23: =INDEX(AB6:AG15,MATCH(AC20,AA6:AA15,1),MATCH(AC17,AB5:AG5,1)) -> 3000
B24: y2_n1: | C24: {=INDEX(B6:G15,MATCH(C20,A6:A15,1),IF(MATCH(C17,B5:G5,1)<E19,MATCH(C17,B5:G5,1)+1,MATCH(C20,A6:A15,1)))} -> 3100 | O24: y1_n2: | P24: =INDEX(O6:S14,IF(MATCH(P19,N6:N14,1)<R17,MATCH(P19,N6:N14,1)+1,MATCH(P19,N6:N14,1)),MATCH(P16,O5:S5,1)) -> #N/A | AB24: y2_n1: | AC24: {=INDEX(AB6:AG15,MATCH(AC20,AA6:AA15,1),IF(MATCH(AC17,AB5:AG5,1)<AE19,MATCH(AC17,AB5:AG5,1)+1,MATCH(AC20,AA6:AA15,1)))} -> 3100
B25: y1_n2: | C25: {=INDEX(B6:G15,IF(MATCH(C20,A6:A15,1)<E18,MATCH(C20,A6:A15,1)+1,MATCH(C20,A6:A15,1)),MATCH(C17,B5:G5,1))} -> 2950 | O25: y2_n2: | P25: =INDEX(O6:S14,IF(MATCH(P19,N6:N14,1)<R17,MATCH(P19,N6:N14,1)+1,MATCH(P19,N6:N14,1)),IF(MATCH(P16,O5:S5,1)<R18,MATCH(P16,O5:S5,1)+1,MATCH(P16,O5:S5,1))) -> #N/A | AB25: y1_n2: | AC25: {=INDEX(AB6:AG15,IF(MATCH(AC20,AA6:AA15,1)<AE18,MATCH(AC20,AA6:AA15,1)+1,MATCH(AC20,AA6:AA15,1)),MATCH(AC17,AB5:AG5,1))} -> 3000
B26: y2_n2: | C26: {=INDEX(B6:G15,IF(MATCH(C20,A6:A15,1)<E18,MATCH(C20,A6:A15,1)+1,MATCH(C20,A6:A15,1)),IF(MATCH(C17,B5:G5,1)<E19,MATCH(C17,B5:G5,1)+1,MATCH(C17,B5:G5,1)))} -> 3100 | O26: y_n1: | P26: =IFERROR(P22+(P16-P17)*(P23-P22)/(P18-P17),P22) -> #N/A | AB26: y2_n2: | AC26: {=INDEX(AB6:AG15,IF(MATCH(AC20,AA6:AA15,1)<AE18,MATCH(AC20,AA6:AA15,1)+1,MATCH(AC20,AA6:AA15,1)),IF(MATCH(AC17,AB5:AG5,1)<AE19,MATCH(AC17,AB5:AG5,1)+1,MATCH(AC17,AB5:AG5,1)))} -> 3100
B27: y_n1: | C27: =IFERROR(C23+(C17-C18)*(C24-C23)/(C19-C18),C23) -> 2950 | O27: y_n2: | P27: =IFERROR(P24+(P16-P17)*(P25-P24)/(P18-P17),P24) -> #N/A | AB27: y_n1: | AC27: =IFERROR(AC23+(AC17-AC18)*(AC24-AC23)/(AC19-AC18),AC23) -> 3000
B28: y_n2: | C28: =IFERROR(C25+(C17-C18)*(C26-C25)/(C19-C18),C25) -> 2950 | O28: Distance | P28: =IFERROR(P26+(P19-P20)*(P27-P26)/(P21-P20),P26) -> #N/A | AB28: y_n2: | AC28: =IFERROR(AC25+(AC17-AC18)*(AC26-AC25)/(AC19-AC18),AC25) -> 3000
B29: Distance | C29: =IFERROR(C27+(C20-C21)*(C28-C27)/(C22-C21),C27) -> 2950 | AB29: Distance | AC29: =IFERROR(AC27+(AC20-AC21)*(AC28-AC27)/(AC22-AC21),AC27) -> 3000
O30: Vikt
B31: Vikt | N31: % | O31: 3600 | P31: 4300 | Q31: 5000 | R31: 5700 | S31: 6000 | AB31: Vikt
A32: % | B32: 2950 | C32: 3430 | D32: 3900 | E32: 4300 | F32: 4750 | G32: 5000 | N32: 10000 | S32: 99999 | AA32: % | AB32: 3000 | AC32: 3450 | AD32: 3900 | AE32: 4350 | AF32: 5000
A33: 9000 | B33: 2580 | C33: 2950 | D33: 3300 | E33: 3600 | F33: 3950 | G33: 99999 | N33: 11000 | S33: 99999 | AA33: 9000 | AB33: 2650 | AC33: 3000 | AD33: 3350 | AE33: 3700 | AF33: 99999
A34: 9500 | B34: 2600 | C34: 3000 | D34: 3350 | E34: 3700 | F34: 4100 | G34: 99999 | N34: 12000 | S34: 99999 | AA34: 9500 | AB34: 2700 | AC34: 3050 | AD34: 3400 | AE34: 3770 | AF34: 99999
A35: 10000 | B35: 2670 | C35: 3100 | D35: 3450 | E35: 3800 | F35: 4200 | G35: 99999 | N35: 13000 | S35: 99999 | AA35: 10000 | AB35: 2710 | AC35: 3100 | AD35: 3500 | AE35: 3850 | AF35: 99999
A36: 10500 | B36: 2700 | C36: 3130 | D36: 3500 | E36: 3900 | F36: 4300 | G36: 99999 | N36: 14000 | S36: 99999 | AA36: 10500 | AB36: 2770 | AC36: 3180 | AD36: 3550 | AE36: 3950 | AF36: 99999
A37: 11000 | B37: 2750 | C37: 3200 | D37: 3600 | E37: 4000 | F37: 4400 | G37: 99999 | N37: 15000 | S37: 99999 | AA37: 11000 | AB37: 2800 | AC37: 3220 | AD37: 3650 | AE37: 4000 | AF37: 99999
A38: 11500 | B38: 2800 | C38: 3250 | D38: 3700 | E38: 4100 | F38: 4500 | G38: 99999 | N38: 16000 | S38: 99999 | AA38: 11500 | AB38: 2900 | AC38: 3300 | AD38: 3700 | AE38: 4100 | AF38: 99999
A39: 12000 | B39: 2900 | C39: 3350 | D39: 3800 | E39: 4200 | F39: 4650 | G39: 99999 | N39: 16600 | S39: 99999 | AA39: 12000 | AB39: 2950 | AC39: 3350 | AD39: 3800 | AE39: 4250 | AF39: 99999
A40: 12500 | B40: 2950 | C40: 3430 | D40: 3900 | E40: 4300 | F40: 4750 | G40: 99999 | N40: 16700 | O40: 99999 | P40: 99999 | Q40: 99999 | R40: 99999 | S40: 99999 | AA40: 12500 | AB40: 3000 | AC40: 3450 | AD40: 3900 | AE40: 4350 | AF40: 99999
...

Sheet OEI CLIMB GRADIENT
B1: Pressure Alt | C1: x_n: | D1: =IF(Landing!$C$9="",Landing!$C$15,MAX(0,Landing!$C$15+30*(1013-Landing!$C$9))) -> 0
B2: Temp in calc | C2: y_n: | D2: =Landing!C8 -> 0
B3: NET GRADIENT OF CLIMB - FLAPS UP
B4: Density altitude
A5: Temp/PA | B5: -500 | C5: 0 | D5: 1000 | E5: 2000 | F5: 3000 | G5: 4000
A6: -40 | B6: 740 | C6: 740 | D6: 730 | E6: 720 | F6: 710 | G6: -999
A7: -30 | B7: 740 | C7: 740 | D7: 730 | E7: 720 | F7: 710 | G7: -999
A8: -20 | B8: 740 | C8: 740 | D8: 730 | E8: 720 | F8: 710 | G8: -999
A9: -10 | B9: 735 | C9: 735 | D9: 720 | E9: 710 | F9: 700 | G9: -999
A10: 0 | B10: 720 | C10: 720 | D10: 710 | E10: 700 | F10: 690 | G10: -999
A11: 10 | B11: 710 | C11: 710 | D11: 700 | E11: 690 | F11: 675 | G11: -999
A12: 20 | B12: 700 | C12: 700 | D12: 690 | E12: 675 | F12: 650 | G12: -999
A13: 30 | B13: 690 | C13: 690 | D13: 660 | E13: 625 | F13: 580 | G13: -999
A14: 40 | B14: 620 | C14: 620 | D14: 580 | E14: 540 | F14: 490 | G14: -999
A15: 45 | B15: -999 | C15: -999 | D15: -999 | E15: -999 | F15: -999 | G15: -999
B17: x_n: | C17: =D1 -> 0 | D17: Table size
B18: x1_n: | C18: =INDEX(B5:G5,MATCH(C17,B5:G5,1)) -> 0 | D18: Rows: | E18: =MATCH(MAX(A6:A15),A6:A15,1) -> 10
B19: x2_n: | C19: {=INDEX(B5:G5,IF(MATCH(C17,B5:G5,1)<E19,MATCH(C17,B5:G5,1)+1,MATCH(C17,B5:G5,1)))} -> 1000 | D19: Columns: | E19: =MATCH(MAX(B5:G5),B5:G5,0) -> 6
B20: y_n: | C20: =D2 -> 0
B21: n1: | C21: =INDEX(A6:A15,MATCH(C20,A6:A15,1)) -> 0
B22: n2: | C22: {=INDEX(A6:A15,IF(MATCH(C20,A6:A15,1)<E18,MATCH(C20,A6:A15,1)+1,MATCH(C20,A6:A15,1)))} -> 10
B23: y1_n1: | C23: =INDEX(B6:G15,MATCH(C20,A6:A15,1),MATCH(C17,B5:G5,1)) -> 720
B24: y2_n1: | C24: {=INDEX(B6:G15,MATCH(C20,A6:A15,1),IF(MATCH(C17,B5:G5,1)<E19,MATCH(C17,B5:G5,1)+1,MATCH(C20,A6:A15,1)))} -> 710
B25: y1_n2: | C25: {=INDEX(B6:G15,IF(MATCH(C20,A6:A15,1)<E18,MATCH(C20,A6:A15,1)+1,MATCH(C20,A6:A15,1)),MATCH(C17,B5:G5,1))} -> 710
B26: y2_n2: | C26: {=INDEX(B6:G15,IF(MATCH(C20,A6:A15,1)<E18,MATCH(C20,A6:A15,1)+1,MATCH(C20,A6:A15,1)),IF(MATCH(C17,B5:G5,1)<E19,MATCH(C17,B5:G5,1)+1,MATCH(C17,B5:G5,1)))} -> 700
B27: y_n1: | C27: =IFERROR(C23+(C17-C18)*(C24-C23)/(C19-C18),C23) -> 720
B28: y_n2: | C28: =IFERROR(C25+(C17-C18)*(C26-C25)/(C19-C18),C25) -> 710
B29: Distance | C29: =IFERROR(C27+(C20-C21)*(C28-C27)/(C22-C21),C27) -> 720
B31: ROC | O31: ROC->Gradient
A32: % | B32: 410 | C32: 530 | D32: 640 | E32: 750 | F32: 900 | P32: % | Q32: 320 | R32: 440 | S32: 550 | T32: 640 | U32: 710 | V32: 760 | W32: 1000 | X32: 1200
A33: 9000 | B33: 920 | C33: 1000 | D33: 1000 | E33: 1000 | F33: -999 | P33: 1 | Q33: 2 | R33: 3 | S33: 4 | T33: 5 | U33: 6 | V33: 7 | W33: 7 | X33: 7
A34: 9500 | B34: 820 | C34: 950 | D34: 1000 | E34: 1000 | F34: -999
A35: 10000 | B35: 740 | C35: 860 | D35: 980 | E35: 1000 | F35: -999 | O35: x_n: | P35: =C56 -> 802.72727 | Q35: Table size
A36: 10500 | B36: 670 | C36: 780 | D36: 910 | E36: 1000 | F36: -999 | O36: x1_n: | P36: =INDEX(Q32:X32,MATCH(P35,Q32:X32,1)) -> 760 | Q36: Rows: | R36: =MATCH(MAX(P33),P33,1) -> 1
A37: 11000 | B37: 595 | C37: 710 | D37: 830 | E37: 930 | F37: -999 | O37: x2_n: | P37: {=INDEX(Q32:X32,IF(MATCH(P35,Q32:X32,1)<R37,MATCH(P35,Q32:X32,1)+1,MATCH(P35,Q32:X32,1)))} -> 1000 | Q37: Columns: | R37: =MATCH(MAX(Q32:X32),Q32:X32,0) -> 8
A38: 11500 | B38: 530 | C38: 640 | D38: 760 | E38: 860 | F38: -999 | O38: y_n: | P38: 1
A39: 12000 | B39: 460 | C39: 580 | D39: 700 | E39: 800 | F39: -999 | O39: n1: | P39: =INDEX(P33,MATCH(P38,P33,1)) -> 1
A40: 12500 | B40: 410 | C40: 530 | D40: 640 | E40: 750 | F40: -999 | O40: n2: | P40: {=INDEX(P33,IF(MATCH(P38,P33,1)<R36,MATCH(P38,P33,1)+1,MATCH(P38,P33,1)))} -> 1
A41: 12600 | B41: -999 | C41: -999 | D41: -999 | E41: -999 | F41: -999 | O41: y1_n1: | P41: =INDEX(Q33:X33,MATCH(P38,P33,1),MATCH(P35,Q32:X32,1)) -> 7
O42: y2_n1: | P42: {=INDEX(Q33:X33,MATCH(P38,P33,1),IF(MATCH(P35,Q32:X32,1)<R37,MATCH(P35,Q32:X32,1)+1,MATCH(P38,P33,1)))} -> 7
...

Sheet NET GRADIENT OF CLIMB
B1: Pressure Alt | C1: x_n: | D1: =IF('Take-off'!$C$9="",'Take-off'!$C$16,MAX(0,'Take-off'!$C$16+30*(1013-'Take-off'!$C$9)))+35 -> 35 | F1: 35 fot extra
B2: Temp in calc | C2: y_n: | D2: =IF('Take-off'!$C$13='Dropdown lists'!$B$30, 'Take-off'!$C$8+10, 'Take-off'!$C$8) -> -35 | E2: Includes ICE-Vane. Could be disregarded for us
B3: NET GRADIENT OF CLIMB - FLAPS UP | O3: NET GRADIENT OF CLIMB - FLAPS TAKEOFF | AB3: NET GRADIENT OF CLIMB - FLAPS APPROACH
B4: Density altitude | O4: Density altitude | AB4: Density altitude
A5: Temp/PA | B5: -500 | C5: 0 | D5: 1000 | E5: 2000 | F5: 3000 | G5: 4000 | O5: Temp/PA | P5: 0 | Q5: 1000 | R5: 2000 | S5: 3000 | T5: 4000 | AA5: Temp/PA | AB5: -500 | AC5: 0 | AD5: 1000 | AE5: 2000 | AF5: 3000 | AG5: 4000
A6: -40 | B6: 5.4 | C6: 5.4 | D6: 5.2 | E6: 5 | F6: 4.8 | G6: -99 | O6: -30 | T6: 99999 | AA6: -40 | AB6: 4.2 | AC6: 4.2 | AD6: 4 | AE6: 3.9 | AF6: 3.6 | AG6: -99
A7: -30 | B7: 5.4 | C7: 5.4 | D7: 5.2 | E7: 5 | F7: 4.8 | G7: -99 | AA7: -30 | AB7: 4.2 | AC7: 4.2 | AD7: 4 | AE7: 3.9 | AF7: 3.6 | AG7: -99
A8: -20 | B8: 5.4 | C8: 5.4 | D8: 5.2 | E8: 5 | F8: 4.8 | G8: -99 | O8: -20 | T8: 99999 | AA8: -20 | AB8: 4.2 | AC8: 4.2 | AD8: 4 | AE8: 3.9 | AF8: 3.6 | AG8: -99
A9: -10 | B9: 5.3 | C9: 5.3 | D9: 5.1 | E9: 4.9 | F9: 4.7 | G9: -99 | O9: -10 | T9: 99999 | AA9: -10 | AB9: 4.1 | AC9: 4.1 | AD9: 3.9 | AE9: 3.6 | AF9: 3.4 | AG9: -99
A10: 0 | B10: 5.1 | C10: 5.1 | D10: 4.9 | E10: 4.65 | F10: 4.4 | G10: -99 | O10: 0 | T10: 99999 | AA10: 0 | AB10: 3.8 | AC10: 3.8 | AD10: 3.6 | AE10: 3.4 | AF10: 3.2 | AG10: -99
A11: 10 | B11: 4.9 | C11: 4.9 | D11: 4.7 | E11: 4.5 | F11: 4.2 | G11: -99 | O11: 10 | T11: 99999 | AA11: 10 | AB11: 3.6 | AC11: 3.6 | AD11: 3.4 | AE11: 3.2 | AF11: 2.9 | AG11: -99
A12: 20 | B12: 4.7 | C12: 4.7 | D12: 4.5 | E12: 4.3 | F12: 3.9 | G12: -99 | O12: 20 | T12: 99999 | AA12: 20 | AB12: 3.4 | AC12: 3.4 | AD12: 3.2 | AE12: 3 | AF12: 2.5 | AG12: -99
A13: 24 | B13: 4.6 | C13: 4.6 | D13: 4.4 | E13: 4.2 | F13: 3.8 | G13: -99 | AA13: 24 | AB13: 3.35 | AC13: 3.35 | AD13: 3.35 | AE13: 2.9 | AF13: 2.4 | AG13: -99
A14: 30 | B14: 4.5 | C14: 4.5 | D14: 4.1 | E14: 3.7 | F14: 3.35 | G14: -99 | O14: 30 | T14: 99999 | AA14: 30 | AB14: 3.2 | AC14: 3.2 | AD14: 2.8 | AE14: 2.4 | AF14: 2 | AG14: -99
A15: 40 | B15: 3.7 | C15: 3.7 | D15: 3.4 | E15: 3 | F15: 2.6 | G15: -99 | AA15: 40 | AB15: 2.4 | AC15: 2.4 | AD15: 2 | AE15: 1.6 | AF15: 1 | AG15: -99
A16: 45 | B16: -99 | C16: -99 | D16: -99 | E16: -99 | F16: -99 | G16: -99 | O16: 35 | P16: 99999 | Q16: 99999 | R16: 99999 | S16: 99999 | T16: 99999 | AA16: 45 | AB16: -99 | AC16: -99 | AD16: -99 | AE16: -99 | AF16: -99 | AG16: -99
B18: x_n: | C18: =D1 -> 35 | D18: Table size | O18: x_n: | P18: =D1 -> 35 | Q18: Table size | AB18: x_n: | AC18: =D1 -> 35 | AD18: Table size
B19: x1_n: | C19: =INDEX(B5:G5,MATCH(C18,B5:G5,1)) -> 0 | D19: Rows: | E19: =MATCH(MAX(A6:A16),A6:A16,1) -> 11 | O19: x1_n: | P19: =INDEX(P5:T5,MATCH(P18,P5:T5,1)) -> 0 | Q19: Rows: | R19: =MATCH(MAX(O6:O16),O6:O16,1) -> 11 | AB19: x1_n: | AC19: =INDEX(AB5:AG5,MATCH(AC18,AB5:AG5,1)) -> 0 | AD19: Rows: | AE19: =MATCH(MAX(AA6:AA16),AA6:AA16,1) -> 11
B20: x2_n: | C20: {=INDEX(B5:G5,IF(MATCH(C18,B5:G5,1)<E20,MATCH(C18,B5:G5,1)+1,MATCH(C18,B5:G5,1)))} -> 1000 | D20: Columns: | E20: =MATCH(MAX(B5:G5),B5:G5,0) -> 6 | O20: x2_n: | P20: {=INDEX(P5:T5,IF(MATCH(P18,P5:T5,1)<R20,MATCH(P18,P5:T5,1)+1,MATCH(P18,P5:T5,1)))} -> 1000 | Q20: Columns: | R20: =MATCH(MAX(P5:T5),P5:T5,0) -> 5 | AB20: x2_n: | AC20: {=INDEX(AB5:AG5,IF(MATCH(AC18,AB5:AG5,1)<AE20,MATCH(AC18,AB5:AG5,1)+1,MATCH(AC18,AB5:AG5,1)))} -> 1000 | AD20: Columns: | AE20: =MATCH(MAX(AB5:AG5),AB5:AG5,0) -> 6
B21: y_n: | C21: =D2 -> -35 | O21: y_n: | P21: =D2 -> -35 | AB21: y_n: | AC21: =D2 -> -35
B22: n1: | C22: =INDEX(A6:A16,MATCH(C21,A6:A16,1)) -> -40 | O22: n1: | P22: =INDEX(O6:O16,MATCH(P21,O6:O16,1)) -> #N/A | AB22: n1: | AC22: =INDEX(AA6:AA16,MATCH(AC21,AA6:AA16,1)) -> -40
B23: n2: | C23: {=INDEX(A6:A16,IF(MATCH(C21,A6:A16,1)<E19,MATCH(C21,A6:A16,1)+1,MATCH(C21,A6:A16,1)))} -> -30 | O23: n2: | P23: {=INDEX(O6:O16,IF(MATCH(P21,O6:O16,1)<R19,MATCH(P21,O6:O16,1)+1,MATCH(P21,O6:O16,1)))} -> #N/A | AB23: n2: | AC23: {=INDEX(AA6:AA16,IF(MATCH(AC21,AA6:AA16,1)<AE19,MATCH(AC21,AA6:AA16,1)+1,MATCH(AC21,AA6:AA16,1)))} -> -30
B24: y1_n1: | C24: =INDEX(B6:G16,MATCH(C21,A6:A16,1),MATCH(C18,B5:G5,1)) -> 5.4 | O24: y1_n1: | P24: =INDEX(P6:T16,MATCH(P21,O6:O16,1),MATCH(P18,P5:T5,1)) -> #N/A | AB24: y1_n1: | AC24: =INDEX(AB6:AG16,MATCH(AC21,AA6:AA16,1),MATCH(AC18,AB5:AG5,1)) -> 4.2
B25: y2_n1: | C25: {=INDEX(B6:G16,MATCH(C21,A6:A16,1),IF(MATCH(C18,B5:G5,1)<E20,MATCH(C18,B5:G5,1)+1,MATCH(C21,A6:A16,1)))} -> 5.2 | O25: y2_n1: | P25: =INDEX(P6:T16,MATCH(P21,O6:O16,1),IF(MATCH(P18,P5:T5,1)<R20,MATCH(P18,P5:T5,1)+1,MATCH(P21,O6:O16,1))) -> #N/A | AB25: y2_n1: | AC25: {=INDEX(AB6:AG16,MATCH(AC21,AA6:AA16,1),IF(MATCH(AC18,AB5:AG5,1)<AE20,MATCH(AC18,AB5:AG5,1)+1,MATCH(AC21,AA6:AA16,1)))} -> 4
B26: y1_n2: | C26: {=INDEX(B6:G16,IF(MATCH(C21,A6:A16,1)<E19,MATCH(C21,A6:A16,1)+1,MATCH(C21,A6:A16,1)),MATCH(C18,B5:G5,1))} -> 5.4 | O26: y1_n2: | P26: =INDEX(P6:T16,IF(MATCH(P21,O6:O16,1)<R19,MATCH(P21,O6:O16,1)+1,MATCH(P21,O6:O16,1)),MATCH(P18,P5:T5,1)) -> #N/A | AB26: y1_n2: | AC26: {=INDEX(AB6:AG16,IF(MATCH(AC21,AA6:AA16,1)<AE19,MATCH(AC21,AA6:AA16,1)+1,MATCH(AC21,AA6:AA16,1)),MATCH(AC18,AB5:AG5,1))} -> 4.2
B27: y2_n2: | C27: {=INDEX(B6:G16,IF(MATCH(C21,A6:A16,1)<E19,MATCH(C21,A6:A16,1)+1,MATCH(C21,A6:A16,1)),IF(MATCH(C18,B5:G5,1)<E20,MATCH(C18,B5:G5,1)+1,MATCH(C18,B5:G5,1)))} -> 5.2 | O27: y2_n2: | P27: =INDEX(P6:T16,IF(MATCH(P21,O6:O16,1)<R19,MATCH(P21,O6:O16,1)+1,MATCH(P21,O6:O16,1)),IF(MATCH(P18,P5:T5,1)<R20,MATCH(P18,P5:T5,1)+1,MATCH(P18,P5:T5,1))) -> #N/A | AB27: y2_n2: | AC27: {=INDEX(AB6:AG16,IF(MATCH(AC21,AA6:AA16,1)<AE19,MATCH(AC21,AA6:AA16,1)+1,MATCH(AC21,AA6:AA16,1)),IF(MATCH(AC18,AB5:AG5,1)<AE20,MATCH(AC18,AB5:AG5,1)+1,MATCH(AC18,AB5:AG5,1)))} -> 4
B28: y_n1: | C28: =IFERROR(C24+(C18-C19)*(C25-C24)/(C20-C19),C24) -> 5.393 | O28: y_n1: | P28: =IFERROR(P24+(P18-P19)*(P25-P24)/(P20-P19),P24) -> #N/A | AB28: y_n1: | AC28: =IFERROR(AC24+(AC18-AC19)*(AC25-AC24)/(AC20-AC19),AC24) -> 4.193
B29: y_n2: | C29: =IFERROR(C26+(C18-C19)*(C27-C26)/(C20-C19),C26) -> 5.393 | O29: y_n2: | P29: =IFERROR(P26+(P18-P19)*(P27-P26)/(P20-P19),P26) -> #N/A | AB29: y_n2: | AC29: =IFERROR(AC26+(AC18-AC19)*(AC27-AC26)/(AC20-AC19),AC26) -> 4.193
B30: Distance | C30: =IFERROR(C28+(C21-C22)*(C29-C28)/(C23-C22),C28) -> 5.393 | O30: Distance | P30: =IFERROR(P28+(P21-P22)*(P29-P28)/(P23-P22),P28) -> #N/A | AB30: Distance | AC30: =IFERROR(AC28+(AC21-AC22)*(AC29-AC28)/(AC23-AC22),AC28) -> 4.193
B32: Gradient | O32: Vikt | AB32: Vikt
A33: % | B33: 2.5 | C33: 3.5 | D33: 4.5 | E33: 5.6 | F33: 6 | N33: % | O33: 1 | P33: 2 | Q33: 3 | R33: 4 | S33: 5 | Z33: % | AA33: 0.3 | AB33: 1.2 | AC33: 2.2 | AD33: 3.5 | AE33: 4.7 | AF33: 5
A34: 9000 | B34: 6.2 | C34: 7.7 | D34: 9.2 | E34: 10.6 | F34: 0 | N34: 10000 | S34: 99999 | Z34: 9000 | AA34: 4.2 | AB34: 5.5 | AC34: 7 | AD34: 8.7 | AE34: 10 | AF34: 99999
A35: 9500 | B35: 5.6 | C35: 6.9 | D35: 8.3 | E35: 9.7 | F35: 0 | N35: 11000 | S35: 99999 | Z35: 9500 | AA35: 3.4 | AB35: 4.6 | AC35: 6.1 | AD35: 7.6 | AE35: 9 | AF35: 99999
A36: 10000 | B36: 5 | C36: 6.2 | D36: 7.6 | E36: 9 | F36: 0 | N36: 12000 | S36: 99999 | Z36: 10000 | AA36: 2.8 | AB36: 4 | AC36: 5.35 | AD36: 6.8 | AE36: 8.2 | AF36: 99999
A37: 10500 | B37: 4.4 | C37: 5.6 | D37: 6.8 | E37: 8.2 | F37: 0 | N37: 13000 | S37: 99999 | Z37: 10500 | AA37: 2.2 | AB37: 3.3 | AC37: 4.6 | AD37: 6 | AE37: 7.4 | AF37: 99999
A38: 11000 | B38: 3.9 | C38: 5 | D38: 6.2 | E38: 7.5 | F38: 0 | N38: 14000 | S38: 99999 | Z38: 11000 | AA38: 1.6 | AB38: 2.8 | AC38: 4 | AD38: 5.3 | AE38: 6.6 | AF38: 99999
A39: 11500 | B39: 3.4 | C39: 4.5 | D39: 5.6 | E39: 6.9 | F39: 0 | N39: 15000 | S39: 99999 | Z39: 11500 | AA39: 1.2 | AB39: 2.2 | AC39: 3.4 | AD39: 4.6 | AE39: 6 | AF39: 99999
A40: 12000 | B40: 2.9 | C40: 4 | D40: 5.1 | E40: 6.2 | F40: 0 | N40: 16000 | S40: 99999 | Z40: 12000 | AA40: 0.7 | AB40: 1.7 | AC40: 2.8 | AD40: 4 | AE40: 5.3 | AF40: 99999
A41: 12500 | B41: 2.5 | C41: 3.5 | D41: 4.5 | E41: 5.6 | F41: 0 | N41: 16600 | S41: 99999 | Z41: 12500 | AA41: 0.3 | AB41: 1.2 | AC41: 2.2 | AD41: 3.5 | AE41: 4.7 | AF41: 99999
A42: 12600 | B42: 0 | C42: 0 | D42: 0 | E42: 0 | F42: 0 | N42: 16700 | O42: 99999 | P42: 99999 | Q42: 99999 | R42: 99999 | S42: 99999 | Z42: 12600 | AA42: 99999 | AB42: 99999 | AC42: 99999 | AD42: 99999 | AE42: 99999 | AF42: 99999
...

Sheet Takeoff distance (2)
B1: Pressure Alt | C1: x_n: | D1: =IF('Take-off'!$C$9="",'Take-off'!$C$16,MAX(0,'Take-off'!$C$16+30*(1013-'Take-off'!$C$9))) -> 0
B2: Temp in calc | C2: y_n: | D2: =IF('Take-off'!$C$13='Dropdown lists'!$B$30, 'Take-off'!$C$8+10, 'Take-off'!$C$8) -> -35 | E2: Includes ICE-Vane. Could be disregarded for us
B3: TAKE OFF DISTANCE - FLAPS UP | O3: TAKE OFF DISTANCE - FLAPS TAKEOFF | AB3: TAKE OFF DISTANCE - FLAPS APPROACH
B4: Density altitude | O4: Density altitude | AB4: Density altitude
A5: Temp/PA | B5: -500 | C5: 0 | D5: 1000 | E5: 2000 | F5: 3000 | G5: 4000 | N5: Temp/PA | O5: 0 | P5: 1000 | Q5: 2000 | R5: 3000 | S5: 4000 | AA5: Temp/PA | AB5: -500 | AC5: 0 | AD5: 1000 | AE5: 2000 | AF5: 3000 | AG5: 4000
A6: -40 | B6: 1600 | C6: 1600 | D6: 1650 | E6: 1750 | F6: 1800 | G6: 99999 | N6: -30 | S6: 99999 | AA6: -40 | AB6: 1580 | AC6: 1580 | AD6: 1650 | AE6: 1700 | AF6: 1800 | AG6: 99999
A7: -30 | B7: 1600 | C7: 1600 | D7: 1650 | E7: 1750 | F7: 1800 | G7: 99999 | AA7: -30 | AB7: 1580 | AC7: 1580 | AD7: 1650 | AE7: 1700 | AF7: 1800 | AG7: 99999
A8: -20 | B8: 1600 | C8: 1600 | D8: 1650 | E8: 1750 | F8: 1800 | G8: 99999 | N8: -20 | S8: 99999 | AA8: -20 | AB8: 1580 | AC8: 1580 | AD8: 1650 | AE8: 1700 | AF8: 1800 | AG8: 99999
A9: -10 | B9: 1650 | C9: 1650 | D9: 1750 | E9: 1850 | F9: 1950 | G9: 99999 | N9: -10 | S9: 99999 | AA9: -10 | AB9: 1600 | AC9: 1600 | AD9: 1700 | AE9: 1750 | AF9: 1900 | AG9: 99999
A10: 0 | B10: 1750 | C10: 1750 | D10: 1850 | E10: 1950 | F10: 2100 | G10: 99999 | N10: 0 | S10: 99999 | AA10: 0 | AB10: 1700 | AC10: 1700 | AD10: 1800 | AE10: 1880 | AF10: 2000 | AG10: 99999
A11: 10 | B11: 1850 | C11: 1850 | D11: 1990 | E11: 2100 | F11: 2220 | G11: 99999 | N11: 10 | S11: 99999 | AA11: 10 | AB11: 1800 | AC11: 1800 | AD11: 1900 | AE11: 2000 | AF11: 2100 | AG11: 99999
A12: 20 | B12: 1960 | C12: 1960 | D12: 2100 | E12: 2230 | F12: 2350 | G12: 99999 | N12: 20 | S12: 99999 | AA12: 20 | AB12: 1900 | AC12: 1900 | AD12: 2000 | AE12: 2150 | AF12: 2300 | AG12: 99999
A13: 30 | B13: 2100 | C13: 2100 | D13: 2250 | E13: 2400 | F13: 2550 | G13: 99999 | AA13: 30 | AB13: 2050 | AC13: 2050 | AD13: 2200 | AE13: 2350 | AF13: 2500 | AG13: 99999
A14: 40 | B14: 2300 | C14: 2300 | D14: 2470 | E14: 2650 | F14: 2875 | G14: 99999 | N14: 30 | S14: 99999 | AA14: 40 | AB14: 2200 | AC14: 2200 | AD14: 2400 | AE14: 2550 | AF14: 2750 | AG14: 99999
A15: 45 | B15: 99999 | C15: 99999 | D15: 99999 | E15: 99999 | F15: 99999 | G15: 99999 | N15: 35 | O15: 99999 | P15: 99999 | Q15: 99999 | R15: 99999 | S15: 99999 | AA15: 45 | AB15: 99999 | AC15: 99999 | AD15: 99999 | AE15: 99999 | AF15: 99999 | AG15: 99999
B17: x_n: | C17: =D1 -> 0 | D17: Table size | O17: x_n: | P17: =D1 -> 0 | Q17: Table size | AB17: x_n: | AC17: =D1 -> 0 | AD17: Table size
B18: x1_n: | C18: =INDEX(B5:G5,MATCH(C17,B5:G5,1)) -> 0 | D18: Rows: | E18: =MATCH(MAX(A6:A15),A6:A15,1) -> 10 | O18: x1_n: | P18: =INDEX(O5:S5,MATCH(P17,O5:S5,1)) -> 0 | Q18: Rows: | R18: =MATCH(MAX(N6:N15),N6:N15,1) -> 10 | AB18: x1_n: | AC18: =INDEX(AB5:AG5,MATCH(AC17,AB5:AG5,1)) -> 0 | AD18: Rows: | AE18: =MATCH(MAX(AA6:AA15),AA6:AA15,1) -> 10
B19: x2_n: | C19: {=INDEX(B5:G5,IF(MATCH(C17,B5:G5,1)<E19,MATCH(C17,B5:G5,1)+1,MATCH(C17,B5:G5,1)))} -> 1000 | D19: Columns: | E19: =MATCH(MAX(B5:G5),B5:G5,0) -> 6 | O19: x2_n: | P19: {=INDEX(O5:S5,IF(MATCH(P17,O5:S5,1)<R19,MATCH(P17,O5:S5,1)+1,MATCH(P17,O5:S5,1)))} -> 1000 | Q19: Columns: | R19: =MATCH(MAX(O5:S5),O5:S5,0) -> 5 | AB19: x2_n: | AC19: {=INDEX(AB5:AG5,IF(MATCH(AC17,AB5:AG5,1)<AE19,MATCH(AC17,AB5:AG5,1)+1,MATCH(AC17,AB5:AG5,1)))} -> 1000 | AD19: Columns: | AE19: =MATCH(MAX(AB5:AG5),AB5:AG5,0) -> 6
B20: y_n: | C20: =D2 -> -35 | O20: y_n: | P20: =D2 -> -35 | AB20: y_n: | AC20: =D2 -> -35
B21: n1: | C21: =INDEX(A6:A15,MATCH(C20,A6:A15,1)) -> -40 | O21: n1: | P21: =INDEX(N6:N15,MATCH(P20,N6:N15,1)) -> #N/A | AB21: n1: | AC21: =INDEX(AA6:AA15,MATCH(AC20,AA6:AA15,1)) -> -40
B22: n2: | C22: {=INDEX(A6:A15,IF(MATCH(C20,A6:A15,1)<E18,MATCH(C20,A6:A15,1)+1,MATCH(C20,A6:A15,1)))} -> -30 | O22: n2: | P22: {=INDEX(N6:N15,IF(MATCH(P20,N6:N15,1)<R18,MATCH(P20,N6:N15,1)+1,MATCH(P20,N6:N15,1)))} -> #N/A | AB22: n2: | AC22: {=INDEX(AA6:AA15,IF(MATCH(AC20,AA6:AA15,1)<AE18,MATCH(AC20,AA6:AA15,1)+1,MATCH(AC20,AA6:AA15,1)))} -> -30
B23: y1_n1: | C23: =INDEX(B6:G15,MATCH(C20,A6:A15,1),MATCH(C17,B5:G5,1)) -> 1600 | O23: y1_n1: | P23: =INDEX(O6:S15,MATCH(P20,N6:N15,1),MATCH(P17,O5:S5,1)) -> #N/A | AB23: y1_n1: | AC23: =INDEX(AB6:AG15,MATCH(AC20,AA6:AA15,1),MATCH(AC17,AB5:AG5,1)) -> 1580
B24: y2_n1: | C24: {=INDEX(B6:G15,MATCH(C20,A6:A15,1),IF(MATCH(C17,B5:G5,1)<E19,MATCH(C17,B5:G5,1)+1,MATCH(C20,A6:A15,1)))} -> 1650 | O24: y2_n1: | P24: =INDEX(O6:S15,MATCH(P20,N6:N15,1),IF(MATCH(P17,O5:S5,1)<R19,MATCH(P17,O5:S5,1)+1,MATCH(P20,N6:N15,1))) -> #N/A | AB24: y2_n1: | AC24: {=INDEX(AB6:AG15,MATCH(AC20,AA6:AA15,1),IF(MATCH(AC17,AB5:AG5,1)<AE19,MATCH(AC17,AB5:AG5,1)+1,MATCH(AC20,AA6:AA15,1)))} -> 1650
B25: y1_n2: | C25: {=INDEX(B6:G15,IF(MATCH(C20,A6:A15,1)<E18,MATCH(C20,A6:A15,1)+1,MATCH(C20,A6:A15,1)),MATCH(C17,B5:G5,1))} -> 1600 | O25: y1_n2: | P25: =INDEX(O6:S15,IF(MATCH(P20,N6:N15,1)<R18,MATCH(P20,N6:N15,1)+1,MATCH(P20,N6:N15,1)),MATCH(P17,O5:S5,1)) -> #N/A | AB25: y1_n2: | AC25: {=INDEX(AB6:AG15,IF(MATCH(AC20,AA6:AA15,1)<AE18,MATCH(AC20,AA6:AA15,1)+1,MATCH(AC20,AA6:AA15,1)),MATCH(AC17,AB5:AG5,1))} -> 1580
B26: y2_n2: | C26: {=INDEX(B6:G15,IF(MATCH(C20,A6:A15,1)<E18,MATCH(C20,A6:A15,1)+1,MATCH(C20,A6:A15,1)),IF(MATCH(C17,B5:G5,1)<E19,MATCH(C17,B5:G5,1)+1,MATCH(C17,B5:G5,1)))} -> 1650 | O26: y2_n2: | P26: =INDEX(O6:S15,IF(MATCH(P20,N6:N15,1)<R18,MATCH(P20,N6:N15,1)+1,MATCH(P20,N6:N15,1)),IF(MATCH(P17,O5:S5,1)<R19,MATCH(P17,O5:S5,1)+1,MATCH(P17,O5:S5,1))) -> #N/A | AB26: y2_n2: | AC26: {=INDEX(AB6:AG15,IF(MATCH(AC20,AA6:AA15,1)<AE18,MATCH(AC20,AA6:AA15,1)+1,MATCH(AC20,AA6:AA15,1)),IF(MATCH(AC17,AB5:AG5,1)<AE19,MATCH(AC17,AB5:AG5,1)+1,MATCH(AC17,AB5:AG5,1)))} -> 1650
B27: y_n1: | C27: =IFERROR(C23+(C17-C18)*(C24-C23)/(C19-C18),C23) -> 1600 | O27: y_n1: | P27: =IFERROR(P23+(P17-P18)*(P24-P23)/(P19-P18),P23) -> #N/A | AB27: y_n1: | AC27: =IFERROR(AC23+(AC17-AC18)*(AC24-AC23)/(AC19-AC18),AC23) -> 1580
B28: y_n2: | C28: =IFERROR(C25+(C17-C18)*(C26-C25)/(C19-C18),C25) -> 1600 | O28: y_n2: | P28: =IFERROR(P25+(P17-P18)*(P26-P25)/(P19-P18),P25) -> #N/A | AB28: y_n2: | AC28: =IFERROR(AC25+(AC17-AC18)*(AC26-AC25)/(AC19-AC18),AC25) -> 1580
B29: Distance | C29: =IFERROR(C27+(C20-C21)*(C28-C27)/(C22-C21),C27) -> 1600 | O29: Distance | P29: =IFERROR(P27+(P20-P21)*(P28-P27)/(P22-P21),P27) -> #N/A | AB29: Distance | AC29: =IFERROR(AC27+(AC20-AC21)*(AC28-AC27)/(AC22-AC21),AC27) -> 1580
B31: Vikt | O31: Vikt | AB31: Vikt
A32: % | B32: 1600 | C32: 2050 | D32: 2500 | E32: 2950 | F32: 3400 | G32: 4000 | N32: % | O32: 1900 | P32: 2350 | Q32: 2850 | R32: 3350 | S32: 4500 | AA32: % | AB32: 1550 | AC32: 2000 | AD32: 2500 | AE32: 3050 | AF32: 3500
A33: 9000 | B33: 1200 | C33: 1500 | D33: 1800 | E33: 2100 | F33: 2410 | G33: 99999 | N33: 10000 | S33: 99999 | AA33: 9000 | AB33: 1200 | AC33: 1500 | AD33: 1850 | AE33: 2200 | AF33: 99999
A34: 9500 | B34: 1250 | C34: 1600 | D34: 1900 | E34: 2250 | F34: 2580 | G34: 99999 | N34: 11000 | S34: 99999 | AA34: 9500 | AB34: 1210 | AC34: 1550 | AD34: 1950 | AE34: 2300 | AF34: 99999
A35: 10000 | B35: 1300 | C35: 1650 | D35: 2000 | E35: 2350 | F35: 2700 | G35: 99999 | N35: 12000 | S35: 99999 | AA35: 10000 | AB35: 1290 | AC35: 1650 | AD35: 2050 | AE35: 2400 | AF35: 99999
A36: 10500 | B36: 1400 | C36: 1750 | D36: 2100 | E36: 2500 | F36: 2850 | G36: 99999 | N36: 13000 | S36: 99999 | AA36: 10500 | AB36: 1350 | AC36: 1700 | AD36: 2150 | AE36: 2550 | AF36: 99999
A37: 11000 | B37: 1450 | C37: 1800 | D37: 2200 | E37: 2600 | F37: 3000 | G37: 99999 | N37: 14000 | S37: 99999 | AA37: 11000 | AB37: 1400 | AC37: 1800 | AD37: 2250 | AE37: 2650 | AF37: 99999
A38: 11500 | B38: 1500 | C38: 1900 | D38: 2300 | E38: 2700 | F38: 3120 | G38: 99999 | N38: 15000 | S38: 99999 | AA38: 11500 | AB38: 1450 | AC38: 1850 | AD38: 2300 | AE38: 2800 | AF38: 99999
