Workbook

Sheet Take-off
B1: SE-LTL
B2: Take-off distance Beech 200 | F2: SE-LTL | G2: Version
B3: Interpoleringsverktyg för startsträcka från AFM. | G3: 46266
B4: Flygplats och bana: | C4: Custom airport
C5: ESND 051850Z AUTO 24015KT 200V270 9999 NCD 14/08 Q0991
B6: Wind direction: | C6: =IFERROR(__xludf.dummyfunction("IF(E6<>"""", E6, IF($G$8, E6, IFERROR(IF(REGEXMATCH(C5, ""\bVRB""), ""000"", VALUE(REGEXEXTRACT(C5, ""\b(\d{3})\d{2,3}(?:G\d{2,3})?(?:KT|MPS)\b""))), ""-"")))"),240) -> 240 | D6: ° | F6: =IF(C24<0, "Tailwind", "")
B7: Wind speed: | C7: =IFERROR(__xludf.dummyfunction("IF(E7<>"""", E7, IF($G$8, E7, IFERROR(VALUE(REGEXEXTRACT(C5, ""\b(?:\d{3}|VRB)(\d{2,3})(?:G\d{2,3})?(?:KT|MPS)\b"")), ""-"")))"),0) -> 0 | D7: kt | E7: 0
B8: Outside air temperature: | C8: =IFERROR(__xludf.dummyfunction("IF(E8<>"""", E8, IF($G$8, E8, IFERROR(VALUE(SUBSTITUTE(REGEXEXTRACT(C5, ""\b(M?\d{2})\/(?:M?\d{2})\b""), ""M"", ""-"")), ""-"")))"),0) -> 0 | D8: °C | E8: 0 | F8: Remove manual MET | G8: =FALSE() -> FALSE
B9: QNH | C9: =IFERROR(__xludf.dummyfunction("IF(E9<>"""", E9, IF($G$8, E9, IFERROR(VALUE(REGEXEXTRACT(C5, ""\bQ(\d{4})\b"")), ""-"")))"),1013) -> 1013 | D9: Hpa | E9: 1013
B10: Runway Condition Code | C10: 5 | E10: MANUAL MET -> | F10: REFRESH METAR | G10: =FALSE() -> FALSE
B11: Runway contaminant | C11: Wet Runway | I11: BORT
B12: Contaminant depth | C12: 3 | D12: mm | E12: Max: | F12: =VLOOKUP(C11,'Dropdown lists'!B34:G40,5,FALSE()) -> 0
B13: Engine Anti-ice | C13: OFF | I13: Engine anti-ice can be disregarded (OFF in calculation) whenever 3300 lbs/ft take-off power can be obtained
B14: Take off mass: | C14: 9000 | D14: Lbs
B15: Airport data (Expandable) | I15: Från 1900an. Men borde vara lika på alla om man får ut max torque. Men det är inte utskrivet vad jag sett.
B16: Treshold elevation: | C16: {=_xlfn.XLOOKUP($C$4, 'Airport data'!$A$5:$A1006, 'Airport data'!$B$5:$B1006)} -> 200 | D16: ft
B17: Runway Slope: | C17: {=_xlfn.XLOOKUP($C$4, 'Airport data'!$A$5:$A1006, 'Airport data'!$G$5:$G1006)} -> 0 | D17: % | E17: + = upphill
B18: RWY Heading: | C18: {=_xlfn.XLOOKUP($C$4, 'Airport data'!$A$5:$A1006, 'Airport data'!$H$5:$H1006)} -> 120 | D18: °
B19: ASDA: | C19: {=_xlfn.XLOOKUP($C$4, 'Airport data'!$A$5:$A1006, 'Airport data'!$E$5:$E1006)-10} -> 1990 | D19: m | E19: Req gradient: | G19: {=_xlfn.XLOOKUP($C$4, 'Airport data'!$A$5:$A1006, 'Airport data'!$I$5:$I1006)} -> 3.3
B20: TORA: | C20: {=_xlfn.XLOOKUP($C$4, 'Airport data'!$A$5:$A1006, 'Airport data'!$C$5:$C1006)-10} -> 1990 | D20: m
B21: TODA: | C21: {=_xlfn.XLOOKUP($C$4, 'Airport data'!$A$5:$A1006, 'Airport data'!$D$5:$D1006)-10} -> 1990 | D21: m | E21: TOR | F21: =C35*1.15 -> 502.55421 | J21: villkorsberoende format wind, xwind, limit
B22: LDA: | C22: {=_xlfn.XLOOKUP($C$4, 'Airport data'!$A$5:$A1006, 'Airport data'!$F$5:$F1006)} -> 2000 | D22: m | J22: Ny källa metar script landing
B23: Calculated data | J23: Jämförelse rätt metar
B24: Head/Tail wind | C24: ='LTL_TAKE OFF Performance FLAPS '!D34 -> 0 | D24: Kt | E24: Take-off Distance Factor | F24: {=_xlfn.XLOOKUP('Take-off'!$C$10,'Dropdown lists'!$B$4:$B$9,'Dropdown lists'!$D$4:$D$9)} -> 1.07
B25: Crosswind | C25: =ABS('LTL_TAKE OFF Performance FLAPS '!C39*C7) -> 0 | D25: Kt | E25: Limit | F25: {=_xlfn.XLOOKUP(C10, 'Dropdown lists'!$B$4:$B$10, 'Dropdown lists'!$E$4:$E$10)} -> 25
B26: FLAPS: | C26: UP | D26: TAKE-OFF | E26: APP | G26: FULL
B27: Dry Runway (Expandable) | I27: Kommer inte att användas med take-off faktorer - Då är RWYCC 6 samma sak
B28: Ground Roll [m] | C28: ='LTL_TAKE OFF Performance FLAPS '!E28 -> 408.41463 | E28: =Blad3!E28 -> 400.20325
B29: Take off distance [m] | C29: =MAX('LTL_TAKE OFF Performance FLAPS '!E29:E30) -> 609.7561 | E29: =MAX(Blad3!E29:E30) -> 786.03104
B30: Accelerade & STOP [m] | C30: ='LTL_TAKE OFF Performance FLAPS '!E32 -> 844.5122 | E30: =Blad3!E32 -> 862.46612
B31: V1 [kts] | C31: ='LTL_TAKE OFF Performance FLAPS '!E$22 -> 94 | E31: =Blad3!E$22 -> 94
B32: VR [kts] | C32: ='LTL_TAKE OFF Performance FLAPS '!E$22 -> 94 | E32: =Blad3!E$22 -> 94
B33: V2 [kts] | C33: ='LTL_TAKE OFF Performance FLAPS '!I22 -> 103 | E33: =Blad3!I$22 -> 102
B34: Selected contaminant
B35: Ground Roll [m] | C35: ='LTL_TAKE OFF Performance FLAPS '!E28*F24 -> 437.00366 | E35: =Blad3!E28*F24 -> 428.21748
B36: Take off distance [m] | C36: =MAX('LTL_TAKE OFF Performance FLAPS '!E29:E31)*F24 -> 652.43902 | E36: =MAX(Blad3!E29:E31)*F24 -> 841.05322
B37: Accelerade & STOP [m] | C37: ='LTL_TAKE OFF Performance FLAPS '!E32*F24 -> 903.62805 | E37: =Blad3!E32*F24 -> 922.83875
B38: V1 [kts] | C38: ='LTL_TAKE OFF Performance FLAPS '!E$22 -> 94 | E38: =Blad3!E$22 -> 94
B39: VR [kts] | C39: ='LTL_TAKE OFF Performance FLAPS '!E$22 -> 94 | E39: =Blad3!E$22 -> 94
B40: V2 [kts] | C40: ='LTL_TAKE OFF Performance FLAPS '!I$22 -> 103 | E40: =Blad3!I$22 -> 102 | I40: Standard Procedure Design Gradient (PDG): 3,3%
...

Sheet Landing
B2: Landning distance Beech 200 - SE-LTL | G2: Version
B3: Interpoleringsverktyg för landningsträcka | G3: 2026-XY-ZV
B4: Flygplats och bana: | C4: Custom airport
C5: ESNU 051850Z 19012KT 9999 FEW011 13/12 Q0986
B6: Wind direction: | C6: =IFERROR(__xludf.dummyfunction("IF(E6<>"""", E6, IF($G$8, E6, IFERROR(IF(REGEXMATCH(C5, ""\bVRB""), ""000"", VALUE(REGEXEXTRACT(C5, ""\b(\d{3})\d{2,3}(?:G\d{2,3})?(?:KT|MPS)\b""))), ""-"")))"),190) -> 190 | D6: ° | F6: =IF(C21<0, "Tailwind", "")
B7: Wind speed: | C7: =IFERROR(__xludf.dummyfunction("IF(E7<>"""", E7, IF($G$8, E7, IFERROR(VALUE(REGEXEXTRACT(C5, ""\b(?:\d{3}|VRB)(\d{2,3})(?:G\d{2,3})?(?:KT|MPS)\b"")), ""-"")))"),12) -> 12 | D7: kt
B8: Outside air temperature: | C8: =IFERROR(__xludf.dummyfunction("IF(E8<>"""", E8, IF($G$8, E8, IFERROR(VALUE(SUBSTITUTE(REGEXEXTRACT(C5, ""\b(M?\d{2})\/(?:M?\d{2})\b""), ""M"", ""-"")), ""-"")))"),13) -> 13 | D8: °C | F8: Remove manual MET | G8: =FALSE() -> FALSE
B9: QNH | C9: =IFERROR(__xludf.dummyfunction("IF(E9<>"""", E9, IF($G$8, E9, IFERROR(VALUE(REGEXEXTRACT(C5, ""\bQ(\d{4})\b"")), ""-"")))"),986) -> 986 | D9: Hpa
B10: Runway Condition Code | C10: 6 | E10: Manual MET -> | F10: REFRESH METAR | G10: =FALSE() -> FALSE
B11: Landing weight | C11: 12500 | D11: Lbs
B12: Max landing weight | C12: 12500 | D12: Lbs
B14: Airport data | C14: =IF(C11>C12, "Overweight landning","")
B15: Elevation: | C15: {=_xlfn.XLOOKUP($C$4,'Airport data'!$A$5:$A1003,'Airport data'!$B$5:$B1003)} -> 200 | D15: ft
B16: Runway Slope: | C16: {=_xlfn.XLOOKUP($C$4,'Airport data'!$A$5:$A1003,'Airport data'!$G$5:$G1003)} -> 0 | D16: % | F16: + = upphill
B17: RWY Heading: | C17: {=_xlfn.XLOOKUP($C$4,'Airport data'!$A$5:$A1003,'Airport data'!$H$5:$H1003)} -> 120 | D17: °
B18: LDA: | C18: {=_xlfn.XLOOKUP($C$4,'Airport data'!$A$5:$A1003,'Airport data'!$F$5:$F1003)} -> 2000 | D18: m
B19: Calculated data
B20: Landing Distance Factor | C20: {=_xlfn.XLOOKUP(C10,'Dropdown lists'!$B$4:$B$9,'Dropdown lists'!$C$4:$C$9)} -> 1.67
B21: Head/Tail wind | C21: ='LTL_LDG Performance'!D32 -> 4.1042417 | D21: Kt
B22: Crosswind | C22: =ABS('LTL_LDG Performance'!C37*C7) -> 11.276311 | D22: Kt | F22: Limit | G22: {=_xlfn.XLOOKUP(C10,'Dropdown lists'!$B$4:$B$9,'Dropdown lists'!$E$4:$E$9)} -> 25
B24: FLAPS: | C24: UP | D24: TAKE-OFF | F24: APP | G24: FULL
B25: Landing Distance
B26: VREF [kts] | C26: ='LTL_LDG Performance'!M21 -> 121 | G26: ='LTL_LDG Performance'!E21 -> 97
B27: Landing Distance factored [m] | C27: =('LTL_LDG Performance'!B88/3.28)*Landing!C20 -> 2109.495 | G27: ='LTL_Landing distance data'!C104*C20 -> 1240.8794
B28: Flap Up based on AFM graph
C29: =IF(ISBLANK(C10), "Dry & Unfactored *1,67", "" )
B30: Missed approach
B31: OEI Climb Gradient [%] | C31: =IF( C21>0, 'LTL_OEI CLIMB GRADIENT'!P47*(125/(125+50%*C21)), 'LTL_OEI CLIMB GRADIENT'!P47*(125/(125-150%*C21)) ) -> 4.4647031 | D31: Gradient includes wind, 150% & 50%
C35: Flaps UP | D35: Flaps FULL
B36: LDA | C36: =Landing!$C$18 -> 2000 | D36: =Landing!$C$18 -> 2000
B37: Landing distance | C37: =C27 -> 2109.495 | D37: =G27 -> 1240.8794

Sheet Airport data
A1: Airport | B1: Runway Threshold Elevation: | C1: TORA | D1: TODA | E1: ASDA | F1: LDA: | G1: RWY Slope: | H1: RWY HDG | I1: Minimum departure climb gradient, obstacles | J1: Uppdaterad | K1: ESCAPE ROUTE INFO
K2: Min cloud base | L2: Routing
B4: [ft] | C4: [m] | D4: [m] | E4: [m] | F4: [m] | G4: [%] | H4: [°] | I4: [%] | J4: [Date]
A5: No airport selected | B5: - | D5: - | E5: - | F5: - | G5: - | H5: - | J5: -
A6: Custom airport | B6: 200 | C6: 2000 | D6: 2000 | E6: 2000 | F6: 2000 | G6: 0 | H6: 120 | I6: 3.3 | N6: ÄNDRA ljusgröna RADER VID BEHOV
P10: ESSA

Sheet Dropdown lists
B1: Factors | E1: X-wind
C2: LDF | D2: Takeoff Faktor
B3: RWCC | C3: Faktor | E3: Limit
B4: 1 | C4: 2.9 | D4: 1.59 | E4: 4
B5: 2 | C5: 2.7 | D5: 1.41 | E5: 9
B6: 3 | C6: 2.4 | D6: 1.22 | E6: 14
B7: 4 | C7: 2.2 | D7: 1.14 | E7: 20
B8: 5 | C8: 2 | D8: 1.07 | E8: 25
B9: 6 | C9: 1.67 | D9: 1 | E9: 25
E10: 25
B12: FLAPS
B19: Runway take off
B27: Engine anti-ice
J29: =IF('Take-off'!$C$11='Dropdown lists'!B34,) -> 0
B30: ON
B31: OFF
B33: Runway contaminant | E33: Faktor | F33: Måttenhet | G33: Max
B34: Wet Runway | E34: 0 | G34: N/A
B35: Compacted snow | E35: 0 | G35: N/A
B36: Dry snow | E36: 0.005 | F36: mm | G36: N/A
B37: Wet snow | E37: 0.01 | F37: mm | G37: 50
B38: Slush | E38: 0.02 | F38: mm | G38: 25
B39: Standing water | E39: 0.02 | F39: mm | G39: 25
B40: No contaminant | E40: 0 | G40: N/A
B44: Technique
B47: Static T/O power
B48: Rolling take off

Sheet LTL_LDG Performance
A1: LANDING PERFORMANCE (Normal)
H2: EMG RETURN | I2: EMG RETURN | J2: FLAPS UP | K2: EMG RETURN | L2: FLAPS UP | M2: Normal
A3: Landing Mass | D3: Speeds | H3: Speeds | J3: Speeds | L3: Speeds
D4: Vref | H4: Vref | J4: Vref | L4: Vref
A5: 9000 | D5: 80 | H5: 80 | J5: 103 | L5: 103
A6: 10000 | D6: 85 | H6: 85 | J6: 108 | L6: 108
A7: 11000 | D7: 90 | H7: 90 | J7: 113 | L7: 113
A8: 12000 | D8: 95 | H8: 95 | J8: 119 | L8: 119
A9: 12500 | D9: 97 | H9: 97 | J9: 121 | L9: 121
A11: Table size Landing distance
B12: Rows: | C12: =MATCH(MAX(A5:A9),A5:A9,0) -> 5
B13: Columns: | C13: =MATCH(MAX(D5),D5,0) -> 1
D15: x_n: | E15: =D4 -> Vref | I15: =H4 -> Vref | K15: =J4 -> Vref | M15: =L4 -> Vref
D16: y_n: | E16: =Landing!C11 -> 12500 | I16: ='Take-off'!C14 -> 9000 | K16: ='Take-off'!C14 -> 9000 | M16: =Landing!C11 -> 12500
D17: n1: | E17: {=INDEX($A$5:$A$9,MATCH(E16,$A$5:$A$9,1))} -> 12500 | I17: {=INDEX($A$5:$A$9,MATCH(I16,$A$5:$A$9,1))} -> 9000 | K17: {=INDEX($A$5:$A$9,MATCH(K16,$A$5:$A$9,1))} -> 9000 | M17: {=INDEX($A$5:$A$9,MATCH(M16,$A$5:$A$9,1))} -> 12500
D18: n2: | E18: {=INDEX($A$5:$A$9,IF(MATCH(E16,$A$5:$A$9,1)<$C$12,MATCH(E16,$A$5:$A$9,1)+1,MATCH(E16,$A$5:$A$9,1)))} -> 12500 | I18: {=INDEX($A$5:$A$9,IF(MATCH(I16,$A$5:$A$9,1)<$C$12,MATCH(I16,$A$5:$A$9,1)+1,MATCH(I16,$A$5:$A$9,1)))} -> 10000 | K18: {=INDEX($A$5:$A$9,IF(MATCH(K16,$A$5:$A$9,1)<$C$12,MATCH(K16,$A$5:$A$9,1)+1,MATCH(K16,$A$5:$A$9,1)))} -> 10000 | M18: {=INDEX($A$5:$A$9,IF(MATCH(M16,$A$5:$A$9,1)<$C$12,MATCH(M16,$A$5:$A$9,1)+1,MATCH(M16,$A$5:$A$9,1)))} -> 12500
D19: y1_n1: | E19: {=INDEX(D5:D9,MATCH(E16,$A$5:$A$9,1),MATCH(E15,D4,1))} -> 97 | I19: {=INDEX(H5:H9,MATCH(I16,$A$5:$A$9,1),MATCH(I15,H4,1))} -> 80 | K19: {=INDEX(J5:J9,MATCH(K16,$A$5:$A$9,1),MATCH(K15,J4,1))} -> 103 | M19: {=INDEX(L5:L9,MATCH(M16,$A$5:$A$9,1),MATCH(M15,L4,1))} -> 121
D20: y1_n2: | E20: {=INDEX(D5:D9,IF(MATCH(E16,$A$5:$A$9,1)<$C$12,MATCH(E16,$A$5:$A$9,1)+1,MATCH(E16,$A$5:$A$9,1)),MATCH(E15,D4,1))} -> 97 | I20: {=INDEX(H5:H9,IF(MATCH(I16,$A$5:$A$9,1)<$C$12,MATCH(I16,$A$5:$A$9,1)+1,MATCH(I16,$A$5:$A$9,1)),MATCH(I15,H4,1))} -> 85 | K20: {=INDEX(J5:J9,IF(MATCH(K16,$A$5:$A$9,1)<$C$12,MATCH(K16,$A$5:$A$9,1)+1,MATCH(K16,$A$5:$A$9,1)),MATCH(K15,J4,1))} -> 108 | M20: {=INDEX(L5:L9,IF(MATCH(M16,$A$5:$A$9,1)<$C$12,MATCH(M16,$A$5:$A$9,1)+1,MATCH(M16,$A$5:$A$9,1)),MATCH(M15,L4,1))} -> 121
D21: Vref: | E21: =IFERROR(E19+(E16-E17)*(E20-E19)/(E18-E17),E19) -> 97 | I21: =IFERROR(I19+(I16-I17)*(I20-I19)/(I18-I17),I19) -> 80 | K21: =IFERROR(K19+(K16-K17)*(K20-K19)/(K18-K17),K19) -> 103 | M21: =IFERROR(M19+(M16-M17)*(M20-M19)/(M18-M17),M19) -> 121
B29: Windcalc
B31: WCA | C31: Factor | D31: H/T wind
B32: =IF(ABS(Landing!C17-Landing!C6)>270,360-ABS(Landing!C17-Landing!C6),Landing!C17-Landing!C6) -> -70 | C32: =IF(ABS(B32)>90,ABS(COS(B32*PI()/180))*(-1),ABS(COS(B32*PI()/180))) -> 0.34202014 | D32: =IF( ISBLANK(Landing!C6), Landing!C7*-1, Landing!C7*C32) -> 4.1042417
B37: Crosswind factor | C37: =IF(ABS(B32)>90,ABS(SIN(B32*PI()/180))*(-1),ABS(SIN(B32*PI()/180))) -> 0.93969262
A48: Emergency Return
B53: Unfactorised | C53: Factorised
B54: ='LTL_Landing distance data'!K104 -> 440.35366 | C54: =B54*C55 -> 880.70732
B55: Landing Distance Factor: | C55: =IF( ISBLANK('Take-off'!C10),MIN('Dropdown lists'!C4:C10), VLOOKUP('Take-off'!C10,'Dropdown lists'!B4:C10,2)) -> 2
A66: LANDING PERFORMANCE (UP)
A68: Landing Distance Flaps LAND [feet] | B68: Landing distance | D68: EMG RETURN
B69: UP | D69: EMG RETURN
A70: 500 | B70: 850
A71: 1000 | B71: 1700
A72: 1500 | B72: 2550
A73: 2000 | B73: 3400
A74: 2500 | B74: 4250
A75: 2900 | B75: 5000 | G75: 2900Ft Max i grafen
A76: 3500 | B76: 99999
A78: Table size Landing distance
B79: Rows: | C79: =MATCH(MAX(A70:A76),A70:A76,0) -> 7
B80: Columns: | C80: =MATCH(MAX(B70),B70,0) -> 1
...

Sheet LTL_TAKE OFF Performance FLAPS 
A1: Take off PERFORMANCE (FLAPS UP)
A2: UP
A3: Landing Mass | D3: Speeds | H3: Speeds
D4: V1/R | H4: V2
A5: 9000 | D5: 94 | H5: 103
A6: 10000 | D6: 94 | H6: 103
A7: 11000 | D7: 94 | H7: 103
A8: 11500 | D8: 94 | H8: 103
A9: 12000 | D9: 94 | H9: 103
A10: 12500 | D10: 94 | H10: 103
D12: Table size Vref | H12: V2
D13: Rows: | E13: =MATCH(MAX($A5:$A10),$A5:$A10,0) -> 6 | I13: =MATCH(MAX($A5:$A10),$A5:$A10,0) -> 6
D14: Columns: | E14: =MATCH(MAX(D5),D5,0) -> 1 | I14: =MATCH(MAX(H5),H5,0) -> 1
D16: x_n: | E16: =D4 -> V1/R | I16: =H4 -> V2
D17: y_n: | E17: ='Take-off'!$C$14 -> 9000 | I17: ='Take-off'!$C$14 -> 9000
D18: n1: | E18: {=INDEX($A5:$A10,MATCH(E17,$A5:$A10,1))} -> 9000 | I18: {=INDEX($A5:$A10,MATCH(I17,$A5:$A10,1))} -> 9000
D19: n2: | E19: {=INDEX($A5:$A10,IF(MATCH(E17,$A5:$A10,1)<E13,MATCH(E17,$A5:$A10,1)+1,MATCH(E17,$A5:$A10,1)))} -> 10000 | I19: {=INDEX($A5:$A10,IF(MATCH(I17,$A5:$A10,1)<I13,MATCH(I17,$A5:$A10,1)+1,MATCH(I17,$A5:$A10,1)))} -> 10000
D20: y1_n1: | E20: {=INDEX(D5:D10,MATCH(E17,$A5:$A10,1),MATCH(E16,D4,1))} -> 94 | I20: {=INDEX(H5:H10,MATCH(I17,$A5:$A10,1),MATCH(I16,H4,1))} -> 103
D21: y1_n2: | E21: {=INDEX(D5:D10,IF(MATCH(E17,$A5:$A10,1)<E13,MATCH(E17,$A5:$A10,1)+1,MATCH(E17,$A5:$A10,1)),MATCH(E16,D4,1))} -> 94 | I21: {=INDEX(H5:H10,IF(MATCH(I17,$A5:$A10,1)<I13,MATCH(I17,$A5:$A10,1)+1,MATCH(I17,$A5:$A10,1)),MATCH(I16,H4,1))} -> 103
D22: Vref: | E22: =IFERROR(E20+(E17-E18)*(E21-E20)/(E19-E18),E20) -> 94 | I22: =IFERROR(I20+(I17-I18)*(I21-I20)/(I19-I18),I20) -> 103
A25: Landing distance required calculations
B27: Flat | C27: Teknik | D27: Slope | E27: Totalt | G27: Factor for Contaminant type | H27: Contaminant depth | I27: Tot before | J27: Correction | K27: Runwayfactor <5 | L27: Runwayfactor <3 | M27: Rulebased factor | O27: Total contaminated
A28: Ground Roll | B28: ='LTL_Takeoff distance (2)'!C75/3.28 -> 408.41463 | C28: 0 | D28: =IF('Take-off'!$C$17>0, ((+'Take-off'!$C$17*5)%*SUM(B28:C28)),0 ) -> 0 | E28: =SUM(B28:D28) -> 408.41463 | G28: =VLOOKUP('Take-off'!$C$11, 'Dropdown lists'!$B$34:$E$40, 3, FALSE()) -> 0 | H28: ='Take-off'!$C$12 -> 3 | I28: =SUM(B28:D28) -> 408.41463 | J28: =I28*(G28*H28) -> 0 | K28: =IF('Take-off'!$C$10<5, 30%*I28, 0) -> 0 | L28: =IF('Take-off'!$C$10<3, 20%*I28, 0) -> 0 | M28: 0 | O28: =SUM(I28:M28) -> 408.41463
A29: Take off distance | B29: ='LTL_Takeoff distance (2)'!C94/3.28 -> 510.80488 | C29: 0 | D29: =IF('Take-off'!$C$17>0, ((+'Take-off'!$C$17*5)%*SUM(B29:C29)),0 ) -> 0 | E29: =SUM(B29:D29)*115% -> 587.42561 | G29: =VLOOKUP('Take-off'!$C$11, 'Dropdown lists'!$B$34:$E$40, 3, FALSE()) -> 0 | H29: ='Take-off'!$C$12 -> 3 | I29: =SUM(B29:D29) -> 510.80488 | J29: =I29*(G29*H29) -> 0 | K29: =IF('Take-off'!$C$10<5, 30%*I29, 0) -> 0 | L29: =IF('Take-off'!$C$10<3, 20%*I29, 0) -> 0 | M29: =15%*SUM(I29:L29) -> 76.620732 | O29: =SUM(I29:M29) -> 587.42561
A30: Accelerate GO DRY | B30: ='LTL_Accelerate and GO (2)'!C75/3.28 -> 609.7561 | C30: 0 | D30: =IF('Take-off'!$C$17>0, ((+'Take-off'!$C$17*5)%*SUM(B30:C30)),0 ) -> 0 | E30: =SUM(B30:D30) -> 609.7561 | G30: =VLOOKUP('Take-off'!$C$11, 'Dropdown lists'!$B$34:$E$40, 3, FALSE()) -> 0 | H30: ='Take-off'!$C$12 -> 3 | I30: =SUM(B30:D30) -> 609.7561 | O30: =E30 -> 609.7561
A31: Accelerate GO WET/CONT | B31: =B30 -> 609.7561 | C31: 0 | D31: =IF('Take-off'!$C$17>0, ((+'Take-off'!$C$17*5)%*SUM(B31:C31)),0 ) -> 0 | E31: =SUM(B31:D31) -> 609.7561 | G31: =VLOOKUP('Take-off'!$C$11, 'Dropdown lists'!$B$34:$E$40, 3, FALSE()) -> 0 | H31: ='Take-off'!$C$12 -> 3 | I31: =SUM(B31:D31) -> 609.7561 | J31: =I31*(G31*H31) -> 0 | K31: =IF('Take-off'!$C$10<5, 30%*I31, 0) -> 0 | L31: =IF('Take-off'!$C$10<3, 20%*I31, 0) -> 0 | M31: 0 | O31: =SUM(I31:N31) -> 609.7561
A32: Accelerate stop | B32: ='LTL_Accelerate and stop2'!C75/3.28 -> 844.5122 | C32: 0 | D32: =IF('Take-off'!$C$17>0, ((+'Take-off'!$C$17*5)%*SUM(B32:C32)),0 ) -> 0 | E32: =SUM(B32:D32) -> 844.5122 | G32: =VLOOKUP('Take-off'!$C$11, 'Dropdown lists'!$B$34:$E$40, 3, FALSE()) -> 0 | H32: ='Take-off'!$C$12 -> 3 | I32: =SUM(B32:D32) -> 844.5122 | J32: =I32*(G32*H32) -> 0 | K32: =IF('Take-off'!$C$10<5, 30%*I32, 0) -> 0 | L32: =IF('Take-off'!$C$10<3, 20%*I32, 0) -> 0 | M32: 0 | O32: =SUM(I32:M32) -> 844.5122
B33: WCA | C33: Factor | D33: H/T wind
B34: =IF(ABS('Take-off'!C18-'Take-off'!C6)>270,360-ABS('Take-off'!C18-'Take-off'!C6),'Take-off'!C18-'Take-off'!C6) -> -120 | C34: =IF(ABS(B34)>90,ABS(COS(B34*PI()/180))*(-1),ABS(COS(B34*PI()/180))) -> -0.5 | D34: =IF( ISBLANK('Take-off'!C6), 'Take-off'!C7*-1, 'Take-off'!C7*C34) -> 0
A35: TDR | B35: Unfactorised | C35: Factorised
B39: Crosswind factor | C39: =IF(ABS(B34)>90,ABS(SIN(B34*PI()/180))*(-1),ABS(SIN(B34*PI()/180))) -> -0.8660254

Sheet Blad3
A1: TAKE OFF PERFORMANCE (FLAPS APPROACH)
A2: TAKE-OFF
A3: Mass | D3: Speeds | H3: Speeds
D4: V1/R | H4: V2
A5: 9000 | D5: 94 | H5: 102
A6: 10000 | D6: 94 | H6: 102
A7: 11000 | D7: 94 | H7: 103
A8: 11500 | D8: 94 | H8: =AVERAGE(H7,H9) -> 104
A9: 12000 | D9: 94 | H9: 105
A10: 12500 | D10: 94 | H10: 106
D12: Table size Vref | H12: V2
D13: Rows: | E13: =MATCH(MAX($A5:$A10),$A5:$A10,0) -> 6 | I13: =MATCH(MAX($A5:$A10),$A5:$A10,0) -> 6
D14: Columns: | E14: =MATCH(MAX(D5),D5,0) -> 1 | I14: =MATCH(MAX(H5),H5,0) -> 1
D16: x_n: | E16: =D4 -> V1/R | I16: =H4 -> V2
D17: y_n: | E17: ='Take-off'!$C$14 -> 9000 | I17: ='Take-off'!$C$14 -> 9000
D18: n1: | E18: {=INDEX($A5:$A10,MATCH(E17,$A5:$A10,1))} -> 9000 | I18: {=INDEX($A5:$A10,MATCH(I17,$A5:$A10,1))} -> 9000
D19: n2: | E19: {=INDEX($A5:$A10,IF(MATCH(E17,$A5:$A10,1)<E13,MATCH(E17,$A5:$A10,1)+1,MATCH(E17,$A5:$A10,1)))} -> 10000 | I19: {=INDEX($A5:$A10,IF(MATCH(I17,$A5:$A10,1)<I13,MATCH(I17,$A5:$A10,1)+1,MATCH(I17,$A5:$A10,1)))} -> 10000
D20: y1_n1: | E20: {=INDEX(D5:D10,MATCH(E17,$A5:$A10,1),MATCH(E16,D4,1))} -> 94 | I20: {=INDEX(H5:H10,MATCH(I17,$A5:$A10,1),MATCH(I16,H4,1))} -> 102
D21: y1_n2: | E21: {=INDEX(D5:D10,IF(MATCH(E17,$A5:$A10,1)<E13,MATCH(E17,$A5:$A10,1)+1,MATCH(E17,$A5:$A10,1)),MATCH(E16,D4,1))} -> 94 | I21: {=INDEX(H5:H10,IF(MATCH(I17,$A5:$A10,1)<I13,MATCH(I17,$A5:$A10,1)+1,MATCH(I17,$A5:$A10,1)),MATCH(I16,H4,1))} -> 102
D22: Vref: | E22: =IFERROR(E20+(E17-E18)*(E21-E20)/(E19-E18),E20) -> 94 | I22: =IFERROR(I20+(I17-I18)*(I21-I20)/(I19-I18),I20) -> 102
A23: Windcorrected distances
A25: Landing distance required calculations
B27: Flat | C27: Technique | D27: Slope | E27: Totalt | G27: Factor for Contaminant type | H27: Contaminant depth | I27: Tot before | J27: Correction | K27: Runwayfactor <5 | L27: Runwayfactor <3 | M27: Rulebased factor | O27: Total contaminated
A28: Ground Roll | B28: ='LTL_Takeoff distance (2)'!AC75/3.28 -> 400.20325 | C28: 0 | D28: 0 | E28: =SUM(B28:D28) -> 400.20325 | G28: =VLOOKUP('Take-off'!$C$11, 'Dropdown lists'!$B$34:$E$40, 3, FALSE()) -> 0 | H28: ='Take-off'!$C$12 -> 3 | I28: =SUM(B28:D28) -> 400.20325 | J28: =I28*(G28*H28) -> 0 | K28: =IF('Take-off'!$C$10<5, 30%*I28, 0) -> 0 | L28: =IF('Take-off'!$C$10<3, 20%*I28, 0) -> 0 | M28: 0 | O28: =SUM(I28:M28) -> 400.20325
A29: Take off distance | B29: ='LTL_Takeoff distance (2)'!AC94/3.28 -> 580.42973 | C29: 0 | D29: =IF('Take-off'!$C$17>0, ((+'Take-off'!$C$17*5)%*SUM(B29:C29)),0 ) -> 0 | E29: =SUM(B29:D29)*115% -> 667.49419 | G29: =VLOOKUP('Take-off'!$C$11, 'Dropdown lists'!$B$34:$E$40, 3, FALSE()) -> 0 | H29: ='Take-off'!$C$12 -> 3 | I29: =SUM(B29:D29) -> 580.42973 | J29: =I29*(G29*H29) -> 0 | K29: =IF('Take-off'!$C$10<5, 30%*I29, 0) -> 0 | L29: =IF('Take-off'!$C$10<3, 20%*I29, 0) -> 0 | M29: =15%*SUM(I29:L29) -> 87.06446 | O29: =SUM(I29:M29) -> 667.49419
A30: Accelerate GO DRY | B30: ='LTL_Accelerate and GO (2)'!AD75/3.28 -> 786.03104 | C30: 0 | D30: =IF('Take-off'!$C$17>0, ((+'Take-off'!$C$17*5)%*SUM(B30:C30)),0 ) -> 0 | E30: =SUM(B30:D30) -> 786.03104 | G30: =VLOOKUP('Take-off'!$C$11, 'Dropdown lists'!$B$34:$E$40, 3, FALSE()) -> 0 | H30: ='Take-off'!$C$12 -> 3 | I30: =SUM(B30:D30) -> 786.03104 | J30: =I30*(G30*H30) -> 0 | K30: =IF('Take-off'!$C$10<5, 30%*I30, 0) -> 0 | L30: =IF('Take-off'!$C$10<3, 20%*I30, 0) -> 0 | M30: 0 | O30: =E30 -> 786.03104
A31: Accelerate GO WET/CONT | B31: =B30 -> 786.03104 | C31: 0 | D31: =IF('Take-off'!$C$17>0, ((+'Take-off'!$C$17*5)%*SUM(B31:C31)),0 ) -> 0 | E31: =SUM(B31:D31) -> 786.03104 | G31: =VLOOKUP('Take-off'!$C$11, 'Dropdown lists'!$B$34:$E$40, 3, FALSE()) -> 0 | H31: ='Take-off'!$C$12 -> 3 | I31: =SUM(B31:D31) -> 786.03104 | J31: =I31*(G31*H31) -> 0 | K31: =IF('Take-off'!$C$10<5, 30%*I31, 0) -> 0 | L31: =IF('Take-off'!$C$10<3, 20%*I31, 0) -> 0 | M31: 0 | O31: =SUM(I31:N31) -> 786.03104
A32: Accelerate STOP distance | B32: ='LTL_Accelerate and stop2'!AC75/3.28 -> 862.46612 | C32: 0 | D32: =IF('Take-off'!$C$17>0, ((+'Take-off'!$C$17*5)%*SUM(B32:C32)),0 ) -> 0 | E32: =SUM(B32:D32) -> 862.46612 | G32: =VLOOKUP('Take-off'!$C$11, 'Dropdown lists'!$B$34:$E$40, 3, FALSE()) -> 0 | H32: ='Take-off'!$C$12 -> 3 | I32: =SUM(B32:D32) -> 862.46612 | J32: =I32*(G32*H32) -> 0 | K32: =IF('Take-off'!$C$10<5, 30%*I32, 0) -> 0 | L32: =IF('Take-off'!$C$10<3, 20%*I32, 0) -> 0 | M32: 0 | O32: =SUM(I32:M32) -> 862.46612
B34: WCA | C34: Factor | D34: H/T wind
B35: =IF(ABS('Take-off'!C18-'Take-off'!C6)>270,360-ABS('Take-off'!C18-'Take-off'!C6),'Take-off'!C18-'Take-off'!C6) -> -120 | C35: =IF(ABS(B35)>90,ABS(COS(B35*PI()/180))*(-1),ABS(COS(B35*PI()/180))) -> -0.5 | D35: =IF( ISBLANK('Take-off'!C6), 'Take-off'!C7*-1, 'Take-off'!C7*C35) -> 0
B40: Crosswind factor | C40: =IF(ABS(B35)>90,ABS(SIN(B35*PI()/180))*(-1),ABS(SIN(B35*PI()/180))) -> -0.8660254
A41: GRadient adjustments

Sheet LTL_Landing distance data
B1: Pressure Alt | C1: x_n: | D1: =IF(Landing!$C$9="",Landing!$C$15,MAX(0,Landing!$C$15+30*(1013-Landing!$C$9))) -> 1010 | F1: EMG Return | G1: =IF('Take-off'!$C$9="",'Take-off'!$C$16,MAX(0,'Take-off'!$C$16+30*(1013-'Take-off'!$C$9))) -> 200
B2: Temp in calc | C2: y_n: | D2: =Landing!C8 -> 13 | G2: =MAX( IF('Take-off'!C13='Dropdown lists'!B30, 'Take-off'!$C$8+5, 'Take-off'!$C$8),0) -> 0
I5: EMG RETURN
C6: NORMAL
A8: Landing
B10: Density Altitude
B11: -500 | C11: 0 | D11: 1000 | E11: 2000 | F11: 3000 | G11: 3500
A12: -40 | B12: 800 | C12: 800 | D12: 830 | E12: 860 | F12: 900 | G12: 99999
A13: -30 | B13: 800 | C13: 800 | D13: 830 | E13: 860 | F13: 900 | G13: 99999
A14: -20 | B14: 800 | C14: 800 | D14: 830 | E14: 860 | F14: 900 | G14: 99999
A15: -10 | B15: 810 | C15: 810 | D15: 850 | E15: 900 | F15: 950 | G15: 99999
A16: 0 | B16: 830 | C16: 830 | D16: 880 | E16: 915 | F16: 975 | G16: 99999
A17: 10 | B17: 850 | C17: 850 | D17: 900 | E17: 930 | F17: 1000 | G17: 99999
A18: 20 | B18: 900 | C18: 900 | D18: 950 | E18: 990 | F18: 1050 | G18: 99999
A19: 30 | B19: 910 | C19: 910 | D19: 975 | E19: 1020 | F19: 1075 | G19: 99999
A20: 40 | B20: 950 | C20: 950 | D20: 1000 | E20: 1100 | F20: 1200 | G20: 99999
A21: 45 | B21: 99999 | C21: 99999 | D21: 99999 | E21: 99999 | F21: 99999 | G21: 99999
B23: x_n: | C23: =D1 -> 1010 | D23: Table size | J23: x_n: | K23: =G1 -> 200 | L23: Table size
B24: x1_n: | C24: {=INDEX($B11:$G11,MATCH(C23,$B11:$G11,1))} -> 1000 | D24: Rows: | E24: =MATCH(MAX($A12:$A21),$A12:$A21,1) -> 10 | J24: x1_n: | K24: {=INDEX($B11:$G11,MATCH(K23,$B11:$G11,1))} -> 0 | L24: Rows: | M24: =MATCH(MAX($A12:$A21),$A12:$A21,1) -> 10
B25: x2_n: | C25: {=INDEX($B11:$G11,IF(MATCH(C23,$B11:$G11,1)<E25,MATCH(C23,$B11:$G11,1)+1,MATCH(C23,$B11:$G11,1)))} -> 2000 | D25: Columns: | E25: =MATCH(MAX($B11:$G11),$B11:$G11,0) -> 6 | J25: x2_n: | K25: {=INDEX($B11:$G11,IF(MATCH(K23,$B11:$G11,1)<M25,MATCH(K23,$B11:$G11,1)+1,MATCH(K23,$B11:$G11,1)))} -> 1000 | L25: Columns: | M25: =MATCH(MAX($B11:$G11),$B11:$G11,0) -> 6
B26: y_n: | C26: =D2 -> 13 | J26: y_n: | K26: =G2 -> 0
B27: n1: | C27: {=INDEX($A12:$A21,MATCH(C26,$A12:$A21,1))} -> 10 | J27: n1: | K27: {=INDEX($A12:$A21,MATCH(K26,$A12:$A21,1))} -> 0
B28: n2: | C28: {=INDEX($A12:$A21,IF(MATCH(C26,$A12:$A21,1)<E24,MATCH(C26,$A12:$A21,1)+1,MATCH(C26,$A12:$A21,1)))} -> 20 | J28: n2: | K28: {=INDEX($A12:$A21,IF(MATCH(K26,$A12:$A21,1)<M24,MATCH(K26,$A12:$A21,1)+1,MATCH(K26,$A12:$A21,1)))} -> 10
B29: y1_n1: | C29: {=INDEX($B12:$G21,MATCH(C26,$A12:$A21,1),MATCH(C23,$B11:$G11,1))} -> 900 | J29: y1_n1: | K29: {=INDEX($B12:$G21,MATCH(K26,$A12:$A21,1),MATCH(K23,$B11:$G11,1))} -> 830
B30: y2_n1: | C30: {=INDEX($B12:$G21,MATCH(C26,$A12:$A21,1),IF(MATCH(C23,$B11:$G11,1)<E25,MATCH(C23,$B11:$G11,1)+1,MATCH(C26,$A12:$A21,1)))} -> 930 | J30: y2_n1: | K30: {=INDEX($B12:$G21,MATCH(K26,$A12:$A21,1),IF(MATCH(K23,$B11:$G11,1)<M25,MATCH(K23,$B11:$G11,1)+1,MATCH(K26,$A12:$A21,1)))} -> 880
B31: y1_n2: | C31: {=INDEX($B12:$G21,IF(MATCH(C26,$A12:$A21,1)<E24,MATCH(C26,$A12:$A21,1)+1,MATCH(C26,$A12:$A21,1)),MATCH(C23,$B11:$G11,1))} -> 950 | J31: y1_n2: | K31: {=INDEX($B12:$G21,IF(MATCH(K26,$A12:$A21,1)<M24,MATCH(K26,$A12:$A21,1)+1,MATCH(K26,$A12:$A21,1)),MATCH(K23,$B11:$G11,1))} -> 850
B32: y2_n2: | C32: {=INDEX($B12:$G21,IF(MATCH(C26,$A12:$A21,1)<E24,MATCH(C26,$A12:$A21,1)+1,MATCH(C26,$A12:$A21,1)),IF(MATCH(C23,$B11:$G11,1)<E25,MATCH(C23,$B11:$G11,1)+1,MATCH(C23,$B11:$G11,1)))} -> 990 | J32: y2_n2: | K32: {=INDEX($B12:$G21,IF(MATCH(K26,$A12:$A21,1)<M24,MATCH(K26,$A12:$A21,1)+1,MATCH(K26,$A12:$A21,1)),IF(MATCH(K23,$B11:$G11,1)<M25,MATCH(K23,$B11:$G11,1)+1,MATCH(K23,$B11:$G11,1)))} -> 900
B33: y_n1: | C33: =IFERROR(C29+(C23-C24)*(C30-C29)/(C25-C24),C29) -> 900.3 | J33: y_n1: | K33: =IFERROR(K29+(K23-K24)*(K30-K29)/(K25-K24),K29) -> 840
B34: y_n2: | C34: =IFERROR(C31+(C23-C24)*(C32-C31)/(C25-C24),C31) -> 950.4 | J34: y_n2: | K34: =IFERROR(K31+(K23-K24)*(K32-K31)/(K25-K24),K31) -> 860
B35: Distance | C35: =IFERROR(C33+(C26-C27)*(C34-C33)/(C28-C27),C33) -> 915.33 | J35: Distance | K35: =IFERROR(K33+(K26-K27)*(K34-K33)/(K28-K27),K33) -> 840
B37: Vikt
B38: 500 | C38: 1000 | D38: 1500 | E38: 2000
A39: 9000 | B39: 375 | C39: 690 | D39: 1090 | E39: 99999
A40: 9500 | B40: 390 | C40: 750 | D40: 1150 | E40: 99999
A41: 10000 | B41: 400 | C41: 780 | D41: 1200 | E41: 99999
A42: 10500 | B42: 410 | C42: 810 | D42: 1250 | E42: 99999
A43: 11000 | B43: 440 | C43: 850 | D43: 1320 | E43: 99999
A44: 11500 | B44: 475 | C44: 900 | D44: 1390 | E44: 99999
A45: 12000 | B45: 490 | C45: 950 | D45: 1450 | E45: 99999
A46: 12500 | B46: 500 | C46: 1000 | D46: 1500 | E46: 99999
...

Sheet LTL_Accelerate and GO (2)
B1: Pressure Alt | C1: x_n: | D1: =IF('Take-off'!$C$9="",'Take-off'!$C$16,MAX(0,'Take-off'!$C$16+30*(1013-'Take-off'!$C$9))) -> 200
B2: Temp in calc | C2: y_n: | D2: =IF('Take-off'!C13='Dropdown lists'!B30, 'Take-off'!$C$8+6, 'Take-off'!$C$8) -> 0 | E2: Includes ICE-Vane. Could be disregarded for us
B3: FLAPS UP | O3: FLAPS TAKEOFF | AB3: FLAPS APPROACH
B4: Density altitude | O4: Density altitude | AB4: Density altitude
A5: Temp/PA | B5: -500 | C5: 0 | D5: 1000 | E5: 2000 | F5: 3000 | G5: 4000 | N5: Temp/PA | O5: 0 | P5: 1000 | Q5: 2000 | R5: 3000 | S5: 4000 | AA5: Temp/PA | AB5: -500 | AC5: 0 | AD5: 1000 | AE5: 2000 | AF5: 3000 | AG5: 4000
A6: -40 | B6: 2700 | C6: 2700 | D6: 2800 | E6: 2900 | F6: 3200 | G6: 99999 | N6: -30 | S6: 99999 | AA6: -40 | AB6: 4200 | AC6: 4200 | AD6: 4400 | AE6: 4600 | AF6: 4900 | AG6: 99999
A7: -30 | B7: 2700 | C7: 2700 | D7: 2800 | E7: 2900 | F7: 3200 | G7: 99999 | AA7: -30 | AB7: 4200 | AC7: 4200 | AD7: 4400 | AE7: 4600 | AF7: 4900 | AG7: 99999
A8: -20 | B8: 2800 | C8: 2800 | D8: 2980 | E8: 3100 | F8: 3400 | G8: 99999 | N8: -20 | S8: 99999 | AA8: -20 | AB8: 4200 | AC8: 4200 | AD8: 4400 | AE8: 4600 | AF8: 4900 | AG8: 99999
A9: -10 | B9: 3000 | C9: 3000 | D9: 3200 | E9: 3400 | F9: 3600 | G9: 99999 | N9: -10 | S9: 99999 | AA9: -10 | AB9: 4400 | AC9: 4400 | AD9: 4700 | AE9: 5000 | AF9: 5200 | AG9: 99999
A10: 0 | B10: 3200 | C10: 3200 | D10: 3400 | E10: 3600 | F10: 3900 | G10: 99999 | N10: 0 | S10: 99999 | AA10: 0 | AB10: 4700 | AC10: 4700 | AD10: 5000 | AE10: 5300 | AF10: 5600 | AG10: 99999
A11: 10 | B11: 3370 | C11: 3370 | D11: 3600 | E11: 3800 | F11: 4200 | G11: 99999 | N11: 10 | S11: 99999 | AA11: 10 | AB11: 5000 | AC11: 5000 | AD11: 5300 | AE11: 5600 | AF11: 6000 | AG11: 99999
A12: 20 | B12: 3570 | C12: 3570 | D12: 3800 | E12: 4150 | F12: 4700 | G12: 99999 | N12: 20 | S12: 99999 | AA12: 20 | AB12: 5300 | AC12: 5300 | AD12: 5600 | AE12: 6000 | AF12: 6400 | AG12: 99999
A13: 30 | B13: 3800 | C13: 3800 | D13: 4200 | E13: 4600 | F13: 5300 | G13: 99999 | AA13: 30 | AB13: 5600 | AC13: 5600 | AD13: 6000 | AE13: 6600 | AF13: 7500 | AG13: 99999
A14: 40 | B14: 4400 | C14: 4400 | D14: 5000 | E14: 5600 | F14: 6800 | G14: 99999 | N14: 30 | S14: 99999 | AA14: 40 | AB14: 6400 | AC14: 6400 | AD14: 7200 | AE14: 8100 | AF14: 9200 | AG14: 99999
A15: 35 | B15: 99999 | C15: 99999 | D15: 99999 | E15: 99999 | F15: 99999 | G15: 99999 | N15: 35 | O15: 99999 | P15: 99999 | Q15: 99999 | R15: 99999 | S15: 99999 | AA15: 45 | AB15: 99999 | AC15: 99999 | AD15: 99999 | AE15: 99999 | AF15: 99999 | AG15: 99999
B17: x_n: | C17: =D1 -> 200 | D17: Table size | O17: x_n: | P17: =D1 -> 200 | Q17: Table size | AB17: x_n: | AC17: =D1 -> 200 | AD17: Table size
B18: x1_n: | C18: {=INDEX(B5:G5,MATCH(C17,B5:G5,1))} -> 0 | D18: Rows: | E18: =MATCH(MAX(A6:A15),A6:A15,1) -> 9 | O18: x1_n: | P18: {=INDEX(O5:S5,MATCH(P17,O5:S5,1))} -> 0 | Q18: Rows: | R18: =MATCH(MAX(N6:N15),N6:N15,1) -> 10 | AB18: x1_n: | AC18: {=INDEX(AB5:AG5,MATCH(AC17,AB5:AG5,1))} -> 0 | AD18: Rows: | AE18: =MATCH(MAX(AA6:AA15),AA6:AA15,1) -> 10
B19: x2_n: | C19: {=INDEX(B5:G5,IF(MATCH(C17,B5:G5,1)<E19,MATCH(C17,B5:G5,1)+1,MATCH(C17,B5:G5,1)))} -> 1000 | D19: Columns: | E19: =MATCH(MAX(B5:G5),B5:G5,0) -> 6 | O19: x2_n: | P19: {=INDEX(O5:S5,IF(MATCH(P17,O5:S5,1)<R19,MATCH(P17,O5:S5,1)+1,MATCH(P17,O5:S5,1)))} -> 1000 | Q19: Columns: | R19: =MATCH(MAX(O5:S5),O5:S5,0) -> 5 | AB19: x2_n: | AC19: {=INDEX(AB5:AG5,IF(MATCH(AC17,AB5:AG5,1)<AE19,MATCH(AC17,AB5:AG5,1)+1,MATCH(AC17,AB5:AG5,1)))} -> 1000 | AD19: Columns: | AE19: =MATCH(MAX(AB5:AG5),AB5:AG5,0) -> 6
B20: y_n: | C20: =D2 -> 0 | O20: y_n: | P20: =D2 -> 0 | AB20: y_n: | AC20: =D2 -> 0
B21: n1: | C21: {=INDEX(A6:A15,MATCH(C20,A6:A15,1))} -> 0 | O21: n1: | P21: {=INDEX(N6:N15,MATCH(P20,N6:N15,1))} -> 0 | AB21: n1: | AC21: {=INDEX(AA6:AA15,MATCH(AC20,AA6:AA15,1))} -> 0
B22: n2: | C22: {=INDEX(A6:A15,IF(MATCH(C20,A6:A15,1)<E18,MATCH(C20,A6:A15,1)+1,MATCH(C20,A6:A15,1)))} -> 10 | O22: n2: | P22: {=INDEX(N6:N15,IF(MATCH(P20,N6:N15,1)<R18,MATCH(P20,N6:N15,1)+1,MATCH(P20,N6:N15,1)))} -> 10 | AB22: n2: | AC22: {=INDEX(AA6:AA15,IF(MATCH(AC20,AA6:AA15,1)<AE18,MATCH(AC20,AA6:AA15,1)+1,MATCH(AC20,AA6:AA15,1)))} -> 10
B23: y1_n1: | C23: {=INDEX(B6:G15,MATCH(C20,A6:A15,1),MATCH(C17,B5:G5,1))} -> 3200 | O23: y1_n1: | P23: =INDEX(O6:S15,MATCH(P20,N6:N15,1),MATCH(P17,O5:S5,1)) -> 0 | AB23: y1_n1: | AC23: {=INDEX(AB6:AG15,MATCH(AC20,AA6:AA15,1),MATCH(AC17,AB5:AG5,1))} -> 4700
B24: y2_n1: | C24: {=INDEX(B6:G15,MATCH(C20,A6:A15,1),IF(MATCH(C17,B5:G5,1)<E19,MATCH(C17,B5:G5,1)+1,MATCH(C20,A6:A15,1)))} -> 3400 | O24: y2_n1: | P24: =INDEX(O6:S15,MATCH(P20,N6:N15,1),IF(MATCH(P17,O5:S5,1)<R19,MATCH(P17,O5:S5,1)+1,MATCH(P20,N6:N15,1))) -> 0 | AB24: y2_n1: | AC24: {=INDEX(AB6:AG15,MATCH(AC20,AA6:AA15,1),IF(MATCH(AC17,AB5:AG5,1)<AE19,MATCH(AC17,AB5:AG5,1)+1,MATCH(AC20,AA6:AA15,1)))} -> 5000
B25: y1_n2: | C25: {=INDEX(B6:G15,IF(MATCH(C20,A6:A15,1)<E18,MATCH(C20,A6:A15,1)+1,MATCH(C20,A6:A15,1)),MATCH(C17,B5:G5,1))} -> 3370 | O25: y1_n2: | P25: =INDEX(O6:S15,IF(MATCH(P20,N6:N15,1)<R18,MATCH(P20,N6:N15,1)+1,MATCH(P20,N6:N15,1)),MATCH(P17,O5:S5,1)) -> 0 | AB25: y1_n2: | AC25: {=INDEX(AB6:AG15,IF(MATCH(AC20,AA6:AA15,1)<AE18,MATCH(AC20,AA6:AA15,1)+1,MATCH(AC20,AA6:AA15,1)),MATCH(AC17,AB5:AG5,1))} -> 5000
B26: y2_n2: | C26: {=INDEX(B6:G15,IF(MATCH(C20,A6:A15,1)<E18,MATCH(C20,A6:A15,1)+1,MATCH(C20,A6:A15,1)),IF(MATCH(C17,B5:G5,1)<E19,MATCH(C17,B5:G5,1)+1,MATCH(C17,B5:G5,1)))} -> 3600 | O26: y2_n2: | P26: =INDEX(O6:S15,IF(MATCH(P20,N6:N15,1)<R18,MATCH(P20,N6:N15,1)+1,MATCH(P20,N6:N15,1)),IF(MATCH(P17,O5:S5,1)<R19,MATCH(P17,O5:S5,1)+1,MATCH(P17,O5:S5,1))) -> 0 | AB26: y2_n2: | AC26: {=INDEX(AB6:AG15,IF(MATCH(AC20,AA6:AA15,1)<AE18,MATCH(AC20,AA6:AA15,1)+1,MATCH(AC20,AA6:AA15,1)),IF(MATCH(AC17,AB5:AG5,1)<AE19,MATCH(AC17,AB5:AG5,1)+1,MATCH(AC17,AB5:AG5,1)))} -> 5300
B27: y_n1: | C27: =IFERROR(C23+(C17-C18)*(C24-C23)/(C19-C18),C23) -> 3240 | O27: y_n1: | P27: =IFERROR(P23+(P17-P18)*(P24-P23)/(P19-P18),P23) -> 0 | AB27: y_n1: | AC27: =IFERROR(AC23+(AC17-AC18)*(AC24-AC23)/(AC19-AC18),AC23) -> 4760
B28: y_n2: | C28: =IFERROR(C25+(C17-C18)*(C26-C25)/(C19-C18),C25) -> 3416 | O28: y_n2: | P28: =IFERROR(P25+(P17-P18)*(P26-P25)/(P19-P18),P25) -> 0 | AB28: y_n2: | AC28: =IFERROR(AC25+(AC17-AC18)*(AC26-AC25)/(AC19-AC18),AC25) -> 5060
B29: Distance | C29: =IFERROR(C27+(C20-C21)*(C28-C27)/(C22-C21),C27) -> 3240 | O29: Distance | P29: =IFERROR(P27+(P20-P21)*(P28-P27)/(P22-P21),P27) -> 0 | AB29: Distance | AC29: =IFERROR(AC27+(AC20-AC21)*(AC28-AC27)/(AC22-AC21),AC27) -> 4760
B31: Vikt | O31: Vikt | AB31: Vikt
A32: % | B32: 2000 | C32: 3000 | D32: 4000 | E32: 5000 | F32: 6000 | G32: 7000 | H32: 8000 | P32: % | Q32: 2000 | R32: 3000 | S32: 4000 | T32: 4500 | AD32: % | AE32: 4200 | AF32: 6400 | AG32: 8400 | AH32: 10400 | AI32: 11000
A33: 9000 | B33: 1200 | C33: 1760 | D33: 2200 | E33: 2600 | F33: 3000 | G33: 3400 | H33: 99999 | P33: 10000 | T33: 99999 | AD33: 9000 | AE33: 2400 | AF33: 3100 | AG33: 3700 | AH33: 4300 | AI33: 99999
A34: 9500 | B34: 1250 | C34: 1800 | D34: 2400 | E34: 2800 | F34: 3200 | G34: 3600 | H34: 99999 | P34: 11000 | T34: 99999 | AD34: 9500 | AE34: 2500 | AF34: 3400 | AG34: 4150 | AH34: 4800 | AI34: 99999
A35: 10000 | B35: 1300 | C35: 2000 | D35: 2600 | E35: 3100 | F35: 3600 | G35: 4000 | H35: 99999 | P35: 12000 | T35: 99999 | AD35: 10000 | AE35: 2700 | AF35: 3700 | AG35: 4600 | AH35: 5400 | AI35: 99999
A36: 10500 | B36: 1400 | C36: 2200 | D36: 2820 | E36: 3400 | F36: 3900 | G36: 4400 | H36: 99999 | P36: 13000 | T36: 99999 | AD36: 10500 | AE36: 3000 | AF36: 4150 | AG36: 5200 | AH36: 6000 | AI36: 99999
A37: 11000 | B37: 1600 | C37: 2350 | D37: 3200 | E37: 3700 | F37: 4400 | G37: 4900 | H37: 99999 | P37: 14000 | T37: 99999 | AD37: 11000 | AE37: 3200 | AF37: 4600 | AG37: 5800 | AH37: 6800 | AI37: 99999
A38: 11500 | B38: 1700 | C38: 2600 | D38: 3400 | E38: 4100 | F38: 4800 | G38: 5450 | H38: 99999 | P38: 15000 | T38: 99999 | AD38: 11500 | AE38: 3600 | AF38: 5150 | AG38: 6500 | AH38: 7800 | AI38: 99999
A39: 12000 | B39: 1810 | C39: 2780 | D39: 3700 | E39: 4500 | F39: 5400 | G39: 6200 | H39: 99999 | P39: 16000 | T39: 99999 | AD39: 12000 | AE39: 3900 | AF39: 5700 | AG39: 7350 | AH39: 9000 | AI39: 99999
A40: 12500 | B40: 2000 | C40: 3000 | D40: 4000 | E40: 5000 | F40: 6000 | G40: 7000 | H40: 99999 | P40: 16600 | T40: 99999 | AD40: 12500 | AE40: 4200 | AF40: 6400 | AG40: 8400 | AH40: 10400 | AI40: 99999
A41: 12600 | B41: 99999 | C41: 99999 | D41: 99999 | E41: 99999 | F41: 99999 | G41: 99999 | H41: 99999 | P41: 16700 | Q41: 99999 | R41: 99999 | S41: 99999 | T41: 99999 | AD41: 12600 | AE41: 99999 | AF41: 99999 | AG41: 99999 | AH41: 99999 | AI41: 99999
B43: x_n: | C43: =C29 -> 3240 | D43: Table size | O43: x_n: | P43: =P29 -> 0 | Q43: Table size | AB43: x_n: | AC43: =AC29 -> 4760 | AD43: Table size
...

Sheet LTL_Accelerate and stop2
B1: Pressure Alt | C1: x_n: | D1: =IF('Take-off'!$C$9="",'Take-off'!$C$16,MAX(0,'Take-off'!$C$16+30*(1013-'Take-off'!$C$9))) -> 200
B2: Temp in calc | C2: y_n: | D2: ='Take-off'!$C$8 -> 0
B3: FLAPS UP | O3: FLAPS TAKEOFF | AB3: FLAPS APPROACH
B4: Density altitude | O4: Density altitude | AB4: Density altitude
A5: Temp/PA | B5: -500 | C5: 0 | D5: 1000 | E5: 2000 | F5: 3000 | G5: 4000 | N5: Temp/PA | O5: 0 | P5: 1000 | Q5: 2000 | R5: 3000 | S5: 4000 | AA5: Temp/PA | AB5: -500 | AC5: 0 | AD5: 1000 | AE5: 2000 | AF5: 3000 | AG5: 4000
A6: -40 | B6: 2800 | C6: 2800 | D6: 2900 | E6: 3000 | F6: 3120 | G6: 99999 | N6: -30 | S6: 99999 | AA6: -40 | AB6: 3000 | AC6: 3000 | AD6: 3100 | AE6: 3200 | AF6: 3350 | AG6: 99999
A7: -30 | B7: 2800 | C7: 2800 | D7: 2900 | E7: 3000 | F7: 3120 | G7: 99999 | AA7: -30 | AB7: 3000 | AC7: 3000 | AD7: 3100 | AE7: 3200 | AF7: 3350 | AG7: 99999
A8: -20 | B8: 2800 | C8: 2800 | D8: 2900 | E8: 3050 | F8: 3200 | G8: 99999 | N8: -20 | S8: 99999 | AA8: -20 | AB8: 3000 | AC8: 3000 | AD8: 3100 | AE8: 3200 | AF8: 3350 | AG8: 99999
A9: -10 | B9: 2900 | C9: 2900 | D9: 3100 | E9: 3200 | F9: 3310 | G9: 99999 | N9: -10 | S9: 99999 | AA9: -10 | AB9: 3050 | AC9: 3050 | AD9: 3200 | AE9: 3300 | AF9: 3450 | AG9: 99999
A10: 0 | B10: 3075 | C10: 3075 | D10: 3200 | E10: 3300 | F10: 3490 | G10: 99999 | N10: 0 | S10: 99999 | AA10: 0 | AB10: 3200 | AC10: 3200 | AD10: 3350 | AE10: 3500 | AF10: 3600 | AG10: 99999
A11: 10 | B11: 3200 | C11: 3200 | D11: 3350 | E11: 3450 | F11: 3650 | G11: 99999 | N11: 10 | S11: 99999 | AA11: 10 | AB11: 3350 | AC11: 3350 | AD11: 3450 | AE11: 3600 | AF11: 3800 | AG11: 99999
A12: 20 | B12: 3300 | C12: 3300 | D12: 3480 | E12: 3600 | F12: 3800 | G12: 99999 | N12: 20 | S12: 99999 | AA12: 20 | AB12: 3450 | AC12: 3450 | AD12: 3650 | AE12: 3800 | AF12: 4000 | AG12: 99999
A13: 30 | B13: 3450 | C13: 3450 | D13: 3650 | E13: 3800 | F13: 4050 | G13: 99999 | AA13: 30 | AB13: 3600 | AC13: 3600 | AD13: 3800 | AE13: 3950 | AF13: 4250 | AG13: 99999
A14: 40 | B14: 3650 | C14: 3650 | D14: 3850 | E14: 4100 | F14: 4350 | G14: 99999 | N14: 30 | S14: 99999 | AA14: 40 | AB14: 3850 | AC14: 3850 | AD14: 4050 | AE14: 4250 | AF14: 4500 | AG14: 99999
A15: 45 | B15: 99999 | C15: 99999 | D15: 99999 | E15: 99999 | F15: 99999 | G15: 99999 | N15: 35 | O15: 99999 | P15: 99999 | Q15: 99999 | R15: 99999 | S15: 99999 | AA15: 45 | AB15: 99999 | AC15: 99999 | AD15: 99999 | AE15: 99999 | AF15: 99999 | AG15: 99999
B17: x_n: | C17: =D1 -> 200 | D17: Table size | O17: x_n: | P17: =D1 -> 200 | Q17: Table size | AB17: x_n: | AC17: =D1 -> 200 | AD17: Table size
B18: x1_n: | C18: {=INDEX(B5:G5,MATCH(C17,B5:G5,1))} -> 0 | D18: Rows: | E18: =MATCH(MAX(A6:A15),A6:A15,1) -> 10 | O18: x1_n: | P18: {=INDEX(O5:S5,MATCH(P17,O5:S5,1))} -> 0 | Q18: Rows: | R18: =MATCH(MAX(N6:N15),N6:N15,1) -> 10 | AB18: x1_n: | AC18: {=INDEX(AB5:AG5,MATCH(AC17,AB5:AG5,1))} -> 0 | AD18: Rows: | AE18: =MATCH(MAX(AA6:AA15),AA6:AA15,1) -> 10
B19: x2_n: | C19: {=INDEX(B5:G5,IF(MATCH(C17,B5:G5,1)<E19,MATCH(C17,B5:G5,1)+1,MATCH(C17,B5:G5,1)))} -> 1000 | D19: Columns: | E19: =MATCH(MAX(B5:G5),B5:G5,0) -> 6 | O19: x2_n: | P19: {=INDEX(O5:S5,IF(MATCH(P17,O5:S5,1)<R19,MATCH(P17,O5:S5,1)+1,MATCH(P17,O5:S5,1)))} -> 1000 | Q19: Columns: | R19: =MATCH(MAX(O5:S5),O5:S5,0) -> 5 | AB19: x2_n: | AC19: {=INDEX(AB5:AG5,IF(MATCH(AC17,AB5:AG5,1)<AE19,MATCH(AC17,AB5:AG5,1)+1,MATCH(AC17,AB5:AG5,1)))} -> 1000 | AD19: Columns: | AE19: =MATCH(MAX(AB5:AG5),AB5:AG5,0) -> 6
B20: y_n: | C20: =D2 -> 0 | O20: y_n: | P20: =D2 -> 0 | AB20: y_n: | AC20: =D2 -> 0
B21: n1: | C21: {=INDEX(A6:A15,MATCH(C20,A6:A15,1))} -> 0 | O21: n1: | P21: {=INDEX(N6:N15,MATCH(P20,N6:N15,1))} -> 0 | AB21: n1: | AC21: {=INDEX(AA6:AA15,MATCH(AC20,AA6:AA15,1))} -> 0
B22: n2: | C22: {=INDEX(A6:A15,IF(MATCH(C20,A6:A15,1)<E18,MATCH(C20,A6:A15,1)+1,MATCH(C20,A6:A15,1)))} -> 10 | O22: n2: | P22: {=INDEX(N6:N15,IF(MATCH(P20,N6:N15,1)<R18,MATCH(P20,N6:N15,1)+1,MATCH(P20,N6:N15,1)))} -> 10 | AB22: n2: | AC22: {=INDEX(AA6:AA15,IF(MATCH(AC20,AA6:AA15,1)<AE18,MATCH(AC20,AA6:AA15,1)+1,MATCH(AC20,AA6:AA15,1)))} -> 10
B23: y1_n1: | C23: {=INDEX(B6:G15,MATCH(C20,A6:A15,1),MATCH(C17,B5:G5,1))} -> 3075 | O23: y1_n1: | P23: =INDEX(O6:S15,MATCH(P20,N6:N15,1),MATCH(P17,O5:S5,1)) -> 0 | AB23: y1_n1: | AC23: {=INDEX(AB6:AG15,MATCH(AC20,AA6:AA15,1),MATCH(AC17,AB5:AG5,1))} -> 3200
B24: y2_n1: | C24: {=INDEX(B6:G15,MATCH(C20,A6:A15,1),IF(MATCH(C17,B5:G5,1)<E19,MATCH(C17,B5:G5,1)+1,MATCH(C20,A6:A15,1)))} -> 3200 | O24: y2_n1: | P24: =INDEX(O6:S15,MATCH(P20,N6:N15,1),IF(MATCH(P17,O5:S5,1)<R19,MATCH(P17,O5:S5,1)+1,MATCH(P20,N6:N15,1))) -> 0 | AB24: y2_n1: | AC24: {=INDEX(AB6:AG15,MATCH(AC20,AA6:AA15,1),IF(MATCH(AC17,AB5:AG5,1)<AE19,MATCH(AC17,AB5:AG5,1)+1,MATCH(AC20,AA6:AA15,1)))} -> 3350
B25: y1_n2: | C25: {=INDEX(B6:G15,IF(MATCH(C20,A6:A15,1)<E18,MATCH(C20,A6:A15,1)+1,MATCH(C20,A6:A15,1)),MATCH(C17,B5:G5,1))} -> 3200 | O25: y1_n2: | P25: =INDEX(O6:S15,IF(MATCH(P20,N6:N15,1)<R18,MATCH(P20,N6:N15,1)+1,MATCH(P20,N6:N15,1)),MATCH(P17,O5:S5,1)) -> 0 | AB25: y1_n2: | AC25: {=INDEX(AB6:AG15,IF(MATCH(AC20,AA6:AA15,1)<AE18,MATCH(AC20,AA6:AA15,1)+1,MATCH(AC20,AA6:AA15,1)),MATCH(AC17,AB5:AG5,1))} -> 3350
B26: y2_n2: | C26: {=INDEX(B6:G15,IF(MATCH(C20,A6:A15,1)<E18,MATCH(C20,A6:A15,1)+1,MATCH(C20,A6:A15,1)),IF(MATCH(C17,B5:G5,1)<E19,MATCH(C17,B5:G5,1)+1,MATCH(C17,B5:G5,1)))} -> 3350 | O26: y2_n2: | P26: =INDEX(O6:S15,IF(MATCH(P20,N6:N15,1)<R18,MATCH(P20,N6:N15,1)+1,MATCH(P20,N6:N15,1)),IF(MATCH(P17,O5:S5,1)<R19,MATCH(P17,O5:S5,1)+1,MATCH(P17,O5:S5,1))) -> 0 | AB26: y2_n2: | AC26: {=INDEX(AB6:AG15,IF(MATCH(AC20,AA6:AA15,1)<AE18,MATCH(AC20,AA6:AA15,1)+1,MATCH(AC20,AA6:AA15,1)),IF(MATCH(AC17,AB5:AG5,1)<AE19,MATCH(AC17,AB5:AG5,1)+1,MATCH(AC17,AB5:AG5,1)))} -> 3450
B27: y_n1: | C27: =IFERROR(C23+(C17-C18)*(C24-C23)/(C19-C18),C23) -> 3100 | O27: y_n1: | P27: =IFERROR(P23+(P17-P18)*(P24-P23)/(P19-P18),P23) -> 0 | AB27: y_n1: | AC27: =IFERROR(AC23+(AC17-AC18)*(AC24-AC23)/(AC19-AC18),AC23) -> 3230
B28: y_n2: | C28: =IFERROR(C25+(C17-C18)*(C26-C25)/(C19-C18),C25) -> 3230 | O28: y_n2: | P28: =IFERROR(P25+(P17-P18)*(P26-P25)/(P19-P18),P25) -> 0 | AB28: y_n2: | AC28: =IFERROR(AC25+(AC17-AC18)*(AC26-AC25)/(AC19-AC18),AC25) -> 3370
B29: Distance | C29: =IFERROR(C27+(C20-C21)*(C28-C27)/(C22-C21),C27) -> 3100 | O29: Distance | P29: =IFERROR(P27+(P20-P21)*(P28-P27)/(P22-P21),P27) -> 0 | AB29: Distance | AC29: =IFERROR(AC27+(AC20-AC21)*(AC28-AC27)/(AC22-AC21),AC27) -> 3230
B31: Vikt | O31: Vikt | AB31: Vikt
A32: % | B32: 2500 | C32: 3000 | D32: 3500 | E32: 4000 | F32: 4500 | G32: 5000 | N32: % | O32: 3600 | P32: 4300 | Q32: 5000 | R32: 5700 | S32: 6000 | AA32: % | AB32: 3000 | AC32: 3450 | AD32: 3900 | AE32: 4350 | AF32: 5000
A33: 9000 | B33: 2200 | C33: 2700 | D33: 3050 | E33: 3400 | F33: 3900 | G33: 99999 | N33: 10000 | S33: 99999 | AA33: 9000 | AB33: 2650 | AC33: 3000 | AD33: 3350 | AE33: 3700 | AF33: 99999
A34: 9500 | B34: 2250 | C34: 2750 | D34: 3110 | E34: 3500 | F34: 3950 | G34: 99999 | N34: 11000 | S34: 99999 | AA34: 9500 | AB34: 2700 | AC34: 3050 | AD34: 3400 | AE34: 3770 | AF34: 99999
A35: 10000 | B35: 2290 | C35: 2780 | D35: 3190 | E35: 3600 | F35: 4000 | G35: 99999 | N35: 12000 | S35: 99999 | AA35: 10000 | AB35: 2710 | AC35: 3100 | AD35: 3500 | AE35: 3850 | AF35: 99999
A36: 10500 | B36: 2310 | C36: 2800 | D36: 3250 | E36: 3675 | F36: 4100 | G36: 99999 | N36: 13000 | S36: 99999 | AA36: 10500 | AB36: 2770 | AC36: 3180 | AD36: 3550 | AE36: 3950 | AF36: 99999
A37: 11000 | B37: 2375 | C37: 2850 | D37: 3300 | E37: 3750 | F37: 4200 | G37: 99999 | N37: 14000 | S37: 99999 | AA37: 11000 | AB37: 2800 | AC37: 3220 | AD37: 3650 | AE37: 4000 | AF37: 99999
A38: 11500 | B38: 2400 | C38: 2900 | D38: 3380 | E38: 3820 | F38: 4300 | G38: 99999 | N38: 15000 | S38: 99999 | AA38: 11500 | AB38: 2900 | AC38: 3300 | AD38: 3700 | AE38: 4100 | AF38: 99999
A39: 12000 | B39: 2450 | C39: 2950 | D39: 3450 | E39: 3910 | F39: 4400 | G39: 99999 | N39: 16000 | S39: 99999 | AA39: 12000 | AB39: 2950 | AC39: 3350 | AD39: 3800 | AE39: 4250 | AF39: 99999
A40: 12500 | B40: 2500 | C40: 3000 | D40: 3500 | E40: 4000 | F40: 4500 | G40: 99999 | N40: 16600 | S40: 99999 | AA40: 12500 | AB40: 3000 | AC40: 3450 | AD40: 3900 | AE40: 4350 | AF40: 99999
A41: 12600 | B41: 99999 | C41: 99999 | D41: 99999 | E41: 99999 | F41: 99999 | G41: 99999 | N41: 16700 | O41: 99999 | P41: 99999 | Q41: 99999 | R41: 99999 | S41: 99999 | AA41: 12600 | AB41: 99999 | AC41: 99999 | AD41: 99999 | AE41: 99999 | AF41: 99999
B43: x_n: | C43: =C29 -> 3100 | D43: Table size | O43: x_n: | P43: =P29 -> 0 | Q43: Table size | AB43: x_n: | AC43: =AC29 -> 3230 | AD43: Table size
...

Sheet LTL_OEI CLIMB GRADIENT
B1: Pressure Alt | C1: x_n: | D1: =IF(Landing!$C$9="",Landing!$C$15,MAX(0,Landing!$C$15+30*(1013-Landing!$C$9))) -> 1010
B2: Temp in calc | C2: y_n: | D2: =Landing!C8 -> 13
B3: NET GRADIENT OF CLIMB - FLAPS UP
B4: Density altitude
A5: Temp/PA | B5: -500 | C5: 0 | D5: 1000 | E5: 2000 | F5: 3000 | G5: 4000
A6: -40 | B6: 790 | C6: 790 | D6: 780 | E6: 760 | F6: 750 | G6: -99
A7: -30 | B7: 790 | C7: 790 | D7: 780 | E7: 760 | F7: 750 | G7: -99
A8: -20 | B8: 770 | C8: 770 | D8: 760 | E8: 740 | F8: 730 | G8: -99
A9: -10 | B9: 760 | C9: 760 | D9: 740 | E9: 730 | F9: 710 | G9: -99
A10: 0 | B10: 740 | C10: 740 | D10: 725 | E10: 710 | F10: 690 | G10: -99
A11: 10 | B11: 720 | C11: 720 | D11: 710 | E11: 690 | F11: 670 | G11: -99
A12: 20 | B12: 700 | C12: 700 | D12: 690 | E12: 670 | F12: 650 | G12: -99
A13: 30 | B13: 680 | C13: 680 | D13: 670 | E13: 660 | F13: 620 | G13: -99
A14: 40 | B14: 665 | C14: 665 | D14: 620 | E14: 580 | F14: 530 | G14: -99
A15: 45 | B15: -99 | C15: -99 | D15: -99 | E15: -99 | F15: -99 | G15: -99
B17: x_n: | C17: =D1 -> 1010 | D17: Table size
B18: x1_n: | C18: {=INDEX(B5:G5,MATCH(C17,B5:G5,1))} -> 1000 | D18: Rows: | E18: =MATCH(MAX(A6:A15),A6:A15,1) -> 10
B19: x2_n: | C19: {=INDEX(B5:G5,IF(MATCH(C17,B5:G5,1)<E19,MATCH(C17,B5:G5,1)+1,MATCH(C17,B5:G5,1)))} -> 2000 | D19: Columns: | E19: =MATCH(MAX(B5:G5),B5:G5,0) -> 6
B20: y_n: | C20: =D2 -> 13
B21: n1: | C21: {=INDEX(A6:A15,MATCH(C20,A6:A15,1))} -> 10
B22: n2: | C22: {=INDEX(A6:A15,IF(MATCH(C20,A6:A15,1)<E18,MATCH(C20,A6:A15,1)+1,MATCH(C20,A6:A15,1)))} -> 20
B23: y1_n1: | C23: {=INDEX(B6:G15,MATCH(C20,A6:A15,1),MATCH(C17,B5:G5,1))} -> 710
B24: y2_n1: | C24: {=INDEX(B6:G15,MATCH(C20,A6:A15,1),IF(MATCH(C17,B5:G5,1)<E19,MATCH(C17,B5:G5,1)+1,MATCH(C20,A6:A15,1)))} -> 690
B25: y1_n2: | C25: {=INDEX(B6:G15,IF(MATCH(C20,A6:A15,1)<E18,MATCH(C20,A6:A15,1)+1,MATCH(C20,A6:A15,1)),MATCH(C17,B5:G5,1))} -> 690
B26: y2_n2: | C26: {=INDEX(B6:G15,IF(MATCH(C20,A6:A15,1)<E18,MATCH(C20,A6:A15,1)+1,MATCH(C20,A6:A15,1)),IF(MATCH(C17,B5:G5,1)<E19,MATCH(C17,B5:G5,1)+1,MATCH(C17,B5:G5,1)))} -> 670
B27: y_n1: | C27: =IFERROR(C23+(C17-C18)*(C24-C23)/(C19-C18),C23) -> 709.8
B28: y_n2: | C28: =IFERROR(C25+(C17-C18)*(C26-C25)/(C19-C18),C25) -> 689.8
B29: Distance | C29: =IFERROR(C27+(C20-C21)*(C28-C27)/(C22-C21),C27) -> 703.8
B31: ROC | O31: ROC->Gradient
A32: % | B32: 500 | C32: 600 | D32: 700 | E32: 800 | F32: 900 | P32: % | Q32: 440 | R32: 500 | S32: 550 | T32: 650 | U32: 760 | V32: 860 | W32: 960 | X32: 1060 | Y32: 1160 | Z32: 1200 | AA32: 1200
A33: 9000 | B33: 1050 | C33: 1150 | D33: 1200 | E33: 1200 | F33: -99 | P33: 1 | Q33: 3 | R33: 3.5 | S33: 4 | T33: 5 | U33: 6 | V33: 7 | W33: 8 | X33: 9 | Y33: 10 | Z33: 10.5 | AA33: 11
A34: 9500 | B34: 940 | C34: 1050 | D34: 1180 | E34: 1200 | F34: -99
A35: 10000 | B35: 860 | C35: 960 | D35: 1080 | E35: 1200 | F35: -99 | O35: x_n: | P35: =C55 -> 603.8 | Q35: Table size
A36: 10500 | B36: 775 | C36: 880 | D36: 950 | E36: 1100 | F36: -99 | O36: x1_n: | P36: {=INDEX(Q32:AA32,MATCH(P35,Q32:AA32,1))} -> 550 | Q36: Rows: | R36: =MATCH(MAX(P33),P33,1) -> 1
A37: 11000 | B37: 700 | C37: 800 | D37: 910 | E37: 1020 | F37: -99 | O37: x2_n: | P37: {=INDEX(Q32:AA32,IF(MATCH(P35,Q32:AA32,1)<R37,MATCH(P35,Q32:AA32,1)+1,MATCH(P35,Q32:AA32,1)))} -> 650 | Q37: Columns: | R37: =MATCH(MAX(Q32:AA32),Q32:AA32,0) -> 10
A38: 11500 | B38: 630 | C38: 725 | D38: 830 | E38: 940 | F38: -99 | O38: y_n: | P38: 1
A39: 12000 | B39: 560 | C39: 660 | D39: 760 | E39: 865 | F39: -99 | O39: n1: | P39: {=INDEX(P33,MATCH(P38,P33,1))} -> 1
A40: 12500 | B40: 500 | C40: 600 | D40: 700 | E40: 800 | F40: -99 | O40: n2: | P40: {=INDEX(P33,IF(MATCH(P38,P33,1)<R36,MATCH(P38,P33,1)+1,MATCH(P38,P33,1)))} -> 1
O41: y1_n1: | P41: {=INDEX(Q33:AA33,MATCH(P38,P33,1),MATCH(P35,Q32:AA32,1))} -> 4
B42: x_n: | C42: =C29 -> 703.8 | D42: Table size | O42: y2_n1: | P42: {=INDEX(Q33:AA33,MATCH(P38,P33,1),IF(MATCH(P35,Q32:AA32,1)<R37,MATCH(P35,Q32:AA32,1)+1,MATCH(P38,P33,1)))} -> 5
...

Sheet LTL_NET GRADIENT OF CLIMB
B1: Pressure Alt | C1: x_n: | D1: =IF('Take-off'!$C$9="",'Take-off'!$C$16,MAX(0,'Take-off'!$C$16+30*(1013-'Take-off'!$C$9)))+35 -> 235 | F1: 35 fot extra
B2: Temp in calc | C2: y_n: | D2: =IF('Take-off'!$C$13='Dropdown lists'!$B$30, 'Take-off'!$C$8+10, 'Take-off'!$C$8) -> 0 | E2: Includes ICE-Vane. Could be disregarded for us
B3: NET GRADIENT OF CLIMB - FLAPS UP | O3: NET GRADIENT OF CLIMB - FLAPS TAKEOFF | AB3: NET GRADIENT OF CLIMB - FLAPS APPROACH
B4: Density altitude | O4: Density altitude | AB4: Density altitude
A5: Temp/PA | B5: -500 | C5: 0 | D5: 1000 | E5: 2000 | F5: 3000 | G5: 4000 | N5: Temp/PA | O5: 0 | P5: 1000 | Q5: 2000 | R5: 3000 | S5: 4000 | AA5: Temp/PA | AB5: -500 | AC5: 0 | AD5: 1000 | AE5: 2000 | AF5: 3000 | AG5: 4000
A6: -40 | B6: 6 | C6: 6 | D6: 5.8 | E6: 5.6 | F6: 5.4 | G6: -99 | N6: -30 | S6: 99999 | AA6: -40 | AB6: 4.2 | AC6: 4.2 | AD6: 4 | AE6: 3.9 | AF6: 3.6 | AG6: -99
A7: -30 | B7: 6 | C7: 6 | D7: 5.8 | E7: 5.6 | F7: 5.4 | G7: -99 | AA7: -30 | AB7: 4.2 | AC7: 4.2 | AD7: 4 | AE7: 3.9 | AF7: 3.6 | AG7: -99
A8: -20 | B8: 6 | C8: 6 | D8: 5.8 | E8: 5.45 | F8: 5.2 | G8: -99 | N8: -20 | S8: 99999 | AA8: -20 | AB8: 4.2 | AC8: 4.2 | AD8: 4 | AE8: 3.9 | AF8: 3.6 | AG8: -99
A9: -10 | B9: 5.75 | C9: 5.75 | D9: 5.5 | E9: 5.2 | F9: 4.9 | G9: -99 | N9: -10 | S9: 99999 | AA9: -10 | AB9: 4.1 | AC9: 4.1 | AD9: 3.9 | AE9: 3.6 | AF9: 3.4 | AG9: -99
A10: 0 | B10: 5.5 | C10: 5.5 | D10: 5.2 | E10: 4.9 | F10: 4.6 | G10: -99 | N10: 0 | S10: 99999 | AA10: 0 | AB10: 3.8 | AC10: 3.8 | AD10: 3.6 | AE10: 3.4 | AF10: 3.2 | AG10: -99
A11: 10 | B11: 5.2 | C11: 5.2 | D11: 4.9 | E11: 4.6 | F11: 4.4 | G11: -99 | N11: 10 | S11: 99999 | AA11: 10 | AB11: 3.6 | AC11: 3.6 | AD11: 3.4 | AE11: 3.2 | AF11: 2.9 | AG11: -99
A12: 20 | B12: 4.95 | C12: 4.95 | D12: 4.65 | E12: 4.4 | F12: 4 | G12: -99 | N12: 20 | S12: 99999 | AA12: 20 | AB12: 3.4 | AC12: 3.4 | AD12: 3.2 | AE12: 3 | AF12: 2.5 | AG12: -99
A13: 30 | B13: 4.7 | C13: 4.7 | D13: 4.25 | E13: 3.9 | F13: 3.4 | G13: -99 | AA13: 30 | AB13: 3.2 | AC13: 3.2 | AD13: 2.8 | AE13: 2.4 | AF13: 2 | AG13: -99
A14: 40 | B14: 4 | C14: 4 | D14: 3.4 | E14: 3 | F14: 2.5 | G14: -99 | N14: 30 | S14: 99999 | AA14: 40 | AB14: 2.4 | AC14: 2.4 | AD14: 2 | AE14: 1.6 | AF14: 1 | AG14: -99
A15: 45 | B15: -99 | C15: -99 | D15: -99 | E15: -99 | F15: -99 | G15: -99 | N15: 35 | O15: 99999 | P15: 99999 | Q15: 99999 | R15: 99999 | S15: 99999 | AA15: 45 | AB15: -99 | AC15: -99 | AD15: -99 | AE15: -99 | AF15: -99 | AG15: -99
B17: x_n: | C17: =D1 -> 235 | D17: Table size | O17: x_n: | P17: =D1 -> 235 | Q17: Table size | AB17: x_n: | AC17: =D1 -> 235 | AD17: Table size
B18: x1_n: | C18: {=INDEX(B5:G5,MATCH(C17,B5:G5,1))} -> 0 | D18: Rows: | E18: =MATCH(MAX(A6:A15),A6:A15,1) -> 10 | O18: x1_n: | P18: {=INDEX(O5:S5,MATCH(P17,O5:S5,1))} -> 0 | Q18: Rows: | R18: =MATCH(MAX(N6:N15),N6:N15,1) -> 10 | AB18: x1_n: | AC18: {=INDEX(AB5:AG5,MATCH(AC17,AB5:AG5,1))} -> 0 | AD18: Rows: | AE18: =MATCH(MAX(AA6:AA15),AA6:AA15,1) -> 10
B19: x2_n: | C19: {=INDEX(B5:G5,IF(MATCH(C17,B5:G5,1)<E19,MATCH(C17,B5:G5,1)+1,MATCH(C17,B5:G5,1)))} -> 1000 | D19: Columns: | E19: =MATCH(MAX(B5:G5),B5:G5,0) -> 6 | O19: x2_n: | P19: {=INDEX(O5:S5,IF(MATCH(P17,O5:S5,1)<R19,MATCH(P17,O5:S5,1)+1,MATCH(P17,O5:S5,1)))} -> 1000 | Q19: Columns: | R19: =MATCH(MAX(O5:S5),O5:S5,0) -> 5 | AB19: x2_n: | AC19: {=INDEX(AB5:AG5,IF(MATCH(AC17,AB5:AG5,1)<AE19,MATCH(AC17,AB5:AG5,1)+1,MATCH(AC17,AB5:AG5,1)))} -> 1000 | AD19: Columns: | AE19: =MATCH(MAX(AB5:AG5),AB5:AG5,0) -> 6
B20: y_n: | C20: =D2 -> 0 | O20: y_n: | P20: =D2 -> 0 | AB20: y_n: | AC20: =D2 -> 0
B21: n1: | C21: {=INDEX(A6:A15,MATCH(C20,A6:A15,1))} -> 0 | O21: n1: | P21: {=INDEX(N6:N15,MATCH(P20,N6:N15,1))} -> 0 | AB21: n1: | AC21: {=INDEX(AA6:AA15,MATCH(AC20,AA6:AA15,1))} -> 0
B22: n2: | C22: {=INDEX(A6:A15,IF(MATCH(C20,A6:A15,1)<E18,MATCH(C20,A6:A15,1)+1,MATCH(C20,A6:A15,1)))} -> 10 | O22: n2: | P22: {=INDEX(N6:N15,IF(MATCH(P20,N6:N15,1)<R18,MATCH(P20,N6:N15,1)+1,MATCH(P20,N6:N15,1)))} -> 10 | AB22: n2: | AC22: {=INDEX(AA6:AA15,IF(MATCH(AC20,AA6:AA15,1)<AE18,MATCH(AC20,AA6:AA15,1)+1,MATCH(AC20,AA6:AA15,1)))} -> 10
B23: y1_n1: | C23: {=INDEX(B6:G15,MATCH(C20,A6:A15,1),MATCH(C17,B5:G5,1))} -> 5.5 | O23: y1_n1: | P23: =INDEX(O6:S15,MATCH(P20,N6:N15,1),MATCH(P17,O5:S5,1)) -> 0 | AB23: y1_n1: | AC23: {=INDEX(AB6:AG15,MATCH(AC20,AA6:AA15,1),MATCH(AC17,AB5:AG5,1))} -> 3.8
B24: y2_n1: | C24: {=INDEX(B6:G15,MATCH(C20,A6:A15,1),IF(MATCH(C17,B5:G5,1)<E19,MATCH(C17,B5:G5,1)+1,MATCH(C20,A6:A15,1)))} -> 5.2 | O24: y2_n1: | P24: =INDEX(O6:S15,MATCH(P20,N6:N15,1),IF(MATCH(P17,O5:S5,1)<R19,MATCH(P17,O5:S5,1)+1,MATCH(P20,N6:N15,1))) -> 0 | AB24: y2_n1: | AC24: {=INDEX(AB6:AG15,MATCH(AC20,AA6:AA15,1),IF(MATCH(AC17,AB5:AG5,1)<AE19,MATCH(AC17,AB5:AG5,1)+1,MATCH(AC20,AA6:AA15,1)))} -> 3.6
B25: y1_n2: | C25: {=INDEX(B6:G15,IF(MATCH(C20,A6:A15,1)<E18,MATCH(C20,A6:A15,1)+1,MATCH(C20,A6:A15,1)),MATCH(C17,B5:G5,1))} -> 5.2 | O25: y1_n2: | P25: =INDEX(O6:S15,IF(MATCH(P20,N6:N15,1)<R18,MATCH(P20,N6:N15,1)+1,MATCH(P20,N6:N15,1)),MATCH(P17,O5:S5,1)) -> 0 | AB25: y1_n2: | AC25: {=INDEX(AB6:AG15,IF(MATCH(AC20,AA6:AA15,1)<AE18,MATCH(AC20,AA6:AA15,1)+1,MATCH(AC20,AA6:AA15,1)),MATCH(AC17,AB5:AG5,1))} -> 3.6
B26: y2_n2: | C26: {=INDEX(B6:G15,IF(MATCH(C20,A6:A15,1)<E18,MATCH(C20,A6:A15,1)+1,MATCH(C20,A6:A15,1)),IF(MATCH(C17,B5:G5,1)<E19,MATCH(C17,B5:G5,1)+1,MATCH(C17,B5:G5,1)))} -> 4.9 | O26: y2_n2: | P26: =INDEX(O6:S15,IF(MATCH(P20,N6:N15,1)<R18,MATCH(P20,N6:N15,1)+1,MATCH(P20,N6:N15,1)),IF(MATCH(P17,O5:S5,1)<R19,MATCH(P17,O5:S5,1)+1,MATCH(P17,O5:S5,1))) -> 0 | AB26: y2_n2: | AC26: {=INDEX(AB6:AG15,IF(MATCH(AC20,AA6:AA15,1)<AE18,MATCH(AC20,AA6:AA15,1)+1,MATCH(AC20,AA6:AA15,1)),IF(MATCH(AC17,AB5:AG5,1)<AE19,MATCH(AC17,AB5:AG5,1)+1,MATCH(AC17,AB5:AG5,1)))} -> 3.4
B27: y_n1: | C27: =IFERROR(C23+(C17-C18)*(C24-C23)/(C19-C18),C23) -> 5.4295 | O27: y_n1: | P27: =IFERROR(P23+(P17-P18)*(P24-P23)/(P19-P18),P23) -> 0 | AB27: y_n1: | AC27: =IFERROR(AC23+(AC17-AC18)*(AC24-AC23)/(AC19-AC18),AC23) -> 3.753
B28: y_n2: | C28: =IFERROR(C25+(C17-C18)*(C26-C25)/(C19-C18),C25) -> 5.1295 | O28: y_n2: | P28: =IFERROR(P25+(P17-P18)*(P26-P25)/(P19-P18),P25) -> 0 | AB28: y_n2: | AC28: =IFERROR(AC25+(AC17-AC18)*(AC26-AC25)/(AC19-AC18),AC25) -> 3.553
B29: Distance | C29: =IFERROR(C27+(C20-C21)*(C28-C27)/(C22-C21),C27) -> 5.4295 | O29: Distance | P29: =IFERROR(P27+(P20-P21)*(P28-P27)/(P22-P21),P27) -> 0 | AB29: Distance | AC29: =IFERROR(AC27+(AC20-AC21)*(AC28-AC27)/(AC22-AC21),AC27) -> 3.753
B31: Gradient | O31: Vikt | AB31: Vikt
A32: % | B32: 2 | C32: 3 | D32: 4 | E32: 5 | F32: 6 | G32: 7 | O32: % | P32: 1 | Q32: 2 | R32: 3 | S32: 4 | T32: 5 | AA32: % | AB32: 0.3 | AC32: 1.2 | AD32: 2.2 | AE32: 3.5 | AF32: 4.7 | AG32: 5
A33: 9000 | B33: 7.2 | C33: 8.6 | D33: 10 | E33: 10.2 | F33: 10.2 | G33: -99 | O33: 10000 | T33: 99999 | AA33: 9000 | AB33: 4.2 | AC33: 5.5 | AD33: 7 | AE33: 8.7 | AF33: 10 | AG33: -99
A34: 9500 | B34: 6.4 | C34: 7.8 | D34: 9 | E34: 10.2 | F34: 10.2 | G34: -99 | O34: 11000 | T34: 99999 | AA34: 9500 | AB34: 3.4 | AC34: 4.6 | AD34: 6.1 | AE34: 7.6 | AF34: 9 | AG34: -99
A35: 10000 | B35: 5.7 | C35: 6.9 | D35: 8.1 | E35: 9.4 | F35: 10.2 | G35: -99 | O35: 12000 | T35: 99999 | AA35: 10000 | AB35: 2.8 | AC35: 4 | AD35: 5.35 | AE35: 6.8 | AF35: 8.2 | AG35: -99
A36: 10500 | B36: 4.9 | C36: 6.1 | D36: 7.2 | E36: 8.4 | F36: 9.6 | G36: -99 | O36: 13000 | T36: 99999 | AA36: 10500 | AB36: 2.2 | AC36: 3.3 | AD36: 4.6 | AE36: 6 | AF36: 7.4 | AG36: -99
A37: 11000 | B37: 4.2 | C37: 5.3 | D37: 6.4 | E37: 7.5 | F37: 8.6 | G37: -99 | O37: 14000 | T37: 99999 | AA37: 11000 | AB37: 1.6 | AC37: 2.8 | AD37: 4 | AE37: 5.3 | AF37: 6.6 | AG37: -99
A38: 11500 | B38: 3.4 | C38: 4.5 | D38: 5.6 | E38: 6.6 | F38: 7.7 | G38: -99 | O38: 15000 | T38: 99999 | AA38: 11500 | AB38: 1.2 | AC38: 2.2 | AD38: 3.4 | AE38: 4.6 | AF38: 6 | AG38: -99
A39: 12000 | B39: 2.8 | C39: 3.75 | D39: 4.8 | E39: 5.8 | F39: 6.8 | G39: -99 | O39: 16000 | T39: 99999 | AA39: 12000 | AB39: 0.7 | AC39: 1.7 | AD39: 2.8 | AE39: 4 | AF39: 5.3 | AG39: -99
A40: 12500 | B40: 2 | C40: 3 | D40: 4 | E40: 5 | F40: 6 | G40: -99 | O40: 16600 | T40: 99999 | AA40: 12500 | AB40: 0.3 | AC40: 1.2 | AD40: 2.2 | AE40: 3.5 | AF40: 4.7 | AG40: -99
A41: 12600 | B41: -99 | C41: -99 | D41: -99 | E41: -99 | F41: -99 | G41: -99 | O41: 16700 | P41: 99999 | Q41: 99999 | R41: 99999 | S41: 99999 | T41: 99999 | AA41: 12600 | AB41: -99 | AC41: -99 | AD41: -99 | AE41: -99 | AF41: -99 | AG41: -99
B43: x_n: | C43: =C29 -> 5.4295 | D43: Table size | O43: x_n: | P43: =P29 -> 0 | Q43: Table size | AB43: x_n: | AC43: =AC29 -> 3.753 | AD43: Table size
...

Sheet LTL_Takeoff distance (2)
B1: Pressure Alt | C1: x_n: | D1: =IF('Take-off'!$C$9="",'Take-off'!$C$16,MAX(0,'Take-off'!$C$16+30*(1013-'Take-off'!$C$9))) -> 200
B2: Temp in calc | C2: y_n: | D2: =IF('Take-off'!$C$13='Dropdown lists'!$B$30, 'Take-off'!$C$8+10, 'Take-off'!$C$8) -> 0 | E2: Includes ICE-Vane. Could be disregarded for us
B3: TAKE OFF DISTANCE - FLAPS UP | O3: TAKE OFF DISTANCE - FLAPS TAKEOFF | AB3: TAKE OFF DISTANCE - FLAPS APPROACH
B4: Density altitude | O4: Density altitude | AB4: Density altitude
A5: Temp/PA | B5: -500 | C5: 0 | D5: 1000 | E5: 2000 | F5: 3000 | G5: 4000 | N5: Temp/PA | O5: 0 | P5: 1000 | Q5: 2000 | R5: 3000 | S5: 4000 | AA5: Temp/PA | AB5: -500 | AC5: 0 | AD5: 1000 | AE5: 2000 | AF5: 3000 | AG5: 4000
A6: -40 | B6: 1400 | C6: 1400 | D6: 1490 | E6: 1550 | F6: 1600 | G6: 99999 | N6: -30 | S6: 99999 | AA6: -40 | AB6: 1550 | AC6: 1550 | AD6: =AVERAGE(AB6,AE6) -> 1625 | AE6: 1700 | AF6: 1800 | AG6: 99999
A7: -30 | B7: 1400 | C7: 1400 | D7: 1490 | E7: 1550 | F7: 1600 | G7: 99999 | AA7: -30 | AB7: 1550 | AC7: 1550 | AD7: 1625 | AE7: 1700 | AF7: 1800 | AG7: 99999
A8: -20 | B8: 1450 | C8: 1450 | D8: 1550 | E8: 1600 | F8: 1700 | G8: 99999 | N8: -20 | S8: 99999 | AA8: -20 | AB8: 1550 | AC8: 1550 | AD8: =AVERAGE(AB8,AE8) -> 1625 | AE8: 1700 | AF8: 1800 | AG8: 99999
A9: -10 | B9: 1550 | C9: 1550 | D9: 1600 | E9: 1700 | F9: 1800 | G9: 99999 | N9: -10 | S9: 99999 | AA9: -10 | AB9: 1600 | AC9: 1600 | AD9: =AVERAGE(AB9,AE9) -> 1700 | AE9: 1800 | AF9: 1900 | AG9: 99999
A10: 0 | B10: 1610 | C10: 1610 | D10: 1700 | E10: 1800 | F10: 1900 | G10: 99999 | N10: 0 | S10: 99999 | AA10: 0 | AB10: 1700 | AC10: 1700 | AD10: =AVERAGE(AB10,AE10) -> 1795 | AE10: 1890 | AF10: 2000 | AG10: 99999
A11: 10 | B11: 1700 | C11: 1700 | D11: 1800 | E11: 1900 | F11: 2015 | G11: 99999 | N11: 10 | S11: 99999 | AA11: 10 | AB11: 1800 | AC11: 1800 | AD11: =AVERAGE(AB11,AE11) -> 1900 | AE11: 2000 | AF11: 2110 | AG11: 99999
A12: 20 | B12: 1780 | C12: 1780 | D12: 1900 | E12: 2000 | F12: 2150 | G12: 99999 | N12: 20 | S12: 99999 | AA12: 20 | AB12: 1900 | AC12: 1900 | AD12: =AVERAGE(AB12,AE12) -> 2025 | AE12: 2150 | AF12: 2300 | AG12: 99999
A13: 30 | B13: 1880 | C13: 1880 | D13: 2000 | E13: 2130 | F13: 2320 | G13: 99999 | AA13: 30 | AB13: 2050 | AC13: 2050 | AD13: =AVERAGE(AB13,AE13) -> 2185 | AE13: 2320 | AF13: 2500 | AG13: 99999
